Workbook

Sheet BOQ
A1: Bill of Quantities for Proposed Single Storey House Construction
A3: Item No. | B3: Description | C3: Unit | D3: Quantity | E3: Rate | F3: Amount
A4: 1 | B4: Preliminaries
A5: 1.1 | B5: Site clearance: Removal of vegetation, undergrowth, bushes, hedges, trees, or similar obstructions, including grubbing roots and disposing of debris off-site to create a level, workable area. | C5: m² | D5: ='Site Preparation'!H5 -> 216.32062 | F5: =IF(C5="","",D5*E5) -> 0
A6: A | B6: Subtotal for Preliminaries and Site Preparation | F6: =SUM(F5) -> 0
F7: =IF(C7="","",D7*E7)
A8: 2 | B8: Excavation and Earthworks | F8: =IF(C8="","",D8*E8)
A9: 2.1 | B9: Trench excavation for foundations: Excavation of trenches to the required depth (1.15 m) for foundation walls, including removal of spoil, shoring if needed, and keeping excavations free of water. | C9: m³ | D9: =Excavation!H6 -> 49.335 | F9: =IF(C9="","",D9*E9) -> 0
A10: B | B10: Subtotal for Excavation and Earthworks | F10: =SUM(F9) -> 0
F11: =IF(C11="","",D11*E11)
A12: 3 | B12: Substructure | F12: =IF(C12="","",D12*E12)
A13: 3.1 | B13: Ground improvement under foundations: Filling and compacting with approved ABC (Aggregate Base Course) or quarry dust in layers to provide a stable base and prevent settlement | C13: m³ | D13: =Substructure!H5 -> 25.74 | F13: =IF(C13="","",D13*E13) -> 0
A14: 3.2 | B14: Plain cement concrete (PCC) as leveling screed: A thin layer (minimum 100 mm thick) of unreinforced concrete under foundation walls to create a clean, level surface for subsequent works | C14: m² | D14: =Substructure!H8 -> 31.44 | F14: =IF(C14="","",D14*E14) -> 0
A15: 3.3 | B15: Reinforced cement concrete (RCC) for column footings: Poured concrete (assumed grade 25 or equivalent) with reinforcement for isolated column bases to distribute loads to the soil | C15: m³ | D15: =Substructure!H10 -> 0.396 | F15: =IF(C15="","",D15*E15) -> 0
A16: 3.4 | B16: Reinforced cement concrete (RCC) for column shafts: Poured concrete for vertical column sections from footings to tie beam level. | C16: m³ | D16: =Substructure!H12 -> 0.606375 | F16: =IF(C16="","",D16*E16) -> 0
A17: 3.5 | B17: Formwork for column footings: Temporary timber or steel molds to shape and support concrete during pouring, including propping, striking, and cleaning. | C17: m² | D17: =Substructure!H15 -> 2.64 | F17: =IF(C17="","",D17*E17) -> 0
A18: 3.6 | B18: Formwork for column shafts: Similar temporary molds for column shafts. | C18: m² | D18: =Substructure!H17 -> 6.93 | F18: =IF(C18="","",D18*E18) -> 0
A19: 3.7 | B19: Random rubble masonry (RRM) works: Masonry using irregular stones bonded with mortar for foundation walls below ground level, providing structural support. | C19: m³ | D19: =Substructure!H20 -> 8.568 | F19: =IF(C19="","",D19*E19) -> 0
A20: 3.8 | B20: Steel reinforcement bars for column footings: High-yield deformed bars (T12) bent, fixed, and lapped as per drawings to reinforce concrete against tension. | C20: kg | D20: ='Bar Schedule'!R10 -> 19.231 | F20: =IF(C20="","",D20*E20) -> 0
A21: 3.9 | B21: Steel reinforcement bars for column shafts: High-yield deformed bars (T10) for substructure shafts. | C21: kg | D21: ='Bar Schedule'!R11 -> 8.099 | F21: =IF(C21="","",D21*E21) -> 0
A22: C | B22: Subtotal for Substructure | F22: =SUM(F13:F21) -> 0
F23: =IF(C23="","",D23*E23)
A24: 4 | B24: Superstructure | F24: =IF(C24="","",D24*E24)
A25: 4.1 | B25: Reinforced cement concrete (RCC) for column shafts: Poured concrete for vertical columns from tie beam to roof level, categorized by height variations (C1 to C6). | C25: m³ | D25: =Superstructure!H13 -> 5.2185 | F25: =IF(C25="","",D25*E25) -> 0
A26: 4.2 | B26: Reinforced cement concrete (RCC) for tie beams: Horizontal beams connecting columns at ground level for stability. | C26: m³ | D26: =Superstructure!H15 -> 2.856 | F26: =IF(C26="","",D26*E26) -> 0
A27: 4.3 | B27: Reinforced cement concrete (RCC) for ground floor slab: Suspended or ground-bearing slab (100 mm thick) to form the floor base. | C27: m³ | D27: =Superstructure!H17 -> 6.4 | F27: =IF(C27="","",D27*E27) -> 0
A28: 4.4 | B28: Random rubble masonry (RRM) works: Stone masonry for lower wall sections or plinth. | C28: m³ | D28: =Superstructure!H20 -> 5.712 | F28: =IF(C28="","",D28*E28) -> 0
A29: 4.5 | B29: External wall blockwork: Hollow or solid concrete blocks (assumed 200 mm thick) in cement mortar for outer walls, with deductions for openings (windows, doors, etc.). | C29: m² | D29: =Superstructure!H37 -> 128.68935 | F29: =IF(C29="","",D29*E29) -> 0
A30: 4.6 | B30: Internal wall blockwork: Similar block masonry for partitions inside the building, with deductions for doors | C30: m² | D30: =Superstructure!H42 -> 49.793398 | F30: =IF(C30="","",D30*E30) -> 0
A31: 4.7 | B31: Steel reinforcement bars for column shafts: High-yield deformed bars (T12) for superstructure columns (C1 to C6). | C31: kg | D31: =SUM('Bar Schedule'!R13:R18) -> 149.361 | F31: =IF(C31="","",D31*E31) -> 0
A32: 4.8 | B32: Steel reinforcement bars for tie beams: High-yield deformed bars (T12) for beams | C32: kg | D32: ='Bar Schedule'!R19 -> 101.587 | F32: =IF(C32="","",D32*E32) -> 0
A33: 4.9 | B33: Mild steel Reinforcements for stirrups (T6) for beams and Columns | C33: kg | D33: ='Bar Schedule'!R20 -> 29.681 | F33: =IF(C33="","",D33*E33) -> 0
A34: D | B34: Subtotal for Superstructure | F34: =SUM(F25:F33) -> 0
F35: =IF(C35="","",D35*E35)
A36: 5 | B36: Roof | F36: =IF(C36="","",D36*E36)
A37: 5.1 | B37: Roof covering: Sheet roofing (e.g., corrugated zinc or tiles) laid over purlins, including fixings and overlaps for weatherproofing. | C37: m² | D37: =Roof!H5 -> 11.5 | F37: =IF(C37="","",D37*E37) -> 0
A38: 5.2 | B38: Rafters: Timber or steel members (c/c spacing 900 mm) sloping to support purlins and roof load. | C38: m | D38: =Roof!H7 -> 130 | F38: =IF(C38="","",D38*E38) -> 0
A39: 5.3 | B39: Purlins: Horizontal members (c/c spacing 1200 mm) fixed to rafters to support roof covering. | C39: m | D39: =Roof!H9 -> 100 | F39: =IF(C39="","",D39*E39) -> 0
A40: 5.4 | B40: Wall plate (50x50 mm): Timber plate fixed to wall tops to anchor rafters. | C40: m | D40: =Roof!H11 -> 13 | F40: =IF(C40="","",D40*E40) -> 0
A41: 5.5 | B41: Gutters: Supply and installation of PVC or galvanized steel gutters (150 mm wide, rectangular profile) fixed to roof eaves with brackets, including joints, end caps, and fittings to collect and channel rainwater from the roof to downpipes, including Facia Board | C41: m | D41: =Roof!H13 -> 11 | F41: =IF(C41="","",D41*E41) -> 0
...

Sheet Site Preparation
A3: Item No | B3: Description | C3: Unit | D3: Times (nr) | E3: Length (m) | F3: Breadth (m) | G3: Height (m) | H3: Quantity | I3: Remarks | M3: ft | N3: m
B4: Site preparation | M4: 1 | N4: 0.3048
A5: 1 | B5: Site clearance, including removing vegetation, undergrowth, bushes, hedges, trees or the like | C5: Sq.m | E5: =(36.75+0.74)*0.3048+(3*2) -> 17.426952 | F5: =(11.5+2.66+4.66+(0.74*3))*0.3048+(3*2) -> 12.412992 | H5: =PRODUCT(D5:G5) -> 216.32062
M6: =225/1000/N4 -> 0.73818898
M10: inch
M11: 1 | N11: =N4/12 -> 0.0254
M17: 171.166
M18: =M17*N4 -> 52.171397

Sheet Excavation
A3: Item No | B3: Description | C3: Unit | D3: Times (nr) | E3: Length (m) | F3: Breadth (m) | G3: Height (m) | H3: Quantity | I3: Remarks
B5: Excavation | M5: =171.166*0.3048 -> 52.171397
B6: Trench Excavation for Foundation | C6: m3 | E6: 57.2 | F6: =750/1000 -> 0.75 | G6: =(450+100+600)/1000 -> 1.15 | H6: =PRODUCT(D6:G6) -> 49.335

Sheet Substructure
A3: Item No | B3: Description | C3: Unit | D3: Times (nr) | E3: Length (m) | F3: Breadth (m) | G3: Height (m) | H3: Quantity | I3: Remarks
B4: Ground Improvement
A5: 1 | B5: Ground Improvement under foundation, fills with well compacted ABC/ Quarry Dust, | C5: m3 | E5: =Excavation!E6 -> 57.2 | F5: =750/1000 -> 0.75 | G5: =600/1000 -> 0.6 | H5: =PRODUCT(D5:G5) -> 25.74
B7: Concrete Works
A8: 2 | B8: Plain Cement Concrete (PCC) as a levelling screed under foundation walls. Minimum thickness: 100 mm | C8: m2 | E8: =E5-(0.6*8) -> 52.4 | F8: =600/1000 -> 0.6 | H8: =PRODUCT(D8:G8) -> 31.44
A10: 3 | B10: RCC Concrete for Column Footings | C10: m3 | D10: 11 | E10: =600/1000 -> 0.6 | F10: =600/1000 -> 0.6 | G10: =100/1000 -> 0.1 | H10: =PRODUCT(D10:G10) -> 0.396
A12: 4 | B12: RCC Concrete for Column Shaft | C12: m3 | D12: 11 | E12: =350/1000 -> 0.35 | F12: =350/1000 -> 0.35 | G12: =450/1000 -> 0.45 | H12: =PRODUCT(D12:G12) -> 0.606375
B14: Formwork
A15: 5 | B15: Formwork for Column Footings | C15: m2 | D15: =11*4 -> 44 | E15: =600/1000 -> 0.6 | G15: =100/1000 -> 0.1 | H15: =PRODUCT(D15:G15) -> 2.64
A17: 6 | B17: Formwork for Column Shaft | C17: m2 | D17: =11*4 -> 44 | E17: =350/1000 -> 0.35 | G17: =450/1000 -> 0.45 | H17: =PRODUCT(D17:G17) -> 6.93
B19: Masonry Works
A20: 7 | B20: RRM works | C20: m3 | E20: =Excavation!E6-(0.35*8) -> 54.4 | F20: =350/1000 -> 0.35 | G20: =450/1000 -> 0.45 | H20: =PRODUCT(D20:G20) -> 8.568
B22: Reinforcement
B23: steel R/F bars in the column footings | C23: Mt

Sheet Superstructure
A3: Item No | B3: Description | C3: Unit | D3: Times (nr) | E3: Length (m) | F3: Breadth (m) | G3: Height (m) | H3: Quantity | I3: Remarks
B5: Concrete Works
A6: 1 | B6: RCC Concrete for Column Shaft
B7: C1 | C7: m3 | D7: 2 | E7: =350/1000 -> 0.35 | F7: =350/1000 -> 0.35 | G7: 4.8 | H7: =PRODUCT(D7:G7) -> 1.176
B8: C2 | C8: m3 | D8: 2 | E8: =350/1000 -> 0.35 | F8: =350/1000 -> 0.35 | G8: 4.6 | H8: =PRODUCT(D8:G8) -> 1.127
B9: C3 | C9: m3 | D9: 2 | E9: =350/1000 -> 0.35 | F9: =350/1000 -> 0.35 | G9: 4.1 | H9: =PRODUCT(D9:G9) -> 1.0045
B10: C4 | C10: m3 | D10: 2 | E10: =350/1000 -> 0.35 | F10: =350/1000 -> 0.35 | G10: 3.05 | H10: =PRODUCT(D10:G10) -> 0.74725
B11: C5 | C11: m3 | D11: 1 | E11: =350/1000 -> 0.35 | F11: =350/1000 -> 0.35 | G11: 3.4 | H11: =PRODUCT(D11:G11) -> 0.4165
B12: C6 | C12: m3 | D12: 2 | E12: =350/1000 -> 0.35 | F12: =350/1000 -> 0.35 | G12: 3.05 | H12: =PRODUCT(D12:G12) -> 0.74725
H13: =SUM(H7:H12) -> 5.2185
A15: 2 | B15: RCC Concrete for Tie Beams | C15: m3 | E15: =Excavation!E6-(0.35*8) -> 54.4 | F15: =350/1000 -> 0.35 | G15: =150/1000 -> 0.15 | H15: =PRODUCT(D15:G15) -> 2.856
B17: Ground Floor Slab | C17: m3 | E17: 64 | G17: 0.1 | H17: =PRODUCT(D17:G17) -> 6.4
B19: Masonry Works
A20: 4 | B20: RRM works | C20: m3 | E20: =E15 -> 54.4 | F20: =350/1000 -> 0.35 | G20: =300/1000 -> 0.3 | H20: =PRODUCT(D20:G20) -> 5.712
A22: 5 | B22: External Wall - Block work
B23: LHS Blind wall | C23: m2 | E23: 45.1 | H23: =PRODUCT(D23:G23) -> 45.1
B24: RHS wall | C24: m2 | E24: 37.7 | H24: =PRODUCT(D24:G24) -> 37.7
B25: Ddt: W2 | C25: m2 | D25: -1 | E25: =1.828*1.6764 -> 3.0644592 | H25: =PRODUCT(D25:G25) -> -3.0644592
B26: Ddt: W3 | C26: m2 | D26: -1 | E26: =1.2192*1.524 -> 1.8580608 | H26: =PRODUCT(D26:G26) -> -1.8580608
B27: Rear wall | C27: m2 | E27: 6.37 | G27: 3.05 | H27: =PRODUCT(D27:G27) -> 19.4285
B28: Ddt: W1 | C28: m2 | D28: -1 | E28: =1.828*1.6764 -> 3.0644592 | H28: =PRODUCT(D28:G28) -> -3.0644592
B29: Ddt: FL | C29: m2 | D29: -1 | E29: =0.9144*0.6096 -> 0.55741824 | H29: =PRODUCT(D29:G29) -> -0.55741824
B30: Ddt: D3 | C30: m2 | D30: -1 | E30: =0.9144*2.1336 -> 1.9509638 | H30: =PRODUCT(D30:G30) -> -1.9509638
B31: Front wall | C31: m2 | E31: 2.75 | G31: 4.8 | H31: =PRODUCT(D31:G31) -> 13.2
B32: Ddt: FW | C32: m2 | D32: -1 | E32: =1.8288*2.5908 -> 4.738055 | H32: =PRODUCT(D32:G32) -> -4.738055
B33: Wall at Entrance | C33: m2 | E33: 3.29 | G33: 4.8 | H33: =PRODUCT(D33:G33) -> 15.792
B34: Ddt: D1 | C34: m2 | D34: -1 | E34: =1.2192*1.6764 -> 2.0438669 | H34: =PRODUCT(D34:G34) -> -2.0438669
B35: Wall at Entrance (Bedroom) | C35: m2 | E35: 3.65 | G35: 4.6 | H35: =PRODUCT(D35:G35) -> 16.79
B36: Ddt: W2 | C36: m2 | D36: -1 | E36: =1.2192*1.6764 -> 2.0438669 | H36: =PRODUCT(D36:G36) -> -2.0438669
H37: =SUM(H23:H36) -> 128.68935
A39: 6 | B39: Internal Wall - Block work | C39: m2 | E39: 18.1 | G39: 3.05 | H39: =PRODUCT(D39:G39) -> 55.205
B40: Ddt: D3 | C40: m2 | D40: -2 | E40: =0.9144*2.1336 -> 1.9509638 | H40: =PRODUCT(D40:G40) -> -3.9019277
B41: Ddt: D4 | C41: m2 | D41: -1 | E41: =0.762*1.9812 -> 1.5096744 | H41: =PRODUCT(D41:G41) -> -1.5096744
H42: =SUM(H39:H41) -> 49.793398

Sheet Roof
A3: Item No | B3: Description | C3: Unit | D3: Times (nr) | E3: Length (m) | F3: Breadth (m) | G3: Height (m) | H3: Quantity | I3: Remarks
A5: 1 | B5: Roof cover | C5: m2 | E5: 11.5 | H5: =PRODUCT(D5:G5) -> 11.5
A7: 2 | B7: Rafters (c/c gap- 900mm) | C7: m | E7: 130 | H7: =PRODUCT(D7:G7) -> 130
A9: 3 | B9: Purlins (c/c gap- 1200mm) | C9: m | E9: 100 | H9: =PRODUCT(D9:G9) -> 100
A11: 4 | B11: Wall plate (50x50 mm) | C11: m | E11: 13 | H11: =PRODUCT(D11:G11) -> 13
A13: 5 | B13: Roof Gutters | C13: m | E13: 11 | H13: =PRODUCT(D13:G13) -> 11
A15: 6 | B15: Down Pipes | C15: m | E15: =3*2 -> 6 | H15: =PRODUCT(D15:G15) -> 6

Sheet Plumbing
A3: Item No | B3: Description | C3: Times (nr) | D3: Length (m) | E3: Breadth (m) | F3: Height (m) | G3: Quantity | H3: Remarks
A5: 1 | B5: 20mm Inlet Pipe (Slon Brand) | D5: =3+3.16+3.6+1 -> 10.76 | G5: =PRODUCT(C5:F5) -> 10.76
A7: 2 | B7: Water Meter | C7: 1 | G7: =PRODUCT(C7:F7) -> 1
A9: 3 | B9: 50mm Outlet Pipe (Slon Brand) | D9: 3 | G9: =PRODUCT(C9:F9) -> 3
A11: 4 | B11: 25mm Distribution Pipes (Slon Brand) | D11: =25 -> 25 | G11: =PRODUCT(C11:F11) -> 25
A12: 5 | B12: Pipe Fittings (Slon Brand, Assorted Sizes)
A15: 6 | B15: Valves and Controls
B16: Gate Valve | C16: 3 | G16: =PRODUCT(C16:F16) -> 3
B17: Ball Valve | C17: 1 | G17: =PRODUCT(C17:F17) -> 1
B18: Non Return Valve | C18: 1 | G18: =PRODUCT(C18:F18) -> 1
A20: 7 | B20: Kitchen Ware Plumbing
A22: 8 | B22: Bathroom Plumbing

Sheet Electrical
A3: Item No | B3: Description | C3: Times (nr) | D3: Length (m) | E3: Breadth (m) | F3: Height (m) | G3: Quantity | H3: Remarks
B5: Electrical Circuits
B6: Bedrooms
B7: Two recessed (canless) light fittings with one ceiling fan, controlled by 01 nrf one way two gang switches and 01 nrf one way one gang switch | C7: 2 | G7: =C7 -> 2 | H7: =1*2 -> 2
B8: Two 13A Socket Outlets and 15A Socket Outlet | C8: 2 | G8: 2 | H8: =1*2 -> 2
B10: Living Area
B11: Six recessed (Canless) light fittings with two ceiling fans. controlled by 03 nrf one way two gang switches and 02 nrf one way one gang switch | C11: 1 | G11: =C11 -> 1
B12: Two recessed (canless) light fittings with one ceiling fan, controlled by 01 nrf one way two gang switches. | C12: 1 | G12: =C12 -> 1 | H12: Dining Area
B13: Two wall light fittings controlled by two gang switch | C13: 1 | G13: =C13 -> 1
B14: Four 13A Socket Outlets | C14: 1 | G14: =C14 -> 1
B15: 01 recessed (canless) light fitting controlled by one gang switch | C15: 1 | G15: =C15 -> 1
B17: External Lightings
B18: Three External wall hanging lights controlled with two gang switch and one gang switch | C18: 1 | G18: =C18 -> 1
B20: Kitchen Wiring | C20: 1 | G20: =C20 -> 1
B22: Bathroom
B23: One recessed (canless) light fittings, one mirror light fitting with two gang switch | C23: 1 | G23: =C23 -> 1
B24: 1 nrf 13A Socket Outlet and 1 nrf 15A Socket Outlet | C24: 1 | G24: =C24 -> 1
B26: DB Termination | C26: 1 | G26: =C26 -> 1

Sheet Doors and Windows
A3: Item No | B3: Description | C3: Unit | D3: Times (nr) | E3: Length (m) | F3: Breadth (m) | G3: Height (m) | H3: Quantity | I3: Remarks
B5: Doors and Windows
B7: Doors
B8: D1 - 4'0" x 6'5" sized Decorated Timber Panel Door with Louvers | C8: nr | D8: 1 | H8: =D8 -> 1
B9: D2 - 4'0" x 6'5" Glazed Door with Louvers | C9: nr
B10: D3 - 3'0" x 7'0" Panelled Door | C10: nr | D10: 3 | H10: =D10 -> 3
B11: D4 - 2'6" x 6'6" P.V.C. Door | C11: nr | D11: 1 | H11: =D11 -> 1
B12: Windows
B13: W1 - 6'0" x 5'6" Timber Framed Glazed Window with Louvers | C13: nr | D13: 1 | H13: =D13 -> 1
B14: W2 - 6'0" x 5'6" Timber Framed Glazed Window with Louvers | C14: nr | D14: 1 | H14: =D14 -> 1
B15: W3 - 6'0" x 5'6" Timber Framed Glazed Window with Louvers | C15: nr | D15: 1 | H15: =D15 -> 1
B16: W4 - 6'0" x 5'6" Timber Framed Glazed Window with Louvers | C16: nr | D16: 1 | H16: =D16 -> 1
B17: FL - 2'0" x 3'0" Timber Framed Glazed Fanlight | C17: nr | D17: 1 | H17: =D17 -> 1
B18: FW - 6'0" x 5'6" French Window with Louvers | C18: nr | D18: 1 | H18: =D18 -> 1

Sheet Finishes
A3: Item No | B3: Description | C3: Unit | D3: Times (nr) | E3: Length (m) | F3: Breadth (m) | G3: Height (m) | H3: Quantity | I3: Remarks
A5: 1 | B5: External wall plastering | C5: m2 | E5: 128.68935 | H5: =PRODUCT(D5:G5) -> 128.68935
A7: 2 | B7: External reveal plastering | C7: m | H7: =PRODUCT(D7:G7) -> 0
A9: 3 | B9: Internal wall plastering | C9: m2 | D9: 2 | E9: 49.793398 | H9: =PRODUCT(D9:G9) -> 99.586796
A11: 4 | B11: Internal reveal plastering | C11: m | H11: =PRODUCT(D11:G11) -> 0
A13: 5 | B13: 2 x 2 floor tiles | C13: m2 | E13: 60.08 | H13: =PRODUCT(D13:G13) -> 60.08
A15: 6 | B15: 2 x 2 bathroom floor tiles | C15: m2 | E15: 3.92 | H15: =PRODUCT(D15:G15) -> 3.92
A17: 7 | B17: 2 x 2 bathroom wall tiles | C17: m2 | E17: 7.738 | G17: 1.8 | H17: =PRODUCT(D17:G17) -> 13.9284
A19: 7 | B19: Internal wall painting | C19: m2 | D19: =D9 -> 2 | E19: =E9 -> 49.793398 | H19: =PRODUCT(D19:G19) -> 99.586796
A21: 8 | B21: External wall painting | C21: m2 | D21: 1 | E21: =E5 -> 128.68935 | H21: =PRODUCT(D21:G21) -> 128.68935

Sheet Bar Schedule
B1: BAR SCHEDULE
B2: NAME OF PROJECT :AUGEMENTATION OF GIRANDURUKOTTE TREATMENT PLANT, MECHANICAL AND ELECTRICAL WORKS
B5: TITLE : | E5: REINFORCEMENT | S5: SHEET NO : | W5: 1 | AB5: T10 | AC5: 0.617
B6: DWG.No. : | E6: House Plan | S6: DATE : | W6: 28.08.2025 | AB6: T12 | AC6: 0.888
B7: Member | D7: Bar Mark | E7: Type & Size | F7: No. of Members | G7: No of Each | H7: Total Number | I7: TOTAL LENGTH (mm) | O7: Length of Each Bar (m) | P7: Total Length (m) | Q7: Unit Weight | R7: Weight (Kg) | S7: Remarks | AB7: T16 | AC7: 1.579
I8: a | J8: b | K8: c | L8: d | M8: e | N8: f | AB8: T20 | AC8: 2.467
B9: Substructure
B10: Column Footing | D10: 1 | E10: T12 | F10: 8 | G10: 4 | H10: =F10*G10 -> 32 | I10: =SQRT(POWER(((600-350)/2),2)*2)-50+50 -> 176.7767 | J10: =450+50 -> 500 | O10: =(I10+J10+K10+L10+M10+N10)/1000 -> 0.6767767 | P10: =O10*H10 -> 21.656854 | Q10: =IF(E10="T10",0.617,IF(E10="T12",0.888,IF(E10="T16",1.579,IF(E10="T20",2.467,IF(E10="T25",3.854,IF(E10="T32",6.315)))))) -> 0.888 | R10: =ROUND(P10*Q10,3) -> 19.231 | AB10: T25 | AC10: 3.854
B11: Column Shaft | D11: 2 | E11: T6 | F11: 8 | G11: =ROUND(((450-50)/150+1),0) -> 4 | H11: =F11*G11 -> 32 | I11: =(350-40*2-10)*4 -> 1040 | J11: =10*10 -> 100 | O11: =(I11+J11+K11+L11+M11+N11)/1000 -> 1.14 | P11: =O11*H11 -> 36.48 | Q11: 0.222 | R11: =ROUND(P11*Q11,3) -> 8.099 | AB11: T32 | AC11: 6.314
B12: Superstructure
B13: Column Shaft | D13: C1 | E13: T12 | F13: 2 | G13: =ROUND(((450-50)/150+1),0) -> 4 | H13: =F13*G13 -> 8 | I13: =4800-50 -> 4750 | O13: =(I13+J13+K13+L13+M13+N13)/1000 -> 4.75 | P13: =O13*H13 -> 38 | Q13: =IF(E13="T10",0.617,IF(E13="T12",0.888,IF(E13="T16",1.579,IF(E13="T20",2.467,IF(E13="T25",3.854,IF(E13="T32",6.315)))))) -> 0.888 | R13: =ROUND(P13*Q13,3) -> 33.744
D14: C2 | E14: T12 | F14: 2 | G14: 4 | H14: =F14*G14 -> 8 | I14: =4600-50 -> 4550 | O14: =(I14+J14+K14+L14+M14+N14)/1000 -> 4.55 | P14: =O14*H14 -> 36.4 | Q14: =IF(E14="T10",0.617,IF(E14="T12",0.888,IF(E14="T16",1.579,IF(E14="T20",2.467,IF(E14="T25",3.854,IF(E14="T32",6.315)))))) -> 0.888 | R14: =ROUND(P14*Q14,3) -> 32.323
D15: C3 | E15: T12 | F15: 2 | G15: 4 | H15: =F15*G15 -> 8 | I15: =4100-50 -> 4050 | O15: =(I15+J15+K15+L15+M15+N15)/1000 -> 4.05 | P15: =O15*H15 -> 32.4 | Q15: =IF(E15="T10",0.617,IF(E15="T12",0.888,IF(E15="T16",1.579,IF(E15="T20",2.467,IF(E15="T25",3.854,IF(E15="T32",6.315)))))) -> 0.888 | R15: =ROUND(P15*Q15,3) -> 28.771
D16: C4 | E16: T12 | F16: 2 | G16: 4 | H16: =F16*G16 -> 8 | I16: =3050-50 -> 3000 | O16: =(I16+J16+K16+L16+M16+N16)/1000 -> 3 | P16: =O16*H16 -> 24 | Q16: =IF(E16="T10",0.617,IF(E16="T12",0.888,IF(E16="T16",1.579,IF(E16="T20",2.467,IF(E16="T25",3.854,IF(E16="T32",6.315)))))) -> 0.888 | R16: =ROUND(P16*Q16,3) -> 21.312
D17: C5 | E17: T12 | F17: 1 | G17: 4 | H17: =F17*G17 -> 4 | I17: =3400-50 -> 3350 | O17: =(I17+J17+K17+L17+M17+N17)/1000 -> 3.35 | P17: =O17*H17 -> 13.4 | Q17: =IF(E17="T10",0.617,IF(E17="T12",0.888,IF(E17="T16",1.579,IF(E17="T20",2.467,IF(E17="T25",3.854,IF(E17="T32",6.315)))))) -> 0.888 | R17: =ROUND(P17*Q17,3) -> 11.899
D18: C6 | E18: T12 | F18: 2 | G18: 4 | H18: =F18*G18 -> 8 | I18: =3050-50 -> 3000 | O18: =(I18+J18+K18+L18+M18+N18)/1000 -> 3 | P18: =O18*H18 -> 24 | Q18: =IF(E18="T10",0.617,IF(E18="T12",0.888,IF(E18="T16",1.579,IF(E18="T20",2.467,IF(E18="T25",3.854,IF(E18="T32",6.315)))))) -> 0.888 | R18: =ROUND(P18*Q18,3) -> 21.312
B19: Tie Beam | D19: 4 | E19: T12 | F19: 1 | G19: 2 | H19: =F19*G19 -> 2 | I19: =Excavation!E6*1000 -> 57200 | O19: =(I19+J19+K19+L19+M19+N19)/1000 -> 57.2 | P19: =O19*H19 -> 114.4 | Q19: =IF(E19="T10",0.617,IF(E19="T12",0.888,IF(E19="T16",1.579,IF(E19="T20",2.467,IF(E19="T25",3.854,IF(E19="T32",6.315)))))) -> 0.888 | R19: =ROUND(P19*Q19,3) -> 101.587 | AG19: 125
B20: Tie Beam | E20: T6 | F20: 1 | G20: =ROUND(((57200)/150+1),0) -> 382 | H20: =F20*G20 -> 382 | I20: 350 | O20: =(I20+J20+K20+L20+M20+N20)/1000 -> 0.35 | P20: =O20*H20 -> 133.7 | Q20: 0.222 | R20: =ROUND(P20*Q20,3) -> 29.681 | AB20: T32 | AC20: 6.314
H21: =F21*G21 -> 0 | O21: =(I21+J21+K21+L21+M21+N21)/1000 -> 0 | P21: =O21*H21 -> 0 | Q21: =IF(E21="T10",0.617,IF(E21="T12",0.888,IF(E21="T16",1.579,IF(E21="T20",2.467,IF(E21="T25",3.854,IF(E21="T32",6.315)))))) -> FALSE | R21: =ROUND(P21*Q21,3) -> 0 | AG21: =AG20-50+50 -> 0
H22: =F22*G22 -> 0 | O22: =(I22+J22+K22+L22+M22+N22)/1000 -> 0 | P22: =O22*H22 -> 0 | Q22: =IF(E22="T10",0.617,IF(E22="T12",0.888,IF(E22="T16",1.579,IF(E22="T20",2.467,IF(E22="T25",3.854,IF(E22="T32",6.315)))))) -> FALSE | R22: =ROUND(P22*Q22,3) -> 0
H23: =F23*G23 -> 0 | O23: =(I23+J23+K23+L23+M23+N23)/1000 -> 0 | P23: =O23*H23 -> 0 | Q23: =IF(E23="T10",0.617,IF(E23="T12",0.888,IF(E23="T16",1.579,IF(E23="T20",2.467,IF(E23="T25",3.854,IF(E23="T32",6.315)))))) -> FALSE | R23: =ROUND(P23*Q23,3) -> 0
H24: =F24*G24 -> 0 | O24: =(I24+J24+K24+L24+M24+N24)/1000 -> 0 | P24: =O24*H24 -> 0 | Q24: =IF(E24="T10",0.617,IF(E24="T12",0.888,IF(E24="T16",1.579,IF(E24="T20",2.467,IF(E24="T25",3.854,IF(E24="T32",6.315)))))) -> FALSE | R24: =ROUND(P24*Q24,3) -> 0 | Z24: =6000-4280 -> 1720
H25: =F25*G25 -> 0 | O25: =(I25+J25+K25+L25+M25+N25)/1000 -> 0 | P25: =O25*H25 -> 0 | Q25: =IF(E25="T10",0.617,IF(E25="T12",0.888,IF(E25="T16",1.579,IF(E25="T20",2.467,IF(E25="T25",3.854,IF(E25="T32",6.315)))))) -> FALSE | R25: =ROUND(P25*Q25,3) -> 0
H26: =F26*G26 -> 0 | O26: =(I26+J26+K26+L26+M26+N26)/1000 -> 0 | P26: =O26*H26 -> 0 | Q26: =IF(E26="T10",0.617,IF(E26="T12",0.888,IF(E26="T16",1.579,IF(E26="T20",2.467,IF(E26="T25",3.854,IF(E26="T32",6.315)))))) -> FALSE | R26: =ROUND(P26*Q26,3) -> 0
H27: =F27*G27 -> 0 | O27: =(I27+J27+K27+L27+M27+N27)/1000 -> 0 | P27: =O27*H27 -> 0 | Q27: =IF(E27="T10",0.617,IF(E27="T12",0.888,IF(E27="T16",1.579,IF(E27="T20",2.467,IF(E27="T25",3.854,IF(E27="T32",6.315)))))) -> FALSE | R27: =ROUND(P27*Q27,3) -> 0
H28: =F28*G28 -> 0 | O28: =(I28+J28+K28+L28+M28+N28)/1000 -> 0 | P28: =O28*H28 -> 0 | Q28: =IF(E28="T10",0.617,IF(E28="T12",0.888,IF(E28="T16",1.579,IF(E28="T20",2.467,IF(E28="T25",3.854,IF(E28="T32",6.315)))))) -> FALSE | R28: =ROUND(P28*Q28,3) -> 0
H29: =F29*G29 -> 0 | O29: =(I29+J29+K29+L29+M29+N29)/1000 -> 0 | P29: =O29*H29 -> 0 | Q29: =IF(E29="T10",0.617,IF(E29="T12",0.888,IF(E29="T16",1.579,IF(E29="T20",2.467,IF(E29="T25",3.854,IF(E29="T32",6.315)))))) -> FALSE | R29: =ROUND(P29*Q29,3) -> 0
H30: =F30*G30 -> 0 | O30: =(I30+J30+K30+L30+M30+N30)/1000 -> 0 | P30: =O30*H30 -> 0 | Q30: =IF(E30="T10",0.617,IF(E30="T12",0.888,IF(E30="T16",1.579,IF(E30="T20",2.467,IF(E30="T25",3.854,IF(E30="T32",6.315)))))) -> FALSE | R30: =ROUND(P30*Q30,3) -> 0
H31: =F31*G31 -> 0 | O31: =(I31+J31+K31+L31+M31+N31)/1000 -> 0 | P31: =O31*H31 -> 0 | Q31: =IF(E31="T10",0.617,IF(E31="T12",0.888,IF(E31="T16",1.579,IF(E31="T20",2.467,IF(E31="T25",3.854,IF(E31="T32",6.315)))))) -> FALSE | R31: =ROUND(P31*Q31,3) -> 0
H32: =F32*G32 -> 0 | O32: =(I32+J32+K32+L32+M32+N32)/1000 -> 0 | P32: =O32*H32 -> 0 | Q32: =IF(E32="T10",0.617,IF(E32="T12",0.888,IF(E32="T16",1.579,IF(E32="T20",2.467,IF(E32="T25",3.854,IF(E32="T32",6.315)))))) -> FALSE | R32: =ROUND(P32*Q32,3) -> 0
H33: =F33*G33 -> 0 | O33: =(I33+J33+K33+L33+M33+N33)/1000 -> 0 | P33: =O33*H33 -> 0 | Q33: =IF(E33="T10",0.617,IF(E33="T12",0.888,IF(E33="T16",1.579,IF(E33="T20",2.467,IF(E33="T25",3.854,IF(E33="T32",6.315)))))) -> FALSE | R33: =ROUND(P33*Q33,3) -> 0
H34: =F34*G34 -> 0 | O34: =(I34+J34+K34+L34+M34+N34)/1000 -> 0 | P34: =O34*H34 -> 0 | Q34: =IF(E34="T10",0.617,IF(E34="T12",0.888,IF(E34="T16",1.579,IF(E34="T20",2.467,IF(E34="T25",3.854,IF(E34="T32",6.315)))))) -> FALSE | R34: =ROUND(P34*Q34,3) -> 0
H35: =F35*G35 -> 0 | O35: =(I35+J35+K35+L35+M35+N35)/1000 -> 0 | P35: =O35*H35 -> 0 | Q35: =IF(E35="T10",0.617,IF(E35="T12",0.888,IF(E35="T16",1.579,IF(E35="T20",2.467,IF(E35="T25",3.854,IF(E35="T32",6.315)))))) -> FALSE | R35: =ROUND(P35*Q35,3) -> 0
H36: =F36*G36 -> 0 | O36: =(I36+J36+K36+L36+M36+N36)/1000 -> 0 | P36: =O36*H36 -> 0 | Q36: =IF(E36="T10",0.617,IF(E36="T12",0.888,IF(E36="T16",1.579,IF(E36="T20",2.467,IF(E36="T25",3.854,IF(E36="T32",6.315)))))) -> FALSE | R36: =ROUND(P36*Q36,3) -> 0
H37: =F37*G37 -> 0 | O37: =(I37+J37+K37+L37+M37+N37)/1000 -> 0 | P37: =O37*H37 -> 0 | Q37: =IF(E37="T10",0.617,IF(E37="T12",0.888,IF(E37="T16",1.579,IF(E37="T20",2.467,IF(E37="T25",3.854,IF(E37="T32",6.315)))))) -> FALSE | R37: =ROUND(P37*Q37,3) -> 0 | Z37: =6000-2910 -> 3090
H38: =F38*G38 -> 0 | O38: =(I38+J38+K38+L38+M38+N38)/1000 -> 0 | P38: =O38*H38 -> 0 | Q38: =IF(E38="T10",0.617,IF(E38="T12",0.888,IF(E38="T16",1.579,IF(E38="T20",2.467,IF(E38="T25",3.854,IF(E38="T32",6.315)))))) -> FALSE | R38: =ROUND(P38*Q38,3) -> 0
H39: =F39*G39 -> 0 | O39: =(I39+J39+K39+L39+M39+N39)/1000 -> 0 | P39: =O39*H39 -> 0 | Q39: =IF(E39="T10",0.617,IF(E39="T12",0.888,IF(E39="T16",1.579,IF(E39="T20",2.467,IF(E39="T25",3.854,IF(E39="T32",6.315)))))) -> FALSE | R39: =ROUND(P39*Q39,3) -> 0
H40: =F40*G40 -> 0 | O40: =(I40+J40+K40+L40+M40+N40)/1000 -> 0 | P40: =O40*H40 -> 0 | Q40: =IF(E40="T10",0.617,IF(E40="T12",0.888,IF(E40="T16",1.579,IF(E40="T20",2.467,IF(E40="T25",3.854,IF(E40="T32",6.315)))))) -> FALSE | R40: =ROUND(P40*Q40,3) -> 0 | Z40: =6000-1890 -> 4110
H41: =F41*G41 -> 0 | O41: =(I41+J41+K41+L41+M41+N41)/1000 -> 0 | P41: =O41*H41 -> 0 | Q41: =IF(E41="T10",0.617,IF(E41="T12",0.888,IF(E41="T16",1.579,IF(E41="T20",2.467,IF(E41="T25",3.854,IF(E41="T32",6.315)))))) -> FALSE | R41: =ROUND(P41*Q41,3) -> 0
H42: =F42*G42 -> 0 | O42: =(I42+J42+K42+L42+M42+N42)/1000 -> 0 | P42: =O42*H42 -> 0 | Q42: =IF(E42="T10",0.617,IF(E42="T12",0.888,IF(E42="T16",1.579,IF(E42="T20",2.467,IF(E42="T25",3.854,IF(E42="T32",6.315)))))) -> FALSE | R42: =ROUND(P42*Q42,3) -> 0
...
