Workbook

Sheet G. SUM
B2: =[1]E.Wk!A1 -> PROPOSED DISTRICT GENERAL HOSPITAL AT HAMBANTOTA
B3: =[2]E.Wk!A2 -> CONSTRUCTION AND COMPLETION OF MAIN BUILDING (BLOCK-E)
B4: GRAND SUMMARY
B5: BILL NO. | C5: DESCRIPTION | D5: AMOUNT
D6: Rs. Cts.
B8: 1 | C8: PRELIMINARIES | D8: =prelem!F72 -> 81569500
B10: 2 | C10: BUILDING WORKS | D10: =SUMMARY!D32 -> 1.3853879e+09
B12: 3 | C12: ATTENDENCE FEE AND BUILDR'S WORK FOR NOMINATED SUB CONTRACTOR'S WORK | D12: ='Money provision'!G40 -> 32560000
C14: SUB TOTAL (1) | D14: =SUM(D8:D12) -> 1.4995174e+09
C16: Less - Provisional Sum (Excluding Money Provision for Nominated sub contractor's work) | D16: =-40484500-3250000 -> -43734500
C18: SUB TOTAL (2) | D18: =SUM(D14:D16) -> 1.4557829e+09
C20: DISCOUNT IF ANY (………..%)
C22: SUB TOTAL AFTER DISCOUNT (3) | D22: =D18+D20 -> 1.4557829e+09
C24: Add - Provisional Sum, above mentioned | D24: =40484500+3250000 -> 43734500
C26: BID PRICE (WITHOUT VAT) CARRIED TO FORM OF BID | D26: =D24+D22 -> 1.4995174e+09
B28: Tender Amount (in words) Rupees : One Billion Four Hundred Ninety Nine million Five Hundred Seventeen Thousand Four Hundred Eleven and Cents Sixty Six Only
B30: Name of Tenderer : ……………………......................…………….……..………...……
B32: Address : ……………...…......................................…………...…………
B34: Tenderer's VAT No. (if any) ……………………………….....................................
B36: Signature and Seal :

Sheet mode-pay
B2: PROPOSED DISTRICT GENERAL HOSPITAL AT HAMBANTOTA
B4: ='[3]mode-pay'!A3 -> BILL OF QUANTITIES
B6: Mode of Payment | C6: Item Nr
B7: Reimbursement of actual cost on submission of the relevant documents acceptable to the Engineer plus 5% of the actual cost of obtaining the Insurance Policies and Securities. | C7: B1/01, B1/02, B1/03, B1/04,
B8: To be paid on signing of the formal Contract Agreement. | C8: B
B9: 60% on completion of temporary buildings or structures. 30% in equal installments over the contract period and balance 10% on dismantling and removal on completion. | C9: B2/01, B3/01, B3/02, B3/03,
B10: Paid on satisfactorily completion of the item. | C10: B2/02, B3/04, B6/04
B11: In equal installments over the contract period. | C11: B2/03, B3/05, B4/01, B4/02, B6/01, B6/02, B6/03, B7/01, B7/02, B8/01, B8/02
B12: Mode of payment to be mutually agreed between Contractor and the Employer at the commencement of contract in relation to the programme of work. | C12: B5/01, B9/01
B13: On the completion of Works. | C13: B7/03

Sheet prelem
B2: PROPOSED DISTRICT GENERAL HOSPITAL AT HAMBANTOTA
B3: CONSTRUCTION AND COMPLETION OF MAIN BUILDING (BLOCK-E)
B4: BILL NO. - 1 | D4: PRELIMINARIES
B6: Item No | C6: Description | D6: Mode of Payment Category | E6: Unit | F6: Amount
B8: B/- | C8: PRELIMINARIES
B9: B1 | C9: Insurance and Securities
B10: B1/01 | C10: Provisional sum for providing a Performance Security. | D10: A | E10: PS | F10: 832000
B12: B1/02 | C12: Provisional sum for providing an Advance Payment Security. | D12: A | E12: PS | F12: 3330000
B14: B1/03 | C14: Provisional sum for insurance of Works, Machinery & Equipment, Plant, Materials, third party persons & property and Employer's personnel & property at site as per the Contract. | D14: A | E14: PS | F14: 6105000
B16: B1/04 | C16: Provisional sum for insurance against accidents and injury to Contractor's personnel as per the Contract. | D16: A | E16: PS | F16: 277500
B18: B2 | C18: Engineer's Facilities
B19: B2/01 | C19: Allow lump sum for constructing, maintaining, dismantling and removal on completion of the Works, a temporary building for Engineer's office, including necessary furniture and fittings, furnishing, sanitary facilities, etc. | D19: C | E19: Item | F19: Existing facilities shall use
B21: B2/02 | C21: Allow lump sum for providing telephone, facsimile facilities, electricity and water services for the Engineer's site office for their use in connection with the Works. | D21: D | E21: Item | F21: Existing facilities shall use
B23: B2/03 | C23: Allow lump sum for maintenance, rental, consumption charges etc. for telephone and facsimile facilities, electricity and water services for the Engineer's site office for their use in connection with the Works. | D23: E | E23: Item | F23: Existing facilities shall use
B25: B3 | C25: Contractor's Facilities
B26: B3/01 | C26: Allow lump sum for constructing, maintaining, dismantling and removal on completion of the Works, a temporary site office including staff rest room and toilets and other facilities for the Contractor's site management office. | D26: C | E26: Item | F26: 550000
B28: B3/02 | C28: Allow lump sum for constructing, maintaining, dismantling and removal on completion of the Works, building to be used as workshops and stores for perishable materials. | D28: C | E28: Item | F28: 400000
B30: B3/03 | C30: Allow lump sum for constructing, maintaining, dismantling and removal on completion of the Works, temporary buildings to accommodate the following; | D30: C | E30: Item | F30: 1825000
C31: 1. Workers' rest room, kitchen
C32: 2. Toilet and wash areas
C33: 3. Sick/First-Aid room
C34: 4. Accommodation for Contractor's staff and workmen including sanitary facilities on site
B36: B3/04 | C36: Allow lump sum for providing telephone and facsimile facilities, electricity and water services for the Contractor's site office for their use in connection with the Works. | D36: D | E36: Item | F36: 150000
B38: B3/05 | C38: Allow lump sum for maintenance, rental, consumption charges, etc. for telephone and facsimile facilities, electricity and water services for the Contractor's site office for their use in connection with the Works. | D38: E | E38: Item | F38: 1100000
B40: B4 | C40: Construction Management and Supervision
B41: B4/01 | C41: Allow lump sum for employing suitably qualified and experienced technical personnel on full time basis for Construction Management Services at the site. | D41: E | E41: Item | F41: 18000000
B43: B4/02 | C43: Allow lump sum for employing technical supervisory staff on full time basis. | D43: E | E43: Item | F43: 17500000
B45: B5 | C45: Setting Out
B46: B5/01 | C46: Allow lump sum for setting out of Works in accordance with drawings and other written information given by the Engineer. | D46: F | E46: Item | F46: 1500000
B48: B6 | C48: Quality, Standards and Progress
B49: B6/01 | C49: Allow lump sum for provision of progress reports including photographic records and other schedules included in the ICTAD publication - Guidelines for Effective Construction Management (ICTAD/CM/01). | D49: E | E49: Item | F49: 220000
B51: B6/02 | C51: Allow lump sum for all cost in connection with preparing samples for testing, making arrangements for testing of materials, Goods, etc., as stipulated in the specification, obtaining test reports and submitting to the Engineer. | D51: E | E51: Item | F51: 630000
B53: B6/03 | C53: Allow lump sum for provision of shop drawings, bar schedules, etc. for Engineer's approval. | D53: E | E53: Item | F53: 260000
B55: B6/04 | C55: Allow lump sum for provision of two sets of (hard copies and soft copies) as-built drawings of all services, (except nominated sub contractor's work) for Engineer's approval. | D55: D | E55: Item | F55: 200000
B57: B7 | C57: Health, Safety and Environment
B58: B7/01 | C58: Allow lump sum for providing all necessary safety measures to workmen at site conforming to the latest industrial safety regulations and as directed by the Engineer. Safety visibility vests, rain-jackets, helmets and safety footwear shall be essential safety items. | D58: E | E58: Item | F58: 6350000
B60: B7/02 | C60: Allow lump sum for making adequate provisions against air and noise pollution of surrounding areas. Hoarding and dust screens shall be provided to control dust escaping to surrounding areas. | D60: E | E60: Item | F60: 450000
B62: B7/03 | C62: Allow lump sum for demobilization, removal of all rubbish & debris and clearing up site on completion, leaving all in good order and handing over. | D62: G | E62: Item | F62: 640000
B64: B8 | C64: Security and Protection
B65: B8/01 | C65: Allow lump sum for employing an adequate number of security personnel and security systems on full time basis throughout the period of construction, and provide all necessary security lighting and a warning system. | D65: E | E65: Item | F65: 3000000
...

Sheet SUMMARY
B2: PROPOSED DISTRICT GENERAL HOSPITAL AT HAMBANTOTA
B3: CONSTRUCTION AND COMPLETION OF MAIN BUILDING (BLOCK-E)
B4: SUMMARY - BILL NO. - 2 - BUILDING WORKS
B6: ITEM | C6: DESCRIPTION | D6: AMOUNT
B8: D | C8: EXCAVATION AND EARTH WORK | D8: =E.wk!G62 -> 6450101
B10: F | C10: CONCRETE WORK | D10: =Concrete!G1016 -> 6.2788055e+08
B12: G | C12: MASONRY WORK | D12: =masonry!G44 -> 65734512
B14: H | C14: WATER PROOFING | D14: =W.proof!G103 -> 51369263
B16: K | C16: METAL WORK | D16: ='Metal wk'!G511 -> 138018049
B18: P | C18: ROOF COVERING | D18: =roofing!G41 -> 5578933
B20: Q | C20: WATER SUPPLY | D20: By Nominated Sub Contractor
B22: S | C22: ELECTRICAL | D22: =Elec!G878 -> 172924342
B24: T | C24: FLOOR/WALL/CEILING FINISHES | D24: =Finishes!G285 -> 2.6729281e+08
B26: V | C26: PAINTING | D26: =Painting!G65 -> 34677025
B28: W | C28: SOIL & WASTE WATER SYSTEM | D28: By Nominated Sub Contractor
B30: Y | C30: MISCELLANEOUS | D30: =miscell!G106 -> 15462326
C32: TOTAL CARRIED TO GRAND SUMMARY | D32: =SUM(D8:D30) -> 1.3853879e+09

Sheet E.wk
B2: PROPOSED DISTRICT GENERAL HOSPITAL AT HAMBANTOTA
B3: CONSTRUCTION AND COMPLETION OF MAIN BUILDING (BLOCK-E)
B4: BILL OF QUANTITIES | D4: EXCAVATION AND EARTHWORK
B5: ITEM NO | C5: DESCRIPTION | D5: UNIT | E5: Qty | F5: RATE (RS) | G5: AMOUNT (RS)
B7: D/- | C7: EXCAVATION AND EARTHWORK
C9: Site Clearing
C10: Reduced level excavation is already done | D10: Note
C12: The Bidder is required to visit the site of the proposed work before pricing the following items. | D12: Note
C14: Refer Pricing Preambles, Soil Investigation Report and Excavation and Earth work secion of the Specification before pricing the following items. | D14: Note
C16: Unless other wise stated, Rate shall include for: | D16: Note
C18: Back filling with selected excavated material & consolidating, surface treatment, compaction before filling / foundation. | D18: Note
B20: D/1 | C20: Excavation for foundation in any materials met with except rock requiring blasting, depth not exceeding 2.0m from the reduce level. Part return fill in ram & surplus disposed of within site as directed.
B21: D/1 | C21: Lower Ground floor
B23: D/1/1 | C23: In Column footing | D23: m3 | E23: 156 | F23: 1536 | G23: =E23*F23 -> 239616
G24: =E24*F24 -> 0
B25: D/1/2 | C25: in pile cap | D25: m3 | E25: 84 | F25: 1233 | G25: =E25*F25 -> 103572
G26: =E26*F26 -> 0
B27: D/1/3 | C27: in ground beam & shear wall | D27: m3 | E27: 93 | F27: 1233 | G27: =E27*F27 -> 114669
G28: =E28*F28 -> 0
B29: D/1/4 | C29: in lift well | D29: m3 | E29: 84 | F29: 1233 | G29: =E29*F29 -> 103572
G30: =E30*F30 -> 0
B31: D/1/5 | C31: Stair case footing | D31: m3 | E31: 4 | F31: 1233 | G31: =E31*F31 -> 4932
B33: D/2 | C33: Excavation for pit in any materials met with except rock requiring blasting, depth not exceeding 3.5m from the reduce level. Part return fill in ram & surplus disposed of within site as directed.
B35: D/2/1 | C35: Pit for water sump | D35: m3 | E35: 512 | F35: 1258 | G35: =E35*F35 -> 644096
G36: =E36*F36 -> 0
B37: D/3 | C37: Uper Ground floor | G37: =E37*F37 -> 0
B38: D/3/1 | C38: In Column footing | D38: m3 | E38: 84 | F38: 1567 | G38: =E38*F38 -> 131628
G39: =E39*F39 -> 0
B40: D/3/2 | C40: in pile cap | D40: m3 | E40: 34 | F40: 1258 | G40: =E40*F40 -> 42772
G41: =E41*F41 -> 0
B42: D/3/3 | C42: in ground beam | D42: m3 | E42: 114 | F42: 1258 | G42: =E42*F42 -> 143412
G43: =E43*F43 -> 0
B44: D/3/4 | C44: Stair case footing | D44: m3 | E44: 4 | F44: 1258 | G44: =E44*F44 -> 5032
B46: D/4 | C46: Rock excavation requiring blasting, depth not exceeding 3.5m from the reduce level and disposed of within site as directed. (Provisional quantity) | D46: m3 | E46: 100 | F46: 16380 | G46: =E46*F46 -> 1638000
G47: =E47*F47 -> 0
B48: D/5 | C48: Filling with excavated soil availabe at site in the area below the ground floor slab to achieve 95% Procted density.
B49: D/5/1 | C49: In lower Ground floor | D49: m3 | E49: 988 | F49: 1010 | G49: =E49*F49 -> 997880
G50: =E50*F50 -> 0
B51: D/5/2 | C51: In Ground floor | D51: m3 | E51: 492 | F51: 1010 | G51: =E51*F51 -> 496920
B53: D/6 | C53: Termite proof physical barrier that contains termite Proof Cementitious parge / Resin applied at DPC level to approved specialist contractor's specifications. Contractor shall provide 15 year warranty for whole treatment
...

Sheet Concrete
B2: PROPOSED DISTRICT GENERAL HOSPITAL AT HAMBANTOTA
B3: CONSTRUCTION AND COMPLETION OF MAIN BUILDING (BLOCK-E)
B4: BILL OF QUANTITIES | D4: CONCRETE WORKS
B5: ITEM NO | C5: DESCRIPTION | D5: UNIT | E5: QTY. | F5: RATE (RS) | G5: AMOUNT (RS)
B7: F | C7: CONCRETE WORKS
C9: Concrete ,Grade 15, 1:3:6 (40)
B10: F/1 | C10: 50mm thick lean concrete under:
C11: Lower ground floor | J11: =SUM(G12:G462) -> 3.093955e+08
B12: F/1/1 | C12: In pile cap | D12: m2 | E12: 117 | F12: 645 | G12: =F12*E12 -> 75465
F13: 0
B14: F/1/2 | C14: In column footing (F1, F2, F3, F4,) | D14: m2 | E14: 104 | F14: 645 | G14: =F14*E14 -> 67080
F15: 0
B16: F/1/3 | C16: In ground beam & shear wall | D16: m2 | E16: 312 | F16: 645 | G16: =F16*E16 -> 201240
F17: 0
B18: F/1/4 | C18: In lift well | D18: m2 | E18: 56 | F18: 645 | G18: =F18*E18 -> 36120
F19: 0
B20: F/1/5 | C20: In Stair footing | D20: m2 | E20: 6 | F20: 645 | G20: =F20*E20 -> 3870
F21: 0
B22: F/1/6 | C22: Water sump Base slab | D22: m2 | E22: 187 | F22: 645 | G22: =F22*E22 -> 120615 | H22: Addendum 02
F23: 0
C24: Ground floor | F24: 0
B25: F/1/7 | C25: In pile cap | D25: m2 | E25: 48 | F25: 645 | G25: =F25*E25 -> 30960
F26: 0
B27: F/1/8 | C27: In column footing (F3, F4,) | D27: m2 | E27: 56 | F27: 645 | G27: =F27*E27 -> 36120
F28: 0
B29: F/1/9 | C29: In ground beam | D29: m2 | E29: 226 | F29: 645 | G29: =F29*E29 -> 145770
F30: 0
B31: F/1/10 | C31: In Stair footing | D31: m2 | E31: 2 | F31: 645 | G31: =F31*E31 -> 1290
F32: 0
B33: F/2 | C33: Concrete filling to form required level (Gr.15 concrete to 50mm avarage thick) in toilet area | F33: 0
B34: F/2/1 | C34: At G/F level | D34: m2 | E34: 1 | F34: 645 | G34: =F34*E34 -> 645
B35: F/2/2 | C35: At 1st F/ level | D35: m2 | E35: 32 | F35: 665 | G35: =F35*E35 -> 21280
B36: F/2/3 | C36: At 2nd F/ level | D36: m2 | E36: 28 | F36: 686 | G36: =F36*E36 -> 19208
B37: F/2/4 | C37: At 3rd F/ level | D37: m2 | E37: 34 | F37: 707 | G37: =F37*E37 -> 24038
B38: F/2/5 | C38: At 4th F/ level | D38: m2 | E38: 19 | F38: 728 | G38: =F38*E38 -> 13832
B39: F/2/6 | C39: At 5th F/ level | D39: m2 | E39: 14 | F39: 751 | G39: =F39*E39 -> 10514
B40: F/2/7 | C40: At 6th F/ level | D40: m2 | E40: 12 | F40: 774 | G40: =F40*E40 -> 9288
B41: F/2/8 | C41: At 7th F/ level | D41: m2 | E41: 12 | F41: 798 | G41: =F41*E41 -> 9576
B42: F/2/9 | C42: At 8th F/ level | D42: m2 | E42: 20 | F42: 822 | G42: =F42*E42 -> 16440
F43: 0
...

Sheet masonry
B2: PROPOSED DISTRICT GENERAL HOSPITAL AT HAMBANTOTA
B3: CONSTRUCTION AND COMPLETION OF MAIN BUILDING (BLOCK-E)
B4: BILL OF QUANTITIES | D4: MASONRY WORK
B5: ITEM NO | C5: DESCRIPTION | D5: UNIT | E5: QTY. | F5: RATE (RS) | G5: AMOUNT (RS)
B7: G | C7: MASONRY WORK
B9: G/1 | C9: Random rubble masonry in cement and sand 1:8 using 150mm to 225mm size broken stone (Provisional quantity) | D9: m3 | E9: 50 | F9: 8777 | G9: =F9*E9 -> 438850
C11: Brick walls in burn clay bricks, size, 225x112x75mm in cement & sand 1:8 in the following.
B12: G/2 | C12: 225mm thick walls
B13: G/2/1 | C13: Lower ground floor level to ground floor level | D13: m2 | E13: 3177 | F13: 2418 | G13: =F13*E13 -> 7681986
B14: G/2/2 | C14: Mezzanine floor | D14: m2 | E14: 63 | F14: 2418 | G14: =F14*E14 -> 152334
B15: G/2/3 | C15: Ground floor level to first floor level | D15: m2 | E15: 3322 | F15: 2418 | G15: =F15*E15 -> 8032596
B16: G/2/4 | C16: 1st floor level to 2nd floor level | D16: m2 | E16: 2126 | F16: 2467 | G16: =F16*E16 -> 5244842
B17: G/2/5 | C17: 2nd floor level to 3rd floor level | D17: m2 | E17: 2026 | F17: 2515 | G17: =F17*E17 -> 5095390
B18: G/2/6 | C18: 3rd floor level to 4th floor level | D18: m2 | E18: 1535 | F18: 2564 | G18: =F18*E18 -> 3935740
B19: G/2/7 | C19: 4th floor level to 5th floor level | D19: m2 | E19: 1193 | F19: 2612 | G19: =F19*E19 -> 3116116
B20: G/2/8 | C20: 5th floor level to 6th floor level | D20: m2 | E20: 1264 | F20: 2660 | G20: =F20*E20 -> 3362240
B21: G/2/9 | C21: 6thfloor level to 7th floor level | D21: m2 | E21: 740 | F21: 2709 | G21: =F21*E21 -> 2004660
B22: G/2/10 | C22: 7thfloor level to 8th floor level | D22: m2 | E22: 732 | F22: 2757 | G22: =F22*E22 -> 2018124
B23: G/2/11 | C23: Above 8th floor level | D23: m2 | E23: 742 | F23: 2805 | G23: =F23*E23 -> 2081310
C25: Pump room, Machine Room
B26: G/2/12 | C26: Pump room on water sump at lower ground floor level | D26: m2 | E26: 82 | F26: 2418 | G26: =F26*E26 -> 198276
B27: G/2/13 | C27: Machine Room on roof slab | D27: m2 | E27: 133 | F27: 2854 | G27: =F27*E27 -> 379582
B29: G/3 | C29: 112.5mm thick walls
C30: Rate shall include for provision of stiffener column, size, 100x112mm, with 2T- 10 R/F bars and horizontal pad, size, 112x40mm,with 2R- 6 R/F bars to walls exceeding 2m in height and 3m in length (unless braced by another cross wall) | D30: Note
B31: G/3/1 | C31: Lower ground floor to ground floor level | D31: m2 | E31: 1147 | F31: 1782 | G31: =F31*E31 -> 2043954
B32: G/3/2 | C32: Mezzanine floor | D32: m2 | E32: 148 | F32: 1782 | G32: =F32*E32 -> 263736
B33: G/3/3 | C33: Ground floor level to first floor level | D33: m2 | E33: 1489 | F33: 1782 | G33: =F33*E33 -> 2653398
B35: G/3/4 | C35: 1st floor level to 2nd floor level | D35: m2 | E35: 1209 | F35: 1818 | G35: =F35*E35 -> 2197962
B36: G/3/5 | C36: 2nd floor level to 3rd floor level | D36: m2 | E36: 2470 | F36: 1854 | G36: =F36*E36 -> 4579380
B37: G/3/6 | C37: 3rd floor level to 4th floor level | D37: m2 | E37: 918 | F37: 1854 | G37: =F37*E37 -> 1701972
B38: G/3/7 | C38: 4th floor level to 5th floor level | D38: m2 | E38: 1241 | F38: 1925 | G38: =F38*E38 -> 2388925
B39: G/3/8 | C39: 5th floor level to 6th floor level | D39: m2 | E39: 1228 | F39: 1961 | G39: =F39*E39 -> 2408108
B40: G/3/9 | C40: 6thfloor level to 7th floor level | D40: m2 | E40: 642 | F40: 1996 | G40: =F40*E40 -> 1281432
B41: G/3/10 | C41: 7thfloor level to 8th floor level | D41: m2 | E41: 645 | F41: 2032 | G41: =F41*E41 -> 1310640
B42: G/3/11 | C42: Above 8th floor level | D42: m2 | E42: 553 | F42: 2103 | G42: =F42*E42 -> 1162959
C44: TOTAL CARRIED TO SUMMARY | F44: Rs | G44: =SUM(G8:G42) -> 65734512

Sheet W.proof
B2: PROPOSED DISTRICT GENERAL HOSPITAL AT HAMBANTOTA
B3: CONSTRUCTION AND COMPLETION OF MAIN BUILDING (BLOCK-E)
B4: BILL OF QUANTITIES | D4: WATER PROOFING
B5: ITEM NO | C5: DESCRIPTION | D5: UNIT | E5: QTY. | F5: RATE (RS) | G5: AMOUNT (RS)
B7: H/- | C7: WATER PROOFING
B9: H/1 | C9: Provide vapor barrier comprising 500g polythene membrane on top of compacted and prepared fill under floors. All joints shall be lapped at least 150mm and shall be included in to rate.
B10: H/1/1 | C10: In Lower G/F | D10: m2 | E10: 3292 | F10: 96 | G10: =E10*F10 -> 316032
B11: H/1/2 | C11: In Lower G/F, retain wall | D11: m2 | E11: 554 | F11: 96 | G11: =E11*F11 -> 53184
B12: H/1/3 | C12: In G/F | D12: m2 | E12: 1637 | F12: 96 | G12: =E12*F12 -> 157152
B14: H/2 | C14: Water proofing in toilets / bathrooms floors & walls up to 2.1m height with "Baralastic" or equalent approved type waterproofing compound. All as per the manufacture's specification & to the Engineer's approval.
C15: Screed for tiling will be protective screed for above water proofing.. | D15: Note
B16: H/2/1 | C16: in Lower ground floor | D16: m2 | E16: 390 | F16: 1437 | G16: =E16*F16 -> 560430
B18: H/2/2 | C18: in Mezzanine floor | D18: m2 | E18: 66 | F18: 1437 | G18: =E18*F18 -> 94842
B20: H/2/3 | C20: in ground floor | D20: m2 | E20: 362 | F20: 1437 | G20: =E20*F20 -> 520194
B22: H/2/4 | C22: in first floor | D22: m2 | E22: 681 | F22: 1452 | G22: =E22*F22 -> 988812
B24: H/2/5 | C24: in 2 nd floor | D24: m2 | E24: 630 | F24: 1466 | G24: =E24*F24 -> 923580
B26: H/2/6 | C26: in 3 rd floor | D26: m2 | E26: 1012 | F26: 1481 | G26: =E26*F26 -> 1498772
B28: H/2/7 | C28: in 4 th floor | D28: m2 | E28: 897 | F28: 1495 | G28: =E28*F28 -> 1341015
B30: H/2/8 | C30: in 5 th floor | D30: m2 | E30: 492 | F30: 1509 | G30: =E30*F30 -> 742428
B32: H/2/9 | C32: in 6 th floor | D32: m2 | E32: 400 | F32: 1524 | G32: =E32*F32 -> 609600
B34: H/2/10 | C34: in 7 th floor | D34: m2 | E34: 428 | F34: 1538 | G34: =E34*F34 -> 658264
B36: H/2/11 | C36: in 8 th floor | D36: m2 | E36: 298 | F36: 1552 | G36: =E36*F36 -> 462496
B38: H/2/12 | C38: in Floor slab at Lower ground floor (Provisional Qty) | D38: m2 | E38: 50 | F38: 1437 | G38: =E38*F38 -> 71850
B40: H/2/13 | C40: in retain wall at Lower ground floor (Provisional Qty) | D40: m2 | E40: 50 | F40: 1437 | G40: =E40*F40 -> 71850
B42: H/3 | C42: WATER FROOFING AND THERMAL INSIULATION IN ROOF SLABS
C44: Refer Drawing : HB/ST/42/T
C45: All water proofing shall continue up to 200mm at adjoining walls/columns etc.
B46: H/3 | C46: Provide even surfaced sloping screed (Thickness varies from 125 to 40mm ) in Gr. 20 concrete on roof slab. Slope shall be kept towards to rain water outlets.
B48: H/3/1 | C48: In single story building at Lower G/F | D48: m2 | E48: 608 | F48: 1200 | G48: =E48*F48 -> 729600
B50: H/3/2 | C50: In 1st floor slab level | D50: m2 | E50: 228 | F50: 1224 | G50: =E50*F50 -> 279072
B52: H/3/3 | C52: In 2nd floor slab level | D52: m2 | E52: 737 | F52: 1248 | G52: =E52*F52 -> 919776
B54: H/3/4 | C54: In 3rd floor slab level | D54: m2 | E54: 1280 | F54: 1272 | G54: =E54*F54 -> 1628160
B56: H/3/5 | C56: In 6th floor slab level | D56: m2 | E56: 1503 | F56: 1344 | G56: =E56*F56 -> 2020032
B58: H/3/6 | C58: In roof slab level | D58: m2 | E58: 1090 | F58: 1392 | G58: =E58*F58 -> 1517280
B60: H/3/7 | C60: In machine room roof slab | D60: m2 | E60: 147 | F60: 1416 | G60: =E60*F60 -> 208152
B62: H/4 | C62: Water proofing with "Radcon " or equalent type approved quality & manufacture in roof terrace, & balcony . Rate shall include for relevant arrangement to proper connection with rain water drainage outlets and filling with mastic sealant where necessary .
B64: H/4/1 | C64: In single story building at Lower G/F | D64: m2 | E64: 608 | F64: 1772 | G64: =E64*F64 -> 1077376
B66: H/4/2 | C66: In 1st floor slab level | D66: m2 | E66: 258 | F66: 1790 | G66: =E66*F66 -> 461820
B68: H/4/3 | C68: In 2nd floor slab level | D68: m2 | E68: 737 | F68: 1808 | G68: =E68*F68 -> 1332496
B70: H/4/4 | C70: In 3rd floor slab level | D70: m2 | E70: 1280 | F70: 1826 | G70: =E70*F70 -> 2337280
...

Sheet Metal wk
B2: =W.proof!B2 -> PROPOSED DISTRICT GENERAL HOSPITAL AT HAMBANTOTA
B3: =W.proof!B3 -> CONSTRUCTION AND COMPLETION OF MAIN BUILDING (BLOCK-E)
B4: =W.proof!B4 -> BILL OF QUANTITIES | D4: METAL WORK
B5: ITEM NO | C5: DESCRIPTION | D5: UNIT | E5: QTY. | F5: RATE (RS) | G5: AMOUNT (RS)
B7: K | C7: METAL WORK
C9: Note:
C11: 1) All doors, windows & partitions items described hereunder shall be fabricated in matt finished anodized Aluminium (avarage coating thickness, 15 micrones + or - 2micrones) extrusions conforming in all respects to the specification and detail drawings.
C13: 2) Each door and window sash shall be fitted with the accessories indicated in the specification/ schedule/BOQ and no extra payment what so ever will be made for any standard fittings and accessories even if such are not incorporated in the specification, schedule and detail drawings.
C15: 3) The items described hereinafter indicate only the types and sizes of the doors and windows together with a very brief description thereof. Particulars should be obtained by reference to the specification, schedule and detail drawings.
C17: 4) Glazing for all windows and fanlights shall be 5mm thick tinted float glass and for doors shall be 5mm thick clear float glass. Paneling shall consist of 3mm thick powder coated aluminum sheeting or 3mm thick laminated sheets as specified.
C19: 5) Sample for door/ window sash and all accessories with shop drawing to be approved by the Engineer
C21: 6) Indication for major materials to be used as follows
C22: Aluminum - Lanka Aluminum Sating Finished (15 Mc ) or Equivalent
C23: Gaskets - Sunplast gasket or Equivalent
C24: Silicone - last gasket or Equivalent
C25: Screws - Stainless steel
C26: Door lock - Alfa or Equivalent
... C34: Refer Dwg. No: HB/AR/21/T
B35: K/1 | C35: Aluminum Window, comprising with sash (Aluminum frame, 5mm thick glass (G) and Al. louvers (L)) and aluminum frame shall be as per the drawing. Rate shall include for hinges, casement fasting and casement staying arrangement.
B36: K/1/1 | C36: Window type W1 overall size 6400mm x 2800mm,
B37: K/1/1/1 | C37: in 4 th floor | D37: Nos. | E37: 1 | F37: 264942 | G37: =E37*F37 -> 264942
B38: K/1/1/2 | C38: in 5 th floor | D38: Nos. | E38: 1 | F38: 264942 | G38: =E38*F38 -> 264942
B39: K/1/1/3 | C39: in 6 th floor | D39: Nos. | E39: 1 | F39: 264942 | G39: =E39*F39 -> 264942
B40: K/1/1/4 | C40: in 7 th floor | D40: Nos. | E40: 2 | F40: 264942 | G40: =E40*F40 -> 529884
B41: K/1/1/5 | C41: in 8 th floor | D41: Nos. | E41: 2 | F41: 264942 | G41: =E41*F41 -> 529884
B43: K/1/2 | C43: Window type W2 overall size 6400mm x 1750mm
B44: K/1/2/1 | C44: in L/G/ floor | D44: Nos. | E44: 2 | F44: 121257 | G44: =E44*F44 -> 242514
B45: K/1/2/2 | C45: in G/ floor | D45: Nos. | E45: 1 | F45: 121257 | G45: =E45*F45 -> 121257
B46: K/1/2/3 | C46: in 1st floor | D46: Nos. | E46: 1 | F46: 121257 | G46: =E46*F46 -> 121257
B47: K/1/2/4 | C47: in 2nd floor | D47: Nos. | E47: 1 | F47: 121257 | G47: =E47*F47 -> 121257
B48: K/1/2/5 | C48: in 3rd floor | D48: Nos. | E48: 7 | F48: 121257 | G48: =E48*F48 -> 848799
B49: K/1/2/6 | C49: in 4th floor | D49: Nos. | E49: 2 | F49: 121257 | G49: =E49*F49 -> 242514
B50: K/1/2/7 | C50: in 5th floor | D50: Nos. | E50: 4 | F50: 121257 | G50: =E50*F50 -> 485028
B51: K/1/2/8 | C51: in 6th floor | D51: Nos. | E51: 1 | F51: 121257 | G51: =E51*F51 -> 121257
B52: K/1/2/9 | C52: in 7th floor | D52: Nos. | E52: 1 | F52: 121257 | G52: =E52*F52 -> 121257
B53: K/1/2/10 | C53: in 8th floor | D53: Nos. | E53: 1 | F53: 121257 | G53: =E53*F53 -> 121257
B55: K/1/3 | C55: Window type W3 overall size 5400mm x 1750mm
B56: K/1/3/1 | C56: in L/G/ floor | D56: Nos. | E56: 12 | F56: 106884 | G56: =E56*F56 -> 1282608
B57: K/1/3/2 | C57: in G/ floor | D57: Nos. | E57: 4 | F57: 106884 | G57: =E57*F57 -> 427536
B58: K/1/3/3 | C58: in 1st floor | D58: Nos. | E58: 8 | F58: 106884 | G58: =E58*F58 -> 855072
...

Sheet roofing
B2: =W.proof!B2 -> PROPOSED DISTRICT GENERAL HOSPITAL AT HAMBANTOTA
B3: =W.proof!B3 -> CONSTRUCTION AND COMPLETION OF MAIN BUILDING (BLOCK-E)
B4: =W.proof!B4 -> BILL OF QUANTITIES | D4: ROOF COVERING AND ROOF PLUMBING
B5: ITEM NO | C5: DESCRIPTION | D5: UNIT | E5: QTY | F5: RATE (RS) | G5: AMOUNT (RS)
B7: P/- | C7: ROOF COVERING / ROOF PLUMBING
C8: Note
C9: Roofing shall consist of Zinc-Aluminum Coloured Bonded profiled high tensile steel complete with all flashings fixings and accessories in strict conforming to British standards 9868:1972 or Indian standards 1252:1975. Thickness of coated sheet shall not be less than 0.47mm. conforming to British standards 9868:1972 or Indian standards
C11: The contractor is required to provide a guarantee for the whole of roof installation against defective materials and defective workmanship for a period of 10 years.
B13: P/1 | C13: Zinc-Aluminum Roof Covering
C15: Roofing shall consist of Zinc-Aluminum Coloured Bonded profiled high tensile steel complete with all flashings fixings and accessories in strict conforming to British standards 9868:1972 or Indian standards 1252:1975. Thickness of coated sheet shall not be less than 0.47mm. conforming to British standards 9868:1972 or Indian standards
B16: P/1/1 | C16: Furnish & install roof covering with 0.47mm thick Zinc-Alum sheet on C purling . C purling measured separately in metal work. | D16: m2 | E16: 270 | F16: 1584 | G16: =E16*F16 -> 427680
B18: P/1/2 | C18: Refer metal work for Trusses, Bracing unit and cladding work. | D18: Note
B20: P/2 | C20: Poly Carbonate sheet Roof Covering
B22: P/2 | C22: Furnish & install Poly Carbonate Roof Covering (curved) as per Dwg. No: HB/AR/60/T, on steel frame work measured separately in Metal work .
B24: P/2/1 | C24: at just above 3rd floor flat roof | D24: m2 | E24: 114 | F24: 8784 | G24: =E24*F24 -> 1001376
B25: P/2/2 | C25: at just above 6th floor flat roof | D25: m2 | E25: 170 | F25: 9281 | G25: =E25*F25 -> 1577770
B26: P/2/3 | C26: at just above 8th floor flat roof | D26: m2 | E26: 170 | F26: 9612 | G26: =E26*F26 -> 1634040
B28: P/3 | C28: Supplying, laying & bedding Zn /Al flashing (to side of RCC wall/beam in Entrance porch roof) with fixing bolt & nut etc. | D28: m | E28: 21 | F28: 1004 | G28: =E28*F28 -> 21084
B30: P/4 | C30: Furnish and install 100x75mm Zn/Al down pipes (0.42mm thick sheet) including all necessary accessories such as, brackets (1.0m C/C) , joints, offsets, bends, shoes etc. Rate shall include for proper connection to rain water gutters/roof slab and surface water drain line As directed by Engineer.
B32: P/4/1 | C32: From RCC gutter box as per drawing (at porch) to pond | D32: m | E32: 18 | F32: 1277 | G32: =E32*F32 -> 22986
B33: P/4/2 | C33: From flat roof (single story Bld.) to Lower G/F | D33: m | E33: 36 | F33: 1277 | G33: =E33*F33 -> 45972
B34: P/4/3 | C34: From 1st floor flat roof to G/F | D34: m | E34: 12 | F34: 1303 | G34: =E34*F34 -> 15636
B35: P/4/4 | C35: From 2nd floor flat roof to G/F | D35: m | E35: 50 | F35: 1329 | G35: =E35*F35 -> 66450
B36: P/4/5 | C36: From 3rd floor slab level to G/F | D36: m | E36: 126 | F36: 1354 | G36: =E36*F36 -> 170604
B37: P/4/6 | C37: From 6th floor slab level to G/F | D37: m | E37: 184 | F37: 1380 | G37: =E37*F37 -> 253920
B38: P/4/7 | C38: From roof slab level to G/F | D38: m | E38: 243 | F38: 1405 | G38: =E38*F38 -> 341415
C41: TOTAL CARRIED TO SUMMARY | F41: RS | G41: =SUM(G15:G39) -> 5578933

Sheet Elec
B2: PROPOSED DISTRICT GENERAL HOSPITAL AT HAMBANTOTA
B3: CONSTRUCTION AND COMPLETION OF MAIN BUILDING (BLOCK-E)
B4: BILL OF QUANTITIES | D4: ELECTRICAL WORKS
B5: ITEM NO | C5: DESCRIPTION | D5: UNIT | E5: Qty | F5: RATE (RS) | G5: AMOUNT (RS)
B7: S | C7: ELECTRICAL WORKS
C9: For the full description of materials and workmanship refer specifications, drawings and preamble notes
C11: ELECTRICAL
C13: PREAMBLE NOTES
C14: EXTENT OF WORK
C15: The extent of work covered in this Bill of Quantities shall consists of all the items covered under the specifications. | E15: note | H15: note
C17: The extent of work covered in this Bill of Quantities shall consists of all the items covered under the specifications.
C18: a) Provisions of holes, chases….etc.
C19: b) All necessary scaffoldings
C20: c) Contractor's overheads & profits
C21: d) All tax, levy or duty | E21: note | H21: note
C23: MAIN SERVICE CONNECTION
C25: It shall be the responsibility of the Contractor to do all the necessary co-ordination work with regards to obtaining of the electrical power connections from the Relevant Authourities . | E25: note | H25: note
C27: WIRING IN GENERAL
C29: All the wiring work done under this contract shall conform to BS 7671: 1992 - IEE wiring regulations-17th Edition and any other regulations stipulated by the Relevant Authourities. | E29: note | H29: note
C31: Rate for point wiring shall include for all the conduits, conduit fittings, casings, fixing material, switches, wiring and terminations, holders for light fittings and socket outlets for power points. | E31: note | H31: note
C33: As a standard of quality for switches and socket outlets, the contractor may use Kevilton, ABB, orange or an equivalent make. | E33: note | H33: note
C35: LIGHT FITTINGS
C37: The light fittings supplied and installed under this contract shall be in every respect suitable for the intended purpose. | E37: note | H37: note
C39: Each fitting shall include bulbs, internal wiring, hanging and fixing material and be complete without any additional item/material being required to make it so. | E39: note | H39: note
C41: PANEL BOARDS AND SWITCHGEAR
C43: The panel boards supplied and installed under this contract shall be complete with all the requires accessories such as neutral bars, earth bars, fixing material……etc. | E43: note | H43: note
C45: EARTHING
C47: Rates for the earthing system shall include for all the wiring from individual DBs to a common earth bar and from there to the earth pit including construction of the pit, concrete cover…….etc. | E47: note | H47: note
B49: S.1 | C49: Below Ground Floor to 8th Floor
C51: ELECTRICAL INSTALLATIONS FINAL SUB CIRCUIT POINT WIRING
C53: LIGHTING FIXTURES
C55: All the wiring work done under this contract shall conform to BS 7671: 1992 - IEE wiring regulations-17th Edition and any other regulations stipulated by the Relevant Authourities. | E55: note | H55: note
C57: Rate for point wiring shall include for all the conduits, conduit fittings, casings, fixing material, switches, wiring and terminations, holders for light fittings and socket outlets for power points. | E57: note | H57: note
C59: As a standard of quality for switches and socket outlets, the contractor may use Kevilton, ABB, orange or an equivalent make. | E59: note | H59: note
C61: LIGHT FITTINGS
C63: The light fittings supplied and installed under this contract shall be in every respect suitable for the intended purpose. | E63: note | H63: note
C65: Each fitting shall include bulbs, internal wiring, and be complete without any additional item/material being required to make it so. | E65: note | H65: note
C67: FINAL SUB CIRCUIT POINT WIRING
C68: Rates for point wiring shall include for all cables, switches(1 way or 2 way as nscessary) Junction boxes, conduits, Pull boxes, clips, earth cables, draw wires, wiring accessories, screws, nails, hardware, fixing and insulating materials, cutting holes. Wire sizes for light points will be 2x1.5mm2 Cu/PVC/PVC 1C Cable+ 2.5mm2 Cu/PVC Earth Cable
B70: K.1.1 | C70: 2x600mm ceiling mounted T5 fluorecent lamp fitting with reflector | D70: nr | E70: 560 | F70: 8840 | G70: =E70*F70 -> 4950400
...

Sheet Finishes
B2: PROPOSED DISTRICT GENERAL HOSPITAL AT HAMBANTOTA
B3: CONSTRUCTION AND COMPLETION OF MAIN BUILDING (BLOCK-E)
B4: =Elec!B4 -> BILL OF QUANTITIES | D4: FINISHES
B5: ITEM NO | C5: DESCRIPTION | D5: UNIT | E5: QTY. | F5: RATE (RS) | G5: AMOUNT (RS)
B7: T/- | C7: WALL/FLOOR/ CEILING FINISHES
B9: T/1 | C9: Floor Tilling
B11: T/1/1 | C11: 300mm x 600mm polished porcelain floor tiles paving to an approved pattern including 1:3 cement and sand on 20mm thick screed bed and point with coloured cement to match and forming neat uniform joint between tiles with removable tape joint. Rate shall include for forming arises edges and cutting tiles into required sizes and shape at arises and where necessary and cleaning on completion. (Prime cost for 300x600mm tile shall be Rs 350.00 to 375.00) | I11: =SUM(G13:G66)/130*100 -> 66542865
B13: T/1/1/1 | C13: in L/G/ floor | D13: m2 | E13: 147 | F13: 3578 | G13: =E13*F13 -> 525966
B14: T/1/1/2 | C14: in G/ floor | D14: m2 | E14: 1897 | F14: 3578 | G14: =E14*F14 -> 6787466
B15: T/1/1/3 | C15: in 1st floor | D15: m2 | E15: 946 | F15: 3650 | G15: =E15*F15 -> 3452900
B17: T1/2 | C17: - ditto- but 600mm x 600mm polished finished porcelain floor tile (Rustic tile) in open areas. (Prime cost for 600x600mm tile shall be Rs 800.00 to 825.00)
B19: T/2/1 | C19: in 2nd floor | D19: m2 | E19: 807 | F19: 4123 | G19: =E19*F19 -> 3327261
B20: T/2/2 | C20: in 3rd floor | D20: m2 | E20: 720 | F20: 4203 | G20: =E20*F20 -> 3026160
B22: T1/3 | C22: - ditto- but 600mm x 300mm mat finished porcelain floor tile (Rustic tile) in open areas. (Prime cost for 600x300mm tile shall be Rs 400.00 to 425.00)
B24: T1/3/1 | C24: in L/G/ floor | D24: m2 | E24: 950 | F24: 3961 | G24: =E24*F24 -> 3762950
B25: T1/3/2 | C25: in Mezz. floor | D25: m2 | E25: 390 | F25: 3961 | G25: =E25*F25 -> 1544790
B26: T1/3/3 | C26: in G/ floor | D26: m2 | E26: 1302 | F26: 3961 | G26: =E26*F26 -> 5157222
B27: T1/3/4 | C27: in 1st floor | D27: m2 | E27: 1333 | F27: 4040 | G27: =E27*F27 -> 5385320
B28: T1/3/5 | C28: in 2nd floor | D28: m2 | E28: 933 | F28: 4119 | G28: =E28*F28 -> 3843027
B29: T1/3/6 | C29: in 3rd floor | D29: m2 | E29: 884 | F29: 4199 | G29: =E29*F29 -> 3711916
B30: T1/3/7 | C30: in 4th floor | D30: m2 | E30: 992 | F30: 4278 | G30: =E30*F30 -> 4243776
B31: T1/3/8 | C31: in 5th floor | D31: m2 | E31: 657 | F31: 4357 | G31: =E31*F31 -> 2862549
B32: T1/3/9 | C32: in 6th floor | D32: m2 | E32: 380 | F32: 4436 | G32: =E32*F32 -> 1685680
B33: T1/3/10 | C33: in 7th floor | D33: m2 | E33: 380 | F33: 4516 | G33: =E33*F33 -> 1716080
B34: T1/3/11 | C34: in 8th floor | D34: m2 | E34: 595 | F34: 4595 | G34: =E34*F34 -> 2734025
B35: T1/3/12 | C35: In main stair case L/GF to 8th floor, step tile shall be with chamfer edge, (Area shall be measured including skirting) | D35: m2 | E35: 334 | F35: 5181 | G35: =E35*F35 -> 1730454
B37: T1/3a | C37: - ditto- but 600mm x 300mm mat finished Ceramic floor tile . (Prime cost for 600x300mm tile shall be Rs 300.00 to 310.00)
B39: T1/3a/1 | C39: in G/ floor and 1st floor | D39: m2 | E39: 2200 | F39: 3165 | G39: =E39*F39 -> 6963000
B41: T1/4 | C41: - ditto- but 600mm x 600mm mat finished porcelain floor tile (Rustic tile) in open areas. (Prime cost for 600x600mm tile shall be Rs 850.00 to 900.00)
B43: T1/4/1 | C43: in L/G/ floor | D43: m2 | E43: 427 | F43: 4206 | G43: =E43*F43 -> 1795962
B44: T1/4/2 | C44: in G/ floor | D44: m2 | E44: 648 | F44: 4206 | G44: =E44*F44 -> 2725488
B45: T1/4/3 | C45: in 1st floor | D45: m2 | E45: 24 | F45: 4290 | G45: =E45*F45 -> 102960
B46: T1/4/4 | C46: in 2nd floor | D46: m2 | E46: 24 | F46: 4374 | G46: =E46*F46 -> 104976
B47: T1/4/5 | C47: in 3rd floor | D47: m2 | E47: 24 | F47: 4458 | G47: =E47*F47 -> 106992
B48: T1/4/6 | C48: in 4th floor | D48: m2 | E48: 768 | F48: 4542 | G48: =E48*F48 -> 3488256
B49: T1/4/7 | C49: in 5th floor | D49: m2 | E49: 670 | F49: 4627 | G49: =E49*F49 -> 3100090
B50: T1/4/8 | C50: in 6th floor | D50: m2 | E50: 530 | F50: 4711 | G50: =E50*F50 -> 2496830
B51: T1/4/9 | C51: in 7th floor | D51: m2 | E51: 530 | F51: 4795 | G51: =E51*F51 -> 2541350
B52: T1/4/10 | C52: in 8th floor | D52: m2 | E52: 257 | F52: 4879 | G52: =E52*F52 -> 1253903
B54: T1/5 | C54: - ditto- but 400mm x 400mm non skipped porcelain floor tile in toilet (Prime cost for 400x400mm tile shall be Rs 375.00 to 400.00) | H54: Addendum01
...

Sheet Painting
B2: PROPOSED DISTRICT GENERAL HOSPITAL AT HAMBANTOTA
B3: CONSTRUCTION AND COMPLETION OF MAIN BUILDING (BLOCK-E)
B4: =Elec!B4 -> BILL OF QUANTITIES | D4: PAINTING
B5: ITEM NO | C5: DESCRIPTION | D5: UNIT | E5: QTY. | F5: RATE (RS) | G5: AMOUNT (RS)
B7: V/- | C7: PAINTING
B9: V/1 | C9: Prepare & apply one under coat & two finishing coats of weather shield paint to external plaster surface of walls & columns in following floors including preparing surface.
B11: V/1/1 | C11: in Lower ground floor | D11: m2 | E11: 1509 | F11: 410 | G11: =E11*F11 -> 618690
B12: V/1/2 | C12: in Mezzanine floor | D12: m2 | E12: 6 | F12: 410 | G12: =E12*F12 -> 2460
B13: V/1/3 | C13: in ground floor | D13: m2 | E13: 1481 | F13: 410 | G13: =E13*F13 -> 607210
B14: V/1/4 | C14: in first floor | D14: m2 | E14: 1462 | F14: 418 | G14: =E14*F14 -> 611116
B15: V/1/5 | C15: in 2 nd floor | D15: m2 | E15: 1472 | F15: 426 | G15: =E15*F15 -> 627072
B16: V/1/6 | C16: in 3 rd floor | D16: m2 | E16: 1589 | F16: 435 | G16: =E16*F16 -> 691215
B17: V/1/7 | C17: in 4 th floor | D17: m2 | E17: 1034 | F17: 443 | G17: =E17*F17 -> 458062
B18: V/1/8 | C18: in 5 th floor | D18: m2 | E18: 1105 | F18: 451 | G18: =E18*F18 -> 498355
B19: V/1/9 | C19: in 6 th floor | D19: m2 | E19: 1202 | F19: 459 | G19: =E19*F19 -> 551718
B20: V/1/10 | C20: in 7 th floor | D20: m2 | E20: 646 | F20: 467 | G20: =E20*F20 -> 301682
B21: V/1/11 | C21: in 8th floor | D21: m2 | E21: 661 | F21: 476 | G21: =E21*F21 -> 314636
B22: V/1/12 | C22: Above 8th floor | D22: m2 | E22: 237 | F22: 484 | G22: =E22*F22 -> 114708
B24: V/2 | C24: Finish with single coat of putty and prepare & apply one under coat & two finishing coats of Emulsion paint to internal plaster surface of walls in following floors, including preparing surface.
B26: V/2/1 | C26: in Lower ground floor | D26: m2 | E26: 8577 | F26: 518 | G26: =E26*F26 -> 4442886
B27: V/2/2 | C27: in Mezzanine floor | D27: m2 | E27: 346 | F27: 518 | G27: =E27*F27 -> 179228
B28: V/2/3 | C28: in ground floor | D28: m2 | E28: 8114 | F28: 518 | G28: =E28*F28 -> 4203052
B29: V/2/4 | C29: in first floor | D29: m2 | E29: 4750 | F29: 528 | G29: =E29*F29 -> 2508000
B30: V/2/5 | C30: in 2 nd floor | D30: m2 | E30: 5880 | F30: 539 | G30: =E30*F30 -> 3169320
B31: V/2/6 | C31: in 3 rd floor | D31: m2 | E31: 3707 | F31: 549 | G31: =E31*F31 -> 2035143
B32: V/2/7 | C32: in 4 th floor | D32: m2 | E32: 3082 | F32: 559 | G32: =E32*F32 -> 1722838
B33: V/2/8 | C33: in 5 th floor | D33: m2 | E33: 3383 | F33: 570 | G33: =E33*F33 -> 1928310
B34: V/2/9 | C34: in 6 th floor | D34: m2 | E34: 2154 | F34: 580 | G34: =E34*F34 -> 1249320
B35: V/2/10 | C35: in 7 th floor | D35: m2 | E35: 2006 | F35: 591 | G35: =E35*F35 -> 1185546
B36: V/2/11 | C36: in 8th floor | D36: m2 | E36: 1937 | F36: 601 | G36: =E36*F36 -> 1164137
B37: V/2/12 | C37: Above 8th floor | D37: m2 | E37: 243 | F37: 611 | G37: =E37*F37 -> 148473
B39: V/3 | C39: Prepare & apply one under coat & two finishing coats of Emulsion paint to skim coated surface of soffits in following floors, including preparing surface.
B41: V/3/1 | C41: in Lower ground floor | D41: m2 | E41: 2002 | F41: 382 | G41: =E41*F41 -> 764764
B42: V/3/2 | C42: in Pump room on water sump at lower ground floor level | D42: m2 | E42: 71 | F42: 382 | G42: =E42*F42 -> 27122
B43: V/3/3 | C43: in Mezzanine floor | D43: m2 | E43: 427 | F43: 382 | G43: =E43*F43 -> 163114
B44: V/3/4 | C44: in ground floor | D44: m2 | E44: 560 | F44: 382 | G44: =E44*F44 -> 213920
B45: V/3/5 | C45: in first floor | D45: m2 | E45: 1718 | F45: 390 | G45: =E45*F45 -> 670020
B46: V/3/6 | C46: in 2 nd floor | D46: m2 | E46: 1186 | F46: 397 | G46: =E46*F46 -> 470842
B47: V/3/7 | C47: in 3 rd floor | D47: m2 | E47: 915 | F47: 405 | G47: =E47*F47 -> 370575
B48: V/3/8 | C48: in 4 th floor | D48: m2 | E48: 741 | F48: 413 | G48: =E48*F48 -> 306033
...

Sheet miscell
B2: PROPOSED DISTRICT GENERAL HOSPITAL AT HAMBANTOTA
B3: CONSTRUCTION AND COMPLETION OF MAIN BUILDING (BLOCK-E)
B4: =[2]Painting!A3 -> BILL OF QUANTITIES | D4: MISCELLANEOUS
B5: ITEM NO | C5: DESCRIPTION | D5: UNIT | E5: QTY | F5: RATE | G5: AMOUNT (RS)
C7: Y- MISCELLANEOUS
B9: Y/1 | C9: RCC beam, 112.5x100mm on brick wall at stair way and balcony. Rate shall include for 2 / 10mm dia tor steel bar, 6mm link at 250 c/c and form work for concrete | D9: m | E9: 273 | F9: 1169 | G9: =F9*E9 -> 319137
B11: Y/2 | C11: RCC Coping, 150mm wide x height varies 100 ~75 mm on RCC upstand wall (measured seperetly) at terros. Rate shall include for 2 / 10mm dia tor steel bar, 6mm link at 250 c/c form work for concrete
B13: Y/2/1 | C13: In single story building at Lower G/F | D13: m | E13: 91 | F13: 1296 | G13: =F13*E13 -> 117936 | Q13: 0
B14: Y/2/2 | C14: In 1st floor slab level | D14: m | E14: 70 | F14: 1322 | G14: =F14*E14 -> 92540 | I14: Addendum01
B15: Y/2/3 | C15: In 2nd floor slab level | D15: m | E15: 154 | F15: 1348 | G15: =F15*E15 -> 207592 | I15: Addendum01
B16: Y/2/4 | C16: In 3rd floor slab level | D16: m | E16: 98 | F16: 1374 | G16: =F16*E16 -> 134652 | I16: Addendum01 | P16: 3
B17: Y/2/5 | C17: In 6th floor slab level | D17: m | E17: 210 | F17: 1452 | G17: =F17*E17 -> 304920 | I17: Addendum01
B18: Y/2/6 | C18: In roof slab level | D18: m | E18: 133 | F18: 1529 | G18: =F18*E18 -> 203357 | I18: Addendum01
B20: Y/3 | C20: RCC Lintal, 112.5x100mm on 112.5 thick brick wall over the window/ door etc at lower G/ floor to 8th floor. Rate shall include for 2 / 10mm dia tor steel bar, 6mm link at 250 c/c and form work for concrete | D20: m | E20: 575 | F20: 1355 | G20: =F20*E20 -> 779125
B22: Y/3/1 | C22: - dito- but 112.5x150mm | D22: m | E22: 200 | F22: 1513 | G22: =F22*E22 -> 302600
B23: Y/3/2 | C23: - dito- but 112.5x300mm | D23: m | E23: 200 | F23: 2839 | G23: =F23*E23 -> 567800
B25: Y/4 | C25: RCC Lintal, 225x150mm on 225 thick brick wall over the window/ door etc at lower G/ floor to 8th floor. Rate shall include for 4 / 10mm dia tor steel bar, 6mm stirup at 100 c/c and form work for concrete | D25: m | E25: 780 | F25: 2747 | G25: =F25*E25 -> 2142660
B27: Y/5 | C27: - dito- but 225x225mm and 4/12mm dia bar and 6mm stirup at 150 c/c | D27: m | E27: 115 | F27: 3948 | G27: =F27*E27 -> 454020
B29: Y/6 | C29: - dito- but 225x300mm and 4/16mm dia bar and 6mm stirup at 100 c/c | D29: m | E29: 115 | F29: 5554 | G29: =F29*E29 -> 638710
B31: Y/7 | C31: - dito- but 225x450mm and 5/16mm dia bar and 10mm stirup at 175 c/c | D31: m | E31: 80 | F31: 8151 | G31: =F31*E31 -> 652080
B33: Y/7a | C33: RCC Vanity top, 600x75mm on 112.5 thick brick wall at lower G/ floor to 8th floor. Rate shall include for 10mm dia tor steel bar, 250 c/c, both way and form work for concrete | D33: m | E33: 158 | F33: 7711 | G33: =F33*E33 -> 1218338
B35: Y/8 | C35: Water sump @ Lower ground floor
C36: Refer Dwg No: HB/ST/24
B37: Y/8/1 | C37: Providing 3mm thk. Chequered plate Manhole cover to opening of top slab (800x800mm). Rate shall include for 2 nos. of hinges and locking arrangement (pad lock) | D37: Item | E37: 1 | F37: 8142 | G37: =F37*E37 -> 8142
B39: Y/8/2 | C39: Providing step rungs embedded to RCC wall below the opening, in 25mm dia heavy duty G.I. pipes including painting | D39: Nr | E39: 10 | F39: 1170 | G39: =F39*E39 -> 11700
B41: Y/8/3 | C41: Providing water stop bar, 10mm thick, 400mm wide MS plate along wall | D41: m | E41: 56 | F41: 6298 | G41: =F41*E41 -> 352688
B43: Y/9 | C43: Over head water tank, 5.5x14x2 m
B45: Y/9/1 | C45: Providing 3mm thk. Chequered plate Manhole cover to opening of top slab (800x800mm). Rate shall include for 2 nos. of hinges and locking arrangement (pad lock) | D45: Item | E45: 1 | F45: 8142 | G45: =F45*E45 -> 8142
B47: Y/9/2 | C47: Providing step rungs embedded to RCC wall (inside & out side of tank) below the opening , in 25mm dia heavy duty G.I. pipes including painting | D47: Nr. | E47: 8 | F47: 1170 | G47: =F47*E47 -> 9360
B49: Y/9/3 | C49: Providing water stop bar, 10mm thick, 400mm wide MS plate along wall | D49: m | E49: 38 | F49: 6298 | G49: =F49*E49 -> 239324
B51: Y/9/4 | C51: Providing Upvc inlet pipe (75mm dia, type 1000), outlet pipe, overflow pipe and washout pipe, | D51: Item | E51: 1 | F51: 4705 | G51: =F51*E51 -> 4705
B53: Y/10 | C53: Wall, Doors and Door frames Protection
C54: Supply and embedded trolley guard in to walls along passages etc. as per manufactures specification ("Acrovyn"or equivalent) to engineers approval . Rate shall include for expansion joint, edge trim, and any other accessories to completion
B56: Y/10/1 | C56: to walls, 225mm wide x 20mm, curved
B58: Y/10/1/1 | C58: at Lower G/F | D58: m | E58: 417 | F58: 1521 | G58: =F58*E58 -> 634257
B59: Y/10/1/2 | C59: at G/F | D59: m | E59: 430 | F59: 1521 | G59: =F59*E59 -> 654030
B60: Y/10/1/3 | C60: at 1st Floor | D60: m | E60: 340 | F60: 1551 | G60: =F60*E60 -> 527340
B61: Y/10/1/4 | C61: at 2nd Floor | D61: m | E61: 410 | F61: 1582 | G61: =F61*E61 -> 648620
B62: Y/10/1/5 | C62: at 3rd Floor | D62: m | E62: 300 | F62: 1612 | G62: =F62*E62 -> 483600
B63: Y/10/1/6 | C63: at 4th Floor | D63: m | E63: 360 | F63: 1643 | G63: =F63*E63 -> 591480
...

Sheet Money provision
B2: PROPOSED DISTRICT GENERAL HOSPITAL AT HAMBANTOTA
B3: CONSTRUCTION AND COMPLETION OF MAIN BUILDING (BLOCK-E)
B4: =W.proof!B4 -> BILL OF QUANTITIES | D4: MONEY PROVISION
B5: ITEM NO | C5: DESCRIPTION | D5: UNIT | E5: QTY | F5: AMOUNT (RS) (Nominated Sub Contractor) | G5: AMOUNT (RS) Main Contractor
C7: Z- MONEY PROVISION - NOMINATED SUB CONTRACTS WORK (NSCW)
C9: Following Provisional sums shall be used by as directed by the Employer/ Consultant and deduct in whole or part if not ordered to be used.
C10: Whole or part of the items shall be awarded to a nominated sub contractor.
C11: Main Contractor shall facilitate to complete NSCW (Providing Stores facility, electricity, water, etc. and keeping proper cordination when NSCW conjunction with civil works)
C12: Nominated Sub Contractor's Payments shall be made directly to him
C13: Main contractor shall undertake the relevant builder's work related to NSCW, and shall be paid based on relevent rates available in the contract.
C14: Main Contractor shall be entitled to an attendance fee, as a percentage of value of NSCW, (quoted below).
C15: Nominated Sub Contractor shall provide shop drawings, warranties as required, handing over notes and commissioning
B17: Z/01 | C17: Provisional sum for Providing Water supply , Soil and waste water System (internal & external) and supply and fixing of Sanitary fittings . | D17: Item | E17: P.Sum | F17: 50000000
B18: Z/01a | C18: Main Contractor's Attendence fee related to above NSCW (10%) | D18: Item | G18: =F17*0.1 -> 5000000
B19: Z/01b | C19: Provisional sum for builder's work (to be done by main contractor) related to above NSCW. | D19: Item | E19: P.Sum | G19: =F17*0.07 -> 3500000
B20: Z/02 | C20: Provisional sum for providing Mechanical Installation (Elevators) | D20: Item | E20: P.Sum | F20: 24000000
B21: Z/02a | C21: Main Contractor's Attendence fee related to above NSCW (5%) | D21: Item | G21: =F20*0.05 -> 1200000
B22: Z/02b | C22: Provisional sum for builder's work (to be done by main contractor) related to above NSCW. | D22: Item | E22: P.Sum | G22: =F20*0.07 -> 1680000
B24: Z/03 | C24: Provisional sum for providing Mechanical Installation (Fire Protection system) | D24: Item | E24: P.Sum | F24: 18000000
B25: Z/03a | C25: Main Contractor's Attendence fee related to above NSCW (8%) | D25: Item | G25: =F24*0.08 -> 1440000
B26: Z/03b | C26: Provisional sum for builder's work (to be done by main contractor) related to above NSCW. | D26: Item | E26: P.Sum | G26: =F24*0.07 -> 1260000
B27: Z/04 | C27: Provisional sum for providing Mechanical Installation (Medical gas system ) | D27: Item | E27: P.Sum | F27: 15000000
B28: Z/04a | C28: Main Contractor's Attendence fee related to above NSCW (8%) | D28: Item | G28: =F27*0.08 -> 1200000
B29: Z/04b | C29: Provisional sum for builder's work (to be done by main contractor) related to above NSCW. | D29: Item | E29: P.Sum | G29: =F27*0.07 -> 1050000
B30: Z/05 | C30: Provisional sum for providing Mechanical Installation (Air conditioning) | D30: Item | E30: P.Sum | F30: 75000000
B31: Z/05a | C31: Main Contractor's Attendence fee related to above NSCW (10%) | D31: Item | G31: =F30*0.1 -> 7500000
B32: Z/05b | C32: Provisional sum for builder's work (to be done by main contractor) related to above NSCW. | D32: Item | E32: P.Sum | G32: =F30*0.07 -> 5250000
B33: Z/06 | C33: Provisional sum for providing Sewage treatment plant | D33: Item | E33: P.Sum | F33: 29000000
B34: Z/06a | C34: Main Contractor's Attendence fee related to above NSCW (5%) | D34: Item | G34: =F33*0.05 -> 1450000
B35: Z/06b | C35: Provisional sum for builder's work (to be done by main contractor) related to above NSCW. | D35: Item | E35: P.Sum | G35: =F33*0.07 -> 2030000
C38: PROVISIONAL SUMS CARRIED TO SUMMARY | F38: 211000000 | G38: =G19+G22+G26+G29+G32+G35 -> 14770000
G39: =G18+G21+G25+G28+G34+G31 -> 17790000
G40: =SUM(G38:G39) -> 32560000
F41: 211000000
