Workbook
Name \b: #N/A
Name \G: #REF!
Name \gvfbd: #REF!
Name \gzfbhxcn: #REF!
Name \i: #N/A
Name \j: #N/A
Name \k: #N/A
Name \m: #N/A
Name \n: #N/A
Name \u: #N/A
Name \V: #REF!
Name \w: #N/A
Name \Y: #REF!
Name __: [2]total!#REF!
Name ____: #REF!
Name __________: #REF!
Name _____________________________TP2: #REF!
Name ____________________________str1: #REF!
Name ____________________________str2: #REF!
Name ____________________________str3: #REF!
Name ____________________________sw1: #REF!
Name ____________________________sw2: #REF!
Name ____________________________sw3: #REF!
Name ____________________________sw4: #REF!
Name ____________________________sw5: #REF!
Name ____________________________sw6: #REF!
Name ____________________________sw7: #REF!
Name ____________________________sw8: #REF!
Name ___________________________BOX2: #REF!
Name ___________________________CAL1: #REF!
Name ___________________________CAL10: #REF!
Name ___________________________CAL11: #REF!
Name ___________________________CAL12: #REF!
Name ___________________________CAL13: #REF!
Name ___________________________CAL14: #REF!
Name ___________________________CAL15: #REF!
Name ___________________________CAL16: #REF!
Name ___________________________CAL2: #REF!
Name ___________________________CAL3: #REF!
Name ___________________________CAL4: #REF!
Name ___________________________CAL5: #REF!
Name ___________________________CAL6: #REF!
Name ___________________________CAL7: #REF!
Name ___________________________CAL8: #REF!
Name ___________________________CAL9: #REF!
Name ___________________________SFL1: #REF!
Name ___________________________SFL2: #REF!
Name ___________________________SFL3: #REF!
Name ___________________________SFM1: #REF!
Name ___________________________SFM2: #REF!
Name ___________________________SFM3: #REF!
Name ___________________________SFM4: #REF!
Name ___________________________SFM5: #REF!
Name ___________________________SFM6: #REF!
Name ___________________________SFM7: #REF!
Name ___________________________SFQ1: #REF!
Name ___________________________SFQ3: #REF!
Name ___________________________SFQ4: #REF!
Name ___________________________SUM1: #REF!
Name ___________________________SUM2: #REF!

Sheet ETD01
A1: BOQ FOR CONSTRUCTION OF SERVER ROOM AT ETD L1 | L1: OH/P
A2: ITEM | B2: DESCRIPTION | C2: UNIT | D2: QTY | E2: RATE-COST | F2: Prliminaries | G2: OH/P | H2: Rate | I2: AMOUNT | J2: Remarks | K2: 0.1 | L2: 0.28
E3: Rs. Cts. | H3: Rs. Cts. | I3: Rs. Cts.
A4: ● | B4: Refer the drawings provided | C4: Note | D4: Note | E4: Note | I4: Note
A5: ● | B5: Rate shall include for all materials, labor, machinery & tools. Ready mix concrete Cement-Sanstha Reinforcement steel - Sanstha PVC - Z - lone Paint - CIC | C5: Note | D5: Note | E5: Note | I5: Note
B6: PRELIMINARIES
A7: ● | B7: The Bidder is advised to visit the proposed work site and it is the Bidders' responsibility to asserting the existing working conditions, governing factors regarding access to the site, the extent of working space, storage area, waste disposal etc. The Bidder is required to consider the above matters and price the BOQ accordingly. No work in any trade shall be carried out in such a manner as to cause any nuisance to adjacent owners, guests or public. All precautions to be taken for protecting existing adjacent properties. Client will provide electricity connection & drinking water connection to the site. | C7: Note | D7: Note | E7: Note | I7: Note
A8: A | B8: MOBILIZATIONS
A9: ● | B9: Installing barrier tapes, warning boards display, safety cones. Contractor should be create safety area of all around the site. As per the safety team guide lines. | C9: Note | D9: Note | E9: Note | I9: Note
A10: A.01 | B10: Proper site covering need to be required around the site, 8ft height. As per client request. | C10: item | D10: 1 | E10: ='Rate beak up'!I14 -> 149200 | F10: =E10*K$2 -> 14920 | G10: =(E10+F10)*L$2 -> 45953.6 | H10: =G10+F10+E10 -> 210073.6 | I10: =H10*D10 -> 210073.6 | L10: =E10*D10 -> 149200 | P10: =F10*D10 -> 14920
A11: B | B11: REMOVING AND EARTH WORKS | L11: =E11*D11 -> 0 | P11: =F11*D11 -> 0
A12: B.01 | B12: Safely removing existing cladding sheet with steel frame work (IF NEEDED) including refixing, fixing for use necessary materials supplying and all necessary arrangements. | C12: m2 | D12: 35 | E12: ='Rate beak up'!I38 -> 1378.0714 | F12: =E12*K$2 -> 137.80714 | G12: =(E12+F12)*L$2 -> 424.446 | H12: =G12+F12+E12 -> 1940.3246 | I12: =H12*D12 -> 67911.36 | L12: =E12*D12 -> 48232.5 | P12: =F12*D12 -> 4823.25
A13: B.02 | B13: Demolition existing concrete floor for construction of column footing including cutting for use asphalt cutter, excavation, debris material disposal and all necessary arrangements. Average size -: 900x900x900mm Column -: 08 nos. | C13: m³ | D13: 8.5 | E13: ='Rate beak up'!I59 -> 7202.0588 | F13: =E13*K$2 -> 720.20588 | G13: =(E13+F13)*L$2 -> 2218.2341 | H13: =G13+F13+E13 -> 10140.499 | I13: =H13*D13 -> 86194.24 | L13: =E13*D13 -> 61217.5 | P13: =F13*D13 -> 6121.75
A14: B.03 | B14: Supply and laying ABC for filling including compaction for use Wacker and all necessary arrangements. Average height -: 300mm layer | C14: m³ | D14: 2.25 | E14: ='Rate beak up'!I81 -> 19103.039 | F14: =E14*K$2 -> 1910.3039 | G14: =(E14+F14)*L$2 -> 5883.736 | H14: =G14+F14+E14 -> 26897.079 | I14: =H14*D14 -> 60518.427 | L14: =E14*D14 -> 42981.837 | P14: =F14*D14 -> 4298.1837
A15: B.04 | B15: Supply and laying dry soil/ red soil back filling including compaction for use Wacker(IF NEEDED) and all necessary arrangements. | C15: m³ | D15: 3.5 | E15: ='Rate beak up'!I101 -> 6740.8171 | F15: =E15*K$2 -> 674.08171 | G15: =(E15+F15)*L$2 -> 2076.1717 | H15: =G15+F15+E15 -> 9491.0705 | I15: =H15*D15 -> 33218.747 | L15: =E15*D15 -> 23592.86 | P15: =F15*D15 -> 2359.286
A16: B.05 | B16: Provisional cost for unexpected removing and earth works | C16: Provisional Cost | E16: 200000 | F16: =E16*K$2 -> 20000 | G16: =(E16+F16)*L$2 -> 61600 | H16: =G16+F16+E16 -> 281600 | I16: =E16 -> 200000 | L16: =E16*D16 -> 0 | P16: =F16*D16 -> 0
A17: C | B17: CONCRETE WORKS | F17: =E17*K$2 -> 0 | G17: =(E17+F17)*L$2 -> 0 | H17: =G17+F17+E17 -> 0 | I17: =H17*D17 -> 0 | L17: =E17*D17 -> 0 | P17: =F17*D17 -> 0
A18: ● | B18: Contractor should be submit test reports to engineer, 1. Concrete test cube As per the engineer instruction. | C18: Note | D18: Note | E18: Note
A19: ● | B19: Contractor should be use bonding agent chemicals for concreting use barra-emulsion or approved equivalent. As per the engineer instruction. | C19: Note | D19: Note | E19: Note
A20: C.01 | B20: Supply and laying 50mm thk G20 screed concrete for under column base including all necessary arrangements. | C20: m2 | D20: 7.5 | E20: ='Rate beak up'!I142 -> 2936.1175 | F20: =E20*K$2 -> 293.61175 | G20: =(E20+F20)*L$2 -> 904.32419 | H20: =G20+F20+E20 -> 4134.0534 | I20: =H20*D20 -> 31005.401 | L20: =E20*D20 -> 22020.881 | P20: =F20*D20 -> 2202.0881
A21: C.02 | B21: Supply and laying G25 concrete for column base including pockering, curing and all necessary arrangements. Average size -: 900x900x200mm | C21: m³ | D21: 1.75 | E21: ='Rate beak up'!I141 -> 39148.233 | F21: =E21*K$2 -> 3914.8233 | G21: =(E21+F21)*L$2 -> 12057.656 | H21: =G21+F21+E21 -> 55120.712 | I21: =H21*D21 -> 96461.247 | L21: =E21*D21 -> 68509.408 | P21: =F21*D21 -> 6850.9408
A22: C.03 | B22: Supply and laying G25 concrete for columns including construction joint, pockering, curing and all necessary arrangements. Average size -: 225x225mm | C22: m³ | D22: 1.75 | E22: ='Rate beak up'!I141 -> 39148.233 | F22: =E22*K$2 -> 3914.8233 | G22: =(E22+F22)*L$2 -> 12057.656 | H22: =G22+F22+E22 -> 55120.712 | I22: =H22*D22 -> 96461.247 | L22: =E22*D22 -> 68509.408 | P22: =F22*D22 -> 6850.9408
A23: C.04 | B23: Supply and laying G25 concrete for plinth beams including reinforcement 4T10, R6@200c/c, formwork, curing and all necessary arrangements. Average size -: 225x150mm | C23: m | D23: 32.5 | E23: ='Rate beak up'!I179 -> 5888.6065 | F23: =E23*K$2 -> 588.86065 | G23: =(E23+F23)*L$2 -> 1813.6908 | H23: =G23+F23+E23 -> 8291.1579 | I23: =H23*D23 -> 269462.63 | L23: =E23*D23 -> 191379.71 | P23: =F23*D23 -> 19137.971
A24: C.05 | B24: Supply and laying G25 concrete for Ramp beam including reinforcement 4T10, R6@150c/c, formwork, curing and all necessary arrangements. Average size -: 150x150mm | C24: m | D24: 6 | E24: ='Rate beak up'!I197 -> 4265.9159 | F24: =E24*K$2 -> 426.59159 | G24: =(E24+F24)*L$2 -> 1313.9021 | H24: =G24+F24+E24 -> 6006.4096 | I24: =H24*D24 -> 36038.458 | L24: =E24*D24 -> 25595.496 | P24: =F24*D24 -> 2559.5496
A25: C.06 | B25: Supply and laying G25, 125mm thk. concrete for Ramp including chipping existing floor, reinforcement T10@200c/c, formwork, curing and all necessary arrangements. | C25: m³ | D25: 1.25 | E25: ='Rate beak up'!I216 -> 71298.229 | F25: =E25*K$2 -> 7129.8229 | G25: =(E25+F25)*L$2 -> 21959.855 | H25: =G25+F25+E25 -> 100387.91 | I25: =H25*D25 -> 125484.88 | L25: =E25*D25 -> 89122.786 | P25: =F25*D25 -> 8912.2786
A26: C.07 | B26: Supply and laying G25,125mm thk. concrete for floor including use BRC mesh, pockering, curing, cube testing and all necessary arrangements. | C26: m³ | D26: 3.75 | E26: ='Rate beak up'!I234 -> 48535.409 | F26: =E26*K$2 -> 4853.5409 | G26: =(E26+F26)*L$2 -> 14948.906 | H26: =G26+F26+E26 -> 68337.856 | I26: =H26*D26 -> 256266.96 | L26: =E26*D26 -> 182007.78 | P26: =F26*D26 -> 18200.778
A27: C.08 | B27: Supply and laying G25 concrete for slab beams including reinforcement 2T16, 3T12, R6@150c/c, formwork, curing and all necessary arrangements. Average size -: 225x225mm | C27: m | D27: 32.5 | E27: ='Rate beak up'!I252 -> 9741.1114 | F27: =E27*K$2 -> 974.11114 | G27: =(E27+F27)*L$2 -> 3000.2623 | H27: =G27+F27+E27 -> 13715.485 | I27: =H27*D27 -> 445753.26 | L27: =E27*D27 -> 316586.12 | P27: =F27*D27 -> 31658.612
A28: C.09 | B28: Supply and laying G25 concrete for slab(125mm thk.) including pockering, curing, cube testing and all necessary arrangements. | C28: m³ | D28: 4.75 | E28: ='Rate beak up'!I162 -> 41626.855 | F28: =E28*K$2 -> 4162.6855 | G28: =(E28+F28)*L$2 -> 12821.071 | H28: =G28+F28+E28 -> 58610.612 | I28: =H28*D28 -> 278400.41 | L28: =E28*D28 -> 197727.56 | P28: =F28*D28 -> 19772.756
A29: C.10 | B29: Supply and laying reinforcement (T10@150c/c ) for column base including bending to shape, laying in position, tying with as directed and all necessary arrangements. | C29: Kg | D29: 65 | E29: ='Rate beak up'!I349 -> 548.98 | F29: =E29*K$2 -> 54.898 | G29: =(E29+F29)*L$2 -> 169.08584 | H29: =G29+F29+E29 -> 772.96384 | I29: =H29*D29 -> 50242.65 | L29: =E29*D29 -> 35683.7 | P29: =F29*D29 -> 3568.37
A30: C.11 | B30: Supply and laying reinforcement (6T12 & R6@200c/c) for column including bending to shape, laying in position, tying with as directed. | C30: Kg | D30: 225 | E30: ='Rate beak up'!I349 -> 548.98 | F30: =E30*K$2 -> 54.898 | G30: =(E30+F30)*L$2 -> 169.08584 | H30: =G30+F30+E30 -> 772.96384 | I30: =H30*D30 -> 173916.86 | L30: =E30*D30 -> 123520.5 | P30: =F30*D30 -> 12352.05
A31: C.12 | B31: Supply and laying reinforcement (T10@ 200c/c) for slab including bending to shape, laying in position, tying with as directed. | C31: Kg | D31: 325 | E31: ='Rate beak up'!I349 -> 548.98 | F31: =E31*K$2 -> 54.898 | G31: =(E31+F31)*L$2 -> 169.08584 | H31: =G31+F31+E31 -> 772.96384 | I31: =H31*D31 -> 251213.25 | L31: =E31*D31 -> 178418.5 | P31: =F31*D31 -> 17841.85
A32: C.13 | B32: Supply and fixing formwork for sides of columns including necessary boarding supports, erecting, framing, removing, cleaning. Approximate Height -: 3600mm | C32: m2 | D32: 30 | E32: ='Rate beak up'!I332 -> 4686.8056 | F32: =E32*K$2 -> 468.68056 | G32: =(E32+F32)*L$2 -> 1443.5361 | H32: =G32+F32+E32 -> 6599.0222 | I32: =H32*D32 -> 197970.67 | L32: =E32*D32 -> 140604.17 | P32: =F32*D32 -> 14060.417
A33: C.14 | B33: Supply and fixing formwork for sides of slab including necessary boarding supports, erecting, framing, removing, cleaning, wetting. Approximate Height -: 125mm | C33: m2 | D33: 35.75 | E33: ='Rate beak up'!I332 -> 4686.8056 | F33: =E33*K$2 -> 468.68056 | G33: =(E33+F33)*L$2 -> 1443.5361 | H33: =G33+F33+E33 -> 6599.0222 | I33: =H33*D33 -> 235915.04 | L33: =E33*D33 -> 167553.3 | P33: =F33*D33 -> 16755.33
A34: D | B34: MASONRY AND FINISHING WORKS | L34: =E34*D34 -> 0 | P34: =F34*D34 -> 0
A35: D.01 | B35: Supply and construction 150mm thk. solid block in 1:5 cement sand mortar. | C35: m2 | D35: 84 | E35: ='Rate beak up'!I405 -> 4089.2519 | F35: =E35*K$2 -> 408.92519 | G35: =(E35+F35)*L$2 -> 1259.4896 | H35: =G35+F35+E35 -> 5757.6667 | I35: =H35*D35 -> 483644 | L35: =E35*D35 -> 343497.16 | P35: =F35*D35 -> 34349.716
A36: D.02 | B36: Supply and plastering 15mm thk. internal walls in 1:3 cement sand mortar including revels, smooth finish. | C36: m2 | D36: 90 | E36: ='Rate beak up'!I447 -> 1988.2328 | F36: =E36*K$2 -> 198.82328 | G36: =(E36+F36)*L$2 -> 612.3757 | H36: =G36+F36+E36 -> 2799.4318 | I36: =H36*D36 -> 251948.86 | L36: =E36*D36 -> 178940.95 | P36: =F36*D36 -> 17894.095
A37: D.03 | B37: Supply and plastering 16mm thk. external walls in 1:5 cement sand mortar including revels, semi - rough finish. | C37: m2 | D37: 80 | E37: ='Rate beak up'!I468 -> 1885.4748 | F37: =E37*K$2 -> 188.54748 | G37: =(E37+F37)*L$2 -> 580.72624 | H37: =G37+F37+E37 -> 2654.7485 | I37: =H37*D37 -> 212379.88 | L37: =E37*D37 -> 150837.98 | P37: =F37*D37 -> 15083.798
A38: D.04 | B38: Prepare and apply plaster surface with two coats of wall putty, painting two coats of filler for internal walls with reveals including painting two coats of approved color emulsion paints. | C38: m² | D38: =D36 -> 90 | E38: ='Rate beak up'!I508 -> 1100.1024 | F38: =E38*K$2 -> 110.01024 | G38: =(E38+F38)*L$2 -> 338.83154 | H38: =G38+F38+E38 -> 1548.9442 | I38: =H38*D38 -> 139404.98 | L38: =E38*D38 -> 99009.216 | P38: =F38*D38 -> 9900.9216
A39: D.05 | B39: Supply and painting two coats of filler for external wall with reveals including painting two coats of approved color weather shield paints and all necessary arrangements. | C39: m² | D39: =D37 -> 80 | E39: ='Rate beak up'!I530 -> 1910.3304 | F39: =E39*K$2 -> 191.03304 | G39: =(E39+F39)*L$2 -> 588.38176 | H39: =G39+F39+E39 -> 2689.7452 | I39: =H39*D39 -> 215179.62 | L39: =E39*D39 -> 152826.43 | P39: =F39*D39 -> 15282.643
A40: D.06 | B40: Prepare and apply plaster surface with two coats of putty, painting two coats of filler for sofit including all necessary arrangements. | C40: m² | D40: 35 | E40: ='Rate beak up'!I552 -> 1960.4586 | F40: =E40*K$2 -> 196.04585 | G40: =(E40+F40)*L$2 -> 603.82123 | H40: =G40+F40+E40 -> 2760.3256 | I40: =H40*D40 -> 96611.397 | L40: =E40*D40 -> 68616.049 | P40: =F40*D40 -> 6861.6049
...

Sheet Rates
B2: PRICE LIST
B4: N0 | C4: ITEM | D4: UNIT | E4: RATE | F4: REMARKS
C6: OH/P
C8: MATERAIL
B9: =COUNT(B$4:B6)+1 -> 1 | C9: G15 Ready mix Concrete | D9: m3 | E9: 24000
B10: =COUNT(B$4:B9)+1 -> 2 | C10: G15 Ready mix Concrete-For Minimum Req | D10: m3 | E10: 0
B11: =COUNT(B$4:B10)+1 -> 3 | C11: G15 Ready mix Concrete-Transport | D11: m3 | E11: 0
B12: =COUNT(B$4:B11)+1 -> 4 | C12: G25 Ready mix Concrete | D12: m3 | E12: 32000
B13: =COUNT(B$4:B12)+1 -> 5 | C13: G25 Ready mix Concrete-For Minimum Req | D13: m3
B14: =COUNT(B$4:B13)+1 -> 6 | C14: G25 Ready mix Concrete-Transport | D14: m3 | J14: =22500+(10500/1.5) -> 29500
B15: =COUNT(B$4:B14)+1 -> 7 | C15: Cement | D15: Bag | E15: =2350+75 -> 2425
B16: =COUNT(B$4:B15)+1 -> 8 | C16: River sand | D16: Cube | E16: =21500+3500 -> 25000 | H16: =7000/50 -> 140
B17: =COUNT(B$4:B16)+1 -> 9 | C17: Metal | D17: Cube | E17: =11500+1500 -> 13000
B18: =COUNT(B$4:B17)+1 -> 10 | C18: Query dust | D18: Cube | E18: =11500+1500 -> 13000
B19: =COUNT(B$4:B18)+1 -> 11 | C19: ABC | D19: Cube | E19: =16500+500 -> 17000
B20: =COUNT(B$4:B19)+1 -> 12 | C20: BRC mesh | D20: m2 | E20: 600
B21: =COUNT(B$4:B20)+1 -> 13 | C21: Rubble | D21: Cube | E21: 11000 | K21: =22/7*25 -> 78.571429
B22: =COUNT(B$4:B21)+1 -> 14 | C22: Plywood sheet - 15mm tk double coated | D22: nos | E22: 9500
B23: =COUNT(B$4:B22)+1 -> 15 | C23: 2 x 2 batten | D23: ft | E23: 50
B24: =COUNT(B$4:B23)+1 -> 16 | C24: 2 x 4 batten | D24: ft | E24: 90
B25: =COUNT(B$4:B24)+1 -> 17 | C25: Wire nail | D25: Kg | E25: 800
B26: =COUNT(B$4:B25)+1 -> 18 | C26: Tor steel with transport | D26: Kg | E26: =345+30 -> 375 | I26: =3189 -> 3189 | K26: 1779
B27: =COUNT(B$4:B26)+1 -> 19 | C27: Binding wire | D27: Kg | E27: 900 | I27: =16*16*6/162 -> 9.4814815 | K27: =144/162*6 -> 5.3333333 | L27: =100*6/162 -> 3.7037037
B28: =COUNT(B$4:B27)+1 -> 20 | C28: Block 400 x 200 x 150mm with transport | D28: nos | E28: =202+25 -> 227 | I28: =I26/I27 -> 336.33984 | K28: =K26/K27 -> 333.5625 | L28: =1000/L27 -> 270
B29: =COUNT(B$4:B28)+1 -> 21 | C29: Water | D29: Gal | E29: 3
B30: =COUNT(B$4:B29)+1 -> 22 | C30: Primer | D30: l | E30: =945+200 -> 1145
B31: =COUNT(B$4:B30)+1 -> 23 | C31: Crack Bridging Exterior Wall Primer | D31: l | E31: =2490 -> 2490
B32: =COUNT(B$4:B31)+1 -> 24 | C32: Emulsion Paint CIC | D32: l | E32: =7465/4+200 -> 2066.25
B33: =COUNT(B$4:B32)+1 -> 25 | C33: Putty | D33: Kg | E33: 150 | G33: =1000/20 -> 50
B34: =COUNT(B$4:B33)+1 -> 26 | C34: Whethersheild Paint CIC | D34: l | E34: =10950/4+200 -> 2937.5
B35: =COUNT(B$4:B34)+1 -> 27 | C35: Sand paper | D35: nos | E35: 450
B36: =COUNT(B$4:B35)+1 -> 28 | C36: Soil | E36: 8000
B37: =COUNT(B$4:B36)+1 -> 29 | C37: 300 x 300 mm tile | D37: nos | E37: =1004+200 -> 1204
B38: =COUNT(B$4:B37)+1 -> 30 | C38: Bricks | E38: 25
C39: LABOUR
B40: =COUNT(B$4:B39)+1 -> 31 | C40: Skill Labour | D40: day | E40: =3500+500 -> 4000
B41: =COUNT(B$4:B40)+1 -> 32 | C41: Skill labour- mason | D41: day | E41: =3500+500 -> 4000
B42: =COUNT(B$4:B41)+1 -> 33 | C42: Skill labour -Painter | D42: day | E42: =3500+500 -> 4000
B43: =COUNT(B$4:B42)+1 -> 34 | C43: Skill labour -Carpenter | D43: day | E43: =3500+500 -> 4000
B44: =COUNT(B$4:B43)+1 -> 35 | C44: Unskill Labour | D44: day | E44: =1800+500 -> 2300
...

Sheet Rate beak up
G1: OH/P | H1: =Rates!E6 -> 0
D4: Proper site covering need to be required around the site, 8ft height. As per client request.
F5: Analysis for | G5: 1 | H5: Cube
C6: No | D6: Item Description | E6: Item Ref | F6: Unit | G6: Quantity | H6: Rate | I6: Amount
D7: Tarporling | F7: nos | G7: 2 | H7: 20000 | I7: =G7*H7 -> 40000
D8: Scaffolding | F8: Item | G8: 1 | H8: 100000 | I8: =G8*H8 -> 100000
D9: Unskill fixing | F9: day | G9: 2 | H9: =Rates!E44 -> 2300 | I9: =G9*H9 -> 4600
D10: Unskill Removing | F10: day | G10: 2 | H10: =H9 -> 2300 | I10: =G10*H10 -> 4600
E12: Total for | F12: =$F$54 -> 1 | G12: Item | I12: =SUM(I7:I11) -> 149200
E13: Rate for 1 | F13: Item | H13: =H1 -> 0 | I13: =I12*H13 -> 0
I14: =I12+I13 -> 149200
D17: Safely removing existing cladding sheet with steel frame work (IF NEEDED) including refixing, fixing for use necessary materials supplying and all necessary arrangements.
F18: Analysis for | G18: 1 | H18: 35
C19: No | D19: Item Description | E19: Item Ref | F19: Unit | G19: Quantity | H19: Rate | I19: Amount
D20: Removing
D21: SK Labour | F21: Day | G21: 1 | H21: =Rates!E40 -> 4000 | I21: =G21*H21 -> 4000
D22: U / SK Labourer | F22: Day | G22: 5 | H22: =Rates!E44 -> 2300 | I22: =G22*H22 -> 11500
D23: U / SK Labourer | F23: Day | H23: =Rates!E44 -> 2300 | I23: =G23*H23 -> 0
D24: Scaffolding | F24: Item | G24: 1 | H24: 5000 | I24: =G24*H24 -> 5000
D25: Fixing
D27: SK Labour | F27: Day | G27: 2 | H27: =H21 -> 4000 | I27: =G27*H27 -> 8000
D28: U / SK Labourer | F28: Day | G28: 6 | H28: =H22 -> 2300 | I28: =G28*H28 -> 13800
D29: Scaffolding | F29: Item | G29: 1 | H29: 5000 | I29: =G29*H29 -> 5000
D31: Allow 2.5% of Items ( 1 ) for Tools | I31: =(I22+I21+I27+I28)*2.5/100 -> 932.5
E32: Total for | F32: =$F$54 -> 1 | G32: =$G$54 -> m3 | I32: =SUM(I21:I31) -> 48232.5
E33: Rate for 1 | F33: =$G$54 -> m3 | I33: =I32/G18 -> 48232.5
E34: Rate(Say) | I34: =I33 -> 48232.5
E35: Rate(Say) | H35: m2 | I35: =I34/H18 -> 1378.0714 | M35: =16*I38 -> 22049.143
E37: OH/P | H37: =H1 -> 0 | I37: =I35*H37 -> 0
E38: Say | I38: =I35+I37 -> 1378.0714
D41: Demolition existing concrete floor for construction of column footing including cutting for use asphalt cutter, excavation, debris material disposal and all necessary arrangements.
F42: Analysis for | G42: =8.5 -> 8.5 | H42: m3
C44: No | D44: Item Description | E44: Item Ref | F44: Unit | G44: Quantity | H44: Rate | I44: Amount
I46: =G46*H46 -> 0
D47: U /sk Labourer | F47: day | G47: =3*3 -> 9 | H47: =Rates!E44 -> 2300 | I47: =G47*H47 -> 20700
D48: Asphalt cutter | F48: day | G48: 2 | H48: 8000 | I48: =G48*H48 -> 16000
D49: Braeker | F49: day | G49: 2 | H49: =5000 -> 5000 | I49: =G49*H49 -> 10000
D50: Grinder | F50: day | G50: 2 | H50: 1000 | I50: =G50*H50 -> 2000
D51: Tipper | F51: day | G51: =1 -> 1 | H51: =Rates!E52 -> 12000 | I51: =G51*H51 -> 12000
D53: Allow 2.5% of Items ( 1 ) for Tools | I53: =(I46+I47)*2.5/100 -> 517.5
...

Sheet Sheet1
D5: Container box- for office
D6: WS | F6: 1 | H6: 90000 | I6: =F6*H6 -> 90000
D7: PM | E7: Part time | F7: 1 | H7: 12500 | I7: =F7*H7 -> 12500 | J7: 1/ Month
D8: PE | E8: Part time | F8: 1 | H8: 10000 | I8: =F8*H8 -> 10000 | J8: 1/ Month
D9: QS | E9: Part time | F9: 1 | H9: 7500 | I9: =F9*H9 -> 7500 | J9: 1/ Month
D10: Transport- Vehicle hire | F10: 1 | H10: 100000 | I10: =F10*H10 -> 100000
D11: Test report | F11: 1 | H11: 50000 | I11: =F11*H11 -> 50000
D12: Welfare -Tea- staff | F12: 9600 | H12: 1 | I12: =F12*H12 -> 9600
D13: Welfare -Tea- Labour | F13: 9600 | H13: 1 | I13: =F13*H13 -> 9600
D14: Stationery | F14: 5000 | H14: 1 | I14: =F14*H14 -> 5000 | J14: =SUM(I5:I14) -> 294200
D15: Compressor | F15: 1 | H15: 15000 | I15: =F15*H15 -> 15000
C17: Safety | D17: Safety boot | F17: 10 | G17: 1 | H17: 5900 | I17: =F17*H17*G17 -> 59000
D18: Safety helmet | F18: 10 | G18: 1 | H18: 450 | I18: =F18*H18*G18 -> 4500
D19: Gloves | F19: 20 | G19: 1 | H19: 220 | I19: =F19*H19*G19 -> 4400
D20: Safety overroll | F20: 10 | G20: 1 | H20: 2750 | I20: =F20*H20*G20 -> 27500
D21: Safety clear glass | F21: 10 | G21: 1 | H21: 300 | I21: =F21*H21*G21 -> 3000
D22: Safety full body harness | F22: 8 | G22: 1 | H22: 14800 | I22: =F22*H22*G22 -> 118400
D23: Scaffolding | F23: 1 | G23: 1 | H23: 50000 | I23: =F23*H23*G23 -> 50000 | J23: =SUM(I17:I23) -> 266800
I25: =SUM(I5:I23) -> 576000
