Workbook
Name \b: #N/A
Name \G: #REF!
Name \gvfbd: #REF!
Name \gzfbhxcn: #REF!
Name \i: #N/A
Name \j: #N/A
Name \k: #N/A
Name \m: #N/A
Name \n: #N/A
Name \u: #N/A
Name \V: #REF!
Name \w: #N/A
Name \Y: #REF!
Name __: [2]total!#REF!
Name ____: #REF!
Name __________: #REF!
Name _____________________________TP2: #REF!
Name ____________________________str1: #REF!
Name ____________________________str2: #REF!
Name ____________________________str3: #REF!
Name ____________________________sw1: #REF!
Name ____________________________sw2: #REF!
Name ____________________________sw3: #REF!
Name ____________________________sw4: #REF!
Name ____________________________sw5: #REF!
Name ____________________________sw6: #REF!
Name ____________________________sw7: #REF!
Name ____________________________sw8: #REF!
Name ___________________________BOX2: #REF!
Name ___________________________CAL1: #REF!
Name ___________________________CAL10: #REF!
Name ___________________________CAL11: #REF!
Name ___________________________CAL12: #REF!
Name ___________________________CAL13: #REF!
Name ___________________________CAL14: #REF!
Name ___________________________CAL15: #REF!
Name ___________________________CAL16: #REF!
Name ___________________________CAL2: #REF!
Name ___________________________CAL3: #REF!
Name ___________________________CAL4: #REF!
Name ___________________________CAL5: #REF!
Name ___________________________CAL6: #REF!
Name ___________________________CAL7: #REF!
Name ___________________________CAL8: #REF!
Name ___________________________CAL9: #REF!
Name ___________________________SFL1: #REF!
Name ___________________________SFL2: #REF!
Name ___________________________SFL3: #REF!
Name ___________________________SFM1: #REF!
Name ___________________________SFM2: #REF!
Name ___________________________SFM3: #REF!
Name ___________________________SFM4: #REF!
Name ___________________________SFM5: #REF!
Name ___________________________SFM6: #REF!
Name ___________________________SFM7: #REF!
Name ___________________________SFQ1: #REF!
Name ___________________________SFQ3: #REF!
Name ___________________________SFQ4: #REF!
Name ___________________________SUM1: #REF!
Name ___________________________SUM2: #REF!

Sheet BoQ
B1: PROPOSED CAR PARK DEVELOPMENT - CPSTL @ KOLONNAWA
B3: ITEM NO | C3: DESCRIPTION | D3: UNIT | E3: QTY. | F3: RATE (Rs.) | G3: AMOUNT (Rs.)
B4: =COUNT(B$3:B3)+1 -> 1 | C4: Removing existing Steel roof structure | D4: m2 | E4: =(13.75*11)+(16.5*11)+(8.25*11)+(30*3.7)+(16.5*11)+(21*4.2) -> 804.2 | F4: ='Rate beak up'!I18 -> 275.805 | G4: =F4*E4 -> 221802.38
G5: =F5*E5 -> 0 | I5: =E4*0.1 -> 80.42
B6: =COUNT(B$3:B5)+1 -> 2 | C6: Demolition of existing floor concrete and disposal of debries from site. | D6: m2 | E6: =(13.75*11)+(16.5*11)+(8.25*11)+(30*3.7)+(16.5*11)+(21*4.2) -> 804.2 | F6: ='Rate beak up'!I35 -> 453.735 | G6: =F6*E6 -> 364893.69 | I6: =I5*1000 -> 80420
J7: =F6/I5 -> 5.6420667
B8: =COUNT(B$3:B7)+1 -> 3 | C8: Removing existing tree roots including back filling using imported soil | D8: nos | E8: 7 | F8: ='Rate beak up'!I54 -> 110805.16 | G8: =F8*E8 -> 775636.16
G9: =F9*E9 -> 0
B10: =COUNT(B$3:B9)+1 -> 4 | C10: Sub grade preparation | D10: m2 | E10: 2473 | F10: ='Rate beak up'!I74 -> 382.05 | G10: =F10*E10 -> 944809.65
G11: =F11*E11 -> 0 | K11: =1.8*30 -> 54
B12: =COUNT(B$3:B11)+1 -> 5 | C12: Excavation and back filling for footings using excavated soil | D12: m3 | E12: =7.9+2.43 -> 10.33 | F12: =Car!E7 -> 14400 | G12: =F12*E12 -> 148752
B14: =COUNT(B$3:B13)+1 -> 6 | C14: G 25 concrete for column footing | D14: m3 | E14: =3.41+3.24 -> 6.65 | F14: ='Rate beak up'!I262 -> 47105.936 | G14: =F14*E14 -> 313254.48 | H14: ='Rate beak up'!I300 -> 34367.491 | I14: ='Rate beak up'!I262 -> 47105.936
K15: =12287/1.18 -> 10412.712
B16: =COUNT(B$3:B15)+1 -> 7 | C16: Form work for footing | D16: m2 | E16: =10.9+43.2 -> 54.1 | F16: ='Rate beak up'!I324 -> 4977.1875 | G16: =F16*E16 -> 269265.84 | H16: ='Rate beak up'!I322 -> 3686.8056 | I16: =H16*1.3 -> 4792.8472
B18: =COUNT(B$3:B17)+1 -> 8 | C18: Reinforcement for footings | D18: kg | E18: =271+97 -> 368 | F18: ='Rate beak up'!I341 -> 721.467 | G18: =F18*E18 -> 265499.86 | H18: ='Rate beak up'!I339 -> 534.42 | I18: ='Rate beak up'!I341 -> 721.467
G19: =E19*F19 -> 0
B20: =COUNT(B$3:B19)+1 -> 9 | C20: G 25 concrete for floor concrete (100mm tk) | D20: m3 | E20: =Sheet1!D13 -> 99.5 | F20: ='Rate beak up'!I262 -> 47105.936 | G20: =E20*F20 -> 4687040.7
G21: =E21*F21 -> 0
B22: 10 | C22: Form work for floor concrete | D22: m2 | E22: =Sheet1!D15 -> 30.2 | F22: ='Rate beak up'!I324 -> 4977.1875 | G22: =E22*F22 -> 150311.06 | H22: =F22/1.35 -> 3686.8056 | I22: =F16/1.2 -> 4147.6563
B24: 11 | C24: Supply and laying 150 x 150mm BRC mesh for floor concrete | D24: m2 | E24: =(269*3+102+86) -> 995 | F24: ='Rate beak up'!I390 -> 802.5 | G24: =E24*F24 -> 798487.5
G25: =E25*F25 -> 0
B26: =COUNT(B$3:B25)+1 -> 12 | C26: Supply and laying cobble type Concrete paving Cement Block (Grade 30) size of 200mm x 100mm x80mm Cement colour. including avg 50mm tk compacted Query dust layer and surface preparation. | D26: m2 | E26: =Sheet1!D27 -> 1317.05 | F26: ='Rate beak up'!I359 -> 6710.6349 | G26: =E26*F26 -> 8838241.7
G27: =E27*F27 -> 0
B28: =COUNT(B$3:B27)+1 -> 13 | C28: Supply and laying of standard kerbs for entrance path including 50mm tk concrete layer under kerb and required cement motor | D28: m | E28: =Sheet1!D48 -> 229.7 | F28: ='Rate beak up'!I374 -> 4858.4327 | G28: =E28*F28 -> 1115982
G29: =E29*F29 -> 0
B30: =COUNT(B$3:B29)+1 -> 14 | C30: Asphalt cutting for drain near motorbike park | D30: m | E30: 45 | F30: ='Rate beak up'!I112 -> 1075.68 | G30: =E30*F30 -> 48405.6
B32: =COUNT(B$3:B31)+1 -> 15 | C32: Concrete U drains internal size 450m x 450mm, base tk 100mm wall tk 100mm including reinforcement T10@ 250 c/c, T10@250c/c and form work, Rate shall includes for excavation and back filling using excavated material | D32: m | E32: =Sheet1!D54 -> 156 | F32: ='Rate beak up'!I144 -> 27208.754 | G32: =E32*F32 -> 4244565.6
G33: =E33*F33 -> 0
B34: 16 | C34: Concrete U drains internal size 450m x 300mm, base tk 100mm wall tk 100mm, including reinforcement T10@ 250 c/c, T10@250c/c and form work, Rate shall includes for excavation and back filling using excavated material | D34: m | E34: =Sheet1!D62 -> 107.6 | F34: ='Rate beak up'!I221 -> 22275.089 | G34: =E34*F34 -> 2396799.6
B36: 17 | C36: Construction of cat pit internal dimension 1200x1200x1800mm, Base and wall tk 150mm with 600x600mm heavy duty manhole cover. rate includes for excavation and backfilling using excavated material. | D36: nos | E36: 4 | F36: ='Rate beak up'!I170 -> 479746.34 | G36: =E36*F36 -> 1918985.3
B38: 18 | C38: Excavation and laying 300mm dia Hume pipe. Rate includes backfilling using excavated material. | D38: m | E38: =7.2*5 -> 36 | F38: ='Rate beak up'!I195 -> 14308.223 | G38: =E38*F38 -> 515096.03
B40: 19 | C40: Supply and fixing fountain as per drawing including all plumbing works | D40: PS | E40: 1 | F40: 1200000 | G40: =E40*F40 -> 1200000
C42: STEEL STRUCTURE | K42: =29160+123120+164160+46560 -> 363000
C43: VEHICLE (CAR) PARK | K43: =K42*1.15 -> 417450
B44: 20 | C44: Supply, Fabrication and Fixing of 75mm Steel pipe Columns with Base plate and Anchor bolts. | D44: nos | E44: 60 | F44: =Car!F35 -> 43381.6 | G44: =E44*F44 -> 2602896
G45: =E45*F45 -> 0
B46: 21 | C46: Supply, Fabrication and Fixing of 50mm and 25mm Steel pipe trusses with painting | D46: nos | E46: 30 | F46: =Car!F51 -> 98149.984 | G46: =E46*F46 -> 2944499.5
G47: =E47*F47 -> 0
B48: 22 | C48: Supply, Fixing of 150x65x2mm Galvanised Purlins. | D48: m | E48: 936 | F48: =Car!F59 -> 3336 | G48: =E48*F48 -> 3122496
G49: =E49*F49 -> 0
...

Sheet Sum
B1: SUMMARY OF TENDER DETAILS
B3: 1 | C3: PROJECT NAME | D3: ='[388]TERMS & CONDITIONS'!B4 -> PROPOSED RENOVATION WORK - ALUMEX PRIME PLANT - EKALA
B4: 2 | C4: ADDRESS | D4: EKALA
B5: 3 | C5: NATURE OF THE PROJECT | D5: MANUFACTURING PLANT
B6: 4 | C6: TOTAL PROJECT DURATION | D6: 2 MONTHS
B7: 5 | C7: PROJECT DURATION CONSIDERED | D7: 2 MONTHS
B8: 6 | C8: TYPE OF MEASUREMENT / TYPE OF CONTRACT | D8: MEASURE AND PAY
B9: 7 | C9: DUTY/TAX CONSESSION | D9: DUTY PAID
B10: 8 | C10: QUOTING TO | D10: ALUMEX PLC
B11: 9 | C11: COSTING DONE BY | D11: MADURANGA PIYUMAL
B12: 10 | C12: SOURCE OF INQUIRY | D12: ALUMEX PLC
B13: 11 | C13: TYPE OF TENDER | D13: CLOSE TENDER
B14: 12 | C14: SUBMISSION STATUS | D14: FIRST SUBMISSION
B15: 13 | C15: ADVANCE PAYMENT PERCENTAGE | D15: 30% OF THE TOTAL CONTRACT SUM
B18: 14 | C18: MATERIAL COST | D18: =Car!F115+'3 wheel'!F107 -> 13684080
B19: 15 | C19: LABOUR COST | D19: =Car!F114+'3 wheel'!F106 -> 4726620
B20: 16 | C20: SUB CONTRACT COST WITH MATERIAL | D20: =[389]BoQ!$G$76 -> 0
B21: 17 | C21: SSCL & FINANCIAL CHARGES | D21: 0
B22: 18 | C22: DIRECT OVERHEAD COST | D22: =BoQ!G71 -> 2531400
B23: 19 | C23: GROSS PROFIT | D23: =D24-D22-D20-D19-D18 -> 31989313
B24: 20 | C24: TOTAL OFFER VALUE ( EXCLUDING VAT & SSCL ) | D24: =BoQ!G75 -> 52931413 | E24: ='[388]BoQ '!G41 -> 1.0609855e+08 | G24: 9519193
B25: 23 | C25: FOREIGN COMPONENT-USD | D25: 0
B26: 21 | C26: GROSS PROFIT PERCENTAGE | D26: =D23/D24 -> 0.60435404
E27: =SUM(D18:D23) -> 52931413
E28: =D24-E27 -> 0

Sheet Rate beak up
G1: OH/P | H1: 0.35
D3: Removing existing Steel roof structure
F4: Analysis for | G4: =(13.75*11)+(16.5*11)+(8.25*11)+(30*3.7)+(16.5*11)+(21*4.2) -> 804.2 | H4: m2
C5: No. | D5: Item Description | E5: Item Ref | F5: Unit | G5: Quantity | H5: Rate | I5: Amount
D6: Skill | F6: day | G6: =3*3 -> 9 | H6: =Rates!E43 -> 4500 | I6: =H6*G6 -> 40500
D7: Unskill | F7: day | G7: =3*7 -> 21 | H7: =Rates!E47 -> 3500 | I7: =H7*G7 -> 73500
D8: Grinder | F8: day | G8: 3 | H8: 2000 | I8: =H8*G8 -> 6000
D9: Tipper 1 cube | F9: day | G9: 1 | H9: =Rates!E55 -> 12000 | I9: =H9*G9 -> 12000
D10: Unskill | F10: day | G10: =2*4 -> 8 | H10: =H7 -> 3500 | I10: =H10*G10 -> 28000
D12: Tools 3% | I12: =(I10+I6+I7)*0.03 -> 4260
E13: Total for | I13: =SUM(I6:I12) -> 164260
E14: Rate for 1 | I14: =I13/G4 -> 204.25267
E15: Rate(Say) | H15: m2 | I15: =ROUND(I14,1) -> 204.3
E16: Rate(Say) | H16: m2 | I16: =I15 -> 204.3
E17: OH/P | H17: =H1 -> 0.35 | I17: =I16*H17 -> 71.505
E18: Say | I18: =I16+I17 -> 275.805
D20: Demolishition
F21: Analysis for | G21: =(13.75*11)+(16.5*11)+(8.25*11)+(30*3.7)+(16.5*11)+(21*4.2) -> 804.2 | H21: m2
C22: No. | D22: Item Description | E22: Item Ref | F22: Unit | G22: Quantity | H22: Rate | I22: Amount
D23: JCB | F23: hr | G23: 18 | H23: =Rates!E57 -> 5500 | I23: =H23*G23 -> 99000
D24: Tipper | F24: day | G24: 8 | H24: =Rates!E59 -> 16000 | I24: =H24*G24 -> 128000
D27: SK Labour | F27: Day | G27: 0 | I27: =H27*G27 -> 0
D28: U / SK Labourer | F28: Day | G28: =12 -> 12 | H28: =Rates!E47 -> 3500 | I28: =H28*G28 -> 42000
D29: Tools 3% | I29: =(I27+I28)*0.03 -> 1260
E30: Total for | I30: =SUM(I23:I29) -> 270260
E31: Rate for 1 | I31: =I30/G21 -> 336.06068
E32: Rate(Say) | H32: m2 | I32: =ROUND(I31,1) -> 336.1
E33: Rate(Say) | H33: m2 | I33: =I32 -> 336.1
E34: OH/P | H34: =H1 -> 0.35 | I34: =I33*H34 -> 117.635
E35: Say | I35: =I33+I34 -> 453.735
D39: Removing existing tree roots inluding back filling using imported soil
F40: Analysis for | G40: 7 | H40: nos
C41: No. | D41: Item Description | E41: Item Ref | F41: Unit | G41: Quantity | H41: Rate | I41: Amount
D42: JCB | F42: hr | G42: =6*7 -> 42 | H42: =Rates!E57 -> 5500 | I42: =H42*G42 -> 231000
D43: Rammer | F43: day | G43: 6 | H43: =Rates!E52 -> 6220 | I43: =H43*G43 -> 37320
D44: Tipper 3 cube | F44: day | G44: 2 | H44: =Rates!E59 -> 16000 | I44: =H44*G44 -> 32000
D45: Soil | F45: Cube | G45: =7*2 -> 14 | H45: =Rates!E36 -> 8000 | I45: =H45*G45 -> 112000
D46: SK Labour | F46: Day | G46: 0 | I46: =H46*G46 -> 0
D47: U / SK Labourer | F47: Day | G47: =7*3+(4*6) -> 45 | H47: =Rates!E47 -> 3500 | I47: =H47*G47 -> 157500
D48: Tools 3% | I48: =(I46+I47)*0.03 -> 4725
...

Sheet Car
E2: 0.2
B5: Excavation and back filling for footings using excavated soil | C5: 2.43 | D5: 12000 | E5: =D5*C5 -> 29160
D6: =E2 -> 0.2 | E6: =D$6*E5+E5 -> 34992
E7: =E6/C5 -> 14400
B9: G 25 concrete for column footing | C9: 3.24 | D9: 38000 | E9: =D9*C9 -> 123120
D10: =E2 -> 0.2 | E10: =D$10*E9+E9 -> 147744
E11: =E10/C9 -> 45600
B14: Form work for footing | C14: 43.2 | D14: 3800 | E14: =D14*C14 -> 164160
D15: =E2 -> 0.2 | E15: =D$15*E14+E14 -> 196992
E16: =E15/C14 -> 4560
B19: Reinforcement for footings | C19: 97 | D19: 480 | E19: =D19*C19 -> 46560
D20: =D15 -> 0.2 | E20: =D$20*E19+E19 -> 55872
E21: =E20/C19 -> 576
B23: Fabrication and Fixing of 75mm Steel pipe Columns with Base plate and Anchor bolts. | C23: nos | D23: 60
B24: Labour | C24: nos | D24: 60 | E24: 9800 | F24: =E24*D24 -> 588000
B25: 16 x 300 mm Galvanised "J" bolts | C25: nos | D25: 240 | E25: 1100 | F25: =E25*D25 -> 264000
B26: 75 x 4 mm thick Dia Steel Pipe | C26: nos | D26: 30 | E26: 32000 | F26: =E26*D26 -> 960000
B27: 10mm thick MS plate - 1.220 x 2.440 m size | C27: nos | D27: 3 | E27: 62000 | F27: =E27*D27 -> 186000
B28: 16x50mm Galvanised Bolt & Nuts with 2 washets G8.8 | C28: nos | D28: 360 | E28: 270 | F28: =E28*D28 -> 97200
B29: QD metal primer Zinc phosphate paint - Red | C29: L | D29: 8 | E29: 2630 | F29: =E29*D29 -> 21040
B30: QD metal primer Zinc phosphate paint - Gray | C30: L | D30: 8 | E30: 2630 | F30: =E30*D30 -> 21040
B31: Spray Auto paint - Jet Black | C31: L | D31: 8 | E31: 2225 | F31: =E31*D31 -> 17800
B32: NC Thinner | C32: L | D32: 20 | E32: 700 | F32: =E32*D32 -> 14000
B33: Total | F33: =SUM(F24:F32) -> 2169080 | G33: =SUM(F25:F32) -> 1581080
B34: Unit rate | F34: =F33/D23 -> 36151.333
B35: Unit rate with OH/P | E35: =E2 -> 0.2 | F35: =F34*E35+F34 -> 43381.6
B39: Fabrication and Fixing of 50mm and 25mm Steel pipe trusses with painting | C39: nos | D39: 30
B40: Labour | C40: nos | D40: 30 | E40: 28000 | F40: =E40*D40 -> 840000
B41: 50 x 3 mm thick GI pipe | C41: nos | D41: 70 | E41: 13347.46 | F41: =E41*D41 -> 934322.2
B42: 25 x 2 mm thick GI pipe | C42: nos | D42: 60 | E42: 6737.29 | F42: =E42*D42 -> 404237.4
B43: 6mm thick MS plate - 1.220 x 2.440 m size | C43: nos | D43: 2 | E43: 38000 | F43: =E43*D43 -> 76000
B44: 12x25mm Galvanised Bolt & Nuts with 2 washets G4.6 | C44: nos | D44: 720 | E44: 100 | F44: =E44*D44 -> 72000
B45: QD metal primer Zinc phosphate paint - Red | C45: L | D45: 14 | E45: 2630 | F45: =E45*D45 -> 36820
B46: QD metal primer Zinc phosphate paint - Gray | C46: L | D46: 14 | E46: 2630 | F46: =E46*D46 -> 36820
B47: Spray Auto paint - Jet Black | C47: L | D47: 14 | E47: 2225 | F47: =E47*D47 -> 31150
B48: NC Thinner | C48: L | D48: 32 | E48: 700 | F48: =E48*D48 -> 22400
B49: Total | F49: =SUM(F40:F48) -> 2453749.6 | G49: =SUM(F41:F48) -> 1613749.6
B50: Unit rate | F50: =F49/D39 -> 81791.653
B51: Unit rate with OH/P | E51: =E35 -> 0.2 | F51: =F50*E51+F50 -> 98149.984
B53: Fixing of 150x65x2mm Galvanised Purlins. | C53: m | D53: 936
...

Sheet 3 wheel
E2: 0.2
B6: Excavation and back filling for footings using excavated soil | C6: 7.9 | D6: 12000 | E6: =D6*C6 -> 94800
D7: =E2 -> 0.2 | E7: =E6*D7+E6 -> 113760
E8: =E7/C6 -> 14400
B10: G 25 concrete for column footing | C10: 3.41 | D10: 38000 | E10: =D10*C10 -> 129580
D11: =E2 -> 0.2 | E11: =E10*D11+E10 -> 155496
E12: =E11/C10 -> 45600
B15: Form work for footing | C15: 10.9 | D15: 3800 | E15: =D15*C15 -> 41420
D16: =E2 -> 0.2 | E16: =E15*D16+E15 -> 49704
E17: =E16/C15 -> 4560
B20: Reinforcement for footings | C20: 271 | D20: 480 | E20: =D20*C20 -> 130080
D21: =D16 -> 0.2 | E21: =E20*D21+E20 -> 156096
E22: =E21/C20 -> 576
B27: Fabrication and Fixing of 50mm & 25mm Steel pipe Columns with Base plate and Anchor bolts. | C27: nos | D27: 13
B28: Labour | C28: nos | D28: 13 | E28: 23200 | F28: =E28*D28 -> 301600
B29: 16 x 300 mm Galvanised "J" bolts | C29: nos | D29: 52 | E29: 1100 | F29: =E29*D29 -> 57200
B30: 50 x 2 mm thick GI pipe | C30: nos | D30: 13 | E30: 11457.63 | F30: =E30*D30 -> 148949.19
B31: 25 x 2 mm thick GI pipe | C31: nos | D31: 13 | E31: 6737.29 | F31: =E31*D31 -> 87584.77
B32: 10mm thick MS plate - 1.220 x 2.440 m size | C32: nos | D32: 1 | E32: 62000 | F32: =E32*D32 -> 62000
B33: 16x50mm Galvanised Bolt & Nuts with 2 washets G8.8 | C33: nos | D33: 156 | E33: 270 | F33: =E33*D33 -> 42120
B34: QD metal primer Zinc phosphate paint - Red | C34: l | D34: 4 | E34: 2630 | F34: =E34*D34 -> 10520
B35: QD metal primer Zinc phosphate paint - Gray | C35: l | D35: 4 | E35: 2630 | F35: =E35*D35 -> 10520
B36: Spray Auto paint - Jet Black | C36: l | D36: 4 | E36: 2225 | F36: =E36*D36 -> 8900
B37: NC Thinner | C37: l | D37: 10 | E37: 700 | F37: =E37*D37 -> 7000
B38: Sub toatl | F38: =SUM(F28:F37) -> 736393.96 | G38: =SUM(F29:F37) -> 434793.96
B39: Unit rate | F39: =F38/D27 -> 56645.689
B40: Unit rate with OH/P | E40: =E2 -> 0.2 | F40: =F39*E40+F39 -> 67974.827
B43: Fabrication and Fixing of 50mm and 25mm Steel pipe trusses with painting. | C43: nos | D43: 13
B44: Labour | C44: nos | D44: 13 | E44: 15400 | F44: =E44*D44 -> 200200
B45: 50 x 3 mm thick GI pipe | C45: nos | D45: 16 | E45: 13347.46 | F45: =E45*D45 -> 213559.36
B46: 25 x 2 mm thick GI pipe | C46: nos | D46: 7 | E46: 6737.29 | F46: =E46*D46 -> 47161.03
B47: 6mm thick MS plate - 1.220 x 2.440 m size | C47: nos | D47: 1 | E47: 38000 | F47: =E47*D47 -> 38000
B48: 12x25mm Galvanised Bolt & Nuts with 2 washets G4.6 | C48: nos | D48: 260 | E48: 100 | F48: =E48*D48 -> 26000
B49: QD metal primer Zinc phosphate paint - Red | C49: l | D49: 8 | E49: 2630 | F49: =E49*D49 -> 21040
B50: QD metal primer Zinc phosphate paint - Gray | C50: l | D50: 8 | E50: 2630 | F50: =E50*D50 -> 21040
B51: Spray Auto paint - Jet Black | C51: l | D51: 8 | E51: 2225 | F51: =E51*D51 -> 17800
B52: NC Thinner | C52: l | D52: 20 | E52: 700 | F52: =E52*D52 -> 14000
B53: Sub toatl | F53: =SUM(F44:F52) -> 598800.39 | G53: =SUM(F45:F52) -> 398600.39
B54: Unit rate | F54: =F53/D43 -> 46061.568
B55: Unit rate with OH/P | E55: =E40 -> 0.2 | F55: =F54*E55+F54 -> 55273.882
...

Sheet Rates
B2: PRICE LIST
B4: N0 | C4: ITEM | D4: UNIT | E4: RATE | F4: REMARKS
C6: OH/P
C8: MATERAIL
B9: =COUNT(B$4:B6)+1 -> 1 | C9: G15 Ready mix Concrete | D9: m3 | E9: 24000
B10: =COUNT(B$4:B9)+1 -> 2 | C10: G15 Ready mix Concrete-For Minimum Req | D10: m3 | E10: 0
B11: =COUNT(B$4:B10)+1 -> 3 | C11: G15 Ready mix Concrete-Transport | D11: m3 | E11: 0
B12: =COUNT(B$4:B11)+1 -> 4 | C12: G25 Ready mix Concrete | D12: m3 | E12: 26000
B13: =COUNT(B$4:B12)+1 -> 5 | C13: G25 Ready mix Concrete-For Minimum Req | D13: m3
B14: =COUNT(B$4:B13)+1 -> 6 | C14: G25 Ready mix Concrete-Transport | D14: m3 | J14: =22500+(10500/1.5) -> 29500
B15: =COUNT(B$4:B14)+1 -> 7 | C15: Cement | D15: Bag | E15: =2350+75 -> 2425
B16: =COUNT(B$4:B15)+1 -> 8 | C16: River sand | D16: Cube | E16: =25500 -> 25500 | H16: =7000/50 -> 140
B17: =COUNT(B$4:B16)+1 -> 9 | C17: Metal | D17: Cube | E17: =11500+1500 -> 13000
B18: =COUNT(B$4:B17)+1 -> 10 | C18: Query dust | D18: Cube | E18: =11500+1500 -> 13000
B19: =COUNT(B$4:B18)+1 -> 11 | C19: ABC | D19: Cube | E19: =16500+500 -> 17000
B20: =COUNT(B$4:B19)+1 -> 12 | C20: BRC mesh | D20: m2 | E20: 600
B21: =COUNT(B$4:B20)+1 -> 13 | C21: Rubble | D21: Cube | E21: 11000 | K21: =22/7*25 -> 78.571429
B22: =COUNT(B$4:B21)+1 -> 14 | C22: Plywood sheet - 15mm tk double coated | D22: nos | E22: 9500
B23: =COUNT(B$4:B22)+1 -> 15 | C23: 2 x 2 batten | D23: ft | E23: 50
B24: =COUNT(B$4:B23)+1 -> 16 | C24: 2 x 4 batten | D24: ft | E24: 90
B25: =COUNT(B$4:B24)+1 -> 17 | C25: Wire nail | D25: Kg | E25: 800
B26: =COUNT(B$4:B25)+1 -> 18 | C26: Tor steel with transport | D26: Kg | E26: =345 -> 345 | I26: =3189 -> 3189 | K26: 1779
B27: =COUNT(B$4:B26)+1 -> 19 | C27: Binding wire | D27: Kg | E27: 900 | I27: =16*16*6/162 -> 9.4814815 | K27: =144/162*6 -> 5.3333333 | L27: =100*6/162 -> 3.7037037
B28: =COUNT(B$4:B27)+1 -> 20 | C28: Block 400 x 200 x 150mm with transport | D28: nos | E28: =202+25 -> 227 | I28: =I26/I27 -> 336.33984 | K28: =K26/K27 -> 333.5625 | L28: =1000/L27 -> 270
B29: =COUNT(B$4:B28)+1 -> 21 | C29: Water | D29: Gal | E29: 3
B30: =COUNT(B$4:B29)+1 -> 22 | C30: Primer | D30: l | E30: =945+200 -> 1145
B31: =COUNT(B$4:B30)+1 -> 23 | C31: Crack Bridging Exterior Wall Primer | D31: l | E31: =2490 -> 2490
B32: =COUNT(B$4:B31)+1 -> 24 | C32: Emulsion Paint CIC | D32: l | E32: =7465/4+200 -> 2066.25
B33: =COUNT(B$4:B32)+1 -> 25 | C33: Putty | D33: Kg | E33: 150 | G33: =1000/20 -> 50
B34: =COUNT(B$4:B33)+1 -> 26 | C34: Whethersheild Paint CIC | D34: l | E34: =10950/4+200 -> 2937.5
B35: =COUNT(B$4:B34)+1 -> 27 | C35: Sand paper | D35: nos | E35: 450
B36: =COUNT(B$4:B35)+1 -> 28 | C36: Soil | E36: 8000
B37: =COUNT(B$4:B36)+1 -> 29 | C37: 300 x 300 mm tile | D37: nos | E37: =1004+200 -> 1204
B38: =COUNT(B$4:B37)+1 -> 30 | C38: Bricks | E38: 25
B39: =COUNT(B$4:B38)+1 -> 31 | C39: interlock | E39: 70
B40: =COUNT(B$4:B39)+1 -> 32 | C40: Kerb | E40: 2450
B41: =COUNT(B$4:B40)+1 -> 33 | C41: Hume pipe 300mm dia | E41: 10000
C42: LABOUR
B43: =COUNT(B$4:B42)+1 -> 34 | C43: Skill Labour | D43: day | E43: 4500
B44: =COUNT(B$4:B43)+1 -> 35 | C44: Skill labour- mason | D44: day | E44: 4500
...

Sheet Sheet1
B3: Excavation footing | D3: =73*0.3*0.3*0.45 -> 2.9565
B7: Footing Conctrete | D7: =73*0.3*0.3*0.45 -> 2.9565
B9: Footing FW | D9: =73*4*0.3*0.45 -> 39.42
B11: Rf Footings | D11: =((0.3+0.4+0.4)*2+(0.3+0.3)*0.617*73) -> 29.2246
B13: Floor concrete | D13: =(269*3+102+86)*0.1 -> 99.5
K14: =269/12 -> 22.416667
B15: Fw | D15: =(23+12)*2*0.1*3+(17+6+17+6)*0.1*2 -> 30.2 | K15: =K14*0.1 -> 2.2416667
N18: =K14*12*0.1 -> 26.9
B19: Interlock | C19: 1 | D19: 417.35
C20: 2 | D20: 157.6 | K20: =102/6 -> 17
C21: 3 | D21: 156.3
C22: 4 | D22: 157.5
C23: 5 | D23: 145.9
C24: 6 | D24: 319.8
D25: =-37.4 -> -37.4
D27: =SUM(D19:D25) -> 1317.05
B29: Kerb | C29: 1 | D29: 10.2
D30: 9.7
D31: =6*3 -> 18
C33: 2 | D33: 26
D34: =6*4 -> 24
C36: 3 | D36: 26
D37: =6*4 -> 24
C39: 4 | D39: =6*4 -> 24
D40: =2*2 -> 4
C42: 5 | D42: =21 -> 21
D43: =6*3 -> 18
C45: 6 | D45: =12.4*2 -> 24.8
D48: =SUM(D29:D46) -> 229.7
B54: Dreain | D54: 156
B59: Drain | D59: =23.2*3 -> 69.6
D60: 14.3
D61: 23.7
D62: =SUM(D59:D61) -> 107.6

Sheet Sheet2
B4: Preliminaries
C5: Item | E5: Qty | F5: Rate | G5: Amount
C7: WS | E7: 3 | F7: 120000 | G7: =E7*F7 -> 360000
C9: PM | D9: Part time | E9: 4 | F9: 12500 | G9: =E9*F9 -> 50000
C10: PE | D10: Part time | E10: 10 | F10: 10000 | G10: =E10*F10 -> 100000
C11: QS | D11: Part time | E11: 2 | F11: 7500 | G11: =E11*F11 -> 15000
C12: Transport- Vehicle hire | E12: 3 | F12: 30000 | G12: =E12*F12 -> 90000
C14: Welfare -Tea- staff | E14: 9600 | F14: 3 | G14: =E14*F14 -> 28800
C15: Welfare -Tea- Labour | E15: 9600 | F15: 3 | G15: =E15*F15 -> 28800
C16: Stationery | E16: 10000 | F16: 3 | G16: =E16*F16 -> 30000
C17: Machine mobilization | G17: 100000
C18: Contraine box for office | E18: 25000 | F18: 3 | G18: =E18*F18 -> 75000
C19: Contraine box for stores | E19: 25000 | F19: 3 | G19: =E19*F19 -> 75000
C20: Mobilzation | E20: 30000 | F20: 2 | G20: =E20*F20 -> 60000
C21: As built | E21: 50000 | F21: 1 | G21: =E21*F21 -> 50000
C22: Shop dwg | E22: 50000 | F22: 1 | G22: =E22*F22 -> 50000
C23: AB
C24: PB
C25: WCI
C26: CAR | H26: =SUM(G6:G26) -> 1112600
C27: Others | G27: 1000000
B29: Safety | C29: Safety boot | E29: 20 | F29: 5900 | G29: =E29*F29 -> 118000
C30: Safety helmet | E30: 20 | F30: 450 | G30: =E30*F30 -> 9000
C31: Gloves | E31: 40 | F31: 220 | G31: =E31*F31 -> 8800
C32: Safety overroll | E32: 20 | F32: 2750 | G32: =E32*F32 -> 55000
C33: Safety clear glass | E33: 20 | F33: 300 | G33: =E33*F33 -> 6000
C34: Safety full body harness | E34: 15 | F34: 14800 | G34: =E34*F34 -> 222000
H35: =SUM(G29:G34) -> 418800
G37: =SUM(G6:G35) -> 2531400
