Workbook
Name ___REM1: #REF!
Name ___REM2: #REF!
Name ___Val101: #REF!
Name ___Val102: #REF!
Name ___Val201: #REF!
Name ___Val202: #REF!
Name ___Val301: #REF!
Name ___Val302: #REF!
Name __REM1: #REF!
Name __REM2: #REF!
Name __Val101: #REF!
Name __Val102: #REF!
Name __Val201: #REF!
Name __Val202: #REF!
Name __Val301: #REF!
Name __Val302: #REF!
Name _REM1: #REF!
Name _REM2: #REF!
Name _Val101: #REF!
Name _Val102: #REF!
Name _Val201: #REF!
Name _Val202: #REF!
Name _Val301: #REF!
Name _Val302: #REF!
Name A: #REF!
Name a: '[2]B-3.2 EB'!#REF!
Name aa: #REF!
Name aa: #REF!
Name aaa: #REF!
Name ad: '[2]B-3.2 EB'!#REF!
Name Anton: #REF!
Name Anton: #REF!
Name as: #REF!
Name asgsdfg: #REF!
Name b: '[2]B-3.2 EB'!#REF!
Name b.two: [3]Sheet1!$E$497
Name B_10_10: '[4]Bill 3 - Site Works'!#REF!
Name B_10_11A: '[4]Bill 3 - Site Works'!#REF!
Name B_10_11B: '[4]Bill 3 - Site Works'!#REF!
Name B_10_12: '[4]Bill 3 - Site Works'!#REF!
Name B_10_13: '[4]Bill 3 - Site Works'!#REF!
Name B_10_14: '[4]Bill 3 - Site Works'!#REF!
Name B_10_2: '[4]Bill 3 - Site Works'!#REF!
Name B_10_3: '[4]Bill 3 - Site Works'!#REF!
Name B_10_4: '[4]Bill 3 - Site Works'!#REF!
Name B_10_5: '[4]Bill 3 - Site Works'!#REF!
Name B_10_6: '[4]Bill 3 - Site Works'!#REF!
Name B_10_7A: '[4]Bill 3 - Site Works'!#REF!
Name B_10_8A: '[4]Bill 3 - Site Works'!#REF!
Name B_10_9: '[4]Bill 3 - Site Works'!#REF!
Name B107A: '[4]Bill 3 - Site Works'!#REF!
Name BB: #REF!
Name bbb: #REF!
Name bhhbhj: #REF!
Name Bill: #REF!
Name bill1: #REF!
Name C_: #REF!
Name CApentry: #REF!
Name cc: #REF!
Name CoolingCapacity: '[5]Room Type'!$O$3

Sheet bar schedule-wattala
B1: BAR BENDING SCHEDULE | H1: BENDING SCHEDULE OF REINFORCEMENTS
B2: Project | C2: : | D2: Proposed 3 storied building - Wattala Mabola Urban council
B3: Consultant | C3: :
B4: Location | C4: : | D4: Wattala Mabola Urban council
B5: Item | C5: Bar mark | D5: Type&Size | E5: Members | F5: Nos per member | G5: Total nos | H5: Shape code (as per BS 4449 code) | I5: Length of a bar (m) | J5: Total length of bars (m) | K5: Lenth of Each Bar (m) | L5: Required Bar Qty | M5: A* | N5: B* | O5: C* | P5: D* | Q5: E* | R5: Total length (m) | Z5: Remarks
M6: m | N6: m | O6: m | P6: m | Q6: m | R6: R6 | S6: R8 | T6: T10 | U6: T12 | V6: T16 | W6: T20 | X6: T25 | Y6: T32
I8: =M8+N8+O8+P8+Q8 -> 0 | K8: 6 | R8: =IF(D8="R6",J8," ") | S8: =IF(D8="R8",J8," ") | T8: =IF(D8="T10",J8," ") | U8: =IF(D8="T12",J8," ") | V8: =IF(D8="T16",J8," ") | W8: =IF(D8="T20",J8," ") | X8: =IF(D8="T25",J8," ") | Y8: =IF(D8="T32",J8," ")
B9: Column Base
B10: F1 | C10: a | D10: T12 | E10: 10 | F10: 30 | G10: =F10*E10 -> 300 | I10: =M10+N10+O10+P10+Q10 -> 2.12 | J10: =G10*I10 -> 636 | K10: =K6*0.888 -> 0 | M10: 1.72 | N10: 0.2 | O10: 0.2 | R10: =IF(D10="R6",J10," ") | S10: =IF(D10="R8",J10," ") | T10: =IF(D10="T10",J10," ") | U10: =IF(D10="T12",J10," ") -> 636 | V10: =IF(D10="T16",J10," ") | W10: =IF(D10="T20",J10," ") | X10: =IF(D10="T25",J10," ") | Y10: =IF(D10="T32",J10," ")
B11: F2 | C11: a | D11: T12 | E11: 14 | F11: 22 | G11: =F11*E11 -> 308 | I11: =M11+N11+O11+P11+Q11 -> 1.82 | J11: =G11*I11 -> 560.56 | K11: =K7*0.888 -> 0 | M11: 1.42 | N11: 0.2 | O11: 0.2 | R11: =IF(D11="R6",J11," ") | S11: =IF(D11="R8",J11," ") | T11: =IF(D11="T10",J11," ") | U11: =IF(D11="T12",J11," ") -> 560.56 | V11: =IF(D11="T16",J11," ") | W11: =IF(D11="T20",J11," ") | X11: =IF(D11="T25",J11," ") | Y11: =IF(D11="T32",J11," ")
B12: F3 | C12: a | D12: T12 | E12: 4 | F12: 16 | G12: =F12*E12 -> 64 | I12: =M12+N12+O12+P12+Q12 -> 1.52 | J12: =G12*I12 -> 97.28 | K12: =K8*0.888 -> 5.328 | M12: 1.12 | N12: 0.2 | O12: 0.2 | R12: =IF(D12="R6",J12," ") | S12: =IF(D12="R8",J12," ") | T12: =IF(D12="T10",J12," ") | U12: =IF(D12="T12",J12," ") -> 97.28 | V12: =IF(D12="T16",J12," ") | W12: =IF(D12="T20",J12," ") | X12: =IF(D12="T25",J12," ") | Y12: =IF(D12="T32",J12," ")
B13: CF1 | C13: a | D13: T12 | E13: 1 | F13: 64 | G13: =F13*E13 -> 64 | I13: =M13+N13+O13+P13+Q13 -> 2.12 | J13: =G13*I13 -> 135.68 | K13: =K9*0.888 -> 0 | M13: 1.72 | N13: 0.2 | O13: 0.2 | R13: =IF(D13="R6",J13," ") | S13: =IF(D13="R8",J13," ") | T13: =IF(D13="T10",J13," ") | U13: =IF(D13="T12",J13," ") -> 135.68 | V13: =IF(D13="T16",J13," ") | W13: =IF(D13="T20",J13," ") | X13: =IF(D13="T25",J13," ") | Y13: =IF(D13="T32",J13," ")
B14: CF1 | C14: a | D14: T12 | E14: 1 | F14: 44 | G14: =F14*E14 -> 44 | I14: =M14+N14+O14+P14+Q14 -> 3.02 | J14: =G14*I14 -> 132.88 | K14: =K10*0.888 -> 0 | M14: 2.62 | N14: 0.2 | O14: 0.2 | R14: =IF(D14="R6",J14," ") | S14: =IF(D14="R8",J14," ") | T14: =IF(D14="T10",J14," ") | U14: =IF(D14="T12",J14," ") -> 132.88 | V14: =IF(D14="T16",J14," ") | W14: =IF(D14="T20",J14," ") | X14: =IF(D14="T25",J14," ") | Y14: =IF(D14="T32",J14," ")
B16: Total length (m) | R16: =SUM(R8:R15) -> 0 | S16: =SUM(S8:S15) -> 0 | T16: =SUM(T8:T15) -> 0 | U16: =SUM(U8:U15) -> 1562.4 | V16: =SUM(V8:V15) -> 0 | W16: =SUM(W8:W15) -> 0 | X16: =SUM(X8:X15) -> 0 | Y16: =SUM(Y8:Y15) -> 0
B17: Weight (Kg/m) | R17: =6*6/162.162 -> 0.22200022 | S17: =8*8/162.162 -> 0.39466706 | T17: =10*10/162.162 -> 0.61666728 | U17: =12*12/162.162 -> 0.88800089 | V17: =16*16/162.162 -> 1.5786682 | W17: =20*20/162.162 -> 2.4666691 | X17: =25*25/162.162 -> 3.8541705 | Y17: =32*32/162.162 -> 6.314673
B18: TOTAL (Kg) | R18: =+R17*R16 -> 0 | S18: =+S17*S16 -> 0 | T18: =+T17*T16 -> 0 | U18: =+U17*U16 -> 1387.4126 | V18: =+V17*V16 -> 0 | W18: =+W17*W16 -> 0 | X18: =+X17*X16 -> 0 | Y18: =+Y17*Y16 -> 0 | Z18: =Y18+X18+W18+V18+U18+T18+S18+R18 -> 1387.4126
B21: Column shaft -upto DPC
B22: C1 | C22: a | D22: T16 | E22: 32 | F22: 4 | G22: =F22*E22 -> 128 | I22: =M22+N22+O22+P22+Q22 -> 1.97 | J22: =G22*I22 -> 252.16 | K22: =K18*0.888 -> 0 | M22: 1.23 | N22: 0.74 | R22: =IF(D22="R6",J22," ") | S22: =IF(D22="R8",J22," ") | T22: =IF(D22="T10",J22," ") | U22: =IF(D22="T12",J22," ") | V22: =IF(D22="T16",J22," ") -> 252.16 | W22: =IF(D22="T20",J22," ") | X22: =IF(D22="T25",J22," ") | Y22: =IF(D22="T32",J22," ")
B23: C2 | C23: a | D23: T16 | E23: 4 | F23: 4 | G23: =F23*E23 -> 16 | I23: =M23+N23+O23+P23+Q23 -> 1.97 | J23: =G23*I23 -> 31.52 | K23: =K19*0.888 -> 0 | M23: 1.23 | N23: 0.74 | R23: =IF(D23="R6",J23," ") | S23: =IF(D23="R8",J23," ") | T23: =IF(D23="T10",J23," ") | U23: =IF(D23="T12",J23," ") | V23: =IF(D23="T16",J23," ") -> 31.52 | W23: =IF(D23="T20",J23," ") | X23: =IF(D23="T25",J23," ") | Y23: =IF(D23="T32",J23," ")
B25: Total length (m) | R25: =SUM(R20:R24) -> 0 | S25: =SUM(S20:S24) -> 0 | T25: =SUM(T20:T24) -> 0 | U25: =SUM(U20:U24) -> 0 | V25: =SUM(V20:V24) -> 283.68 | W25: =SUM(W20:W24) -> 0 | X25: =SUM(X20:X24) -> 0 | Y25: =SUM(Y20:Y24) -> 0
B26: Weight (Kg/m) | R26: =6*6/162.162 -> 0.22200022 | S26: =8*8/162.162 -> 0.39466706 | T26: =10*10/162.162 -> 0.61666728 | U26: =12*12/162.162 -> 0.88800089 | V26: =16*16/162.162 -> 1.5786682 | W26: =20*20/162.162 -> 2.4666691 | X26: =25*25/162.162 -> 3.8541705 | Y26: =32*32/162.162 -> 6.314673
B27: TOTAL (Kg) | R27: =+R26*R25 -> 0 | S27: =+S26*S25 -> 0 | T27: =+T26*T25 -> 0 | U27: =+U26*U25 -> 0 | V27: =+V26*V25 -> 447.83661 | W27: =+W26*W25 -> 0 | X27: =+X26*X25 -> 0 | Y27: =+Y26*Y25 -> 0 | Z27: =Y27+X27+W27+V27+U27+T27+S27+R27 -> 447.83661
B30: Plinth Beam
B31: pb 300X300 | C31: a | D31: T16 | E31: 1 | F31: 4 | G31: =F31*E31 -> 4 | I31: =M31+N31+O31+P31+Q31 -> 179 | J31: =G31*I31 -> 716 | K31: =K27*0.888 -> 0 | M31: 179 | R31: =IF(D31="R6",J31," ") | S31: =IF(D31="R8",J31," ") | T31: =IF(D31="T10",J31," ") | U31: =IF(D31="T12",J31," ") | V31: =IF(D31="T16",J31," ") -> 716 | W31: =IF(D31="T20",J31," ") | X31: =IF(D31="T25",J31," ") | Y31: =IF(D31="T32",J31," ")
B32: pb 225X300 | C32: a | D32: T16 | E32: 1 | F32: 4 | G32: =F32*E32 -> 4 | I32: =M32+N32+O32+P32+Q32 -> 48 | J32: =G32*I32 -> 192 | K32: =K28*0.888 -> 0 | M32: 48 | R32: =IF(D32="R6",J32," ") | S32: =IF(D32="R8",J32," ") | T32: =IF(D32="T10",J32," ") | U32: =IF(D32="T12",J32," ") | V32: =IF(D32="T16",J32," ") -> 192 | W32: =IF(D32="T20",J32," ") | X32: =IF(D32="T25",J32," ") | Y32: =IF(D32="T32",J32," ")
B34: Total length (m) | R34: =SUM(R29:R33) -> 0 | S34: =SUM(S29:S33) -> 0 | T34: =SUM(T29:T33) -> 0 | U34: =SUM(U29:U33) -> 0 | V34: =SUM(V29:V33) -> 908 | W34: =SUM(W29:W33) -> 0 | X34: =SUM(X29:X33) -> 0 | Y34: =SUM(Y29:Y33) -> 0
B35: Weight (Kg/m) | R35: =6*6/162.162 -> 0.22200022 | S35: =8*8/162.162 -> 0.39466706 | T35: =10*10/162.162 -> 0.61666728 | U35: =12*12/162.162 -> 0.88800089 | V35: =16*16/162.162 -> 1.5786682 | W35: =20*20/162.162 -> 2.4666691 | X35: =25*25/162.162 -> 3.8541705 | Y35: =32*32/162.162 -> 6.314673
B36: TOTAL (Kg) | R36: =+R35*R34 -> 0 | S36: =+S35*S34 -> 0 | T36: =+T35*T34 -> 0 | U36: =+U35*U34 -> 0 | V36: =+V35*V34 -> 1433.4308 | W36: =+W35*W34 -> 0 | X36: =+X35*X34 -> 0 | Y36: =+Y35*Y34 -> 0 | Z36: =Y36+X36+W36+V36+U36+T36+S36+R36 -> 1433.4308
B38: Column shaft -DPC -1st
B39: C1 | C39: a | D39: T16 | E39: 32 | F39: 4 | G39: =F39*E39 -> 128 | I39: =M39+N39+O39+P39+Q39 -> 4 | J39: =G39*I39 -> 512 | K39: =K35*0.888 -> 0 | M39: 4 | R39: =IF(D39="R6",J39," ") | S39: =IF(D39="R8",J39," ") | T39: =IF(D39="T10",J39," ") | U39: =IF(D39="T12",J39," ") | V39: =IF(D39="T16",J39," ") -> 512 | W39: =IF(D39="T20",J39," ") | X39: =IF(D39="T25",J39," ") | Y39: =IF(D39="T32",J39," ")
B40: C2 | C40: a | D40: T16 | E40: 4 | F40: 4 | G40: =F40*E40 -> 16 | I40: =M40+N40+O40+P40+Q40 -> 4 | J40: =G40*I40 -> 64 | K40: =K36*0.888 -> 0 | M40: 4 | R40: =IF(D40="R6",J40," ") | S40: =IF(D40="R8",J40," ") | T40: =IF(D40="T10",J40," ") | U40: =IF(D40="T12",J40," ") | V40: =IF(D40="T16",J40," ") -> 64 | W40: =IF(D40="T20",J40," ") | X40: =IF(D40="T25",J40," ") | Y40: =IF(D40="T32",J40," ")
B42: Total length (m) | R42: =SUM(R37:R41) -> 0 | S42: =SUM(S37:S41) -> 0 | T42: =SUM(T37:T41) -> 0 | U42: =SUM(U37:U41) -> 0 | V42: =SUM(V37:V41) -> 576 | W42: =SUM(W37:W41) -> 0 | X42: =SUM(X37:X41) -> 0 | Y42: =SUM(Y37:Y41) -> 0
B43: Weight (Kg/m) | R43: =6*6/162.162 -> 0.22200022 | S43: =8*8/162.162 -> 0.39466706 | T43: =10*10/162.162 -> 0.61666728 | U43: =12*12/162.162 -> 0.88800089 | V43: =16*16/162.162 -> 1.5786682 | W43: =20*20/162.162 -> 2.4666691 | X43: =25*25/162.162 -> 3.8541705 | Y43: =32*32/162.162 -> 6.314673
B44: TOTAL (Kg) | R44: =+R43*R42 -> 0 | S44: =+S43*S42 -> 0 | T44: =+T43*T42 -> 0 | U44: =+U43*U42 -> 0 | V44: =+V43*V42 -> 909.31291 | W44: =+W43*W42 -> 0 | X44: =+X43*X42 -> 0 | Y44: =+Y43*Y42 -> 0 | Z44: =Y44+X44+W44+V44+U44+T44+S44+R44 -> 909.31291
B47: G/F beam
B48: 1,7 A1-C | C48: B | D48: T16 | E48: 2 | F48: 2 | G48: =F48*E48 -> 4 | I48: =M48+N48+O48+P48+Q48 -> 12.75 | J48: =G48*I48 -> 51 | K48: =K44*0.888 -> 0 | M48: 12.75 | R48: =IF(D48="R6",J48," ") | S48: =IF(D48="R8",J48," ") | T48: =IF(D48="T10",J48," ") | U48: =IF(D48="T12",J48," ") | V48: =IF(D48="T16",J48," ") -> 51 | W48: =IF(D48="T20",J48," ") | X48: =IF(D48="T25",J48," ") | Y48: =IF(D48="T32",J48," ")
C49: T | D49: T16 | E49: 2 | F49: 2 | G49: =F49*E49 -> 4 | I49: =M49+N49+O49+P49+Q49 -> 12.75 | J49: =G49*I49 -> 51 | K49: =K45*0.888 -> 0 | M49: 12.75 | R49: =IF(D49="R6",J49," ") | S49: =IF(D49="R8",J49," ") | T49: =IF(D49="T10",J49," ") | U49: =IF(D49="T12",J49," ") | V49: =IF(D49="T16",J49," ") -> 51 | W49: =IF(D49="T20",J49," ") | X49: =IF(D49="T25",J49," ") | Y49: =IF(D49="T32",J49," ")
C50: T | D50: T16 | E50: 2 | F50: 1 | G50: =F50*E50 -> 2 | I50: =M50+N50+O50+P50+Q50 -> 1.8 | J50: =G50*I50 -> 3.6 | K50: =K46*0.888 -> 0 | M50: 1.8 | R50: =IF(D50="R6",J50," ") | S50: =IF(D50="R8",J50," ") | T50: =IF(D50="T10",J50," ") | U50: =IF(D50="T12",J50," ") | V50: =IF(D50="T16",J50," ") -> 3.6 | W50: =IF(D50="T20",J50," ") | X50: =IF(D50="T25",J50," ") | Y50: =IF(D50="T32",J50," ")
C51: T | D51: T16 | E51: 2 | F51: 2 | G51: =F51*E51 -> 4 | I51: =M51+N51+O51+P51+Q51 -> 2.95 | J51: =G51*I51 -> 11.8 | K51: =K47*0.888 -> 0 | M51: 2.95 | R51: =IF(D51="R6",J51," ") | S51: =IF(D51="R8",J51," ") | T51: =IF(D51="T10",J51," ") | U51: =IF(D51="T12",J51," ") | V51: =IF(D51="T16",J51," ") -> 11.8 | W51: =IF(D51="T20",J51," ") | X51: =IF(D51="T25",J51," ") | Y51: =IF(D51="T32",J51," ")
C52: T | D52: T16 | E52: 2 | F52: 2 | G52: =F52*E52 -> 4 | I52: =M52+N52+O52+P52+Q52 -> 2.95 | J52: =G52*I52 -> 11.8 | K52: =K48*0.888 -> 0 | M52: 2.95 | R52: =IF(D52="R6",J52," ") | S52: =IF(D52="R8",J52," ") | T52: =IF(D52="T10",J52," ") | U52: =IF(D52="T12",J52," ") | V52: =IF(D52="T16",J52," ") -> 11.8 | W52: =IF(D52="T20",J52," ") | X52: =IF(D52="T25",J52," ") | Y52: =IF(D52="T32",J52," ")
...

Sheet M sheet- dodangoda (2)
A1: NO | B1: DESCRIPTION | C1: NOS | F1: LENGTH | G1: WIDTH | H1: HEIGHT | I1: QTY | J1: T.QTY | O1: UNIT
K2: 1.1
K3: =$K$2 -> 1.1 | L3: =K3*J3 -> 0 | M3: =ROUND(L3,1) -> 0 | N3: =ROUNDUP(M3,0) -> 0 | P3: 1.1
B4: top soil remove | J4: 615 | K4: 1.03 | L4: =K4*J4 -> 633.45 | M4: =ROUND(L4,1) -> 633.5 | N4: =ROUNDUP(M4,0) -> 634
K5: =$K$2 -> 1.1 | L5: =K5*J5 -> 0 | M5: =ROUND(L5,1) -> 0 | N5: =ROUNDUP(M5,0) -> 0
K6: =$K$2 -> 1.1 | L6: =K6*J6 -> 0 | M6: =ROUND(L6,1) -> 0 | N6: =ROUNDUP(M6,0) -> 0
B7: anti termite | J7: 290 | K7: =$K$2 -> 1.1 | L7: =K7*J7 -> 319 | M7: =ROUND(L7,1) -> 319 | N7: =ROUNDUP(M7,0) -> 319
J8: =J7*10.76 -> 3120.4 | K8: =$K$2 -> 1.1 | L8: =K8*J8 -> 3432.44 | M8: =ROUND(L8,1) -> 3432.4 | N8: =ROUNDUP(M8,0) -> 3433
K9: =$K$2 -> 1.1 | L9: =K9*J9 -> 0 | M9: =ROUND(L9,1) -> 0 | N9: =ROUNDUP(M9,0) -> 0
K10: =$K$2 -> 1.1 | L10: =K10*J10 -> 0 | M10: =ROUND(L10,1) -> 0 | N10: =ROUNDUP(M10,0) -> 0
K11: =$K$2 -> 1.1 | L11: =K11*J11 -> 0 | M11: =ROUND(L11,1) -> 0 | N11: =ROUNDUP(M11,0) -> 0
K12: =$K$2 -> 1.1 | L12: =K12*J12 -> 0 | M12: =ROUND(L12,1) -> 0 | N12: =ROUNDUP(M12,0) -> 0
K13: =$K$2 -> 1.1 | L13: =K13*J13 -> 0 | M13: =ROUND(L13,1) -> 0 | N13: =ROUNDUP(M13,0) -> 0
K14: =$K$2 -> 1.1 | L14: =K14*J14 -> 0 | M14: =ROUND(L14,1) -> 0 | N14: =ROUNDUP(M14,0) -> 0
K15: =$K$2 -> 1.1 | L15: =K15*J15 -> 0 | M15: =ROUND(L15,1) -> 0 | N15: =ROUNDUP(M15,0) -> 0
K16: =$K$2 -> 1.1 | L16: =K16*J16 -> 0 | M16: =ROUND(L16,1) -> 0 | N16: =ROUNDUP(M16,0) -> 0
K17: =$K$2 -> 1.1 | L17: =K17*J17 -> 0 | M17: =ROUND(L17,1) -> 0 | N17: =ROUNDUP(M17,0) -> 0
K18: =$K$2 -> 1.1 | L18: =K18*J18 -> 0 | M18: =ROUND(L18,1) -> 0 | N18: =ROUNDUP(M18,0) -> 0
K19: =$K$2 -> 1.1 | L19: =K19*J19 -> 0 | M19: =ROUND(L19,1) -> 0 | N19: =ROUNDUP(M19,0) -> 0
K20: =$K$2 -> 1.1 | L20: =K20*J20 -> 0 | M20: =ROUND(L20,1) -> 0 | N20: =ROUNDUP(M20,0) -> 0
... K532: =$K$2 -> 1.1 | L532: =K532*J532 -> 0 | M532: =ROUND(L532,1) -> 0 | N532: =ROUNDUP(M532,0) -> 0
A534: 1 | B534: clearing site vegetation | F534: =60+9 -> 69 | G534: =21+6 -> 27 | I534: =G534*F534 -> 1863 | J534: =I534 -> 1863 | K534: =$K$2 -> 1.1 | L534: =K534*J534 -> 2049.3 | M534: =ROUND(L534,1) -> 2049.3 | N534: =ROUNDUP(M534,0) -> 2050 | O534: m2
J535: =J534*10.76 -> 20045.88 | K535: =$K$2 -> 1.1 | L535: =K535*J535 -> 22050.468 | M535: =ROUND(L535,1) -> 22050.5 | N535: =ROUNDUP(M535,0) -> 22051 | O535: ft2 | P535: =J534/9.29 -> 200.53821
J536: =J535/100 -> 200.4588 | K536: 1.03 | L536: =K536*J536 -> 206.47256 | M536: =ROUND(L536,1) -> 206.5 | N536: =ROUNDUP(M536,0) -> 207 | O536: sqr
K537: =$K$2 -> 1.1 | L537: =K537*J537 -> 0 | M537: =ROUND(L537,1) -> 0 | N537: =ROUNDUP(M537,0) -> 0
B538: top soil remove | F538: 60 | G538: 21 | I538: =G538*F538 -> 1260 | J538: =I538 -> 1260 | K538: =$K$2 -> 1.1 | L538: =K538*J538 -> 1386 | M538: =ROUND(L538,1) -> 1386 | N538: =ROUNDUP(M538,0) -> 1386 | O538: m2
J539: =J538*10.76 -> 13557.6 | K539: =$K$2 -> 1.1 | L539: =K539*J539 -> 14913.36 | M539: =ROUND(L539,1) -> 14913.4 | N539: =ROUNDUP(M539,0) -> 14914 | O539: ft2
J540: =J539/100 -> 135.576 | K540: 1.05 | L540: =K540*J540 -> 142.3548 | M540: =ROUND(L540,1) -> 142.4 | N540: =ROUNDUP(M540,0) -> 143 | O540: sqr | P540: =N540-J540 -> 7.424
K541: =$K$2 -> 1.1 | L541: =K541*J541 -> 0 | M541: =ROUND(L541,1) -> 0 | N541: =ROUNDUP(M541,0) -> 0
B542: approved earth piled at site | F542: =F538 -> 60 | G542: =G538 -> 21 | H542: 1.5 | I542: =H542*G542*F542 -> 1890 | J542: =I542 -> 1890 | K542: =$K$2 -> 1.1 | L542: =K542*J542 -> 2079 | M542: =ROUND(L542,1) -> 2079 | N542: =ROUNDUP(M542,0) -> 2079 | O542: m3
J543: =J542/2.83 -> 667.84452 | K543: 1.05 | L543: =K543*J543 -> 701.23675 | M543: =ROUND(L543,1) -> 701.2 | N543: =ROUNDUP(M543,0) -> 702 | O543: cube | P543: =N543-J543 -> 34.155477
K544: =$K$2 -> 1.1 | L544: =K544*J544 -> 0 | M544: =ROUND(L544,1) -> 0 | N544: =ROUNDUP(M544,0) -> 0
B545: back filling | K545: =$K$2 -> 1.1 | L545: =K545*J545 -> 0 | M545: =ROUND(L545,1) -> 0 | N545: =ROUNDUP(M545,0) -> 0
K546: =$K$2 -> 1.1 | L546: =K546*J546 -> 0 | M546: =ROUND(L546,1) -> 0 | N546: =ROUNDUP(M546,0) -> 0
K547: =$K$2 -> 1.1 | L547: =K547*J547 -> 0 | M547: =ROUND(L547,1) -> 0 | N547: =ROUNDUP(M547,0) -> 0
B548: anti termite | F548: =F542 -> 60 | G548: =G542 -> 21 | I548: =G548*F548 -> 1260 | J548: =I548 -> 1260 | K548: =$K$2 -> 1.1 | L548: =K548*J548 -> 1386 | M548: =ROUND(L548,1) -> 1386 | N548: =ROUNDUP(M548,0) -> 1386
J549: =J548*10.76 -> 13557.6 | K549: 1.01 | L549: =K549*J549 -> 13693.176 | M549: =ROUND(L549,1) -> 13693.2 | N549: =ROUNDUP(M549,0) -> 13694 | P549: =N549-J549 -> 136.4
K550: =$K$2 -> 1.1 | L550: =K550*J550 -> 0 | M550: =ROUND(L550,1) -> 0 | N550: =ROUNDUP(M550,0) -> 0
K551: =$K$2 -> 1.1 | L551: =K551*J551 -> 0 | M551: =ROUND(L551,1) -> 0 | N551: =ROUNDUP(M551,0) -> 0
B552: excvtion
...

Sheet front
J6: =450*4 -> 1800
A10: BILLS OF QUANTITIES
A12: CONSTRUCTION OF PROPOSED RESIDENT PROJECT FOR MR.ROLF AT HIKKADUWA. | N12: =#REF!*45 -> #REF! | O12: =310 -> 310 | P12: =N12-O12 -> #REF! | S12: =19.5*2 -> 39
S13: =S12*5 -> 195
O15: =O12/45 -> 6.8888889
O16: =O15*338 -> 2328.4444 | S16: =S13/45 -> 4.3333333
S17: =S16*338 -> 1464.6667
S18: =S17*5 -> 7323.3333
B61: 180000
B62: =B61*12 -> 2160000
B63: =B62/300 -> 7200
B65: 100000
B66: =B65*12 -> 1200000
B67: =B66/300 -> 4000
B70: =B62-B66 -> 960000

Sheet grnd summry- tender
A1: CONSTRUCTION OF PROPOSED RESIDENT PROJECT FOR MR.ROLF AT HIKKADUWA. | M1: =1850+2500 -> 4350 | N1: =M1*1.25 -> 5437.5
A2: MAIN SUMMARY | D2: 200000000 | E2: 100000000
A3: BILL NO | B3: DESCRIPTION | C3: AMOUNT (Rs.) | H3: =C7+#REF! -> #REF! | K3: =C9/9 -> 5274321.5
D4: =D2*0.2 -> 40000000
A5: Bill No. 01 | B5: PRELIMINARIES | C5: =+prelims!I135 -> 318750 | D5: =D2*0.05 -> 10000000 | E5: =C5/C7*100 -> 0.67603188 | G5: =C5/C7 -> 0.0067603188 | H5: =C7+C15+#REF! -> #REF! | I5: =C5/H5*100 -> #REF! | J5: =C5/H3*100 -> #REF!
A7: Bill No. 02 | B7: MAIN BUILDING | C7: =+summary!C19 -> 47150143 | D7: =SUM(D4:D5) -> 50000000 | E7: =C5/E2*100 -> 0.31875 | H7: =60000000-C5 -> 59681250 | I7: =SUM(C7:C15) -> 1.4358793e+08 | M7: =1850/10.76 -> 171.93309
K8: =#REF!*8500 -> #REF! | M8: =4399 -> 4399
B9: SUB TOTAL-I | C9: =SUM(C4:C7) -> 47468893 | D9: =C5+C7 -> 47468893 | I9: =C9-summary!#REF!-'grnd summry- tender'!#REF! -> #REF! | K9: =C9*0.95 -> 45095449 | L9: =C9/9000 -> 5274.3215
E10: =52*3.9*0.3 -> 60.84
B11: Less : Discount (If any) | E11: =E10*21500 -> 1308060
G12: =1650/350 -> 4.7142857
B13: SUB TOTAL-II-CARRIED TO FORM OF BID | C13: =SUM(C9) -> 47468893 | D13: 2.0491928e+08 | E13: =59*3.9*2 -> 460.2
D14: =C13-D13 -> -1.5745038e+08 | E14: =E13*1450 -> 667290
A15: Bill No. 03 | B15: PROVISIONAL SUM | C15: =Ps!H9 -> 1500000 | H15: =SUM(C5:C7) -> 47468893 | I15: =SUM(C9:C15) -> 96437786 | J15: =C13/9000 -> 5274.3215 | K15: =9000*9100 -> 81900000
E16: =E10*95 -> 5779.8
B17: SUB TOTAL III | C17: =SUM(C13:C15) -> 48968893 | D17: ='[19]grnd summry- tender'!$C$13 -> 52997390 | E17: =E16*282 -> 1629903.6
G18: =2022-18 -> 2004
A19: Bill No. 05 | B19: ADD- CONTINGENCIES- 10% | D19: =D17+C17 -> 1.0196628e+08 | E19: =E17+E14+E11+#REF! -> #REF! | H19: =SUM(C7:C8) -> 47150143 | I19: =SUM(C9:C19) -> 1.4540668e+08 | J19: =C15/9000 -> 166.66667 | K19: =9000*9100 -> 81900000
B21: SUB TOTAL IV | C21: =+C17 -> 48968893 | I21: =C5/C7*100 -> 0.67603188 | J21: =H7*3% -> 1790437.5 | K21: =C5/H7*100 -> 0.53408734 | M21: =H7*0.0486 -> 2900508.8 | N21: =C21-#REF! -> #REF!
A23: NOTE: - price exclude to excavation (excavation, dry earth filling, back filing) work, random rubble masonry work and concrete ( concrete, formwork,reinforcement)work
B25: ADD 15% VAT | C25: =C21*0.15 -> 7345334 | D25: =D19*1.08 -> 1.1012359e+08 | E25: =C9/24 -> 1977870.6 | L25: =10000*2*12 -> 240000
I26: =C7+C5 -> 47468893 | N26: =#REF!/187 -> #REF!
B27: TOTAL PROJECT COST WITH VAT | C27: =C21+C25 -> 56314227 | L27: =SUM(L25:L26) -> 240000
F28: =34+6 -> 40 | I28: =I26/9000 -> 5274.3215
A29: Total Bid Sum to be taken in to Form of Bid in words Rupees : …………………………………….
A30: …………………………………………………………………………………..…………………..Only
E31: ='[20]grnd summry- tender'!$C$19 -> 2.6071837e+08 | K31: =C13-C73 -> -12531107
A33: Bidder's VAT Registration No: ………………………………...………………
E34: =C17-E31 -> -2.1174948e+08 | I34: 90875054
K35: =K31*1.44% -> -180447.94
A36: ……………………….
A37: Signature of Bidder: Date: ……………………………….
G38: 2600000
G39: =G38*0.2 -> 520000
A40: Name and Address of Bidder:
A41: ………………………………………………………………….……….
A42: ……………………………………………….………………………….
A43: ………………………………………………………………….……….
A46: ……………………………. ……………………………….
A47: Signature of Witness: (1) Signature of Witness: (2) | E47: =6000*13500 -> 81000000 | F47: 40000000
...

Sheet prelims
A1: Nos | B1: Description | C1: Mode of payment catogary | D1: Qty | E1: Unit | F1: Cost | G1: OH & P% | H1: Rate ( Rs.) | I1: Amount | J1: 0.8
B2: BILL NO. 01
A3: 1/PR | B3: A - PRELIMINARIES
B5: This Bill Provides for the typical general items complimentary to the works wich are required to be provided by the Contractor in compliance with the Conditions of Contract and Contract Data in the execution of the works according to the Contract.
B7: If the Engineer is of the opinion that any item in this section has not been provided fully by the Contractor the Engineer may adjust the amounts quoted by the Contractor for the items concerned
B9: Reimbursement of actual cost on submission of the relevant document acceptable to the Engineer plus 5% of the actual cost of obtaining the insurance policies and securities
B11: Mode of Payment Category
B12: Reimbursement of actual cost on submission of A
B13: the relavent document acceptable to the
B14: engineering plus 5% of the actaul cost of obtaining
B15: the insurance policies and securities
B17: To be paid on signal of the format contract B
B18: agreement
B20: 60% on completion of temporary building or C
B21: structures. 30% in equl installments over the
... B36: The Bidder is fully responsible for identiflying the limitataions, restrictions and difficulties imposed due to the locally of the site and its environs and should include in his prices for all contingencies that may arise as a result
A38: 1 | B38: Insurance and Securities
A40: =A38+0.01 -> 1.01 | B40: Allow sum for providing performance security | C40: A | D40: 1 | E40: Item | I40: N/A
A42: =A40+0.01 -> 1.02 | B42: Allow sum for providing advance payment security | C42: A | D42: 1 | E42: Item | I42: N/A
A44: =A42+0.01 -> 1.03 | B44: Allow Sum for insurance of Works, Machinery & Equipment, Plant, Materials, Third party persons & property and Eimployer's personal & property at site per the Contract | C44: A | D44: 1 | E44: Item | I44: N/A
B46: The minimim insurance.cover shall be:
B48: The minimum cover for insurance of the Works and Plant and Materials is 110% of the Initial Controct Price.
B50: The maximum deductible for insurance uf the Works and of Plant and Materials is 5% of the Initial Contract Price.
B52: The minimunm cover for loss or damage to Equipment is the replacement cost
B54: The maximum deductible for insurance of Equipment is 5% of minimun cover for equipment.
B56: The minimum cover for insurance of (orher propert other than the site) is Ra. 2Million per event and totul limit of indemnity shall be Rs 10 Million
B58: The mininum cover for insurance of personal injury or death.
B60: For third party and employees of the Employer and other persons engaged by the Employer in the Works is Rs.5,000,000/- per event
B62: Injury or damage to persons including employer and consultant and their employees and other consultants employed by the employer shall be covered by the personnel accident insurance cover for Rs 2 million per event effective from the date of commencement of contract until end of the defects liability period (total number of persons insured are not exceeding 10 nrs)
A64: =A44+0.01 -> 1.04 | B64: Allow Sum for insurance against accidents and injury to Contractor's personnel as per the Contract. | C64: A | D64: 1 | E64: Item | I64: N/A
B66: The iminimum cover for personal injury or death
B67: For the Contractor's workmen is Rs. 500,000/= per event
B68: Contractor s employees other than workmen is Rs.5.000.000/= per event
A70: 2 | B70: Engineer's Facilities
A72: =A70+0.01 -> 2.01 | B72: Allow lump sum for constructing, maintaining, dismantling and removal on completion of the Works, a temporary air conditioned TFU for Engineer's office with toilet,elecricity facility in conformity with the plans provided for Engineer's requirements, including furniture and fittings, furnishing, sanitary facilities necessary and other facilities. | C72: C | D72: 1 | E72: Item
B73: The follwing facilities shall be provided
B74: (1) 2-0"x4-0" Table with drawers for Engineer's representative with medium back chair
B75: (2) Chair for Engineer's Representative( two nr of low back chair)
B76: (3) lockable Cupboard for storage of drawings, documents and stationery
B77: (4) Pedestal fan
...

Sheet summary
A2: COLLECTION BILL NO.02 - MAIN BUILDING
A4: Nos | B4: Description | C4: Amount
A7: B | B7: =exca!B2 -> B - EXCAVATION & EARTH WORK | C7: =+exca!H57 -> 733800 | D7: 0.75
A8: F | B8: =masnry!B2 -> F - MASONRY WORKS | C8: =+masnry!H44 -> 5928300 | D8: 0.75
A9: G | B9: =flooring!B2 -> J - FLOORING WORK | C9: =+flooring!H11 -> 201660 | D9: 0.75
A10: H | B10: =waterprof!B2 -> E - WATER PROOFING WORK | C10: =+waterprof!H50 -> 947610 | D10: 0.8
A11: J | B11: =plastering!B2 -> K - PLASTERING WORK | C11: =+plastering!H62 -> 4495240 | D11: 0.75
A12: K | B12: =tile!B2 -> L - TILING WORK | C12: =+tile!H278 -> 8817580 | D12: 0.85
A13: L | B13: =paint!B2 -> M - COLOUR WASHING, PAINTING & POLISHING | C13: =+paint!H25 -> 2418543.2 | D13: 0.75
A14: Q | B14: =plumbing!B2 -> S - PLUMBING AND DRAINAGE WORK | C14: =+plumbing!H235 -> 2545670 | D14: 0.85
A15: S | B15: =electicle!B2 -> V - ELECTRICAL INSTALLATION. | C15: =+'electicle '!H302 -> 6307830 | D15: 0.8
A16: T | B16: =metal!B2 -> W - METAL WORK | C16: =+metal!H160 -> 10787630 | D16: 0.9
A17: U | B17: =roof!B2 -> Q - ROOFING AND CEILING | C17: =+roof!H4 -> 3966280 | D17: 0.85
B19: TOTAL CARRIED TO GRAND SUMMARY | C19: =SUM(C6:C17) -> 47150143
B36: bank washroom partition extend to wall | C36: 690 | E36: =C6+C7+#REF!+C8+C9+C10+C11+C12+C13+#REF!+C14+C15+C16+#REF!+#REF! -> #REF!
B37: hall dooe change to glazed to timber | C37: 1360
B38: second floor slab canteliver | C38: 1360
B39: first floor shops to civerd material? 20/9 | C39: 650
C42: =SUM(C36:C41) -> 4060
C45: =C19/C42 -> 11613.336

Sheet exca
A1: Nos | B1: Description | C1: Qty | D1: Unit | E1: Cost | F1: OH & P % | G1: Rate | H1: Amount | I1: =+summary!D7 -> 0.75
B2: B - EXCAVATION & EARTH WORK
B3: SITE PREPERATION
B4: Note :
B5: For the full description of materials
B6: and workmanship refer "Specification
B7: of works", "Pricing Preambles" and
B8: "Drawings".
A10: B 01 | B10: Clearing site vegetation manually including removal of bushes, shurb removing rubbish. | C10: 300 | D10: Sqm | E10: 1000 | F10: =+I1 -> 0.75 | G10: =ROUNDUP(E10/F10,-1) -> 1340 | H10: =C10*G10 -> 402000 | J10: =+C10*10.76 -> 3228
A12: B 02 | B12: Removing top soil including mud, machinery to a nessasary depth and removing all debris away from site, location decided by client withing 3 km | C12: 300 | D12: Sqm | E12: =+[21]RBD!$F$95 -> 278 | F12: =+$I$1 -> 0.75 | G12: =ROUNDUP(E12/F12,-1) -> 380 | H12: =C12*G12 -> 114000
B14: EXCAVATION
B16: Note:
B17: All excavations are measured net. No allowance made for working space.
B19: Excavations as follows in any materials met with except in rock requiring blasting.
B21: Excavation for foundation commencing from formed ground level.
A22: B 03 | B22: Excavation for column, wall, staircase foundations in any material (except rock requiring blasting) up to depth (as per the drawings), part return fill in and ram and surplus depositted within site as directed. | D22: m3
B24: Earth Work Supports
A25: B 04 | B25: Temporary earth work supports, in open planking in trenches total depth up todepth (as per the drawings) | D25: Sqm
B27: Filling & Compaction
B28: Note:-
B29: Approved earth shall mean filling materials that comply to the following :
A30: ( a ) | B30: The earth shall be free of vegetation, roots, boulders, easily decomposable materials, chemicals, industrial waste, plastic etc.
A31: ( b ) | B31: The maximum size of particle shall not exceed 75mm.
A32: ( c ) | B32: The earth shall be well graded and the silt and clay (fines) content shall not be more than 25%
A33: ( d ) | B33: The Standerd proctor density shall be grater than 1.70g/cm3
B35: Dry Earth Filling
A36: B 05 | B36: Supplying and compaction of Approved earth,compaction of earth including watering and compaction in 225mm thick layers with proctor density, using machine rammer/roller vibrator, rate to include to compaction maching charges and other nessasary related work | D36: m3
B38: Qurry Dust Filling
B39: Supplying and compaction of qurry dust compaction of earth including watering and compaction in 225mm thick layers with proctor density, using machine rammer/roller vibrator, rate to include to compaction maching charges and other nessasary related work | D39: m3
B45: Back Filling
A46: B 06 | B46: Supplying and compaction of Approved earth,compaction of earth including watering and compaction in 225mm thick layers with proctor density, using machine rammer or roller vibrator, rate to include to compaction maching charges and other nessasary related work | D46: m3
B48: Antitermite -Tretement
A49: B 07 | B49: Antitermite-treatement for the new construction with applying Biflexthrine 10Tc (Biflex ) or approved equivelant , Dialuted chemicals 1:200 ratio with water after supplying the sealed bottle with lables to the site and should be followed the manufacture standards of application including horizontal & vertical barriers. It should be 10 years warranty on application. | C49: 180 | D49: Sqm | E49: =+[21]RBD!$F$146 -> 904 | F49: =+$I$1 -> 0.75 | G49: =ROUNDUP(E49/F49,-1) -> 1210 | H49: =C49*G49 -> 217800
B51: Transport
A52: B 09 | B52: Transport of any Material / Debris by any means in bulk including loading | D52: Item
B54: Water Disposal
A55: B 10 | B55: Disposal of Ground Water and Surface Water | D55: Item
B57: EXCAVATION & EARTH WORK CARRIED TO COLLECTION | H57: =SUM(H9:H56) -> 733800
D89: =600/10.76 -> 55.762082 | I89: =1000/50 -> 20
D90: =D89*0.05 -> 2.7881041 | I90: =50/1000 -> 0.05 | K90: =D90/2.83 -> 0.98519579
...

Sheet masnry
A1: Nos | B1: Description | C1: Qty | D1: Unit | E1: Cost | F1: OH & P% | G1: Rate ( Rs.) | H1: Amount | I1: =+summary!D8 -> 0.75
B2: F - MASONRY WORKS | J2: =2890/338 -> 8.5502959 | P2: =#REF!*100 -> #REF! | Q2: =P2/9.29 -> #REF! | R2: =Q2*0.225 -> #REF! | S2: =R2/2.83 -> #REF! | T2: =S2*N3 -> #REF! | U2: =T2/#REF! -> #REF!
A3: 1 | B3: BRICK MASONRY | N3: 81297 | O3: =N3/12*9 -> 60972.75
B4: Note : | N4: 85362 | O4: =N4/12*9 -> 64021.5 | S4: =#REF!*2.83 -> #REF! | T4: =S4/300*225 -> #REF!
B5: For the full description of materials | N5: 86988 | O5: =N5/12*9 -> 65241 | U5: =#REF!/T4 -> #REF! | W5: 3099 | X5: =W5*#REF! -> #REF!
B6: and workmanship refer "Specification | N6: =N7/10.76 -> #REF! | O6: =#REF!/0.3*0.225 -> #REF! | P6: =O6/9.29 -> #REF! | R6: =#REF!*100 -> #REF!
B7: of works", "Pricing Preambles" and | N7: ='m shet rolf'!#REF! -> #REF! | O7: =#REF!*0.225 -> #REF! | R7: =R6/35.29 -> #REF! | S7: =#REF!*2.83 -> #REF!
B8: "Drawings". | N8: =N7*P6 -> #REF! | U8: =9/12 -> 0.75
B10: Vertical solid walls, 225mm thick. | P10: 27881
A11: =A3+0.01 -> 1.01 | B11: Brick work in cement and sand 1:5 in super Structure in ground floor. ( 9" thick brick work) | C11: ='m shet rolf'!N28 -> 244 | D11: Sqm | E11: =+'Rate Breakdowns'!G592 -> 5802.9333 | F11: =+I1 -> 0.75 | G11: =ROUNDUP(E11/F11,-1) -> 7740 | H11: =C11*G11 -> 1888560 | N11: =G11/4*9 -> 17415 | P11: =P10/4.5*9 -> 55762 | Q11: =P11-#REF! -> #REF! | S11: =+C11*10.76/100 -> 26.2544 | T11: 9.779764 | V11: =G13-G11 -> 40 | W11: 387.4
N12: =N11/9.29 -> 1874.5963 | Q12: =#REF!-#REF! -> #REF! | Y12: =27881 -> 27881
A13: =A11+0.01 -> 1.02 | B13: Brick work in cement and sand 1:5 in First floor level.(9" thick brick work) | C13: ='m shet rolf'!N50 -> 182 | D13: Sqm | E13: =+E11*1.005 -> 5831.9479 | F13: =+$I$1 -> 0.75 | G13: =ROUNDUP(E13/F13,-1) -> 7780 | H13: =C13*G13 -> 1415960 | O13: =G11*1.12 -> 8668.8 | Q13: =G11+Q12 -> #REF! | S13: =+C13*10.76/100 -> 19.5832 | T13: 13.927744 | V13: =G15-G13 -> 40 | W13: 581.1 | Y13: =Y12/4.5*9 -> 55762
Y14: =#REF!/12*9 -> #REF!
A15: =A13+0.01 -> 1.03 | B15: Brick work in cement and sand 1:5 in Second floor level.(9" thick brick work) | C15: ='m shet rolf'!N73 -> 261 | D15: Sqm | E15: =+E11*1.01 -> 5860.9626 | F15: =+$I$1 -> 0.75 | G15: =ROUNDUP(E15/F15,-1) -> 7820 | H15: =C15*G15 -> 2041020 | P15: =#REF!*100 -> #REF! | S15: =+C15*10.76/100 -> 28.0836 | T15: 14.462516 | V15: =#REF!-G15 -> #REF! | W15: 968.5 | Y15: =Y14*#REF! -> #REF!
A17: =A15+0.01 -> 1.04 | B17: Brick work in cement and sand 1:8 in Water tank floor level.(9" thick brick work) | C17: ='m shet rolf'!N75 -> 60 | D17: Sqm | E17: =+E11*1.015 -> 5889.9773 | F17: =+$I$1 -> 0.75 | G17: =ROUNDUP(E17/F17,-1) -> 7860 | H17: =C17*G17 -> 471600
B19: Vertical solid walls, 112.5mm thick.
A21: =A17+0.01 -> 1.05 | B21: Brick work in cement and sand 1:5 in super Structure in ground floor. ( 4 1/2"" thick brick work) | D21: Sqm | N21: =G21/4*9 -> 0 | P21: =P20/4.5*9 -> 0 | Q21: =P21-#REF! -> #REF! | S21: =+C21*10.76/100 -> 0 | T21: 9.779764 | V21: =G23-G21 -> 3960 | W21: 387.4
N22: =N21/9.29 -> 0 | Q22: =#REF!-#REF! -> #REF! | Y22: =27881 -> 27881
A23: =A21+0.01 -> 1.06 | B23: Brick work in cement and sand 1:5 in First floor level( 4 1/2"" thick brick work) | C23: ='m shet rolf'!N81 -> 14 | D23: Sqm | E23: =+'Rate Breakdowns'!G645 -> 2963.6175 | F23: =+$I$1 -> 0.75 | G23: =ROUNDUP(E23/F23,-1) -> 3960 | H23: =C23*G23 -> 55440 | O23: =G21*1.12 -> 0 | Q23: =G21+Q22 -> #REF! | S23: =+C23*10.76/100 -> 1.5064 | T23: 13.927744 | V23: =G25-G23 -> 20 | W23: 581.1 | Y23: =Y22/4.5*9 -> 55762
Y24: =#REF!/12*9 -> #REF!
A25: =A23+0.01 -> 1.07 | B25: Brick work in cement and sand 1:5 in Second floor level.(( 4 1/2"" thick brick work) | C25: =C23 -> 14 | D25: Sqm | E25: =+E23*1.005 -> 2978.4356 | F25: =+$I$1 -> 0.75 | G25: =ROUNDUP(E25/F25,-1) -> 3980 | H25: =C25*G25 -> 55720 | P25: =#REF!*100 -> #REF! | S25: =+C25*10.76/100 -> 1.5064 | T25: 14.462516 | V25: =#REF!-G25 -> #REF! | W25: 968.5 | Y25: =Y24*#REF! -> #REF!
A27: =A25+0.01 -> 1.08 | B27: Brick work in cement and sand 1:8 in Roof floor level.( 4 1/2"" thick brick work) | D27: Sqm
A29: G1.1 | B29: 6" thick cement sand Cellular block wall (blocks confirming to S.L.S. 855 and subject to the approval of sample blocks) in cement and sand mortar 1:5 in ground floor. | D29: Sqm
A31: G1.2 | B31: 6" thick cement sand Cellular block wall (blocks confirming to S.L.S. 855 and subject to the approval of sample blocks) in cement and sand mortar 1:5 in first floor. | D31: Sqm
A33: G1.3 | B33: 4" thick cement sand Cellular block wall (blocks confirming to S.L.S. 855 and subject to the approval of sample blocks) in cement and sand mortar 1:5 in Second FLoor. | D33: Sqm
A35: G1.4 | B35: 4" thick cement sand Cellular block wall (blocks confirming to S.L.S. 855 and subject to the approval of sample blocks) in cement and sand mortar 1:5 in roof FLoor. | D35: Sqm
A36: G1.5 | B36: 4" thick cement sand Cellular block wall (blocks confirming to S.L.S. 855 and subject to the approval of sample blocks) in cement and sand mortar 1:5 in Roof FLoor. | D36: Sqm
A38: G1.5 | B38: 4" thick cement sand Cellular block wall (blocks confirming to S.L.S. 855 and subject to the approval of sample blocks) in cement and sand mortar 1:5 in Fourth FLoor. | D38: Sqm
A40: G1.5 | B40: 4" thick cement sand Cellular block wall (blocks confirming to S.L.S. 855 and subject to the approval of sample blocks) in cement and sand mortar 1:5 in Roof FLoor. | D40: Sqm
B41: H - RUBBLE MASONRY | P41: =#REF!*100 -> #REF!
A42: H 01 | B42: Random rubble (6"-9") masonry in cement mortar 1:5 in wall foundation. | D42: m3 | N42: =27+27+12+12 -> 78 | O42: =N42*1.05 -> 81.9 | P42: =O42/9.29 -> 8.8159311 | S42: =14.36/2.83 -> 5.0742049
B44: MASONRY WORKS CARRIED TO COLLECTION | H44: =SUM(H11:H43) -> 5928300

Sheet flooring
A1: Nos | B1: Description | C1: Qty | D1: Unit | E1: Cost | F1: OH & P% | G1: Rate ( Rs.) | H1: Amount | I1: =+summary!D9 -> 0.75
B2: J - FLOORING WORK
A4: J 01 | B4: 3/4" thick D.P.C. in cement sand 1:3 finished with 2 coats of D.P.C. tar and blinded with sand. | C4: 50 | D4: Sqm | E4: =+'Rate Breakdowns'!G854 -> 1403.0281 | F4: =+$I$1 -> 0.75 | G4: =ROUNDUP(E4/F4,-1) -> 1880 | H4: =C4*G4 -> 94000
A6: J 02 | B6: Gauge 750 polythene damp proof membrane with 6" laps laid under floors. | C6: ='m shet rolf'!N83 -> 222 | D6: Sqm | E6: =+'Rate Breakdowns'!G112 -> 255.65124 | F6: =+$I$1 -> 0.75 | G6: =ROUNDUP(E6/F6,-1) -> 350 | H6: =C6*G6 -> 77700
A8: J 03 | B8: Rendering 1/2" thick in cement sand 1:3 finished smooth with cement slurry without colour pigment and expansion joints filled with construction expansion joint sealent including the cost for cleaning the joints prior application of construction expansion joint sealent by M/s Bitumix or approved equivalent.
B9: Water tank slab/Roof Slab | C9: ='m shet rolf'!N86 -> 14 | D9: Sqm | E9: 1600 | F9: =+$I$1 -> 0.75 | G9: =ROUNDUP(E9/F9,-1) -> 2140 | H9: =C9*G9 -> 29960
B11: FLOORING WORK CARRIED TO COLLECTION | H11: =SUM(H3:H10) -> 201660
C15: =5*8 -> 40
C16: =C15/10.76 -> 3.7174721

Sheet waterprof
A1: Nos | B1: Description | C1: Qty | D1: Unit | E1: Cost | F1: OH & P% | G1: Rate ( Rs.) | H1: Amount | I1: =+summary!D10 -> 0.8
B2: E - WATER PROOFING WORK
B4: The rates for Items are strictly applicable, subject to the fulfillment of the following conditions.
B6: The water proofing material shall conform to relevant British, Euro or ASTM specifications
B8: Recommended Distributors/Agents who are marketing water proofing material/product are 1. M/s Finco Ltd. 2. M/s HE Engineering 3. M/s Ranki International 4. M/s Solico Engineering 5. M/s Sika Lanka
B9: The contractor shall submmit;
B11: (a) A written certificate stating that all material and workmanship are in conformity with the specifications and the manufactures requirements.
B13: (b) The contractor shall jointly with manufacture/supplier of the waterproofing materials shall furnish a warranty to the Employer valid for a period of 10 years after handing over of the work against dampness and/or moisture penetration through treated surfaces due to defective materials and/or workmanship
B15: payments for items shall be made on receipt of above certificate
B17: The rates for items include the cost of surface preparation, ande the cost of protective masonry screed. Appropriate B.S.R. item rate shall be used for protective layer. The approving authority for products shall be the Engineer.
A29: E. 01 | B29: Internal Wet Areas without Exposure to Sunlight Sq.ft. (Cementitious water proofing using Barralastic or approved equivalnt)
B31: Application of cementitious water proofing using Barralastic or approved equivalnt for internal wet areas such as toilet floors and walls (Walls Up to 1.50m) where the surfaces are not directly exposed to sunlight and weathering. Rate shall include to cleaning the substrate and 1:3 cement sand bedding and all other work as per manufacturer's specifications on application and shall include ponding test for a 300mm water height kept for a period of 48 hours for horizontal surfaces.
A32: E. 01.1 | B32: Ground Floor | C32: ='m shet rolf'!N94 -> 19 | D32: S.qm | E32: =+'Rate Breakdowns'!G539 -> 3634.1032 | F32: =+I1 -> 0.8 | G32: =ROUNDUP(E32/F32,-1) -> 4550 | H32: =C32*G32 -> 86450
A33: E. 01.2 | B33: First Floor | C33: ='m shet rolf'!N116 -> 54 | D33: S.qm | E33: =+E32*1.005 -> 3652.2737 | F33: =+$I$1 -> 0.8 | G33: =ROUNDUP(E33/F33,-1) -> 4570 | H33: =C33*G33 -> 246780
A34: E. 01.3 | B34: Second Floor | C34: ='m shet rolf'!N139 -> 36 | D34: S.qm | E34: =+E32*1.01 -> 3670.4443 | F34: =+$I$1 -> 0.8 | G34: =ROUNDUP(E34/F34,-1) -> 4590 | H34: =C34*G34 -> 165240
A35: E. 01.4 | B35: Roof Floor | D35: S.qm
A37: E. 02 | B37: Areas exposed to sunlight (Balconies, Sun-Shades Concrete Gutters etc) (Elastomeric water proofing using thoroseal or approved equivalent.)
B39: Application of two coats of elastomeric water proofing material using thoroseal or approved equivalnt capable to withstand temperature variation for wet areas exposed to sunlight and weathering. ( balconies, sun-shades, concrete gutters etc.) rate shall include for cleaning the substrate and all other work as per manufacturer's specifications on application and shall include ponding test for a 300mm water height kept for a period of 48 hours for horizontal surfaces and cement sand finished with neat finish smooth rendering
A40: E. 02.1 | B40: Ground Floor | D40: S.qm
A41: E. 02.2 | B41: First Floor | C41: ='m shet rolf'!N157 -> 55 | D41: S.qm | E41: =+E33 -> 3652.2737 | F41: =+$I$1 -> 0.8 | G41: =ROUNDUP(E41/F41,-1) -> 4570 | H41: =C41*G41 -> 251350
A42: E. 02.3 | B42: Second Floor | C42: ='m shet rolf'!N162 -> 29 | D42: S.qm | E42: =+E34 -> 3670.4443 | F42: =+$I$1 -> 0.8 | G42: =ROUNDUP(E42/F42,-1) -> 4590 | H42: =C42*G42 -> 133110
A43: E. 02.4 | B43: Roof Floor | C43: =flooring!C9 -> 14 | D43: S.qm | E43: =+E32*1.015 -> 3688.6148 | F43: =+$I$1 -> 0.8 | G43: =ROUNDUP(E43/F43,-1) -> 4620 | H43: =C43*G43 -> 64680
A44: E. 02.5 | B44: Water Tank Floor | D44: S.qm
A45: E 03 | B45: laying of Topseal 3mm thick,Torch-on membrane or any othere quivalent product marketed /installed by a specialist contractor registered at ICTAD under waterproofing category including 1:3 cement,sand protective screed laid to slope.Rate shall include the formation of edges,torch welding and fixing metal stripon vertical walls at termination edges.
A46: E.03.01 | B46: Fourth Floor | D46: S.qm
A47: E.03.02 | B47: Roof Slab | D47: S.qm
A48: E.03.03 | B48: Water Tank/Lift Room Slab | D48: S.qm
B50: WATER PROOFING WORK CARRIED TO COLLECTION | H50: =SUM(H32:H49) -> 947610
H56: =#REF!+H41+H46 -> #REF!

Sheet plastering
A1: Nos | B1: Description | C1: Qty | D1: Unit | E1: Cost | F1: OH & P% | G1: Rate ( Rs.) | H1: Amount | I1: =+summary!D11 -> 0.75
B2: K - PLASTERING WORK
B3: Note:
B4: 1. The rate for plastering items includes the cost of "Febmix"as a workability enhancer.
B6: 2. For coarse textured plaster ( identified as "semi-rough") all the sand should pass through 4.0mm sieve.
P7: =O7*0.6 -> 0 | Q7: =P7*10.76 -> 0
B8: External Plaster | P8: =P7/9.29 -> 0
A9: K 01 | B9: 5/8" thick plastering to plinth wall in cement sand 1:3 including finishing with cement slurry floating. Rate includes cost of "Febmix" as a workability enhancer. | C9: 52 | D9: S.qm | E9: =+'Rate Breakdowns'!G703 -> 1874.5358 | F9: =+$I$1 -> 0.75 | G9: =ROUNDUP(E9/F9,-1) -> 2500 | H9: =C9*G9 -> 130000
A11: K 02 | B11: Plastering 5/8" thick to walls in cement and sand 1:5 finished semi-rough. Rate includes cost of "Febmix"as a workability enhancer.
A12: K2.1 | B12: In Ground floor | C12: ='m shet rolf'!N178 -> 133 | D12: S.qm | E12: =+'Rate Breakdowns'!G767 -> 1871.1632 | F12: =+$I$1 -> 0.75 | G12: =ROUNDUP(E12/F12,-1) -> 2500 | H12: =C12*G12 -> 332500
A13: K2.2 | B13: In First floor | C13: ='m shet rolf'!N204 -> 182 | D13: S.qm | E13: =+E12*1.01 -> 1889.8748 | F13: =+$I$1 -> 0.75 | G13: =ROUNDUP(E13/F13,-1) -> 2520 | H13: =C13*G13 -> 458640
A14: K2.3 | B14: In Second Floor | C14: ='m shet rolf'!N227 -> 152 | D14: S.qm | E14: =+E12*1.02 -> 1908.5865 | F14: =+$I$1 -> 0.75 | G14: =ROUNDUP(E14/F14,-1) -> 2550 | H14: =C14*G14 -> 387600
A15: K2.4 | B15: In Water Tank Floor | C15: ='m shet rolf'!N240 -> 52 | D15: S.qm | E15: =+E12*1.03 -> 1927.2981 | F15: =+$I$1 -> 0.75 | G15: =ROUNDUP(E15/F15,-1) -> 2570 | H15: =C15*G15 -> 133640
A17: K 03 | B17: External revels
A18: K 03.1 | B18: Plastering 5/8" thick to reveals in ground floor in cement and sand 1:5 finished semi-rough. Rate includes cost of "Febmix"as a workability enhancer. | C18: ='m shet rolf'!N191 -> 116 | D18: L.m | E18: 600 | F18: =+$I$1 -> 0.75 | G18: =ROUNDUP(E18/F18,-1) -> 800 | H18: =C18*G18 -> 92800
A20: K 03.2 | B20: Plastering 5/8" thick to reveals in first floor in cement and sand 1:5 finished semi-rough in first floor. Rate includes cost of "Febmix"as a workability enhancer. | C20: ='m shet rolf'!N215 -> 110 | D20: L.m | E20: 630 | F20: =+$I$1 -> 0.75 | G20: =ROUNDUP(E20/F20,-1) -> 840 | H20: =C20*G20 -> 92400
A22: K 03.3 | B22: Plastering 5/8" thick to reveals in second floor in cement and sand 1:5 finished semi-rough in Second floor. Rate includes cost of "Febmix"as a workability enhancer. | C22: ='m shet rolf'!N238 -> 115 | D22: L.m | E22: 660 | F22: =+$I$1 -> 0.75 | G22: =ROUNDUP(E22/F22,-1) -> 880 | H22: =C22*G22 -> 101200
A24: K 03.4 | B24: Plastering 5/8" thick to reveals in third floor in cement and sand 1:5 finished semi-rough in third floor. Rate includes cost of "Febmix"as a workability enhancer. | D24: L.m
A26: K 03.5 | B26: Plastering 5/8" thick to reveals in roof floor in cement and sand 1:5 finished semi-rough in Fourth floor. Rate includes cost of "Febmix"as a workability enhancer. | D26: L.m
B35: Internal Plaster
A36: K 04 | B36: Plastering 5/8" thick to walls,columns in cement and sand 1:5 finished smooth with two coats of skim coat.
A37: K4.1 | B37: In Ground floor | C37: ='m shet rolf'!N259 -> 258 | D37: S.qm | E37: =+'Rate Breakdowns'!G739 -> 1531.5225 | F37: =+$I$1 -> 0.75 | G37: =ROUNDUP(E37/F37,-1) -> 2050 | H37: =C37*G37 -> 528900
A38: K4.2 | B38: In First floor | C38: ='m shet rolf'!N289 -> 298 | D38: S.qm | E38: =+E37*1.005 -> 1539.1801 | F38: =+$I$1 -> 0.75 | G38: =ROUNDUP(E38/F38,-1) -> 2060 | H38: =C38*G38 -> 613880
A39: K4.3 | B39: in Second Floor | C39: ='m shet rolf'!N314 -> 333 | D39: S.qm | E39: =+E37*1.01 -> 1546.8377 | F39: =+$I$1 -> 0.75 | G39: =ROUNDUP(E39/F39,-1) -> 2070 | H39: =C39*G39 -> 689310
A40: K4.4 | B40: In Third Floor | D40: S.qm
A42: K 05 | B42: Internal Revels
A43: K 05.1 | B43: Plastering 5/8" thick to reveals in ground floor in cement andsand 1:5 finished smooth with two coats of skim coat in ground floor.Rate includes cost of "Febmix"as a workability enhancer. | C43: ='m shet rolf'!N276 -> 163 | D43: =D20 -> L.m | E43: 600 | F43: =+$I$1 -> 0.75 | G43: =ROUNDUP(E43/F43,-1) -> 800 | H43: =C43*G43 -> 130400
A45: K 05.2 | B45: Plastering 5/8" thick to reveals in first floor in cement and sand 1:5 finished smooth with two coats of skim coat in first floor. Rate includes cost of "Febmix"as a workability enhancer. | C45: ='m shet rolf'!N301 -> 169 | D45: =D43 -> L.m | E45: 600 | F45: =+$I$1 -> 0.75 | G45: =ROUNDUP(E45/F45,-1) -> 800 | H45: =C45*G45 -> 135200
A47: K 05.3 | B47: Plastering 5/8" thick to reveals in second floor in cement and sand 1:5 finished smooth with two coats of skim coat in Second floor. Rate includes cost of "Febmix"as a workability enhancer. | C47: ='m shet rolf'!N326 -> 188 | D47: =D45 -> L.m | E47: 600 | F47: =+$I$1 -> 0.75 | G47: =ROUNDUP(E47/F47,-1) -> 800 | H47: =C47*G47 -> 150400
A49: K 05.4 | B49: Plastering 5/8" thick to reveals in third floor in cement and sand 1:5 finished smooth with two coats of skim coat in Third floor. Rate includes cost of "Febmix"as a workability enhancer. | D49: =D47 -> L.m
A51: K 06 | B51: Applying two coats of skim coat ( Not exceeding 3 mm thick) to soffit of slab,beams sunshade & stair cases Inc. preparation surface.
A52: K6.1 | B52: In Ground floor | C52: ='m shet rolf'!N329+concrete!C224 -> 245 | D52: S.qm | E52: 830 | F52: =+$I$1 -> 0.75 | G52: =ROUNDUP(E52/F52,-1) -> 1110 | H52: =C52*G52 -> 271950
A53: K6.2 | B53: In First floor | C53: ='m shet rolf'!N331+concrete!C225 -> 208 | D53: S.qm | E53: 830 | F53: =+$I$1 -> 0.75 | G53: =ROUNDUP(E53/F53,-1) -> 1110 | H53: =C53*G53 -> 230880
A54: K6.3 | B54: in Water Tank level | C54: ='m shet rolf'!N333+concrete!C226 -> 14 | D54: S.qm | E54: 830 | F54: =+$I$1 -> 0.75 | G54: =ROUNDUP(E54/F54,-1) -> 1110 | H54: =C54*G54 -> 15540
A55: K6.4 | B55: Water Tank Slab | D55: S.qm
A57: K 07 | B57: Drip Edge
B58: Forming drip for sunshade edge cement & sand 1: 3 finished semi rough in ground floor. Rate includes cost of "Febmix"as a workability enhancer.
A59: K 07.01 | B59: In Ground floor | D59: =D45 -> L.m
A60: K 07.02 | B60: In First floor | D60: =D59 -> L.m
A61: K 07.03 | B61: in Second Floor | D61: =D47 -> L.m
...

Sheet tile
A1: Nos | B1: Description | C1: Qty | D1: Unit | E1: Cost | F1: OH & P% | G1: Rate ( Rs.) | H1: Amount | I1: =+summary!D12 -> 0.85
B2: L - TILING WORK
B3: Note:
B5: Ceramic Tiles should comply to SLS 1181:2019 "specification and shall comply to relevant abrasion resistant class.
B7: Copy of the first grade tile purchase bill should be produced at the time of payment.
B9: Tiles should comply with European standard specification CEN 177.
B11: Rates include the cost of 1:3 cement:sand motar leveling bed and adhesives
B13: For tile item Should be tile range manufractured by Lanka Floor, Wall Tile or approved equivalant.
A15: 1 | B15: Wall Tiling
B16: Glazed wall tiling of size 300mm x 600mm approved colour, supplying and fixing to walls on a 1:3 cement sand mortar layer, and pointed with tile grout to match the tile. (Prime Cost of tile Rs.600.00 per sqft)
A17: =A15+0.01 -> 1.01 | B17: Ground Floor | C17: ='m shet rolf'!N103 -> 32 | D17: Sqm | E17: =+'Rate Breakdowns'!G972 -> 9167.6904 | F17: =+$I$1 -> 0.85 | G17: =ROUNDUP(E17/F17,-1) -> 10790 | H17: =C17*G17 -> 345280
A18: =A17+0.01 -> 1.02 | B18: First Floor | C18: ='m shet rolf'!N128 -> 92 | D18: Sqm | E18: =+E17*1.01 -> 9259.3673 | F18: =+$I$1 -> 0.85 | G18: =ROUNDUP(E18/F18,-1) -> 10900 | H18: =C18*G18 -> 1002800
A19: =A18+0.01 -> 1.03 | B19: Second floor | C19: ='m shet rolf'!N151 -> 61 | D19: Sqm | E19: =+E17*1.02 -> 9351.0442 | F19: =+$I$1 -> 0.85 | G19: =ROUNDUP(E19/F19,-1) -> 11010 | H19: =C19*G19 -> 671610
A20: =A19+0.01 -> 1.04 | B20: Third floor | D20: Sqm | F20: =+$I$1 -> 0.85 | G20: =ROUNDUP(E20/F20,-1) -> 0 | H20: =C20*G20 -> 0
B22: Floor Tiling
B23: Note :
B24: Tile Shall be Homogenous, porcelain floor tiles of industrial grade floor tile range manufactured by Rocell , Lanka Wall Tile or approved equivalent.
B25: Rates include the cost of 1:3 cement:sand motar leveling bed and adhesives and matching grout
B27: Copy of the first grade tile purchase bill should be produced at the time of payment.
A29: 2 | B29: Ground Floor
A30: =A29+0.01 -> 2.01 | B30: Supplying of 300mm X300mm temples stone work with masory work
B31: In Ground floor | C31: ='m shet rolf'!N351 -> 33 | D31: Sqm | E31: 1450 | F31: =+$I$1 -> 0.85 | G31: =ROUNDUP(E31/F31,-1) -> 1710 | H31: =C31*G31 -> 56430 | P31: =E31-#REF! -> #REF!
A34: =A30+0.01 -> 2.02 | B34: FF2- Homogeneous Porcelain glazed non slip ceramic gloss floor tile 600mm x 1200mm non slip floor tie paving on 1:3 cement & sand bedding with suitable adhesives and pointed with tile grout to match the tile. (Prime Cost of tile Rs.600.00 per sqft)
B35: In Ground floor | C35: ='m shet rolf'!N340 -> 105 | D35: Sqm | E35: =+'Rate Breakdowns'!G972*1.03 -> 9442.7211 | F35: =+$I$1 -> 0.85 | G35: =ROUNDUP(E35/F35,-1) -> 11110 | H35: =C35*G35 -> 1166550
A37: =A34+0.01 -> 2.03 | B37: Supply and laying of 4" high skirting including tile grout to match the tile of tiling
B38: In Ground floor | C38: ='m shet rolf'!N342 -> 56 | D38: L.m | E38: =+'Rate Breakdowns'!G1029 -> 1560.6098 | F38: =+$I$1 -> 0.85 | G38: =ROUNDUP(E38/F38,-1) -> 1840 | H38: =C38*G38 -> 103040
A40: =A37+0.01 -> 2.04 | B40: FF3- Homogeneous Porcelain glazed floor tile 600mm x 600mm paving on 1:3 cement & sand bedding with suitable adhesives and pointed with tile grout to match the tile. (Prime Cost of tile Rs.600.00 per sqft) | P40: =4*2 -> 8 | Q40: =P40*P41 -> 1282
B41: In Ground Floor | C41: ='m shet rolf'!N345 -> 32 | D41: Sqm | E41: =+'Rate Breakdowns'!G972 -> 9167.6904 | F41: =+$I$1 -> 0.85 | G41: =ROUNDUP(E41/F41,-1) -> 10790 | H41: =C41*G41 -> 345280 | P41: =1282/8 -> 160.25
A43: =A40+0.01 -> 2.05 | B43: Supply and laying of 4" high skirting including tile grout to match the tile of tiling
B44: In Ground Floor area | C44: ='m shet rolf'!N349 -> 33 | D44: L.m | E44: =+'Rate Breakdowns'!G1029 -> 1560.6098 | F44: =+$I$1 -> 0.85 | G44: =ROUNDUP(E44/F44,-1) -> 1840 | H44: =C44*G44 -> 60720
A46: =A43+0.01 -> 2.06 | B46: FF4- Homogeneous semi rough floor tile 600mm x 1600mm non slip floor tie paving on 1:3 cement & sand bedding with suitable adhesives and pointed with tile grout to match the tile. (Prime Cost of tile Rs.600.00 per sqft)
B47: In Ground Floor | C47: ='m shet rolf'!N356 -> 12 | D47: Sqm | E47: =+'Rate Breakdowns'!G972*1.15 -> 10542.844 | F47: =+$I$1 -> 0.85 | G47: =ROUNDUP(E47/F47,-1) -> 12410 | H47: =C47*G47 -> 148920
A49: =A46+0.01 -> 2.07 | B49: Supply and laying of 4" high skirting including tile grout to match the tile of tiling
B50: In Ground Floor area | C50: ='m shet rolf'!N357 -> 14 | D50: L.m | E50: =+'Rate Breakdowns'!G1029 -> 1560.6098 | F50: =+$I$1 -> 0.85 | G50: =ROUNDUP(E50/F50,-1) -> 1840 | H50: =C50*G50 -> 25760
A52: =A49+0.01 -> 2.08 | B52: FF5- Homogeneous floor tile 600mm x 600mm paving on 1:3 cement & sand bedding with suitable adhesives and pointed with tile grout to match the tile. (Prime Cost of tile Rs.600.00 per sqft)
B53: In Ground Floor area | C53: ='m shet rolf'!N353 -> 6 | D53: Sqm | E53: =+E41 -> 9167.6904 | F53: =+$I$1 -> 0.85 | G53: =ROUNDUP(E53/F53,-1) -> 10790 | H53: =C53*G53 -> 64740
A55: =A52+0.01 -> 2.09 | B55: Supply and laying of 4" high skirting including tile grout to match the tile of tiling
B56: In Ground Floor area | C56: ='m shet rolf'!N354 -> 10 | D56: L.m | E56: =+E50 -> 1560.6098 | F56: =+$I$1 -> 0.85 | G56: =ROUNDUP(E56/F56,-1) -> 1840 | H56: =C56*G56 -> 18400
A58: =A55+0.01 -> 2.1 | B58: FF6- Homogeneous Porcelain semi - glazed/matt wash room floor tile 300mm x 600mm paving on 1:3 cement & sand bedding and pointed with tile grout to match the tile.(Prime Cost of tile Rs.600.00 per sqft)
B59: In Ground floor | C59: ='m shet rolf'!N97 -> 6 | D59: Sqm | E59: =+E41 -> 9167.6904 | F59: =+$I$1 -> 0.85 | G59: =ROUNDUP(E59/F59,-1) -> 10790 | H59: =C59*G59 -> 64740
...

Sheet paint
A1: Nos | B1: Description | C1: Qty | D1: Unit | E1: Cost | F1: OH & P% | G1: Rate ( Rs.) | H1: Amount | I1: =+summary!D13 -> 0.75
B2: M - COLOUR WASHING, PAINTING & POLISHING
B3: Method of application is accordiong to the manufacturer's method specifications
B5: Internal Emultion Paint
A6: M 01 | B6: Painting walls, columns, Revels with one coat of wall primer and two coats of emulsion paint including preparing surface.
A7: M1.1 | B7: In Ground floor | C7: =plastering!C37+(plastering!C43*0.225) -> 294.675 | D7: Sqm | E7: =+'Rate Breakdowns'!G1104 -> 649.65554 | F7: =+$I$1 -> 0.75 | G7: =ROUNDUP(E7/F7,-1) -> 870 | H7: =C7*G7 -> 256367.25 | N7: =+K7*10.76/100 -> 0 | O7: =+L7*10.76/100 -> 0 | P7: =+M7-O7 -> 0 | R7: =+N7+P7 -> 0 | T7: =SUM(M7:N7) -> 0
A8: M1.2 | B8: In First floor | C8: =plastering!C38+(plastering!C45*0.225) -> 336.025 | D8: Sqm | E8: =+E7*1.005 -> 652.90382 | F8: =+$I$1 -> 0.75 | G8: =ROUNDUP(E8/F8,-1) -> 880 | H8: =C8*G8 -> 295702 | N8: =+K8*10.76/100 -> 0 | O8: =+L8*10.76/100 -> 0 | P8: =+M8-O8 -> 0 | R8: =+N8+P8 -> 0 | T8: =SUM(M8:N8) -> 0
A9: M1.3 | B9: In Second Floor | C9: =plastering!C39+(plastering!C47*0.225) -> 375.3 | D9: Sqm | E9: =+E7*1.01 -> 656.1521 | F9: =+$I$1 -> 0.75 | G9: =ROUNDUP(E9/F9,-1) -> 880 | H9: =C9*G9 -> 330264
A10: M1.4 | B10: In Third Floor | D10: Sqm
A12: M 03 | B12: Painting soffit & Beams with one coat of wall primer and two coats of emulsion paint including preparing surface.
A13: M3.1 | B13: In Ground floor | C13: =plastering!C52 -> 245 | D13: Sqm | E13: =+'Rate Breakdowns'!G1129 -> 762.6803 | F13: =+$I$1 -> 0.75 | G13: =ROUNDUP(E13/F13,-1) -> 1020 | H13: =C13*G13 -> 249900
A14: M3.2 | B14: In First floor | C14: =plastering!C53 -> 208 | D14: Sqm | E14: =+E13*1.005 -> 766.4937 | F14: =+$I$1 -> 0.75 | G14: =ROUNDUP(E14/F14,-1) -> 1030 | H14: =C14*G14 -> 214240
A15: M3.3 | B15: in Water Tank level | C15: =plastering!C54 -> 14 | D15: Sqm | E15: =+E13*1.01 -> 770.3071 | F15: =+$I$1 -> 0.75 | G15: =ROUNDUP(E15/F15,-1) -> 1030 | H15: =C15*G15 -> 14420
A16: M3.4 | B16: In Third Floor | D16: Sqm
B18: Exterior Emultion Paint
A19: M 04 | B19: Painting walls,slab and revels with one coat of Exterior wall primer and two coats of weathershield weatherproof acrylic exterior emultion paint including preparing surface. including preparing surface for exterior application before applicatin of emulsion paint.
A20: M4.1 | B20: In Ground floor | C20: =plastering!C12+(plastering!C18*0.1) -> 144.6 | D20: Sqm | E20: =+'Rate Breakdowns'!G1155 -> 1419.591 | F20: =+$I$1 -> 0.75 | G20: =ROUNDUP(E20/F20,-1) -> 1900 | H20: =C20*G20 -> 274740
A21: M4.2 | B21: In First floor | C21: =plastering!C13+(plastering!C20*0.1) -> 193 | D21: Sqm | E21: =+E20*1.005 -> 1426.6889 | F21: =+$I$1 -> 0.75 | G21: =ROUNDUP(E21/F21,-1) -> 1910 | H21: =C21*G21 -> 368630
A22: M4.3 | B22: In Second Floor | C22: =plastering!C14+(plastering!C22*0.1) -> 163.5 | D22: Sqm | E22: =+E20*1.01 -> 1433.7869 | F22: =+$I$1 -> 0.75 | G22: =ROUNDUP(E22/F22,-1) -> 1920 | H22: =C22*G22 -> 313920
A23: M4.4 | B23: in Water Tank level | C23: =plastering!C15 -> 52 | D23: Sqm | E23: =+E20*1.015 -> 1440.8848 | F23: =+$I$1 -> 0.75 | G23: =ROUNDUP(E23/F23,-1) -> 1930 | H23: =C23*G23 -> 100360
B25: COLOUR WASHING, PAINTING & POLISHING WORK CARRIED TO COLLECTION | H25: =SUM(H3:H24) -> 2418543.2
H33: =#REF!+#REF!+#REF!+#REF!+#REF! -> #REF!

Sheet plumbing
A1: Nos | B1: Description | C1: Qty | D1: Unit | E1: Cost | F1: OH & P% | G1: Rate ( Rs.) | H1: Amount | I1: =+summary!D14 -> 0.85
B2: S - PLUMBING AND DRAINAGE WORK
B3: S - SANITARY FITTINGS
B4: Note :
B5: In view of the variety of sanitary ware and fittings available in the market, it has become necessary to prescribe the exact quality requirements in terms of performance and durability aspects. The "Rocell , American Standard, Lanka Tiles - coloma " brands and respective model numbers have been chosen as a bench mark to establish the said requirements.
B7: The brand name and model number appearing in the respective BSR items are purely meant to describe the performance standard of the said fitting/item and does not imply in any way that only the "Rocell ,American Standard, Lanka Tiles - coloma " brands are recommended or considered to be restricted to the "Rocell & American Standard" brands.
B9: Any other make/brand that has equivalent performance characteristics are considered as equivalent provided such fittings meet with the following criteria.
B10: (a). Has an authorized local agent in Sri Lanka
B11: (b). The local agent has been in the trade of the offered make for not less than 5 years.
B12: (c).The cistern mechanism shall have an assurance for the availability of spares for the next 3 years.
B13: (d). The fittings are manufactured in conformity to BS, JIS, A.S.T.M., A.S. or S.L.S. standards.
B14: (e).The dimensions and performance characteristics are in par with the stated model.
B15: (f).Contractor should submit the purchasing bill and the required warranty for all "Rocell , American Standard, Lanka Tiles - coloma " products
... B26: Disable Fittings & Accessories
