Workbook
Name ___REM1: #REF!
Name ___REM1: #REF!
Name ___REM2: #REF!
Name ___REM2: #REF!
Name ___Val101: #REF!
Name ___Val101: #REF!
Name ___Val102: #REF!
Name ___Val102: #REF!
Name ___Val201: #REF!
Name ___Val201: #REF!
Name ___Val202: #REF!
Name ___Val202: #REF!
Name ___Val301: #REF!
Name ___Val301: #REF!
Name ___Val302: #REF!
Name ___Val302: #REF!
Name __REM1: #REF!
Name __REM1: #REF!
Name __REM2: #REF!
Name __REM2: #REF!
Name __Val101: #REF!
Name __Val101: #REF!
Name __Val102: #REF!
Name __Val102: #REF!
Name __Val201: #REF!
Name __Val201: #REF!
Name __Val202: #REF!
Name __Val202: #REF!
Name __Val301: #REF!
Name __Val301: #REF!
Name __Val302: #REF!
Name __Val302: #REF!
Name _REM1: #REF!
Name _REM1: #REF!
Name _REM2: #REF!
Name _REM2: #REF!
Name _Val101: #REF!
Name _Val101: #REF!
Name _Val102: #REF!
Name _Val102: #REF!
Name _Val201: #REF!
Name _Val201: #REF!
Name _Val202: #REF!
Name _Val202: #REF!
Name _Val301: #REF!
Name _Val301: #REF!
Name _Val302: #REF!
Name _Val302: #REF!
Name a: '[2]B-3.2 EB'!#REF!
Name aa: #REF!
Name aa: #REF!
Name aaa: #REF!
Name aaa: #REF!
Name ad: '[2]B-3.2 EB'!#REF!
Name Anton: #REF!
Name Anton: #REF!
Name as: #REF!
Name as: #REF!
Name asgsdfg: #REF!
Name asgsdfg: #REF!

Sheet front
A5: BILLS OF QUANTITIES
A9: PROPOSED HOUSE DESIGN FOR MR.RATHEESHAN AT JAFFNA.

Sheet summary
A2: COLLECTION BILL NO.02 - MAIN BUILDING
A4: Nos | B4: Description | C4: Amount
A6: A | B6: A - PRELIMINARIES | C6: =+prelims!I120 -> 405000
A7: B | B7: =exca!B2 -> B - EXCAVATION & EARTH WORK | C7: =exca!H44 -> 1396040 | D7: 0.75
A8: C | B8: =concrete!B2 -> C - CONCRETE | C8: =concrete!H187 -> 27693390 | D8: 0.75
A9: F | B9: =masnry!B2 -> F - MASONRY WORKS | C9: =masnry!H30 -> 7755790 | D9: 0.75
A10: G | B10: =floring!B2 -> J - FLOORING WORK | C10: =floring!H11 -> 273380 | D10: 0.75
A11: H | B11: =waterprof!B2 -> E - WATER PROOFING WORK | C11: =+waterprof!H38 -> 1519290 | D11: 0.75
A12: J | B12: =plastering!B2 -> K - PLASTERING WORK | C12: =plastering!H39 -> 3622140 | D12: 0.75
A13: K | B13: =tile!B2 -> L -TILING WORK | C13: =+tile!H115 -> 16408650 | D13: 0.85
A14: L | B14: =paint!B2 -> M - COLOUR WASHING, PAINTING & POLISHING | C14: =paint!H26 -> 2793270 | D14: 0.75
A15: Q | B15: =plumbing!B2 -> S - PLUMBING AND DRAINAGE WORK | C15: =plumbing!H129 -> 4426560 | D15: 0.75
A16: V | B16: ='electicle '!B2 -> V - ELECTRICAL INSTALLATION. | C16: ='electicle '!H236 -> 5143870 | D16: 0.75
A17: T | B17: =metal!B2 -> W - METAL WORK | C17: =metal!H131 -> 17065250 | D17: 0.85
B20: TOTAL CARRIED TO GRAND SUMMARY | C20: =SUM(C6:C19) -> 88502630
C21: =SUM(C7:C17) -> 88097630
C22: =+C21/5560 -> 15844.897

Sheet prelims
A1: Nos | B1: Description | C1: Mode of payment catogary | D1: Qty | E1: Unit | F1: COST | G1: OHP% | H1: Rate | I1: Amount | J1: 1
B2: BILL NO. 01
A3: 1/PR | B3: A - PRELIMINARIES
B5: This Bill Provides for the typical general items complimentary to the works wich are required to be provided by the Contractor in compliance with the Conditions of Contract and Contract Data in the execution of the works according to the Contract.
B7: If the Engineer is of the opinion that any item in this section has not been provided fully by the Contractor the Engineer may adjust the amounts quoted by the Contractor for the items concerned
B9: Reimbursement of actual cost on submission of the relevant document acceptable to the Engineer plus 5% of the actual cost of obtaining the insurance policies and securities
B11: Mode of Payment Category
B12: Reimbursement of actual cost on submission of A
B13: the relavent document acceptable to the
B14: engineering plus 5% of the actaul cost of obtaining
B15: the insurance policies and securities
B17: To be paid on signal of the format contract B
B18: agreement
B20: 60% on completion of temporary building or C
B21: structures. 30% in equl installments over the
... B36: The Bidder is fully responsible for identiflying the limitataions, restrictions and difficulties imposed due to the locally of the site and its environs and should include in his prices for all contingencies that may arise as a result
A38: 1 | B38: Insurance and Securities
A40: =A38+0.01 -> 1.01 | B40: Allow sum for providing performance security | C40: A | D40: 1 | E40: Item | I40: N/A
A42: =A40+0.01 -> 1.02 | B42: Allow sum for providing advance payment security | C42: A | D42: 1 | E42: Item | I42: N/A
A44: =A42+0.01 -> 1.03 | B44: Allow Sum for insurance of Works, Machinery & Equipment, Plant, Materials, Third party persons & property and Eimployer's personal & property at site per the Contract | C44: A | D44: 1 | E44: Item | I44: N/A
B46: The minimim insurance.cover shall be:
B48: The minimum cover for insurance of the Works and Plant and Materials is 110% of the Initial Controct Price.
B50: The maximum deductible for insurance uf the Works and of Plant and Materials is 5% of the Initial Contract Price.
B52: The minimunm cover for loss or damage to Equipment is the replacement cost
B54: The maximum deductible for insurance of Equipment is 5% of minimun cover for equipment.
B56: The minimum cover for insurance of (orher propert other than the site) is Ra. 2Million per event and totul limit of indemnity shall be Rs 10 Million
B58: The mininum cover for insurance of personal injury or death.
B60: For third party and employees of the Employer and other persons engaged by the Employer in the Works is Rs.5,000,000/- per event
B62: Injury or damage to persons including employer and consultant and their employees and other consultants employed by the employer shall be covered by the personnel accident insurance cover for Rs 2 million per event effective from the date of commencement of contract until end of the defects liability period (total number of persons insured are not exceeding 10 nrs)
A64: =A44+0.01 -> 1.04 | B64: Allow Sum for insurance against accidents and injury to Contractor's personnel as per the Contract. | C64: A | D64: 1 | E64: Item | I64: N/A
B66: The iminimum cover for personal injury or death
B67: For the Contractor's workmen is Rs. 500,000/= per event
B68: Contractor s employees other than workmen is Rs.5.000.000/= per event
A70: 2 | B70: Engineer's Facilities
A72: =A70+0.01 -> 2.01 | B72: Allow lump sum for constructing, maintaining, dismantling and removal on completion of the Works, a temporary air conditioned TFU for Engineer's office with toilet,elecricity facility in conformity with the plans provided for Engineer's requirements, including furniture and fittings, furnishing, sanitary facilities necessary and other facilities. | C72: C | D72: 1 | E72: Item
B73: The follwing facilities shall be provided
B74: (1) 2-0"x4-0" Table with drawers for Engineer's representative with medium back chair
B75: (2) Chair for Engineer's Representative( two nr of low back chair)
B76: (3) lockable Cupboard for storage of drawings, documents and stationery
B77: (4) Pedestal fan
...

Sheet waterprof
A1: Nos | B1: Description | C1: Qty | D1: Unit | E1: COST | F1: OHP% | G1: Rate | H1: Amount | I1: =+summary!D11 -> 0.75
B2: E - WATER PROOFING WORK
B4: The rates for Items are strictly applicable, subject to the fulfillment of the following conditions.
B6: The water proofing material shall conform to relevant British, Euro or ASTM specifications
B8: Recommended Distributors/Agents who are marketing water proofing material/product are 1. M/s Finco Ltd. 2. M/s HE Engineering 3. M/s Ranki International 4. M/s Solico Engineering 5. M/s Sika Lanka
B9: The contractor shall submmit;
B11: (a) A written certificate stating that all material and workmanship are in conformity with the specifications and the manufactures requirements.
B13: (b) The contractor shall jointly with manufacture/supplier of the waterproofing materials shall furnish a warranty to the Employer valid for a period of 10 years after handing over of the work against dampness and/or moisture penetration through treated surfaces due to defective materials and/or workmanship
B15: payments for items shall be made on receipt of above certificate
B17: The rates for items include the cost of surface preparation, ande the cost of protective masonry screed. Appropriate B.S.R. item rate shall be used for protective layer. The approving authority for products shall be the Engineer.
A19: E. 01 | B19: Internal Wet Areas without Exposure to Sunlight Sq.ft. (Cementitious water proofing using Barralastic or approved equivalnt)
B20: Application of cementitious water proofing using Barralastic or approved equivalnt for internal wet areas such as toilet floors and walls (Walls Up to 1.50m) where the surfaces are not directly exposed to sunlight and weathering. Rate shall include to cleaning the substrate and 1:3 cement sand bedding and all other work as per manufacturer's specifications on application and shall include ponding test for a 300mm water height kept for a period of 48 hours for horizontal surfaces.
A21: E. 01.1 | B21: Ground Floor | C21: ='m shet Mr Ratheshon'!N103 -> 32 | D21: S.qm | E21: =+RBD!F943 -> 3467.043 | F21: =+$I$1 -> 0.75 | G21: =ROUNDUP(E21/F21,-1) -> 4630 | H21: =+G21*C21 -> 148160
A22: E. 01.2 | B22: First Floor | C22: ='m shet Mr Ratheshon'!N106 -> 38 | D22: S.qm | E22: =+E21*1.02 -> 3536.3839 | F22: =+$I$1 -> 0.75 | G22: =ROUNDUP(E22/F22,-1) -> 4720 | H22: =+G22*C22 -> 179360
A23: E. 01.3 | B23: Roof top Floor | C23: ='m shet Mr Ratheshon'!N112 -> 25 | D23: S.qm | E23: =+'RBD Material'!H38*10.76 -> 4788.2 | F23: =+$I$1 -> 0.75 | G23: =ROUNDUP(E23/F23,-1) -> 6390 | H23: =+G23*C23 -> 159750
A24: E. 01.4 | B24: Roof Floor | D24: S.qm
A26: E. 02 | B26: Areas exposed to sunlight (Balconies, Sun-Shades Concrete Gutters etc) (Elastomeric water proofing using thoroseal or approved equivalent.)
B28: Application of two coats of elastomeric water proofing material using thoroseal or approved equivalnt capable to withstand temperature variation for wet areas exposed to sunlight and weathering. ( balconies, sun-shades, concrete gutters etc.) rate shall include for cleaning the substrate and all other work as per manufacturer's specifications on application and shall include ponding test for a 300mm water height kept for a period of 48 hours for horizontal surfaces and cement sand finished with neat finish smooth rendering.
A29: E. 02.1 | B29: Ground Floor | C29: ='m shet Mr Ratheshon'!N116 -> 11 | D29: S.qm | E29: =+E21 -> 3467.043 | F29: =+$I$1 -> 0.75 | G29: =ROUNDUP(E29/F29,-1) -> 4630 | H29: =+G29*C29 -> 50930
A30: E. 02.2 | B30: First Floor | C30: ='m shet Mr Ratheshon'!N123 -> 63 | D30: S.qm | E30: =+E29*1.02 -> 3536.3839 | F30: =+$I$1 -> 0.75 | G30: =ROUNDUP(E30/F30,-1) -> 4720 | H30: =+G30*C30 -> 297360
A31: E. 02.3 | B31: Roof level Floor | C31: ='m shet Mr Ratheshon'!N127 -> 107 | D31: S.qm | E31: =+E23 -> 4788.2 | F31: =+$I$1 -> 0.75 | G31: =ROUNDUP(E31/F31,-1) -> 6390 | H31: =+G31*C31 -> 683730
A32: E. 02.4 | B32: Water Tank Floor | C32: ='m shet Mr Ratheshon'!N454 -> 0 | D32: S.qm
A33: E. 02.5 | B33: laying of Topseal 3mm thick,Torch-on membrane or any othere quivalent product marketed /installed by a specialist contractor registered at ICTAD under waterproofing category including 1:3 cement,sand protective screed laid to slope.Rate shall include the formation of edges,torch welding and fixing metal stripon vertical walls at termination edges.
A34: E. 02.6 | B34: Fourth Floor | D34: S.qm
A35: E. 02.7 | B35: Roof Slab | D35: S.qm
A36: E. 02.8 | B36: Water Tank/Lift Room Slab | C36: ='m shet Mr Ratheshon'!N585 -> 0 | D36: S.qm
B38: WATER PROOFING WORK CARRIED TO COLLECTION | H38: =SUM(H19:H37) -> 1519290

Sheet concrete
A1: Nos | B1: Description | C1: Qty | D1: Unit | E1: COST | F1: OHP% | G1: Rate | H1: Amount | I1: =+summary!D8 -> 0.75
B2: C - CONCRETE
B3: Note:
B4: Rates for concrete are grouped under following categories
B6: 1. In-situ plain concrete (mixed at site either manually or with machine)
B8: 2. Reinforced concrete of Grade 20 &25 (mixed at site with a concrete mixer )
B10: These items are meant for Footings, Columns, Plinth beams, Floor beams, Tie-beams & Stair case. i.e. load bearing members. | Q10: =H74+H169 -> 936220
B12: 3. Ready mixed concrete of Grade 20 ,Grade 25 . Grade 30
B14: 4. Site produced concrete of Grade 20 - (machine mix or in case of small quantities manually mixed)
B16: These items are meant for pre-cast lintols, stiffeners, copings,concrete drains, etc.
B18: 5. Curing for In situ plain concrete, In situ reinforced concrete, Site produced concrete of Grade 20 & Ready mix concrete
B20: In - Situ Plain Concrete (mixed at site either manually or with machine)
B21: The Quality of the concrete should confirm to the relevant B.S., S.L.S. and ICTAD specification for Building works.
B22: UP TO DPC LEVEL
B23: In - Situ Plain Concrete (mixed at site either manually or with machine)
A25: C 01 | B25: Cement concrete 1:3:6 (1") laid to a thickness of 2" in wall foundations, under column/stair footings,plinth beams including placing in position,compacting and curing. | C25: 147 | D25: Sqm | E25: =+RBD!H116 -> 1331.7386 | F25: =+$I$1 -> 0.75 | G25: =ROUNDUP(E25/F25,-1) -> 1780 | H25: =+G25*C25 -> 261660
B27: IN - SITU REINFORCED CONCRETE
B29: In - Situ Reinforced Concrete Of Grade 25 &30 (mixed at site with a concrete mixer )
B31: Grade 25 concrete shall be used for footings, columns, beams,staircases, tie-beams of reinforced concrete elements in multi-storied building (excluding lintols, stiffener columns, copings, non-structural columns and Drains).
B32: Constituent material shall comply to following;
B34: (i) Cement of strength class 42.5N and shall comply with SLS 107 (Ordinary Portland Cement) & SLS 1253 (Portland Limestone Cement) , that has been stored under proper conditions and has manufactured within 90 days at the time of concreting.
B36: (iii) Clean river sand without impurities and clay particles of grain distribution falling within the prescribed grading limit in BS 882:1992.
B38: iv) Well graded coarse aggregate free of impurities with maximum aggregate size being 20mm. grain distribution falling within the prescribed grading limit in BS 882:1992.
B40: (v) Clean portable water
B42: Volume batching of constituent material (a) The equivalent nominal mix suggest for volume batching the Grade 25 & 30 concrete is given in table 4.4 of ICTAD specification for Building Work SCA/4/I of July 2004 for a 50kg cement bag and measuring boxes is reproduced below.
B44: Coarse aggregate to be proportioned for the volume batching using the measurement boxes as indicated in the Clause 4.3.1 ICTAD/SCA/4/I. The internal dimensions of the boxes are 400 x 350 x 250mm (which is 0.035m3 and corresponds to the volume of 1 bag of cement weighing 50 kg). The proportioning of sand shall be on the basis of its dry volume and in the case of damp sand allowance for bulkage shall be made as given in Appendix 4C of ICTAD specification.
B46: Water:Cement ratio shall not exceed 0.45. Based on this Water:Cement ratio, volume of water required (either weight or converted volume of water) shall be decided for a given cement content. Required water content shall then be added by measuring the volume from a calibrated measuring Jar.
B48: Cement shall be added in bag form.
... B71: (b).Quality assurance report signed by the contractor’s technical officer or agent, Divisional Engineer’s technical officer who has witnessed the concreting along with senior technical officer in charge of the site.
A73: C 02 | B73: Volume Batched Grade 25 concrete prepared at site using mixer and vibrator in ground floor.Rate shall include the cost of curing continously for 7 days. Upto DPC
A74: C2.1 | B74: In column/strip footing | C74: 16 | D74: m3 | E74: =+RBD!F204 -> 33871.94 | F74: =+$I$1 -> 0.75 | G74: =ROUNDUP(E74/F74,-1) -> 45170 | H74: =+G74*C74 -> 722720
A75: C2.2 | B75: In column shaft | C75: 2 | D75: m3 | E75: =+E74*1.1 -> 37259.134 | F75: =+$I$1 -> 0.75 | G75: =ROUNDUP(E75/F75,-1) -> 49680 | H75: =+G75*C75 -> 99360
A76: C2.3 | B76: In plinth Beams | C76: 13 | D76: m3 | E76: =+E74 -> 33871.94 | F76: =+$I$1 -> 0.75 | G76: =ROUNDUP(E76/F76,-1) -> 45170 | H76: =+G76*C76 -> 587210
A77: C2.4 | B77: In staircases | C77: 1.5 | D77: m3 | E77: =+E74*1.15 -> 38952.731 | F77: =+$I$1 -> 0.75 | G77: =ROUNDUP(E77/F77,-1) -> 51940 | H77: =+G77*C77 -> 77910
A79: C 03 | B79: Volume Batched Grade 20/ready mix reinforced concrete floors laid on ground. Rate shall include the cost of curing continously for 10 days. ( rate include to transport from batching plant. Rate shall inclue for placing, levelling, vibrating & curing the concrete & pump car cost)
A80: C3.1 | B80: Ground floor concrete(100mm thick) | C80: 25 | D80: m3 | E80: =+RBD!F160 -> 30459.227 | F80: =+$I$1 -> 0.75 | G80: =ROUNDUP(E80/F80,-1) -> 40620 | H80: =+G80*C80 -> 1015500
B82: SUPER STRUCTURE
A84: C 04 | B84: Volume Batched Grade 25 concrete prepared at site using mixer or Grade 25 ready mix( rate include to transport from batching plant. Rate shall inclue for placing, levelling, vibrating & curing the concrete & pump car cost) and vibrator in ground floor. Rate shall include the cost of curing continously for 7 days.
A85: C4.1 | B85: In column shaft from ground floor level to First floor level | C85: 7 | D85: m3 | E85: =+E75 -> 37259.134 | F85: =+$I$1 -> 0.75 | G85: =ROUNDUP(E85/F85,-1) -> 49680 | H85: =+G85*C85 -> 347760
A87: C4.2 | B87: In column shaft from First floor level to Second floor level | C87: 6 | D87: m3 | E87: =+E85*1.05 -> 39122.09 | F87: =+$I$1 -> 0.75 | G87: =ROUNDUP(E87/F87,-1) -> 52170 | H87: =+G87*C87 -> 313020
...

Sheet RBD
A1: REINFORCEMENT
A4: R/F cost delivered to Site
B5: Decription | C5: Unit | D5: Qty | E5: Rate | F5: Amount
B7: Price per Ton | C7: Ton | D7: 1 | E7: =+'RBD Material'!D3*1000 -> 365000 | F7: =D7*E7 -> 365000
B8: Loading & Unloading Cost (1hr Un/Sk Labour per 1 Ton) | C8: hr | D8: 3 | E8: 375 | F8: =D8*E8 -> 1125
B9: Transport Cost (Miximum 20km range) | C9: Turn | D9: 1 | E9: 6500 | F9: =D9*E9 -> 6500
A13: Total Cost per 1 Ton of R/F Delivered to Site | F13: =SUM(F7:F12) -> 372625
A14: Total Cost per 1 Kg R/F Delivered to Site | F14: =F13/1000 -> 372.625
B15: Rate Analysis for BOQ Work Items
B16: Pay Item No:
B17: Work Item : | C17: Rebar work
B18: Assumed Quantity for rate build-up : | C18: 500 | D18: Kg
B19: Norm Ref. :
A21: Item no. | B21: Component | C21: Unit | D21: Quantity | E21: Rate (LKR) | F21: Amount (LKR) | G21: Remarks
A23: A.1 | B23: Subcontract for Rebar Bending / Binding | C23: Kg | D23: =+C18 -> 500 | E23: =+'RBD Material'!H5 -> 30 | F23: =+E23*D23 -> 15000
B25: Subtotal -A | F25: =SUM(F23:F24) -> 15000
A27: Item no. | B27: Plant/Equipment Component | C27: Unit | D27: Quantity | E27: Rate (LKR) | F27: Amount (LKR)
B32: Total Cost for Plant/Equipment - B
A34: Item no. | B34: Material Component | C34: Unit | D34: Quantity | E34: Rate (LKR) | F34: Amount (LKR)
A36: C.1 | B36: Rebar | C36: Kg | D36: =+C18 -> 500 | E36: =+F14 -> 372.625 | F36: =+E36*D36 -> 186312.5
A37: C.2 | B37: Cover Blocks | C37: Ps | F37: =+F36*4% -> 7452.5
A38: C.3 | B38: Binding wire | C38: Kg | D38: =+D36*0.02 -> 10 | E38: =+'RBD Material'!D4 -> 370 | F38: =+E38*D38 -> 3700
B40: Total Cost for Material - C | F40: =SUM(F35:F39) -> 197465
A42: Item no. | B42: Miscellaneous Cost Component | C42: Unit | D42: Quantity | E42: Rate (LKR) | F42: Amount (LKR)
A44: 4 | B44: Allow for tools | C44: Allow | D44: 0.01 | E44: =+F25 -> 15000 | F44: =+E44*D44 -> 150
A45: 5 | B45: Allow for Material wastage | C45: Allow | D45: 0.07 | E45: =+F40 -> 197465 | F45: =+E45*D45 -> 13822.55
B47: Total Cost for Miscellaneous - D | F47: =SUM(F44:F46) -> 13972.55
B49: Estimated Direct Cost - E | C49: ( A + B + C + D ) | F49: =+F47+F40+F32+F25 -> 226437.55
B51: Overheads/Preliminary and Profit - F | C51: 0 | D51: of E
B53: Total - H | C53: ( E + F ) | F53: =+F49+F51 -> 226437.55
B55: Rate per unit | C55: ( H / + | D55: 10 | E55: =+C18 -> 500 | F55: =+F53/E55 -> 452.8751
B57: Say Rate(LKR) | C57: per 1 Kg | F57: =+F55 -> 452.8751
A59: CONCRETE
A62: Cement Bag cost delivered to Site
B63: Decription | C63: Unit | D63: Qty | E63: Rate | F63: Amount
B65: Cement Bag (50kg) | C65: Bag | D65: 100 | E65: =+'RBD Material'!D5 -> 2200 | F65: =D65*E65 -> 220000
B66: Loading & Unloading Cost | C66: Bag | D66: =+D65 -> 100 | E66: 30 | F66: =D66*E66 -> 3000
B67: Transport Cost (Miximum 20km range) | C67: Load | D67: 1 | E67: 9000 | F67: =D67*E67 -> 9000
A71: Total Cost per 50 Cement bags | F71: =SUM(F65:F70) -> 232000
A72: Total Cost per 1nr Cement bag delivered to Site | F72: =+F71/D65 -> 2320
...

Sheet masnry
A1: Nos | B1: Description | C1: Qty | D1: Unit | E1: COST | F1: OHP% | G1: Rate | H1: Amount | I1: =+summary!D12 -> 0.75
B2: F - MASONRY WORKS
A3: F | B3: BRICK MASONRY
A4: 1 | B4: Note :
B5: For the full description of materials
B6: and workmanship refer "Specification
B7: of works", "Pricing Preambles" and
B8: "Drawings".
B10: Vertical solid walls, 225mm thick.
A11: =A4+0.01 -> 1.01 | B11: Brick work in cement and sand 1:5 in super Structure in ground floor. ( 9" thick brick work) | C11: ='m shet Mr Ratheshon'!N30 -> 221 | D11: Sqm | E11: =+'Rate Breakdowns'!G669 -> 5906.8084 | F11: =+$I$1 -> 0.75 | G11: =ROUNDUP(E11/F11,-1) -> 7880 | H11: =+G11*C11 -> 1741480
A13: =A11+0.01 -> 1.02 | B13: Brick work in cement and sand 1:5 in First floor level.(9" thick brick work) | C13: ='m shet Mr Ratheshon'!N46 -> 227 | D13: Sqm | E13: =+E11*1.05 -> 6202.1488 | F13: =+$I$1 -> 0.75 | G13: =ROUNDUP(E13/F13,-1) -> 8270 | H13: =+G13*C13 -> 1877290
A15: =A13+0.01 -> 1.03 | B15: Brick work in cement and sand 1:5 in Roof floor level.(9" thick brick work) | C15: ='m shet Mr Ratheshon'!N53 -> 58 | D15: Sqm | E15: =+E11*1.1 -> 6497.4892 | F15: =+$I$1 -> 0.75 | G15: =ROUNDUP(E15/F15,-1) -> 8670 | H15: =+G15*C15 -> 502860
B17: Vertical solid walls, 150mm thick.
A18: =A15+0.01 -> 1.04 | B18: Brick work in cement and sand 1:5 in super Structure in ground floor. ( 6" thick brick work) | C18: ='m shet Mr Ratheshon'!N65 -> 70 | D18: Sqm | E18: =+'Rate Breakdowns'!G696 -> 4023.0288 | F18: =+$I$1 -> 0.75 | G18: =ROUNDUP(E18/F18,-1) -> 5370 | H18: =+G18*C18 -> 375900
A20: =A18+0.01 -> 1.05 | B20: Brick work in cement and sand 1:5 in super Structure in First floor level. ( 6" thick brick work) | C20: ='m shet Mr Ratheshon'!N76 -> 119 | D20: Sqm | E20: =+E18*1.05 -> 4224.1802 | F20: =+$I$1 -> 0.75 | G20: =ROUNDUP(E20/F20,-1) -> 5640 | H20: =+G20*C20 -> 671160
A22: =A20+0.01 -> 1.06 | B22: Brick work in cement and sand 1:5 in Roof floor level.(6" thick brick work) | C22: ='m shet Mr Ratheshon'!N85 -> 70 | D22: Sqm | E22: =+E18*1.1 -> 4425.3317 | F22: =+$I$1 -> 0.75 | G22: =ROUNDUP(E22/F22,-1) -> 5910 | H22: =+G22*C22 -> 413700
B24: Vertical solid walls, 100mm thick.
A25: =A22+0.01 -> 1.07 | B25: Brick work in cement and sand 1:5 in super Structure in ground floor. ( 4" thick brick work) | C25: ='m shet Mr Ratheshon'!N95 -> 68 | D25: Sqm | E25: =+'Rate Breakdowns'!G722 -> 2960.7649 | F25: =+$I$1 -> 0.75 | G25: =ROUNDUP(E25/F25,-1) -> 3950 | H25: =+G25*C25 -> 268600
B27: H - RUBBLE MASONRY
A28: H 01 | B28: Random rubble (6"-9") masonry in cement mortar 1:5 in wall foundation. | C28: 80 | D28: m3 | E28: =+'Rate Breakdowns'!G644 -> 17854.461 | F28: =+$I$1 -> 0.75 | G28: =ROUNDUP(E28/F28,-1) -> 23810 | H28: =+G28*C28 -> 1904800
B30: MASONRY WORKS CARRIED TO COLLECTION | H30: =SUM(H9:H28) -> 7755790

Sheet plumbing
A1: Nos | B1: Description | C1: Qty | D1: Unit | E1: COST | F1: OHP% | G1: Rate | H1: Amount | I1: =+summary!D15 -> 0.75
B2: S - PLUMBING AND DRAINAGE WORK
B3: S - SANITARY FITTINGS
B4: Note :
B5: In view of the variety of sanitary ware and fittings available in the market, it has become necessary to prescribe the exact quality requirements in terms of performance and durability aspects. The "Rocell , American Standard, Lanka Tiles - coloma " brands and respective model numbers have been chosen as a bench mark to establish the said requirements.
B7: The brand name and model number appearing in the respective BSR items are purely meant to describe the performance standard of the said fitting/item and does not imply in any way that only the "Rocell ,American Standard, Lanka Tiles - coloma " brands are recommended or considered to be restricted to the "Rocell & American Standard" brands.
B9: Any other make/brand that has equivalent performance characteristics are considered as equivalent provided such fittings meet with the following criteria.
B10: (a). Has an authorized local agent in Sri Lanka
B11: (b). The local agent has been in the trade of the offered make for not less than 5 years.
B12: (c).The cistern mechanism shall have an assurance for the availability of spares for the next 3 years.
B13: (d). The fittings are manufactured in conformity to BS, JIS, A.S.T.M., A.S. or S.L.S. standards.
B14: (e).The dimensions and performance characteristics are in par with the stated model.
B15: (f).Contractor should submit the purchasing bill and the required warranty for all "Rocell , American Standard, Lanka Tiles - coloma " products
... B22: (c).Manufacturer's Warranty for Lanka Tiles - coloma Brand.
A24: S 01 | B24: Supply and fix white vitreous china (vc) floor standing Vanity wash basin with overflow hole and single tap hole in center of "Rocell" brand or approved equivalent complete to working order inclusive of the 1 1/4" chromium plated waste outlet of "Rocell" brand or approved equivalent and 1 1/4" chromium plated siphon cleanable bottle trap of "Rocell" brand or approved equivalent. (Prime cost of the floor standing wash basin is Rs.40,000.00)
B25: Ground Floor | C25: 4 | D25: Nr | E25: =40000+4500 -> 44500 | F25: =+$I$1 -> 0.75 | G25: =ROUNDUP(E25/F25,-1) -> 59340 | H25: =+G25*C25 -> 237360
B26: First Floor | C26: 3 | D26: Nr | E26: =+E25*1.03 -> 45835 | F26: =+$I$1 -> 0.75 | G26: =ROUNDUP(E26/F26,-1) -> 61120 | H26: =+G26*C26 -> 183360
B27: Second Floor | C27: 1 | D27: Nr | E27: =+E25*1.06 -> 47170 | F27: =+$I$1 -> 0.75 | G27: =ROUNDUP(E27/F27,-1) -> 62900 | H27: =+G27*C27 -> 62900
A29: S 02 | B29: Supply and fix white vitreous china (vc) floor standing close coupled semi . back to wall water closet suite with wash down flushing with 6/3 liters dual flushing has horizontal outlet with vario drain bend and two lateral holes for bottom water connection , P trap, cistern with water inlet from rear of "Rocell" brand or approved equivalent complete to working order inclusive of universal bend of "Rocell" brand. (Prime cost of the water closet, tank and seat cover is Rs.60,000.00)
B30: Ground Floor | C30: 3 | D30: Nr | E30: =60000+4800 -> 64800 | F30: =+$I$1 -> 0.75 | G30: =ROUNDUP(E30/F30,-1) -> 86400 | H30: =+G30*C30 -> 259200
B31: First Floor | C31: 3 | D31: Nr | E31: =+E30*1.03 -> 66744 | F31: =+$I$1 -> 0.75 | G31: =ROUNDUP(E31/F31,-1) -> 89000 | H31: =+G31*C31 -> 267000
B32: Second Floor | C32: 1 | D32: Nr | E32: =+E30*1.06 -> 68688 | F32: =+$I$1 -> 0.75 | G32: =ROUNDUP(E32/F32,-1) -> 91590 | H32: =+G32*C32 -> 91590
A34: S 07 | B34: Supply and fix Chromium plated 1/2" dia. angle valve of "Rocell" brand . model or approved equivalent. (Prime cost of the Chromium plated 1/2" dia. angle valve is Rs. 2,500.00)
B35: Ground Floor | C35: 4 | D35: Nr | E35: =2500+450 -> 2950 | F35: =+$I$1 -> 0.75 | G35: =ROUNDUP(E35/F35,-1) -> 3940 | H35: =+G35*C35 -> 15760
B36: First Floor | C36: 3 | D36: Nr | E36: =+E35*1.03 -> 3038.5 | F36: =+$I$1 -> 0.75 | G36: =ROUNDUP(E36/F36,-1) -> 4060 | H36: =+G36*C36 -> 12180
B37: Second Floor | C37: 1 | D37: Nr | E37: =+E35*1.06 -> 3127 | F37: =+$I$1 -> 0.75 | G37: =ROUNDUP(E37/F37,-1) -> 4170 | H37: =+G37*C37 -> 4170
A39: S 08 | B39: Supply and fix Chromium plated 1 1/4" chromium plated push type waste outlet of "Rocell" brand or approved equivalent. (Prime cost of the Chromium plated 1 1/4" chromium plated waste outlet is Rs. 2,500.00)
B40: Ground Floor | C40: 3 | D40: Nr | E40: =2500+400 -> 2900 | F40: =+$I$1 -> 0.75 | G40: =ROUNDUP(E40/F40,-1) -> 3870 | H40: =+G40*C40 -> 11610
B41: First Floor | C41: 3 | D41: Nr | E41: =+E40*1.03 -> 2987 | F41: =+$I$1 -> 0.75 | G41: =ROUNDUP(E41/F41,-1) -> 3990 | H41: =+G41*C41 -> 11970
B42: Second Floor | C42: 1 | D42: Nr | E42: =+E40*1.06 -> 3074 | F42: =+$I$1 -> 0.75 | G42: =ROUNDUP(E42/F42,-1) -> 4100 | H42: =+G42*C42 -> 4100
A44: S 09 | B44: Supply and fix Chromium plated 1/2" dia. 36" long flexible horse of "Rocell" brand or approved equivalent. (Prime cost of the Chromium plated 1/2" dia. 18" long flexible horse is Rs. 3,000.00)
B45: Ground Floor | C45: 4 | D45: Nr | E45: =3000+450 -> 3450 | F45: =+$I$1 -> 0.75 | G45: =ROUNDUP(E45/F45,-1) -> 4600 | H45: =+G45*C45 -> 18400
B46: First Floor | C46: 3 | D46: Nr | E46: =+E45*1.03 -> 3553.5 | F46: =+$I$1 -> 0.75 | G46: =ROUNDUP(E46/F46,-1) -> 4740 | H46: =+G46*C46 -> 14220
B47: Second Floor | C47: 1 | D47: Nr | E47: =+E45*1.06 -> 3657 | F47: =+$I$1 -> 0.75 | G47: =ROUNDUP(E47/F47,-1) -> 4880 | H47: =+G47*C47 -> 4880
A49: S 10 | B49: Supply and fix chromium plated Bidet Spray of "Rocell" brand or . approved equivalent. (Prime cost of the chromium plated Bidet Spray is Rs. 5,000.00)
B50: Ground Floor | C50: 3 | D50: Nr | E50: =5000+500 -> 5500 | F50: =+$I$1 -> 0.75 | G50: =ROUNDUP(E50/F50,-1) -> 7340 | H50: =+G50*C50 -> 22020
B51: First Floor | C51: 3 | D51: Nr | E51: =+E50*1.03 -> 5665 | F51: =+$I$1 -> 0.75 | G51: =ROUNDUP(E51/F51,-1) -> 7560 | H51: =+G51*C51 -> 22680
B52: Second Floor | C52: 1 | D52: Nr | E52: =+E50*1.06 -> 5830 | F52: =+$I$1 -> 0.75 | G52: =ROUNDUP(E52/F52,-1) -> 7780 | H52: =+G52*C52 -> 7780
A54: S 12 | B54: Supply and fix 5mm thick mirror of size 18" x 24" double coated with pencil edge back strecher. (Prime cost of the 5mm thick mirror of size 18" x 24" is Rs. 4,000.00)
B55: Ground Floor | D55: Nr
...

Sheet metal
A1: Nos | B1: Description | C1: Qty | D1: Unit | E1: COST | F1: OHP% | G1: Rate | H1: Amount | I1: =+summary!D17 -> 0.85
B2: W - METAL WORK
B3: Note:
B4: Aluminium doors, windows and partitions shall confirm to the following requirements:
B6: 1. Aluminium alloy should confirm to- ISO - 9001:2008, SLS 1410:2011 / SLS 1411:2011
B8: 2. Anodized coating thickness should be 25 ± 5 microns
B10: 3.Aluminium extrusions available in the Local Market are being either manufactured in Sri Lanka or imported material. Due to the continuous change of the extrusion profiles and thicknesses from time to time, it has become very difficult to specify standard section sizes that are to be used for door /window frames and sash members. Hence the rates given herein are based on the recommended minimum sizes and thicknesses of profiles published by leading Aluminium profile manufacturers (Alumex Plc, Swisstek Aluminium Limited) as at present for the doors, windows, fanlights and partitions.
B12: before the fabrication contractor must submitt the following information.
B13: 1. The specifications and thickness of Aluminium extrusions proposes to use on the works.
B14: 2. Full size cross sections of profiles.
B15: 3. Documentary evidence from the Profile Manufacture to the effect that the proposed profile will serve for the intended purpose.
B16: 4. A Manufacturer's test certificate be produced as evidence that the powder coating is of required thickness.
B18: 5. Physical properties :-
... B30: The rates shall include Neoprene gasket, pop rivets, Rawl plugs,Screws,Aluminium cleats etc.
A32: 1 | B32: Metal Ceiling
A33: =A32+0.01 -> 1.01 | B33: Supplying & Installing of 600mmx 600mm non perforated white metal sheet ceiling, supported by concealed type furring suspended system installed in a flat horizontal manner using furing bars clipped on to inter locking hot dipped GI main tees with clips, ciling to be susppended using GI 04mm thick hanger rods (Prime cost of 2'-0" x 2'-0" sheet is Rs.2,640.00)
B34: Ground Floor- banak area | D34: Sqr.
B36: Aluminium Panel Ceiling
A37: =A32+0.01 -> 1.01 | B37: Supplying & installing of suspended Aluminium Panel Ceiling in 600mm x 600 grid size reveal / bevel type using hot dipped GI pre –engineered inter - locking main tees (38mm x 14mm) and cross tees (25mm x 14mm) and wall angles expose areas finished with white baked enamel finish and suspended on 4 mm dia. adjustable hanger rods with spring clips. Ceiling panels will be Compton aluminium tiles 600mm x 600mm x 0.7mm (thickness) and complete to working order as per manufacture's specifications..
B38: Ground Floor- | D38: Sqm
A40: 1 | B40: Hand Rail
B41: G.I Tube Hand Rail
A42: =A40+0.01 -> 1.01 | B42: Staircase handr/Balcony rail as per the design | C42: 1 | D42: P.S | E42: =45*11500*3.28 -> 1697400 | F42: =+$I$1 -> 0.85 | G42: =ROUNDUP(E42/F42,-1) -> 1996950 | H42: =+G42*C42 -> 1996950
A44: =A42+0.01 -> 1.02 | B44: Powder coated perforated mesh Hand Rail
B45: Supplying, fabricating & fixing of perforated mesh hand rail upto 1.2m height 50mm dia 2.3mm thick G.I round bar upright @ 3000mm c/c as vertical members fixed bottom end to steps with the 150mm dia 8mm thick M.S. plate connecting with 4 nos of 8mm dia.anchor bolts and work complete in order. Rate Shall include for applying one coat of etch primer (50% of etch primer base and 50% etch primer activator),one coat of anti-corrosive primer with two coats of enamel paint. (Prime cost is Rs, 1,250.00 per sqft)
A47: 3 | B47: Partitions
A49: =A47+0.01 -> 3.01 | B49: Tempored Glass Partition
B50: P1 in 37.5mm x 25mm x 1.4mm thick hairline finished stainless steel 'U' channel framed work and 12mm thick tempered glass with printed PVC stickering fixed with silicon joints as per the detailed drawing and finishes as specified as per the drawings | D50: Sqr.
A52: =A49+0.01 -> 3.02 | B52: HPL Partition
B54: First Floor | D54: Sqm
A56: =A52+0.01 -> 3.03 | B56: Tempored fixed Glass
B57: 37.5mm x 25mm x 1.4mm thick hairline finished stainless steel 'U' channel framed work and 12mm thick tempered glass with printed PVC stickering fixed with silicon joints as per the detailed drawing and finishes as specified as per the drawings
B58: Second Floor | D58: Sqr.
A60: 2 | B60: Doors & Windows
B61: Doors
A63: =A60+0.01 -> 2.01 | B63: Door type D1 size 1200mm x 3600mm class I teak timber solid Paneled door per the detail drawings with all necessary iron mongaries | C63: 1 | D63: nr | E63: =+K63 -> 320734.08 | F63: =+$I$1 -> 0.85 | G63: =ROUNDUP(E63/F63,-1) -> 377340 | H63: =+G63*C63 -> 377340 | I63: =1.2*3.6*10.76 -> 46.4832 | J63: 6900 | K63: =+J63*I63 -> 320734.08
A65: =A63+0.01 -> 2.02 | B65: Door type D2 size 900mm x 2600mm class I teak timber solid Paneled door per the detail drawings with all necessary iron mongaries | C65: 1 | D65: =D63 -> nr | E65: =+K65 -> 157365 | F65: =+$I$1 -> 0.85 | G65: =ROUNDUP(E65/F65,-1) -> 185140 | H65: =+G65*C65 -> 185140 | I65: =0.9*2.6*10.76 -> 25.1784 | J65: 6250 | K65: =+J65*I65 -> 157365
A67: =A65+0.01 -> 2.03 | B67: Door type D3 size 900mm x 3000mm class I teak timber solid Paneled door per the detail drawings with all necessary iron mongaries | C67: 1 | D67: =D65 -> nr | E67: =+K67 -> 181575 | F67: =+$I$1 -> 0.85 | G67: =ROUNDUP(E67/F67,-1) -> 213620 | H67: =+G67*C67 -> 213620 | I67: =0.9*3*10.76 -> 29.052 | J67: 6250 | K67: =+J67*I67 -> 181575
A69: =A67+0.01 -> 2.04 | B69: Door type D4 size 900mm x 2100mm class I teak timber solid Paneled door per the detail drawings with all necessary iron mongaries | C69: 5 | D69: =D67 -> nr | E69: =+K69 -> 127102.5 | F69: =+$I$1 -> 0.85 | G69: =ROUNDUP(E69/F69,-1) -> 149540 | H69: =+G69*C69 -> 747700 | I69: =0.9*2.1*10.76 -> 20.3364 | J69: 6250 | K69: =+J69*I69 -> 127102.5
A71: =A69+0.01 -> 2.05 | B71: Door type D5 size 750mm x 2100mm class I teak timber solid Paneled door per the detail drawings with all necessary iron mongaries | C71: 7 | D71: =D69 -> nr | E71: =+K71 -> 105918.75 | F71: =+$I$1 -> 0.85 | G71: =ROUNDUP(E71/F71,-1) -> 124620 | H71: =+G71*C71 -> 872340 | I71: =0.75*2.1*10.76 -> 16.947 | J71: 6250 | K71: =+J71*I71 -> 105918.75
...

Sheet tile
A1: Nos | B1: Description | C1: Qty | D1: Unit | E1: COST | F1: OHP% | G1: Rate | H1: Amount | I1: =+summary!D13 -> 0.85
B2: L -TILING WORK
B3: Note:
B5: Ceramic Tiles should comply to SLS 1181:2019 "specification and shall comply to relevant abrasion resistant class.
B7: Copy of the first grade tile purchase bill should be produced at the time of payment.
B9: Tiles should comply with European standard specification CEN 177.
B11: Rates include the cost of 1:3 cement:sand motar leveling bed and adhesives
B13: For tile item Should be tile range manufractured by Lanka Floor, Wall Tile or approved equivalant.
A15: L. 01 | B15: Wall Tiling
B16: Glazed wall tiling of size 300mm x 600mm approved colour, supplying and fixing to walls on a 1:3 cement sand mortar layer, and pointed with tile grout to match the tile. (Prime Cost of tile Rs.600.00 per sqft)
A17: L.01.1 | B17: Ground Floor | C17: ='m shet Mr Ratheshon'!N722 -> 83 | D17: Sqm | E17: =+RBD!F633 -> 9228.4229 | F17: =+$I$1 -> 0.85 | G17: =ROUNDUP(E17/F17,-1) -> 10860 | H17: =+G17*C17 -> 901380
A18: L.01.2 | B18: First Floor | C18: ='m shet Mr Ratheshon'!N726 -> 102 | D18: Sqm | E18: =+E17*1.03 -> 9505.2756 | F18: =+$I$1 -> 0.85 | G18: =ROUNDUP(E18/F18,-1) -> 11190 | H18: =+G18*C18 -> 1141380
A19: L.01.3 | B19: Roof floor | C19: ='m shet Mr Ratheshon'!N728 -> 26 | D19: Sqm | E19: =+E17*1.06 -> 9782.1283 | F19: =+$I$1 -> 0.85 | G19: =ROUNDUP(E19/F19,-1) -> 11510 | H19: =+G19*C19 -> 299260
B21: Floor Tiling
B22: Note :
B23: Tile Shall be Homogenous, porcelain floor tiles of industrial grade floor tile range manufactured by Rocell , Lanka Wall Tile or approved equivalent.
B24: Rates include the cost of 1:3 cement:sand motar leveling bed and adhesives and matching grout
B26: Copy of the first grade tile purchase bill should be produced at the time of payment.
A28: L.02 | B28: Ground Floor
A29: L.02.1 | B29: (FF 08) Supplying of 300mm x 300mm temples stone work with masory work | C29: ='m shet Mr Ratheshon'!N731 -> 31 | D29: Sqm | E29: =+RBD!F857 -> 16506.29 | F29: =+$I$1 -> 0.85 | G29: =ROUNDUP(E29/F29,-1) -> 19420 | H29: =+G29*C28 -> 0
B30: In Ground floor
A32: L.02.2 | B32: (FF1) 600mmx1200mm homogeneous floor tile marble floor tile paving on 1:3 cement & sand bedding with suitable adhesives and pointed with tile grout to match the tile. (Prime Cost of tile Rs.600.00 per sqft)
B33: In Ground Floor | C33: ='m shet Mr Ratheshon'!N739 -> 138 | D33: Sqm | E33: =+RBD!F589 -> 8713.435 | F33: =+$I$1 -> 0.85 | G33: =ROUNDUP(E33/F33,-1) -> 10260 | H33: =+G33*C33 -> 1415880
B34: In First Floor | C34: ='m shet Mr Ratheshon'!N741 -> 17 | D34: Sqm | E34: =+E33*1.02 -> 8887.7037 | F34: =+$I$1 -> 0.85 | G34: =ROUNDUP(E34/F34,-1) -> 10460 | H34: =+G34*C34 -> 177820
B35: In Second Floor | C35: ='m shet Mr Ratheshon'!N743 -> 15 | D35: Sqm | E35: =+E33*1.04 -> 9061.9724 | F35: =+$I$1 -> 0.85 | G35: =ROUNDUP(E35/F35,-1) -> 10670 | H35: =+G35*C35 -> 160050
A41: L.02.3 | B41: (FF1) Supply and laying of 4" high skirting including tile grout to match the tile of tiling
B42: In Ground floor | C42: ='m shet Mr Ratheshon'!N748 -> 82 | D42: L.m | E42: =+RBD!F723 -> 956.60757 | F42: =+$I$1 -> 0.85 | G42: =ROUNDUP(E42/F42,-1) -> 1130 | H42: =+G42*C42 -> 92660
B43: =B34 -> In First Floor | C43: ='m shet Mr Ratheshon'!N751 -> 20 | D43: L.m | E43: =+E42*1.01 -> 966.17364 | F43: =+$I$1 -> 0.85 | G43: =ROUNDUP(E43/F43,-1) -> 1140 | H43: =+G43*C43 -> 22800
B44: =B35 -> In Second Floor | C44: ='m shet Mr Ratheshon'!N757 -> 19 | D44: L.m | E44: =+E42*1.02 -> 975.73972 | F44: =+$I$1 -> 0.85 | G44: =ROUNDUP(E44/F44,-1) -> 1150 | H44: =+G44*C44 -> 21850
A46: L.02.4 | B46: (FF2) 900mm x 900mm homogeneous floor tile full body matt floor tile paving on 1:3 cement & sand bedding with suitable adhesives and pointed with tile grout to match the tile. (Prime Cost of tile Rs.600.00 per sqft)
B47: In Ground Floor | C47: ='m shet Mr Ratheshon'!N760 -> 45 | D47: Sqm | E47: =+RBD!F589 -> 8713.435 | F47: =+$I$1 -> 0.85 | G47: =ROUNDUP(E47/F47,-1) -> 10260 | H47: =+G47*C47 -> 461700
A49: L.02.5 | B49: (FF2) Supply and laying of 4" high skirting including tile grout to match the tile of tiling
B50: In Ground floor | C50: ='m shet Mr Ratheshon'!N763 -> 11 | D50: L.m | E50: =+RBD!F723 -> 956.60757 | F50: =+$I$1 -> 0.85 | G50: =ROUNDUP(E50/F50,-1) -> 1130 | H50: =+G50*C50 -> 12430
A52: L.02.6 | B52: (FF3) 600mm x 600mm homogeneous floor tile Full Body Semi Matt Floor tile ( Type 01 ) paving on 1:3 cement & sand bedding with suitable adhesives and pointed with tile grout to match the tile. (Prime Cost of tile Rs.600.00 per sqft)
B53: =B44 -> In Second Floor | C53: ='m shet Mr Ratheshon'!N766 -> 20 | D53: Sqm | E53: =+E47*1.04 -> 9061.9724 | F53: =+$I$1 -> 0.85 | G53: =ROUNDUP(E53/F53,-1) -> 10670 | H53: =+G53*C53 -> 213400
A55: L.02.7 | B55: (FF3) Supply and laying of 4" high skirting including tile grout to match the tile of tiling
B56: =B53 -> In Second Floor | C56: ='m shet Mr Ratheshon'!N769 -> 17 | D56: L.m | E56: =+E50*1.04 -> 994.87187 | F56: =+$I$1 -> 0.85 | G56: =ROUNDUP(E56/F56,-1) -> 1180 | H56: =+G56*C56 -> 20060
A58: L.02.8 | B58: (FF4) 600mm x 600mm homogeneous floor tile Full Body Semi Matt Floor Tile ( Type 02 ) paving on 1:3 cement & sand bedding with suitable adhesives and pointed with tile grout to match the tile. (Prime Cost of tile Rs.600.00 per sqft)
B59: In Ground Floor | C59: ='m shet Mr Ratheshon'!N773 -> 18 | D59: Sqm | E59: =+RBD!F589 -> 8713.435 | F59: =+$I$1 -> 0.85 | G59: =ROUNDUP(E59/F59,-1) -> 10260 | H59: =+G59*C59 -> 184680
B60: In First Floor | C60: ='m shet Mr Ratheshon'!N776 -> 16 | D60: Sqm | E60: =+E59*1.02 -> 8887.7037 | F60: =+$I$1 -> 0.85 | G60: =ROUNDUP(E60/F60,-1) -> 10460 | H60: =+G60*C60 -> 167360
...

Sheet RBD Material
B2: Material | F2: Subcontract | J2: Machine
B3: Reinforcement | C3: Kg | D3: 365 | F3: Excavation | G3: m3 | H3: 2200 | J3: Concrete Mixture | K3: Day | L3: =5000+1000 -> 6000
B4: Binding wire | C4: Kg | D4: 370 | J4: Poker Vibrator | K4: Day | L4: =2000+400 -> 2400
B5: Cement | C5: Bag | D5: 2200 | F5: Rebar Binding / Bending | G5: Kg | H5: 30 | J5: Jumping Compactor | K5: Day | L5: 5000
B6: Cement (With Transport) | C6: Bag | D6: =+RBD!F72 -> 2320 | F6: FW - Footing | G6: m2 | H6: 2100 | J6: JCB | K6: Hr | L6: 5500
B7: River Sand | C7: Cube | D7: 24500 | F7: FW - Coulmn shaft | G7: m2 | H7: 2250 | J7: Tipper | K7: Trip | L7: 6000
B8: Metal (3/4" Agg) | C8: Cube | D8: 13500
B9: Checken Mesh | C9: Sqft | D9: =13500/300 -> 45 | F9: FW - Tie Beam | G9: m2 | H9: 1900
B10: Febmix (Admixture) | C10: Liter | D10: 330 | F10: FW - Column | G10: m2 | H10: 1950
F11: FW - Slab | G11: m2 | H11: 2300
B12: Skim Coat (20kg) | C12: Bag | D12: 1100 | F12: FW - Beam | G12: m2 | H12: 2450
B13: Acrylic Wall Filler | C13: Liter | D13: 650 | F13: FW - Staircase | G13: m2 | H13: 2650
B14: Emulsion Paints | C14: Liter | D14: 3100 | F14: Concrete Mixing | G14: m3 | H14: 3500
B15: Weathershield paint | C15: Liter | D15: 3700 | F15: Concrete Laying | G15: m3 | H15: 1700
B16: External Acrylic filler | C16: Liter | D16: 900
B17: Floor Tile | C17: Sqft | D17: 600 | F17: Internal Plaster (+Column & Beam) | G17: m2 | H17: =55*10.76 -> 591.8
B18: Bathroom Wall Tile | C18: Sqft | D18: 600 | F18: External Plaster (+Column & Beam) | G18: m2 | H18: =70*10.76 -> 753.2
B19: Bathroom Floor Tile | C19: Sqft | D19: 600 | F19: Reveal | G19: m | H19: =80*3.24 -> 259.2
B20: Pool Tiling (100 x 100mm) | C20: Sqft | D20: 2550 | F20: Checken mesh Attached | G20: m | H20: =50*3.24 -> 162
F21: Weather Gard | G21: m | H21: =230*3.24 -> 745.2
B22: Staircase Floor Tile | C22: Sqft | D22: 450 | N22: Pool Tiling (100 x 100mm)
B23: Tile Adhesive ( 25 Kg ) | C23: Bag | D23: 2650 | F23: Internal Paint | G23: m2 | H23: =45*10.76 -> 484.2
B24: Tile Grout (1Kg ) | C24: Bag | D24: 280 | F24: Internal Slab Soffit Paint | G24: m2 | H24: =60*10.76 -> 645.6
F25: External Paint | G25: m2 | H25: =33*10.76 -> 355.08
B26: Dry Soil | C26: Cube | D26: 8000
F27: Floor Tiling | G27: m2 | H27: =90*10.76 -> 968.4
F28: Bathroom Floor Tiling | G28: m2 | H28: =120*10.76 -> 1291.2
F29: Tile Skirting | G29: m | H29: =120*3.28 -> 393.6
F30: Wall Tiling | G30: m2 | H30: =180*10.76 -> 1936.8
F31: Staircase Tiling | G31: m2 | H31: =400*10.76 -> 4304
F32: Pool Tiling | G32: m2 | H32: =270*10.76 -> 2905.2
F33: Granite work (With M) | G33: Sqft | H33: =2450 -> 2450
F34: Laying Point Stone | G34: Sqft | H34: 700
F36: Waterproofing work (with material / 4 coat) | G36: Sqft | H36: 310
F37: Waterproofing work (with material / 6 coat) | G37: Sqft | H37: 410
F38: Waterproofing work (Roof Top) Torch Membrane | G38: Sqft | H38: 445
F39: Angle fillet preparation | G39: ft | H39: 190
F41: Titanium works (with material) | G41: Sqft | H41: 660

Sheet floring
A1: Nos | B1: Description | C1: Qty | D1: Unit | E1: COST | F1: OHP% | G1: Rate | H1: Amount | I1: =+summary!D10 -> 0.75
B2: J - FLOORING WORK
A4: J 01 | B4: 3/4" thick D.P.C. in cement sand 1:3 finished with 2 coats of D.P.C. tar and blinded with sand. | C4: ='m shet Mr Ratheshon'!N717 -> 102 | D4: Sqm | E4: 670 | F4: =+$I$1 -> 0.75 | G4: =ROUNDUP(E4/F4,-1) -> 900 | H4: =+G4*C4 -> 91800
A6: J 02 | B6: Gauge 750 polythene damp proof membrane with 6" laps laid under floors. | C6: ='m shet Mr Ratheshon'!N98 -> 265 | D6: Sqm | E6: 228 | F6: =+$I$1 -> 0.75 | G6: =ROUNDUP(E6/F6,-1) -> 310 | H6: =+G6*C6 -> 82150
A8: J 03 | B8: Rendering 1/2" thick in cement sand 1:3 finished smooth with cement slurry without colour pigment and expansion joints filled with construction expansion joint sealent including the cost for cleaning the joints prior application of construction expansion joint sealent by M/s Bitumix or approved equivalent.
B9: Water tank slab/Roof Slab | C9: ='m shet Mr Ratheshon'!N673 -> 61 | D9: Sqm | E9: 1219 | F9: =+$I$1 -> 0.75 | G9: =ROUNDUP(E9/F9,-1) -> 1630 | H9: =+G9*C9 -> 99430
B11: FLOORING WORK CARRIED TO COLLECTION | H11: =SUM(H3:H9) -> 273380

Sheet exca
A1: Nos | B1: Description | C1: Qty | D1: Unit | E1: COST | F1: OHP% | G1: Rate | H1: Amount | I1: =+summary!D7 -> 0.75
B2: B - EXCAVATION & EARTH WORK
B3: SITE PREPERATION
B4: Note :
B5: For the full description of materials
B6: and workmanship refer "Specification
B7: of works", "Pricing Preambles" and
B8: "Drawings".
A10: B 01 | B10: Clearing site vegetation manually including removal of bushes, shurb removing rubbish. | C10: ='m shet Mr Ratheshon'!N196 -> 285 | D10: Sqm | E10: =+RBD!F985 -> 133.75 | F10: =+$I$1 -> 0.75 | G10: =ROUNDUP(E10/F10,-1) -> 180 | H10: =+G10*C10 -> 51300
A12: B 02 | B12: Removing top soil including mud, machinery to a nessasary depth and removing all debris away from site, location decided by client withing 3 km | C12: =C10 -> 285 | D12: Sqm | E12: =+RBD!F1028 -> 331.66667 | F12: =+$I$1 -> 0.75 | G12: =ROUNDUP(E12/F12,-1) -> 450 | H12: =+G12*C12 -> 128250
B14: EXCAVATION
B16: Note:
B17: All excavations are measured net. No allowance made for working space.
B19: Excavations as follows in any materials met with except in rock requiring blasting.
B21: Excavation for foundation commencing from formed ground level.
A22: B 03 | B22: Excavation for column, wall, staircase foundations in any material (except rock requiring blasting) up to depth (as per the drawings), part return fill in and ram and surplus depositted within site as directed. | C22: ='m shet Mr Ratheshon'!N243 -> 128 | D22: m3 | E22: =+RBD!F1069 -> 2310 | F22: =+$I$1 -> 0.75 | G22: =ROUNDUP(E22/F22,-1) -> 3080 | H22: =+G22*C22 -> 394240
B24: Filling & Compaction
B25: Note:-
B26: Approved earth shall mean filling materials that comply to the following :
A27: ( a ) | B27: The earth shall be free of vegetation, roots, boulders, easily decomposable materials, chemicals, industrial waste, plastic etc.
A28: ( b ) | B28: The maximum size of particle shall not exceed 75mm.
A29: ( c ) | B29: The earth shall be well graded and the silt and clay (fines) content shall not be more than 25%
A30: ( d ) | B30: The Standerd proctor density shall be grater than 1.70g/cm3
B32: Back Filling
A33: B 04 | B33: Supplying and compaction of Approved earth,compaction of earth including watering and compaction in 225mm thick layers with proctor density, using machine rammer or roller vibrator, rate to include to compaction maching charges and other nessasary related work | C33: 65 | D33: m3 | E33: =+RBD!F1110 -> 5207.0671 | F33: =+$I$1 -> 0.75 | G33: =ROUNDUP(E33/F33,-1) -> 6950 | H33: =+G33*C33 -> 451750
B35: Antitermite -Tretement
A36: B 05 | B36: Antitermite-treatement for the new construction with applying Biflexthrine 10Tc (Biflex ) or approved equivelant , Dialuted chemicals 1:200 ratio with water after supplying the sealed bottle with lables to the site and should be followed the manufacture standards of application including horizontal & vertical barriers. It should be 10 years warranty on application. | C36: =C12 -> 285 | D36: Sqm | E36: =+(75+15)*10.76 -> 968.4 | F36: =+$I$1 -> 0.75 | G36: =ROUNDUP(E36/F36,-1) -> 1300 | H36: =+G36*C36 -> 370500
B38: Transport
A39: B 09 | B39: Transport of any Material / Debris by any means in bulk including loading | D39: Item
B41: Water Disposal
A42: B 10 | B42: Disposal of Ground Water and Surface Water | D42: Item
B44: EXCAVATION & EARTH WORK CARRIED TO COLLECTION | H44: =SUM(H2:H43) -> 1396040

Sheet plastering
A1: Nos | B1: Description | C1: Qty | D1: Unit | E1: COST | F1: OHP% | G1: Rate | H1: Amount | I1: =+summary!D12 -> 0.75
B2: K - PLASTERING WORK
B3: Note:
B4: 1. The rate for plastering items includes the cost of "Febmix"as a workability enhancer.
B6: 2. For coarse textured plaster ( identified as "semi-rough") all the sand should pass through 4.0mm sieve.
B8: External Plaster
A9: K 01 | B9: Plastering 5/8" thick to walls in cement and sand 1:5 finished semi-rough. Rate includes cost of "Febmix"as a workability enhancer.
A10: K1.1 | B10: In Ground floor | C10: 156 | D10: S.qm | E10: =+RBD!F332 -> 1875.4971 | F10: =+$I$1 -> 0.75 | G10: =ROUNDUP(E10/F10,-1) -> 2510 | H10: =+G10*C10 -> 391560
A11: K1.2 | B11: In First floor | C11: 226 | D11: S.qm | E11: =+E10*1.05 -> 1969.272 | F11: =+$I$1 -> 0.75 | G11: =ROUNDUP(E11/F11,-1) -> 2630 | H11: =+G11*C11 -> 594380
A12: K1.3 | B12: In Roof top Floor | C12: 138 | D12: S.qm | E12: =+E10*1.1 -> 2063.0468 | F12: =+$I$1 -> 0.75 | G12: =ROUNDUP(E12/F12,-1) -> 2760 | H12: =+G12*C12 -> 380880
A14: K 02 | B14: External revels
A15: K 02.1 | B15: Plastering 5/8" thick to reveals in ground floor in cement and sand 1:5 finished semi-rough. Rate includes cost of "Febmix"as a workability enhancer. | C15: 204 | D15: L.m | E15: =+RBD!F371 -> 389.384 | F15: =+$I$1 -> 0.75 | G15: =ROUNDUP(E15/F15,-1) -> 520 | H15: =+G15*C15 -> 106080
A17: K 02.2 | B17: Plastering 5/8" thick to reveals in first floor in cement and sand 1:5 finished semi-rough in first floor. Rate includes cost of "Febmix"as a workability enhancer. | C17: 92 | D17: L.m | E17: =+E15*1.1 -> 428.3224 | F17: =+$I$1 -> 0.75 | G17: =ROUNDUP(E17/F17,-1) -> 580 | H17: =+G17*C17 -> 53360
A19: K 02.3 | B19: Plastering 5/8" thick to reveals in second floor in cement and sand 1:5 finished semi-rough in Second floor. Rate includes cost of "Febmix"as a workability enhancer. | C19: 90 | D19: L.m | E19: =+E15*1.2 -> 467.2608 | F19: =+$I$1 -> 0.75 | G19: =ROUNDUP(E19/F19,-1) -> 630 | H19: =+G19*C19 -> 56700
B21: Internal Plaster
A22: K 03 | B22: Plastering 5/8" thick to walls,columns in cement and sand 1:5 finished smooth with two coats of skim coat.
A23: K3.1 | B23: In Ground floor | C23: 359 | D23: S.qm | E23: =+RBD!F249 -> 1556.7514 | F23: =+$I$1 -> 0.75 | G23: =ROUNDUP(E23/F23,-1) -> 2080 | H23: =+G23*C23 -> 746720
A24: K3.2 | B24: In First floor | C24: 346 | D24: S.qm | E24: =+E23*1.02 -> 1587.8864 | F24: =+$I$1 -> 0.75 | G24: =ROUNDUP(E24/F24,-1) -> 2120 | H24: =+G24*C24 -> 733520
A25: K3.3 | B25: =B12 -> In Roof top Floor | C25: 126 | D25: S.qm | E25: =+E23*1.04 -> 1619.0214 | F25: =+$I$1 -> 0.75 | G25: =ROUNDUP(E25/F25,-1) -> 2160 | H25: =+G25*C25 -> 272160
A27: K 05 | B27: Internal Revels
A28: K 05.1 | B28: Plastering 5/8" thick to reveals in ground floor in cement andsand 1:5 finished smooth with two coats of skim coat in ground floor.Rate includes cost of "Febmix"as a workability enhancer. | C28: 204 | D28: =D17 -> L.m | E28: =+RBD!F288 -> 276.884 | F28: =+$I$1 -> 0.75 | G28: =ROUNDUP(E28/F28,-1) -> 370 | H28: =+G28*C28 -> 75480
A30: K 05.2 | B30: Plastering 5/8" thick to reveals in first floor in cement and sand 1:5 finished smooth with two coats of skim coat in first floor. Rate includes cost of "Febmix"as a workability enhancer. | C30: 92 | D30: =D28 -> L.m | E30: =+E28*1.02 -> 282.42168 | F30: =+$I$1 -> 0.75 | G30: =ROUNDUP(E30/F30,-1) -> 380 | H30: =+G30*C30 -> 34960
A32: K 05.3 | B32: Plastering 5/8" thick to reveals in second floor in cement and sand 1:5 finished smooth with two coats of skim coat in Second floor. Rate includes cost of "Febmix"as a workability enhancer. | C32: 90 | D32: =D30 -> L.m | E32: =+E28*1.04 -> 287.95936 | F32: =+$I$1 -> 0.75 | G32: =ROUNDUP(E32/F32,-1) -> 390 | H32: =+G32*C32 -> 35100
A34: K 06 | B34: Applying two coats of skim coat ( Not exceeding 3 mm thick) to soffit of slab,beams sunshade & stair cases Inc. preparation surface.
A35: K6.1 | B35: In Ground floor | C35: 198 | D35: S.qm | E35: =+'RBD Material'!D12/60+300 -> 318.33333 | F35: =+$I$1 -> 0.75 | G35: =ROUNDUP(E35/F35,-1) -> 430 | H35: =+G35*C35 -> 85140
A36: K6.2 | B36: In First floor | C36: 110 | D36: S.qm | E36: =+E35*1.2 -> 382 | F36: =+$I$1 -> 0.75 | G36: =ROUNDUP(E36/F36,-1) -> 510 | H36: =+G36*C36 -> 56100
B39: PLASTERING WORK CARRIED TO COLLECTION | H39: =SUM(H5:H38) -> 3622140

Sheet paint
A1: Nos | B1: Description | C1: Qty | D1: Unit | E1: COST | F1: OHP% | G1: Rate | H1: Amount | I1: =+summary!D14 -> 0.75
B2: M - COLOUR WASHING, PAINTING & POLISHING
B3: Method of application is accordiong to the manufacturer's method specifications
B5: Internal Emultion Paint
A6: M 01 | B6: Painting walls, columns, Revels with one coat of wall primer and two coats of emulsion paint including preparing surface.
A7: M1.1 | B7: In Ground floor | C7: =plastering!C23 -> 359 | D7: Sqm | E7: =+RBD!F455 -> 1135.4859 | F7: =+$I$1 -> 0.75 | G7: =ROUNDUP(E7/F7,-1) -> 1520 | H7: =+G7*C7 -> 545680
A8: M1.2 | B8: In First floor | C8: =plastering!C24 -> 346 | D8: Sqm | E8: =+E7*1.02 -> 1158.1956 | F8: =+$I$1 -> 0.75 | G8: =ROUNDUP(E8/F8,-1) -> 1550 | H8: =+G8*C8 -> 536300
A9: M1.3 | B9: In Second Floor | C9: =plastering!C25 -> 126 | D9: Sqm | E9: =+E7*1.04 -> 1180.9053 | F9: =+$I$1 -> 0.75 | G9: =ROUNDUP(E9/F9,-1) -> 1580 | H9: =+G9*C9 -> 199080
A10: M1.4 | B10: In Third Floor | D10: Sqm
A12: M 03 | B12: Painting soffit & Beams with one coat of wall primer and two coats of emulsion paint including preparing surface.
A13: M3.1 | B13: In Ground floor | C13: =plastering!C35 -> 198 | D13: Sqm | E13: =+RBD!F500 -> 1300.1139 | F13: =+$I$1 -> 0.75 | G13: =ROUNDUP(E13/F13,-1) -> 1740 | H13: =+G13*C13 -> 344520
A14: M3.2 | B14: In First floor | C14: =plastering!C36 -> 110 | D14: Sqm | E14: =+E13*1.02 -> 1326.1161 | F14: =+$I$1 -> 0.75 | G14: =ROUNDUP(E14/F14,-1) -> 1770 | H14: =+G14*C14 -> 194700
B16: Exterior Emultion Paint
A17: M 04 | B17: Painting walls,slab and revels with one coat of Exterior wall primer and two coats of weathershield weatherproof acrylic exterior emultion paint including preparing surface. including preparing surface for exterior application before applicatin of emulsion paint.
A18: M4.1 | B18: In Ground floor | C18: =plastering!C10 -> 156 | D18: Sqm | E18: =+RBD!F543 -> 1216.446 | F18: =+$I$1 -> 0.75 | G18: =ROUNDUP(E18/F18,-1) -> 1630 | H18: =+G18*C18 -> 254280
A19: M4.2 | B19: In First floor | C19: =plastering!C11 -> 226 | D19: Sqm | E19: =+E18*1.05 -> 1277.2683 | F19: =+$I$1 -> 0.75 | G19: =ROUNDUP(E19/F19,-1) -> 1710 | H19: =+G19*C19 -> 386460
A20: M4.3 | B20: In Second Floor | C20: =plastering!C12 -> 138 | D20: Sqm | E20: =+E18*1.1 -> 1338.0906 | F20: =+$I$1 -> 0.75 | G20: =ROUNDUP(E20/F20,-1) -> 1790 | H20: =+G20*C20 -> 247020
B22: Titanium works
A23: M 05 | B23: Supplying and laying 3mm thick titanium layer on the 12mm thick 1:3 cement sand rough finish bed including 3mm thick glass expansions,after 24 hours wetting the floor for 4 -5 days, and cutting with 100 sanding grit while watering , then cut with 400 sanding grit & after that smooth the floor with 1000 sanding grit pads & apply two coats of sealer on dried clean floor. sealering should be carried out as per the manufacturer's specification. Finally polish with buffing pads to achieve good shine. | C23: 9 | D23: Sqm | E23: =+'RBD Material'!H41*10.76 -> 7101.6 | F23: =+$I$1 -> 0.75 | G23: =ROUNDUP(E23/F23,-1) -> 9470 | H23: =+G23*C23 -> 85230
B26: COLOUR WASHING, PAINTING & POLISHING WORK CARRIED TO COLLECTION | H26: =SUM(H3:H25) -> 2793270

Sheet electicle 
A1: Nos | B1: Description | C1: Qty | D1: Unit | E1: COST | F1: OHP% | G1: Rate | H1: Amount | I1: =+summary!D16 -> 0.75
B2: V - ELECTRICAL INSTALLATION. | I2: 0.9
B3: Note:
B4: Work shall be done in accordance with specifications for electrical and mechanical works - ICTAD Publication No.SCA/8 of Aug.2000(2nd Edition -Revised)
B6: Internal light wiring shall comply with the drawings and shall be in 230/440 volt PVC insulated copper cables
B8: All switches and socket outlets shall be plated type make"Clipsal", " Orange X5", "Krypton" or any other approved equivalent complying to SLS1000:1993 for switches & SLS 1998 : 1991 for soket outlets .
B10: Rate to include switch boxes, Rowl plugs, square pin plug base, Chromium plated M.S. chains, brass hooks, ceiling roses, holders and any other item necessary.
B12: All distribution boards should be incorporated with multi 9, Orange Industrial, Merlin Gerin, , Hager, LS, Moeller/EATON, clipsal,SIEMENS make MCB's (Miniature circuit Breaker ) and cabtree, Clipsal ,Orange Industrial 10 kA, LS , Merlin Gerin,Schinieider make R.C.C.B.'s (Residual Current circuit Breaker) and Schinieider, Merlin Gerin, LS, Dormans Smith ,Orange Industrial (10K), Biticano , Clockner moeller make M.C.C.B.'s (Moulded Case Circuit Breakers)
B14: The whole installation shall be carried out according to CEB/IEE wiring regulations.
B16: All the M.C.C.B.'s, MCB's and RCCB's for the distribution boards should be purchased from the following authorized agents or from heir dealers and a certificate or invoice along with their Company seal and Part No., numbers and warranty should be produced at the time of payment.
B17: a). All MCB, RCCB, shall have 20 Years warranty and hence products which comes with 20 years warranty are permitted.
B18: b). All MCCB shall have 2 Years warranty and hence products which comes with 2 years warranty are permitted.
B19: e). All socket and switches shall have 20 Years warranty and hence products which comes with 20 years warranty are permitted.
B21: Point wiring only with and including switches (Rate includes wiring from MCB through switch to lamp point and includes the switch, switch box, lamp holder wire and conduit)
... B53: Breaker's - European Brand
B55: Inspection and testing | M55: =32000*0.05 -> 1600
A57: V01.01 | B57: Testing of the electrical installation and submission of certificate from a chartered Electrical Engineer registered at CEB. | C57: 1 | D57: Item | G57: 45000 | H57: =+G57*C57 -> 45000
A59: V01.02 | B59: Charges for verifying the wiring done with meggar test & continuity test before commensing installation of Distribution Board & Electrical Fittings | C59: 1 | D59: Item | G59: 55000 | H59: =+G59*C59 -> 55000
A61: V02 | B61: Main Cabling System
B63: All the Cables quoted below shall be on measure and pay basis.
B65: Rates should include for all necessary cable accessories such as cable ties, Cable Lugs, Glands, identification tags, and all accessories for complete installation
