Workbook
Name ___REM1: #REF!
Name ___REM1: #REF!
Name ___REM1: #REF!
Name ___REM2: #REF!
Name ___REM2: #REF!
Name ___Val101: #REF!
Name ___Val101: #REF!
Name ___Val102: #REF!
Name ___Val102: #REF!
Name ___Val201: #REF!
Name ___Val201: #REF!
Name ___Val202: #REF!
Name ___Val202: #REF!
Name ___Val301: #REF!
Name ___Val301: #REF!
Name ___Val302: #REF!
Name ___Val302: #REF!
Name __REM1: #REF!
Name __REM1: #REF!
Name __REM2: #REF!
Name __REM2: #REF!
Name __Val101: #REF!
Name __Val101: #REF!
Name __Val102: #REF!
Name __Val102: #REF!
Name __Val201: #REF!
Name __Val201: #REF!
Name __Val202: #REF!
Name __Val202: #REF!
Name __Val301: #REF!
Name __Val301: #REF!
Name __Val302: #REF!
Name __Val302: #REF!
Name _REM1: #REF!
Name _REM1: #REF!
Name _REM1: #REF!
Name _REM2: #REF!
Name _REM2: #REF!
Name _REM2: #REF!
Name _Val101: #REF!
Name _Val101: #REF!
Name _Val101: #REF!
Name _Val102: #REF!
Name _Val102: #REF!
Name _Val201: #REF!
Name _Val201: #REF!
Name _Val202: #REF!
Name _Val202: #REF!
Name _Val301: #REF!
Name _Val301: #REF!
Name _Val302: #REF!
Name _Val302: #REF!
Name a: '[2]B-3.2 EB'!#REF!
Name A: #REF!
Name a: '[2]B-3.2 EB'!#REF!
Name a: '[2]B-3.2 EB'!#REF!
Name a: '[2]B-3.2 EB'!#REF!
Name a: '[2]B-3.2 EB'!#REF!
Name a: '[2]B-3.2 EB'!#REF!
Name a: '[2]B-3.2 EB'!#REF!

Sheet front
A11: BILLS OF QUANTITIES
A15: PROPOSED RESIDENT FOR MR. RIZWAN AT DEMATAGODA

Sheet grnd summry- tender
A1: PROPOSED RESIDENT FOR MR. RIZWAN AT DEMATAGODA
A2: MAIN SUMMARY
A3: BILL ITEM | B3: DESCRIPTION | C3: AMOUNT (Rs.)
A5: A.1 | B5: PRELIMINARIES | C5: =+prelims!I105 -> 760010
A7: A.2 | B7: MAIN BUILDING | C7: =summary!C21 -> 97007884
A9: B | B9: SUB TOTAL-I | C9: =SUM(C5:C8) -> 97767894
B11: Less : Discount (If any)
A13: C | B13: SUB TOTAL-II-CARRIED TO FORM OF BID | C13: =SUM(C9:C12) -> 97767894
B15: PROVISIONAL SUM
A17: D | B17: SUB TOTAL III | C17: =SUM(C13:C16) -> 97767894
B19: ADD- CONTINGENCIES- 10%
A21: E | B21: SUB TOTAL IV | C21: =SUM(C17:C20) -> 97767894
B23: ADD 15% VAT
A25: F | B25: TOTAL PROJECT COST WITH VAT | C25: =SUM(C21:C24) -> 97767894
A27: Total Bid Sum to be taken in to Form of Bid in words Rupees : …………………………………….
A28: …………………………………………………………………………………..…………………..Only
A31: Bidder's VAT Registration No: ………………………………...………………
A34: ……………………….
A35: Signature of Bidder: Date: ……………………………….
A38: Name and Address of Bidder:
A39: ………………………………………………………………….……….
A40: ……………………………………………….………………………….
A41: ………………………………………………………………….……….
A44: ……………………………. ……………………………….
A45: Signature of Witness: (1) Signature of Witness: (2)
A46: Name and Address of Witness: (1) Name and Address of Witness: (2)
... A50: Date: ………………………….. Date: ………………………………
B52: ground floor | C52: =97.7*10.76 -> 1051.252
B53: first floor | C53: =95*10.76 -> 1022.2
B54: second floor | C54: =95*10.76 -> 1022.2
B55: 3rd | C55: =95*10.76 -> 1022.2
B58: total floor area | C58: =SUM(C52:C55) -> 4117.852
B60: rate per sqft | C60: =C7/C58 -> 23557.885
A71: 60000000 | B71: 60000000 | C71: 60000000
B72: v bvbnbvnbn | C72: =A71*0.0144 -> 864000
C73: =C13*1.44% -> 1407857.7
B76: Prepare Schemetic design and detail drawings | C76: 0.23
B77: Prepare Building services detail drawings | C77: 0.18
B78: Prepare Structural detail drawings | C78: 0.22
B79: Prepare Cost Estimate | C79: 0.1
...

Sheet summary
A1: PROPOSED RESIDENT FOR MR. RIZWAN AT DEMATAGODA
A2: MAIN BUILDING
A4: Nos | B4: Description | C4: Amount
A7: B | B7: =exca!B2 -> EXCAVATION & EARTH WORK | C7: =exca!H39 -> 1432370 | D7: 0.75 | E7: =+C7/$C$21 -> 0.014765501
A8: C | B8: =concrete!B2 -> C - CONCRETE | C8: =concrete!H139 -> 24287535 | D8: 0.75 | E8: =+C8/$C$21 -> 0.25036661
A9: F | B9: =masnry!B2 -> F - MASONRY WORKS | C9: =masnry!H28 -> 7721693.5 | D9: 0.75 | E9: =+C9/$C$21 -> 0.079598618
A10: G | B10: =floring!B2 -> J - FLOORING WORK | C10: =floring!H11 -> 171350 | D10: 0.75 | E10: =+C10/$C$21 -> 0.0017663513
A11: H | B11: =waterprof!B2 -> R - WATER PROOFING WORK | C11: =waterprof!H20 -> 1695509 | D11: 0.75 | E11: =+C11/$C$21 -> 0.017478054
A12: J | B12: =plastering!B2 -> K - PLASTERING WORK | C12: =plastering!H56 -> 6189263 | D12: 0.75 | E12: =+C12/$C$21 -> 0.063801649
A13: K | B13: L - TILING WORK | C13: =+tile!H115 -> 9368340 | D13: 0.75 | E13: =+C13/$C$21 -> 0.096572975
A14: L | B14: =paint!B2 -> M - COLOUR WASHING, PAINTING & POLISHING | C14: =paint!H26 -> 4072270 | D14: 0.75 | E14: =+C14/$C$21 -> 0.041978753
A15: Q | B15: S - PLUMBING AND DRAINAGE WORK | C15: =+'plumbing '!H216 -> 6770880 | D15: 0.75 | E15: =+C15/$C$21 -> 0.069797213
A16: S | B16: V - ELECTRICAL INSTALLATION. | C16: =+'electicle '!H174 -> 7265890 | D16: 0.75 | E16: =+C16/$C$21 -> 0.074899994
A17: T | B17: W - METAL WORK | C17: =+'metal '!H105 -> 19471520 | D17: 0.85 | E17: =+C17/$C$21 -> 0.200721
A18: V | B18: V- SWIMMING POOL (700 CUFT) | C18: =+Pool!H55 -> 8561263.8 | D18: 0.75 | E18: =+C18/$C$21 -> 0.088253278
B21: TOTAL CARRIED TO GRAND SUMMARY | C21: =SUM(C7:C20) -> 97007884
B25: Floor Area | C25: =1993+1993+1993+661 -> 6640
C26: =+C21/C25 -> 14609.621
C28: 10500
C29: =+C26*C25 -> 97007884

Sheet Main sum
A2: PROPOSED RESIDENT FOR MR. RIZWAN AT DEMATAGODA
B3: MAIN SUMMARY
B5: PRELIMINARIES | C5: Rs. | D5: =+prelims!I105 -> 760010
B7: EXCAVATION & EARTH WORK | C7: Rs. | D7: =+exca!H39 -> 1432370
B9: CONCRETE / FORM WORK AND REINFORCEMENT | C9: Rs. | D9: =+concrete!H139 -> 24287535
B11: MASONRY WORKS | C11: Rs. | D11: =+masnry!H28 -> 7721693.5
B13: FLOORING WORK | C13: Rs. | D13: =+floring!H11 -> 171350
B15: PLASTERING WORK | C15: Rs. | D15: =+plastering!H56 -> 6189263
B17: TILING WORK | C17: Rs. | D17: =+tile!H115 -> 9368340
B19: COLOUR WASHING, PAINTING & POLISHING | C19: Rs. | D19: =+paint!H26 -> 4072270
B21: PLUMBING AND DRAINAGE WORK | C21: Rs. | D21: =+'plumbing '!H216 -> 6770880
B23: ELECTRICAL INSTALLATION. | C23: Rs. | D23: =+'electicle '!H174 -> 7265890
B25: HANDRAIL / DOORS AND WINDOWS | C25: Rs. | D25: =+'metal '!H105 -> 19471520
B27: WATER PROOFING WORK | C27: Rs. | D27: =+waterprof!H20 -> 1695509
C29: Rs. | D29: =+waterprof!H22 -> 0
C31: Rs. | D31: =+waterprof!H24 -> 0
C33: Rs. | D33: =+waterprof!H26 -> 0
B35: SUB TOTAL - 01 | D35: =SUM(D5:D28) -> 89206630
B36: 00% contingency | D36: =D35*0 -> 0
B37: SUB TOTAL | C37: Rs. | D37: =SUM(D35:D36) -> 89206630
B38: TOTAL ( Excluding VAT ) carried to Form of Bid | C38: Rs. | D38: =SUM(D37:D37) -> 89206630
B49: Date ………………………………………

Sheet prelims
A1: Nos | B1: Description | C1: Mode of payment catogary | D1: Qty | E1: Unit | F1: COST | G1: OHP% | H1: Rate | I1: Amount | J1: 0.75
B2: BILL NO. 01
A3: 1/PR | B3: PRELIMINARIES
A5: PR.1 | B5: Insurance and Securities
B7: Allow sum for Bonds and Gurantee | C7: A | I7: Provide by client.
A9: =A7+0.01 -> 0.01 | B9: Allow sum for providing advance payment security | C9: A | D9: 1 | E9: Item
A11: =A9+0.01 -> 0.02 | B11: Allow Sum for insurance of Works, Machinery & Equipment, Plant, Materials, Third party persons & property and Eimployer's personal & property at site per the Contract | C11: A | D11: 1 | E11: Item
B13: The minimim insurance.cover shall be:
B15: The minimum cover for insurance of the Works and Plant and Materials is 110% of the Initial Controct Price.
B17: The maximum deductible for insurance uf the Works and of Plant and Materials is 5% of the Initial Contract Price.
B19: The minimunm cover for loss or damage to Equipment is the replacement cost
B21: The maximum deductible for insurance of Equipment is 5% of minimun cover for equipment.
B23: The minimum cover for insurance of (orher propert other than the site) is Ra. 2Million per event and totul limit of indemnity shall be Rs 10 Million
B25: The mininum cover for insurance of personal injury or death.
B27: For third party and employees of the Employer and other persons engaged by the Employer in the Works is Rs.5,000,000/- per event
B29: Injury or damage to persons including employer and consultant and their employees and other consultants employed by the employer shall be covered by the personnel accident insurance cover for Rs 2 million per event effective from the date of commencement of contract until end of the defects liability period (total number of persons insured are not exceeding 10 nrs)
A31: =A11+0.01 -> 0.03 | B31: Allow Sum for insurance against accidents and injury to Contractor's personnel as per the Contract. | C31: A | D31: 1 | E31: Item
B33: The iminimum cover for personal injury or death
B34: For the Contractor's workmen is Rs. 500,000/= per event
B35: Contractor s employees other than workmen is Rs.5.000.000/= per event
A36: 2 | B36: Engineer's Facilities
A38: =A36+0.01 -> 2.01 | B38: Allow lump sum for constructing, maintaining, dismantling and removal on completion of the Works, a temporary air conditioned TFU for Engineer's office with toilet,elecricity facility in conformity with the plans provided for Engineer's requirements, including furniture and fittings, furnishing, sanitary facilities necessary and other facilities. | C38: C | D38: 1 | E38: Item
B39: The follwing facilities shall be provided
B40: (1) 2-0"x4-0" Table with drawers for Engineer's representative with medium back chair
B41: (2) Chair for Engineer's Representative( two nr of low back chair)
B42: (3) lockable Cupboard for storage of drawings, documents and stationery
B43: (4) Pedestal fan
B44: (5) 30 Gb monthly data package( WIFI Router),contractor should paid data package monthly
B45: (6) 1200mm X 1200mm white board
B46: (7) I5 computer with printer
B47: (8) Adequate Size Meeting table and 6 nr of chair
A49: PR.2 | B49: Contractor's Facilities
B51: Allow lump sum for constructing, maintaining, dismantling and removal on completion of the Works, a temporary office,stores and workshop with toilet,elecricity facility in conformity with the plans provided for Engineer's requirements, including furniture and fittings, furnishing, sanitary facilities necessary and other facilities. | C51: C | D51: 1 | E51: Item | F51: 175000 | G51: =+$J$1 -> 0.75 | H51: =ROUNDUP(F51/G51,-1) -> 233340 | I51: =+H51*D51 -> 233340
A53: =A51+0.01 -> 0.01 | B53: Allow lump sum for constructing, maintaining, dismantling and removal on completion of the Works, building to be uses as workshops and stores for perishable materials. Buildings shall be constructed in accordance with the drawing prepared by the Contractor and concurred by the Engineer | C53: C | D53: 1 | E53: Item
A55: =A53+0.01 -> 0.02 | B55: Allow lump sum for providing Accommodation, including all sanitory facility for Contractor's staff and workmen | C55: C | D55: 1 | E55: Item
A57: 3 | B57: Construction Managment and Supervision
A59: =A57+0.01 -> 3.01 | B59: Allow sum for employing suitable qualified and axperienced technical personnal on full time for construction maragement services at the site. | C59: E | D59: 1 | E59: Item
B60: Site Engineer( Full Time)
B61: Project Manager ( C.Eng with 10 year experience- part time)
B62: MEP Engineer( Building Service Eng with 10 year experience- part time)
...

Sheet exca
A1: Nos | B1: Description | C1: Qty | D1: Unit | E1: COST | F1: OHP% | G1: Rate | H1: Amount | I1: =+summary!D7 -> 0.75
A2: B | B2: EXCAVATION & EARTH WORK
B3: SITE PREPERATION
A5: B 01 | B5: Clearing site vegetation manually including removal of bushes, shurb removing rubbish. | C5: 316 | D5: Sqm | E5: 150 | F5: =+$I$1 -> 0.75 | G5: =ROUNDUP(E5/F5,-1) -> 200 | H5: =+G5*C5 -> 63200
A7: B 02 | B7: Removing top soil including mud, machinery to a nessasary depth and removing all debris away from site, location decided by client withing 3 km | C7: =C5 -> 316 | D7: Sqm | E7: =+'Rate Breakdowns'!G17 -> 301.39935 | F7: =+$I$1 -> 0.75 | G7: =ROUNDUP(E7/F7,-1) -> 410 | H7: =+G7*C7 -> 129560
B9: EXCAVATION
B11: Note:
B12: All excavations are measured net. No allowance made for working space.
B14: Excavations as follows in any materials met with except in rock requiring blasting.
B16: Excavation for foundation commencing from formed ground level.
A17: B 03 | B17: Excavation for column, wall, staircase foundations in any material (except rock requiring blasting) up to depth (as per the drawings), part return fill in and ram and surplus depositted within site as directed. | C17: =45+65+5 -> 115 | D17: m3 | E17: =+'Rate Breakdowns'!G32 -> 2120.1413 | F17: =+$I$1 -> 0.75 | G17: =ROUNDUP(E17/F17,-1) -> 2830 | H17: =+G17*C17 -> 325450
B19: Filling & Compaction
B20: Approved earth shall mean filling materials that comply to the following :
A21: ( a ) | B21: The earth will be free of vegetation, roots, boulders, easily decomposable materials, chemicals, industrial waste, plastic etc.
A22: ( b ) | B22: The maximum size of particle shall not exceed 75mm.
A23: ( c ) | B23: The earth shall be well graded and the silt and clay (fines) content shall not be more than 25%
B25: Dry Earth Filling
A26: B 05 | B26: Supplying and compaction of Approved earth,compaction of earth including watering and compaction in 225mm thick layers with proctor density, using machine rammer/roller vibrator, rate to include to compaction maching charges and other nessasary related work | C26: =+C32 -> 21 | D26: m3 | E26: =+'Rate Breakdowns'!G87 -> 4478.7986 | F26: =+$I$1 -> 0.75 | G26: =ROUNDUP(E26/F26,-1) -> 5980 | H26: =+G26*C26 -> 125580
B28: Back Filling
A29: B 06 | B29: Supplying and compaction of Approved earth,compaction of earth including watering and compaction in 225mm thick layers with proctor density, using machine rammer or roller vibrator, rate to include to compaction maching charges and other nessasary related work | C29: 70 | D29: m3 | E29: =+'Rate Breakdowns'!G87 -> 4478.7986 | F29: =+$I$1 -> 0.75 | G29: =ROUNDUP(E29/F29,-1) -> 5980 | H29: =+G29*C29 -> 418600
A31: B 07 | B31: Qurry Dust and ABC Filling
B32: Supplying and compaction of qurry dust compaction of earth including watering and compaction in 225mm thick layers with proctor density, using machine rammer/roller vibrator, rate to include to compaction maching charges and other nessasary related work | C32: 21 | D32: m3 | E32: =+'Rate Breakdowns'!G115 -> 3776.5018 | F32: =+$I$1 -> 0.75 | G32: =ROUNDUP(E32/F32,-1) -> 5040 | H32: =+G32*C32 -> 105840
A33: B 08 | B33: Antitermite -Tretement
B34: Antitermite-treatement for the new construction with applying Biflexthrine 10Tc (Biflex ) or approved equivelant , Dialuted chemicals 1:200 ratio with water after supplying the sealed bottle with lables to the site and should be followed the manufacture standards of application including horizontal & vertical barriers. It should be 10 years warranty on application. | C34: 210 | D34: Sqm | E34: =75*10.76 -> 807 | F34: =+$I$1 -> 0.75 | G34: =ROUNDUP(E34/F34,-1) -> 1080 | H34: =+G34*C34 -> 226800
B36: Water Disposal
A37: B 9 | B37: Disposal of Ground Water and Surface Water | C37: 1 | D37: Item | E37: 28000 | F37: =+$I$1 -> 0.75 | G37: =ROUNDUP(E37/F37,-1) -> 37340 | H37: =+G37*C37 -> 37340
B39: EXCAVATION & EARTH WORK CARRIED TO COLLECTION | H39: =SUM(H3:H38) -> 1432370
D71: =600/10.76 -> 55.762082 | I71: =1000/50 -> 20
D72: =D71*0.05 -> 2.7881041 | I72: =50/1000 -> 0.05 | K72: =D72/2.83 -> 0.98519579
C75: cemnt | D75: =13*K72 -> 12.807545
C76: sand | D76: =0.53*K72 -> 0.52215377
C77: metal | D77: =0.92*K72 -> 0.90638013

Sheet concrete
A1: Nos | B1: Description | C1: Qty | D1: Unit | E1: COST | F1: OHP% | G1: Rate | H1: Amount | I1: =+summary!D8 -> 0.75
B2: C - CONCRETE
B4: UP TO DPC LEVEL
B5: G50 Concrete (mixed at site either manually or with machine)
A7: C 01 | B7: Cement concrete 1:3:6 (1") laid to a thickness of 2" in wall foundations, under column/stair footings,plinth beams including placing in position,compacting and curing. | C7: 96 | D7: Sqm | E7: =+'Rate Breakdowns'!G311 -> 1656.2357 | F7: =+I1 -> 0.75 | G7: =ROUNDUP(E7/F7,-1) -> 2210 | H7: =+G7*C7 -> 212160
B9: IN - SITU REINFORCED CONCRETE
B11: In - Situ Reinforced Concrete Of Grade 25 &30 (mixed at site with a concrete mixer )
B13: Grade 25 concrete will be used for footings, columns, beams,staircases, tie-beams of reinforced concrete elements in multi-storied building (excluding lintols, stiffener columns, copings, non-structural columns and Drains).
A14: C 02 | B14: Volume Batched Grade 25 concrete prepared at site using mixer and vibrator in ground floor.Rate has been included the cost of curing continuously for 7 days. Upto DPC.
A15: C2.1 | B15: In column/strip footing | C15: 19 | D15: m3 | E15: =+'Rate Breakdowns'!G282 -> 32745.362 | F15: =+$I$1 -> 0.75 | G15: =ROUNDUP(E15/F15,-1) -> 43670 | H15: =+G15*C15 -> 829730
A16: C2.2 | B16: In column shaft | C16: 2 | D16: m3 | E16: =+E15 -> 32745.362 | F16: =+$I$1 -> 0.75 | G16: =ROUNDUP(E16/F16,-1) -> 43670 | H16: =+G16*C16 -> 87340
A17: C2.3 | B17: In plinth Beams | C17: 10 | D17: m3 | E17: =+E15 -> 32745.362 | F17: =+$I$1 -> 0.75 | G17: =ROUNDUP(E17/F17,-1) -> 43670 | H17: =+G17*C17 -> 436700
A18: C2.4 | B18: In staircases | C18: 1 | D18: m3 | E18: =+E15 -> 32745.362 | F18: =+$I$1 -> 0.75 | G18: =ROUNDUP(E18/F18,-1) -> 43670 | H18: =+G18*C18 -> 43670
A19: C2.5 | B19: In Lift base and lift wall | D19: m3
A21: C 03 | B21: Volume Batched Grade 20/ready mix reinforced concrete floors laid on ground. Rate has been included the cost of curing continously for 10 days. ( rate include to transport from batching plant. inclue for placing, levelling, vibrating & curing the concrete & pump car cost)
A22: C3.1 | B22: Ground floor concrete(75mm thick) | C22: 14 | D22: m3 | E22: =+'Rate Breakdowns'!G252 -> 29746.025 | F22: =+$I$1 -> 0.75 | G22: =ROUNDUP(E22/F22,-1) -> 39670 | H22: =+G22*C22 -> 555380
B24: SUPER STRUCTURE
A26: C3.5 | B26: Volume Batched Grade 20 concrete prepared at site using mixer and vibrator for reinforced cast in situ lintols, copings, stiffeners and drains and pantry slab, kitchen vanity slab
A27: C3.5.1 | B27: Ground Floor | D27: m3
A28: C3.5.2 | B28: First Floor | D28: m3
A29: C3.5.3 | B29: Second Floor | D29: m3
A30: C3.5.4 | B30: Third Floor | D30: m3
A31: C3.5.5 | B31: Fouth Floor | D31: m3
A33: C 04 | B33: Volume Batched Grade 25 concrete prepared at site using mixer or Grade 25 ready mix (rate include to transport from batching plant. Rate has been included for placing, levelling, vibrating & curing the concrete & pump car cost) and vibrator in ground floor. and include the cost of curing continously for 7 days.
A34: C4.1 | B34: In column shaft from ground floor level to First floor level | C34: 6 | D34: m3 | E34: =+'Rate Breakdowns'!G282 -> 32745.362 | F34: =+$I$1 -> 0.75 | G34: =ROUNDUP(E34/F34,-1) -> 43670 | H34: =+G34*C34 -> 262020 | I34: =+C34/0.125 -> 48
A35: C4.2 | B35: In column shaft from First floor level to Second floor level | C35: 6 | D35: m3 | E35: =+E34*1.03 -> 33727.723 | F35: =+$I$1 -> 0.75 | G35: =ROUNDUP(E35/F35,-1) -> 44980 | H35: =+G35*C35 -> 269880
A36: C4.3 | B36: In column shaft from Second floor level to Terrace floor level | C36: 6 | D36: m3 | E36: =+E34*1.06 -> 34710.084 | F36: =+$I$1 -> 0.75 | G36: =ROUNDUP(E36/F36,-1) -> 46290 | H36: =+G36*C36 -> 277740
A37: C4.3 | B37: In column shaft from Terrace floor level to Roof level | C37: 2.5 | D37: m3 | E37: =+E34*1.09 -> 35692.445 | F37: =+$I$1 -> 0.75 | G37: =ROUNDUP(E37/F37,-1) -> 47590 | H37: =+G37*C37 -> 118975
A39: C4.4 | B39: In staircase from ground floor level to First floor level | C39: 2.5 | D39: m3 | E39: =+E35 -> 33727.723 | F39: =+$I$1 -> 0.75 | G39: =ROUNDUP(E39/F39,-1) -> 44980 | H39: =+G39*C39 -> 112450
A40: C4.5 | B40: In staircase from First floor level to Second floor level | C40: 2.5 | D40: m3 | E40: =+E36 -> 34710.084 | F40: =+$I$1 -> 0.75 | G40: =ROUNDUP(E40/F40,-1) -> 46290 | H40: =+G40*C40 -> 115725
A41: C4.5 | B41: In staircase from Second floor level to Terrace floor level | C41: 2.5 | D41: m3 | E41: =+E37 -> 35692.445 | F41: =+$I$1 -> 0.75 | G41: =ROUNDUP(E41/F41,-1) -> 47590 | H41: =+G41*C41 -> 118975
B44: READY MIX CONCRETE
A46: C 05 | B46: Ready mix concrete of grade 20(20 N/mm2) confirming to SLS 1144- 1997, rate include to transport from batching plant. Rate has been inclued for placing, levelling, vibrating & curing the concrete & pump car cost. | Q46: =32294/30 -> 1076.4667
A47: C5.1 | B47: In Reinforced beam at First floor level | C47: 11 | D47: Cu.m | E47: =+E35 -> 33727.723 | F47: =+$I$1 -> 0.75 | G47: =ROUNDUP(E47/F47,-1) -> 44980 | H47: =+G47*C47 -> 494780 | Q47: =+P47/M47 -> #DIV/0!
A48: C5.2 | B48: In Reinforced beam at second floor level | C48: 11 | D48: Cu.m | E48: =+E36 -> 34710.084 | F48: =+$I$1 -> 0.75 | G48: =ROUNDUP(E48/F48,-1) -> 46290 | H48: =+G48*C48 -> 509190 | Q48: =+P48/M48 -> #DIV/0! | R48: =10.7+5.9 -> 16.6 | S48: =R48*0.55*0.3 -> 2.739
A49: C5.3 | B49: In Reinforced beam at Terrace floor level (with Swimming Pool) | C49: =6+13 -> 19 | D49: Cu.m | E49: =+E37 -> 35692.445 | F49: =+$I$1 -> 0.75 | G49: =ROUNDUP(E49/F49,-1) -> 47590 | H49: =+G49*C49 -> 904210
A50: C5.4 | B50: In Reinforced beam at Roof level | C50: 4 | D50: Cu.m | E50: =+E34*1.12 -> 36674.806 | F50: =+$I$1 -> 0.75 | G50: =ROUNDUP(E50/F50,-1) -> 48900 | H50: =+G50*C50 -> 195600
A52: C5.5 | B52: In Reinforced slab at First floor level | C52: 22 | D52: Cu.m | E52: =+E47 -> 33727.723 | F52: =+$I$1 -> 0.75 | G52: =ROUNDUP(E52/F52,-1) -> 44980 | H52: =+G52*C52 -> 989560 | I52: =+C52/0.125 -> 176 | J52: =+I52*10.76 -> 1893.76
A53: C5.6 | B53: In Reinforced Slab at second floor level | C53: 22 | D53: Cu.m | E53: =+E48 -> 34710.084 | F53: =+$I$1 -> 0.75 | G53: =ROUNDUP(E53/F53,-1) -> 46290 | H53: =+G53*C53 -> 1018380 | I53: =+C53/0.125 -> 176 | J53: =+I53*10.76 -> 1893.76
A54: C5.7 | B54: In Reinforced slab at Terrace floor level (with Swimming Pool) | C54: =8+20 -> 28 | D54: Cu.m | E54: =+E49 -> 35692.445 | F54: =+$I$1 -> 0.75 | G54: =ROUNDUP(E54/F54,-1) -> 47590 | H54: =+G54*C54 -> 1332520 | I54: =+C54/0.125 -> 224 | J54: =+I54*10.76 -> 2410.24
...

Sheet masnry
A1: Nos | B1: Description | C1: Qty | D1: Unit | E1: COST | F1: OHP% | G1: Rate | H1: Amount | I1: =+summary!D9 -> 0.75
B2: F - MASONRY WORKS
A3: F | B3: BRICK MASONRY
B5: Vertical solid walls, 225mm thick.
B6: Brick work in cement and sand 1:5 in super Structure. ( 9" thick brick work)
A7: F.1 | B7: Ground Floor | C7: 184 | D7: Sqm | E7: =+'Rate Breakdowns'!G669 -> 5906.8084 | F7: =+$I$1 -> 0.75 | G7: =ROUNDUP(E7/F7,-1) -> 7880 | H7: =+G7*C7 -> 1449920
A8: F.2 | B8: 1st Floor | C8: 247 | D8: Sqm | E8: =+E7*1.01 -> 5965.8765 | F8: =+$I$1 -> 0.75 | G8: =ROUNDUP(E8/F8,-1) -> 7960 | H8: =+G8*C8 -> 1966120
A9: F.3 | B9: 2nd Floor | C9: 247 | D9: Sqm | E9: =+E7*1.02 -> 6024.9446 | F9: =+$I$1 -> 0.75 | G9: =ROUNDUP(E9/F9,-1) -> 8040 | H9: =+G9*C9 -> 1985880
A10: F.4 | B10: 3rd Floor /Terrace Floor | C10: 93 | D10: Sqm | E10: =+E7*1.03 -> 6084.0126 | F10: =+$I$1 -> 0.75 | G10: =ROUNDUP(E10/F10,-1) -> 8120 | H10: =+G10*C10 -> 755160
A12: G | B12: CELLULAR AND BLOCK MASONRY
B14: Vertical solid walls,115mm thick.
B15: Brick Work in cement and sand 1:8 . (4 1/2" thick brick work)
A16: G.1 | B16: Ground Floor | C16: 64 | D16: Sqm | E16: =+'Rate Breakdowns'!G722 -> 2960.7649 | F16: =+$I$1 -> 0.75 | G16: =ROUNDUP(E16/F16,-1) -> 3950 | H16: =+G16*C16 -> 252800
A17: G.2 | B17: 1st Floor | C17: 20 | D17: Sqm | E17: =+E16*1.01 -> 2990.3726 | F17: =+$I$1 -> 0.75 | G17: =ROUNDUP(E17/F17,-1) -> 3990 | H17: =+G17*C17 -> 79800
A18: G.3 | B18: 2nd Floor | C18: 20 | D18: Sqm | E18: =+E16*1.02 -> 3019.9802 | F18: =+$I$1 -> 0.75 | G18: =ROUNDUP(E18/F18,-1) -> 4030 | H18: =+G18*C18 -> 80600
A19: G.4 | B19: 3rd Floor /Terrace Floor | C19: 41 | D19: Sqm | E19: =+E16*1.03 -> 3049.5879 | F19: =+$I$1 -> 0.75 | G19: =ROUNDUP(E19/F19,-1) -> 4070 | H19: =+G19*C19 -> 166870
B21: H - RUBBLE MASONRY
A22: H 01 | B22: Random rubble (6"-9") masonry in cement mortar 1:5 in wall foundation. | C22: 41.35 | D22: m3 | E22: =+'Rate Breakdowns'!G644 -> 17854.461 | F22: =+$I$1 -> 0.75 | G22: =ROUNDUP(E22/F22,-1) -> 23810 | H22: =+G22*C22 -> 984543.5
B28: MASONRY WORKS CARRIED TO COLLECTION | H28: =SUM(H2:H27) -> 7721693.5

Sheet floring
A1: Nos | B1: Description | C1: Qty | D1: Unit | E1: COST | F1: OHP% | G1: Rate | H1: Amount | I1: =+summary!D10 -> 0.75
B2: J - FLOORING WORK
A4: J 01 | B4: 3/4" thick D.P.C. in cement sand 1:3 finished with 2 coats of D.P.C. tar and blinded with sand. | C4: 65 | D4: Sqm | E4: =+'Rate Breakdowns'!G159 -> 670.72121 | F4: =+$I$1 -> 0.75 | G4: =ROUNDUP(E4/F4,-1) -> 900 | H4: =+G4*C4 -> 58500
A6: J 02 | B6: Gauge 750 polythene damp proof membrane with 6" laps laid under floors. | C6: 180 | D6: Sqm | E6: =+'Rate Breakdowns'!G137 -> 228.74058 | F6: =+$I$1 -> 0.75 | G6: =ROUNDUP(E6/F6,-1) -> 310 | H6: =+G6*C6 -> 55800
A8: J 03 | B8: Rendering 1/2" thick in cement sand 1:3 finished smooth with cement slurry without colour pigment and expansion joints filled with construction expansion joint sealent including the cost for cleaning the joints prior application of construction expansion joint sealent by M/s Bitumix or approved equivalent.
B9: Water tank slab/Roof Slab | C9: 35 | D9: Sqm | E9: =+'Rate Breakdowns'!G1059 -> 1219.819 | F9: =+$I$1 -> 0.75 | G9: =ROUNDUP(E9/F9,-1) -> 1630 | H9: =+G9*C9 -> 57050
B11: FLOORING WORK CARRIED TO COLLECTION | H11: =SUM(H2:H10) -> 171350

Sheet plastering
A1: Nos | B1: Description | C1: Qty | D1: Unit | E1: COST | F1: OHP% | G1: Rate | H1: Amount | I1: 0.75
B2: K - PLASTERING WORK
B3: Note:
B4: 1. The rate for plastering items includes the cost of "Febmix"as a workability enhancer.
B6: 2. For coarse textured plaster ( identified as "semi-rough") all the sand should pass through 4.0mm sieve.
B8: External Plaster
A9: K 01 | B9: 5/8" thick plastering to plinth wall in cement sand 1:3 including finishing with cement slurry floating. Rate includes cost of "Febmix" as a workability enhancer. | C9: =89*0.45 -> 40.05 | D9: S.qm | E9: =+'Rate Breakdowns'!G1024 -> 2738.1963 | F9: =+$I$1 -> 0.75 | G9: =ROUNDUP(E9/F9,-1) -> 3660 | H9: =+G9*C9 -> 146583
A11: K 02 | B11: Plastering 5/8" thick to walls in cement and sand 1:5 finished semi-rough. Rate includes cost of "Febmix"as a workability enhancer.
A12: K2.1 | B12: In Ground floor | C12: 182 | D12: S.qm | E12: =+'Rate Breakdowns'!G972 -> 1532.7348 | F12: =+$I$1 -> 0.75 | G12: =ROUNDUP(E12/F12,-1) -> 2050 | H12: =+G12*C12 -> 373100
A13: K2.2 | B13: In First floor | C13: 207 | D13: S.qm | E13: =+E12*1.02 -> 1563.3895 | F13: =+$I$1 -> 0.75 | G13: =ROUNDUP(E13/F13,-1) -> 2090 | H13: =+G13*C13 -> 432630
A14: K2.3 | B14: In Second Floor | C14: 207 | D14: S.qm | E14: =+E12*1.04 -> 1594.0442 | F14: =+$I$1 -> 0.75 | G14: =ROUNDUP(E14/F14,-1) -> 2130 | H14: =+G14*C14 -> 440910
A15: K2.4 | B15: In Terrace Floor | C15: 111 | D15: S.qm | E15: =+E12*1.06 -> 1624.6989 | F15: =+$I$1 -> 0.75 | G15: =ROUNDUP(E15/F15,-1) -> 2170 | H15: =+G15*C15 -> 240870
A17: K 03 | B17: External revels
B18: Plastering 5/8" thick to reveals in cement and sand 1:5 finished semi-rough. Rate includes cost of "Febmix"as a workability enhancer.
A19: K.3.1 | B19: In Ground floor | C19: 126 | D19: L.m | E19: =190*3.28 -> 623.2 | F19: =+$I$1 -> 0.75 | G19: =ROUNDUP(E19/F19,-1) -> 840 | H19: =+G19*C19 -> 105840
A20: K.3.2 | B20: In First floor | C20: 142 | D20: L.m | E20: =190*3.28 -> 623.2 | F20: =+$I$1 -> 0.75 | G20: =ROUNDUP(E20/F20,-1) -> 840 | H20: =+G20*C20 -> 119280
A21: K.3.3 | B21: In Second Floor | C21: 142 | D21: L.m | E21: =190*3.28 -> 623.2 | F21: =+$I$1 -> 0.75 | G21: =ROUNDUP(E21/F21,-1) -> 840 | H21: =+G21*C21 -> 119280
A22: K.3.4 | B22: In Terrace Floor | C22: 64 | D22: L.m | E22: =190*3.28 -> 623.2 | F22: =+$I$1 -> 0.75 | G22: =ROUNDUP(E22/F22,-1) -> 840 | H22: =+G22*C22 -> 53760
B24: Internal Plaster
A25: K 04 | B25: Plastering 5/8" thick to walls,columns in cement and sand 1:5 finished smooth with two coats of skim coat.
A26: K4.1 | B26: In Ground floor | C26: 329 | D26: S.qm | E26: =+'Rate Breakdowns'!G946 -> 1642.7173 | F26: =+$I$1 -> 0.75 | G26: =ROUNDUP(E26/F26,-1) -> 2200 | H26: =+G26*C26 -> 723800
A27: K4.2 | B27: In First floor | C27: 451 | D27: S.qm | E27: =+E26*1.01 -> 1659.1445 | F27: =+$I$1 -> 0.75 | G27: =ROUNDUP(E27/F27,-1) -> 2220 | H27: =+G27*C27 -> 1001220
A28: K4.3 | B28: In Second Floor | C28: 451 | D28: S.qm | E28: =+E26*1.02 -> 1675.5716 | F28: =+$I$1 -> 0.75 | G28: =ROUNDUP(E28/F28,-1) -> 2240 | H28: =+G28*C28 -> 1010240
A29: K4.4 | B29: In Terrace Floor | C29: 187 | D29: S.qm | E29: =+E26*1.03 -> 1691.9988 | F29: =+$I$1 -> 0.75 | G29: =ROUNDUP(E29/F29,-1) -> 2260 | H29: =+G29*C29 -> 422620
A32: K 05 | B32: Internal Revels
B33: Plastering 5/8" thick to reveals in cement andsand 1:5 finished smooth with two coats of skim coat in ground floor.Rate includes cost of "Febmix"as a workability enhancer.
A34: K5.1 | B34: In Ground floor | C34: 156 | D34: =D20 -> L.m | E34: =170*3.28 -> 557.6 | F34: =+$I$1 -> 0.75 | G34: =ROUNDUP(E34/F34,-1) -> 750 | H34: =+G34*C34 -> 117000
A35: K5.2 | B35: In First floor | C35: 190 | D35: =D21 -> L.m | E35: =170*3.28 -> 557.6 | F35: =+$I$1 -> 0.75 | G35: =ROUNDUP(E35/F35,-1) -> 750 | H35: =+G35*C35 -> 142500
A36: K5.3 | B36: In Second Floor | C36: 190 | D36: =D22 -> L.m | E36: =170*3.28 -> 557.6 | F36: =+$I$1 -> 0.75 | G36: =ROUNDUP(E36/F36,-1) -> 750 | H36: =+G36*C36 -> 142500
A37: K5.4 | B37: In Terrace Floor | C37: 86 | D37: =D23 -> 0 | E37: =170*3.28 -> 557.6 | F37: =+$I$1 -> 0.75 | G37: =ROUNDUP(E37/F37,-1) -> 750 | H37: =+G37*C37 -> 64500
A39: K 06 | B39: Applying two coats of skim coat ( Not exceeding 3 mm thick) to soffit of slab,beams sunshade & stair cases Inc. preparation surface.
A40: K6.1 | B40: In First floor slab | C40: 172 | D40: S.qm | E40: =+'Rate Breakdowns'!G1525 -> 590.4521 | F40: =+$I$1 -> 0.75 | G40: =ROUNDUP(E40/F40,-1) -> 790 | H40: =+G40*C40 -> 135880
A41: K6.2 | B41: In Second Floor slab | C41: 172 | D41: S.qm | E41: =+E40*1.02 -> 602.26114 | F41: =+$I$1 -> 0.75 | G41: =ROUNDUP(E41/F41,-1) -> 810 | H41: =+G41*C41 -> 139320
A42: K6.3 | B42: In Terrace Floor slab | C42: 140 | D42: S.qm | E42: =+E40*1.03 -> 608.16566 | F42: =+$I$1 -> 0.75 | G42: =ROUNDUP(E42/F42,-1) -> 820 | H42: =+G42*C42 -> 114800
A43: K6.4 | B43: Roof Flab slab | C43: 53 | D43: S.qm | E43: =+E40*1.04 -> 614.07018 | F43: =+$I$1 -> 0.75 | G43: =ROUNDUP(E43/F43,-1) -> 820 | H43: =+G43*C43 -> 43460
A46: K 07 | B46: Drip Edge
B47: Forming drip for sunshade edge cement & sand 1: 3 finished semi rough in ground floor. Rate includes cost of "Febmix"as a workability enhancer.
A48: K 07.01 | B48: In First floor slab | C48: 38 | D48: L.m | E48: =190*3.28 -> 623.2 | F48: =+$I$1 -> 0.75 | G48: =ROUNDUP(E48/F48,-1) -> 840 | H48: =+G48*C48 -> 31920
A49: K 07.02 | B49: In Second Floor slab | C49: 38 | D49: L.m | E49: =190*3.28*1.2 -> 747.84 | F49: =+$I$1 -> 0.75 | G49: =ROUNDUP(E49/F49,-1) -> 1000 | H49: =+G49*C49 -> 38000
A50: K 07.03 | B50: In Terrace Floor slab | C50: 25 | D50: L.m | E50: =190*3.28*1.4 -> 872.48 | F50: =+$I$1 -> 0.75 | G50: =ROUNDUP(E50/F50,-1) -> 1170 | H50: =+G50*C50 -> 29250
...

Sheet tile
A1: Nos | B1: Description | C1: Qty | D1: Unit | E1: COST | F1: OHP% | G1: Rate | H1: Amount | I1: =+summary!D13 -> 0.75
B2: L - TILING WORK
B3: Floor Tiling
B4: Note :
B5: Tile will be Homogenous, porcelain floor tiles of industrial grade floor tile range manufactured by Rocell , Lanka Tile or approved equivalent.
B6: Rates include the cost of 1:3 cement:sand motar leveling bed and adhesives and matching grout
B8: Copy of the first grade tile purchase bill should be produced at the time of payment.
A10: L01 | B10: Floor Finishing For Staircase
A12: L01.1 | B12: Supplying and laying of treated timber kumbuk flooring for Staircase Floor. (Rate to include to floor bed and other necessasry related work)
A14: L01.1.1 | B14: Staircase (Ground Floor to 1st Floor) | C14: 8 | D14: Sqm | E14: =(2330*10.76)+'Rate Breakdowns'!G1149 -> 26255.876 | F14: =+$I$1 -> 0.75 | G14: =ROUNDUP(E14/F14,-1) -> 35010 | H14: =+G14*C14 -> 280080
A15: L01.1.2 | B15: Staircase (1st Floor to 2nd Floor) | C15: 8 | D15: Sqm | E15: =(2330*10.76)+'Rate Breakdowns'!G1150 -> 25180.937 | F15: =+$I$1 -> 0.75 | G15: =ROUNDUP(E15/F15,-1) -> 33580 | H15: =+G15*C15 -> 268640
A16: L01.1.3 | B16: Staircase (2nd Floor to Terrace Floor) | C16: 8 | D16: Sqm | E16: =(2330*10.76)+'Rate Breakdowns'!G1151 -> 25070.8 | F16: =+$I$1 -> 0.75 | G16: =ROUNDUP(E16/F16,-1) -> 33430 | H16: =+G16*C16 -> 267440
A18: L01.2 | B18: Supply and laying of 4" high timber skirting to match the flooring
A19: L01.2.1 | B19: Staircase (Ground Floor to 1st Floor) | C19: 18 | D19: L.m | E19: =2547+450 -> 2997 | F19: =+$I$1 -> 0.75 | G19: =ROUNDUP(E19/F19,-1) -> 4000 | H19: =+G19*C19 -> 72000
A20: L01.2.2 | B20: Staircase (1st Floor to 2nd Floor) | C20: =+C19 -> 18 | D20: L.m | E20: =2547+450 -> 2997 | F20: =+$I$1 -> 0.75 | G20: =ROUNDUP(E20/F20,-1) -> 4000 | H20: =+G20*C20 -> 72000
A21: L01.2.3 | B21: Staircase (2nd Floor to Terrace Floor) | C21: =+C19 -> 18 | D21: L.m | E21: =2547+450 -> 2997 | F21: =+$I$1 -> 0.75 | G21: =ROUNDUP(E21/F21,-1) -> 4000 | H21: =+G21*C21 -> 72000
A23: L02 | B23: Tiling For Bathroom
A25: L02.1 | B25: Homogeneous Porcelain semi - glazed/matt wash room floor tile 600mm x 600mm paving on 1:3 cement & sand bedding and pointed with tile grout to match the tile. (Prime Cost of tile Rs.500.00 per sqft)
A26: L02.1.1 | B26: In Ground Floor Bathroom | C26: 4 | D26: Sqm | E26: =+'Rate Breakdowns'!G1267 -> 7973.3416 | F26: =+$I$1 -> 0.75 | G26: =ROUNDUP(E26/F26,-1) -> 10640 | H26: =+G26*C26 -> 42560
A27: L02.1.2 | B27: In 1st Floor Bathroom | C27: 13 | D27: Sqm | E27: =+E26*1.02 -> 8132.8085 | F27: =+$I$1 -> 0.75 | G27: =ROUNDUP(E27/F27,-1) -> 10850 | H27: =+G27*C27 -> 141050
A28: L02.1.3 | B28: In 2nd Floor Bathroom | C28: 13 | D28: Sqm | E28: =+E26*1.04 -> 8292.2753 | F28: =+$I$1 -> 0.75 | G28: =ROUNDUP(E28/F28,-1) -> 11060 | H28: =+G28*C28 -> 143780
A29: L02.1.4 | B29: In Terrace Floor Bathroom | C29: 4 | D29: Sqm | E29: =+E26*1.06 -> 8451.7421 | F29: =+$I$1 -> 0.75 | G29: =ROUNDUP(E29/F29,-1) -> 11270 | H29: =+G29*C29 -> 45080
A31: L02.2 | B31: Homogeneous Porcelain glazed Wall tile 300mm x 600mm paving on plaster and pointed with tile grout to match the tile. (Prime Cost of tile Rs.550.00 per sqft)
A32: L02.2.1 | B32: In Ground Floor Bathroom | C32: 17 | D32: Sqm | E32: =+'Rate Breakdowns'!G1297 -> 9307.8949 | F32: =+$I$1 -> 0.75 | G32: =ROUNDUP(E32/F32,-1) -> 12420 | H32: =+G32*C32 -> 211140
A33: L02.2.2 | B33: In 1st Floor Bathroom | C33: 51 | D33: Sqm | E33: =+E32*1.02 -> 9494.0528 | F33: =+$I$1 -> 0.75 | G33: =ROUNDUP(E33/F33,-1) -> 12660 | H33: =+G33*C33 -> 645660
A34: L02.2.3 | B34: In 2nd Floor Bathroom | C34: 51 | D34: Sqm | E34: =+E32*1.04 -> 9680.2107 | F34: =+$I$1 -> 0.75 | G34: =ROUNDUP(E34/F34,-1) -> 12910 | H34: =+G34*C34 -> 658410
A35: L02.2.4 | B35: In Terrace Floor Bathroom | C35: 20 | D35: Sqm | E35: =+E32*1.06 -> 9866.3686 | F35: =+$I$1 -> 0.75 | G35: =ROUNDUP(E35/F35,-1) -> 13160 | H35: =+G35*C35 -> 263200
A37: L03 | B37: LIVING & BEDROOM FLOOR TILE
A39: L03.1 | B39: Homogeneous Porcelain glazed floor tile 600mm x 600mm paving on 1:3 cement & sand bedding and pointed with tile grout to match the tile. (Prime Cost of tile Rs.500.00 per sqft)
A40: L03.1.1 | B40: In Ground Floor | C40: 123 | D40: Sqm | E40: =+'Rate Breakdowns'!G1267 -> 7973.3416 | F40: =+$I$1 -> 0.75 | G40: =ROUNDUP(E40/F40,-1) -> 10640 | H40: =+G40*C40 -> 1308720
A41: L03.1.2 | B41: In 1st Floor | C41: 113 | D41: Sqm | E41: =+E40*1.02 -> 8132.8085 | F41: =+$I$1 -> 0.75 | G41: =ROUNDUP(E41/F41,-1) -> 10850 | H41: =+G41*C41 -> 1226050
A42: L03.1.3 | B42: In 2nd Floor | C42: 113 | D42: Sqm | E42: =+E40*1.04 -> 8292.2753 | F42: =+$I$1 -> 0.75 | G42: =ROUNDUP(E42/F42,-1) -> 11060 | H42: =+G42*C42 -> 1249780
A43: L03.1.4 | B43: In Terrace Floor | C43: 0 | D43: Sqm | E43: =+E40*1.06 -> 8451.7421 | F43: =+$I$1 -> 0.75 | G43: =ROUNDUP(E43/F43,-1) -> 11270 | H43: =+G43*C43 -> 0
A45: L03.2 | B45: Supply and laying of 4" high skirting including tile grout to match the tile of tiling
A46: L03.2.1 | B46: In Ground Floor | C46: 96 | D46: L.m | E46: =+'Rate Breakdowns'!G1358 -> 998.104 | F46: =+$I$1 -> 0.75 | G46: =ROUNDUP(E46/F46,-1) -> 1340 | H46: =+G46*C46 -> 128640
A47: L03.2.2 | B47: In 1st Floor | C47: 106 | D47: L.m | E47: =+E46*1.02 -> 1018.0661 | F47: =+$I$1 -> 0.75 | G47: =ROUNDUP(E47/F47,-1) -> 1360 | H47: =+G47*C47 -> 144160
A48: L03.2.3 | B48: In 2nd Floor | C48: 106 | D48: L.m | E48: =+E46*1.04 -> 1038.0282 | F48: =+$I$1 -> 0.75 | G48: =ROUNDUP(E48/F48,-1) -> 1390 | H48: =+G48*C48 -> 147340
A49: L03.2.4 | B49: In Terrace Floor | C49: 80 | D49: L.m | E49: =+E46*1.06 -> 1057.9902 | F49: =+$I$1 -> 0.75 | G49: =ROUNDUP(E49/F49,-1) -> 1420 | H49: =+G49*C49 -> 113600
A52: L04 | B52: BALCONY FLOOR TILE
B78: FF2- Homogeneous Porcelain semi - glazed/matt wash room floor tile 300mm x 600mm paving on 1:3 cement & sand bedding and pointed with tile grout to match the tile.(Prime Cost of tile Rs.400.00 per sqft)
...

Sheet paint
A1: Nos | B1: Description | C1: Qty | D1: Unit | E1: COST | F1: OHP% | G1: Rate | H1: Amount | I1: =+summary!D14 -> 0.75
B2: M - COLOUR WASHING, PAINTING & POLISHING
B3: Method of application is accordiong to the manufacturer's method specifications
B5: Internal Emultion Paint
A6: M 01 | B6: Painting walls, columns, Revels with one coat of wall primer and two coats of emulsion paint including preparing surface.
A7: M1.1 | B7: In Ground floor | C7: 329 | D7: Sqm | E7: =+'Rate Breakdowns'!G1500 -> 967.07939 | F7: =+$I$1 -> 0.75 | G7: =ROUNDUP(E7/F7,-1) -> 1290 | H7: =+G7*C7 -> 424410
A8: M1.2 | B8: In First floor | C8: 451 | D8: Sqm | E8: =+E7*1.01 -> 976.75018 | F8: =+$I$1 -> 0.75 | G8: =ROUNDUP(E8/F8,-1) -> 1310 | H8: =+G8*C8 -> 590810
A9: M1.3 | B9: In Second Floor | C9: 451 | D9: Sqm | E9: =+E7*1.02 -> 986.42097 | F9: =+$I$1 -> 0.75 | G9: =ROUNDUP(E9/F9,-1) -> 1320 | H9: =+G9*C9 -> 595320
A10: M1.4 | B10: In Terrace Floor slab | C10: 187 | D10: Sqm | E10: =+E8*1.03 -> 1006.0527 | F10: =+$I$1 -> 0.75 | G10: =ROUNDUP(E10/F10,-1) -> 1350 | H10: =+G10*C10 -> 252450
A12: M 03 | B12: Painting soffit & Beams with one coat of wall primer and two coats of emulsion paint including preparing surface.
A13: M3.2 | B13: In First floor slab | C13: 172 | D13: Sqm | E13: =+'Rate Breakdowns'!G1549 -> 741.87137 | F13: =+$I$1 -> 0.75 | G13: =ROUNDUP(E13/F13,-1) -> 990 | H13: =+G13*C13 -> 170280
A14: M3.3 | B14: In Second Floor slab | C14: 172 | D14: Sqm | E14: =+E13*1.01 -> 749.29008 | F14: =+$I$1 -> 0.75 | G14: =ROUNDUP(E14/F14,-1) -> 1000 | H14: =+G14*C14 -> 172000
A15: M3.4 | B15: In Terrace Floor slab | C15: 140 | D15: Sqm | E15: =+E14*1.02 -> 764.27588 | F15: =+$I$1 -> 0.75 | G15: =ROUNDUP(E15/F15,-1) -> 1020 | H15: =+G15*C15 -> 142800
A16: M3.5 | B16: Roof Flab slab | C16: 53 | D16: Sqm | E16: =+E15*1.03 -> 787.20416 | F16: =+$I$1 -> 0.75 | G16: =ROUNDUP(E16/F16,-1) -> 1050 | H16: =+G16*C16 -> 55650
B18: Exterior Emultion Paint
A19: M 04 | B19: Painting walls,slab and revels with one coat of Exterior wall primer and two coats of weathershield weatherproof acrylic exterior emultion paint including preparing surface. including preparing surface for exterior application before applicatin of emulsion paint.
A20: M4.1 | B20: In Ground floor | C20: 182 | D20: Sqm | E20: =+'Rate Breakdowns'!G1581 -> 1719.3864 | F20: =+$I$1 -> 0.75 | G20: =ROUNDUP(E20/F20,-1) -> 2300 | H20: =+G20*C20 -> 418600
A21: M4.2 | B21: In First floor | C21: 207 | D21: Sqm | E21: =+E20*1.02 -> 1753.7742 | F21: =+$I$1 -> 0.75 | G21: =ROUNDUP(E21/F21,-1) -> 2340 | H21: =+G21*C21 -> 484380
A22: M4.3 | B22: In Second Floor | C22: 207 | D22: Sqm | E22: =+E20*1.04 -> 1788.1619 | F22: =+$I$1 -> 0.75 | G22: =ROUNDUP(E22/F22,-1) -> 2390 | H22: =+G22*C22 -> 494730
A23: M4.4 | B23: In Terrace Floor | C23: 111 | D23: Sqm | E23: =+E20*1.06 -> 1822.5496 | F23: =+$I$1 -> 0.75 | G23: =ROUNDUP(E23/F23,-1) -> 2440 | H23: =+G23*C23 -> 270840
B26: COLOUR WASHING, PAINTING & POLISHING WORK CARRIED TO COLLECTION | H26: =SUM(H4:H25) -> 4072270

Sheet plumbing 
A1: Nos | B1: Description | C1: Qty | D1: Unit | E1: COST | F1: OHP% | G1: Rate | H1: Amount | I1: 0.75
B2: S - PLUMBING AND DRAINAGE WORK
B3: S - SANITARY FITTINGS
B6: Disable Fittings & Accessories
A7: S 01 | B7: Supply and fix ceramic wall hung wash basin for disabled of "Vitra" brand, Model No.6147 with Plush Lock waste & overflow & Bottle Trap Chrome plated or approved equivalent.(Prime cost of the wash basin is Rs.45,000.00) | D7: Nr
A9: S 02 | B9: Supply and fix Disable Water Closet "Vitra" brand-Model No.6927 with seat cover & water tank or approved equivalent complete to working order.(Prime cost of is Rs.65,000.00) | D9: Nr
A11: S 03 | B11: Supply and fix Chromium plated single level wash basin mixer tap without pop-up waste with connection flex of "cobra" brand or approved equivalent with 5 year written warranty from the authorized agent.(Prime cost of is Rs.25,000.00) | D11: Nr
A13: S 04 | B13: Supply and fix Heavy duty Straight grab bar for disabled of "J&T" brand,model "GB029" or approved equivalent.(Prime cost of is Rs.10,000.00) | D13: Nr
A16: S 01 | B16: Supply and fix white vitreous china (vc) floor standing wash basin and pedestal with overflow hole and single tap hole in center of "Rocell" brand or approved equivalent complete to working order inclusive of the 1 1/4" chromium plated waste outlet of "Rocell" brand or approved equivalent and 1 1/4" chromium plated siphon cleanable bottle trap of "Rocell" brand or approved equivalent. (Prime cost of the floor standing wash basin and pedestal is Rs.20,185.00)
B17: Ground Floor | D17: Nr
B18: Third Floor | D18: Nr
B19: Fourth Floor | D19: Nr
A21: S 01 | B21: Supply and fix white vitreous china (vc) floor standing Vanity wash basin with overflow hole and single tap hole in center of "Rocell" brand or approved equivalent complete to working order inclusive of the 1 1/4" chromium plated waste outlet of "Rocell" brand or approved equivalent and 1 1/4" chromium plated siphon cleanable bottle trap of "Rocell" brand or approved equivalent. (Prime cost of the floor standing wash basin is Rs.45,000.00)
B22: In Ground floor | C22: 1 | D22: Nr | E22: =45000+6500 -> 51500 | F22: =+$I$1 -> 0.75 | G22: =ROUNDUP(E22/F22,-1) -> 68670 | H22: =+G22*C22 -> 68670
B23: In 1st floor | C23: 3 | D23: Nr | E23: =+E22*1.02 -> 52530 | F23: =+$I$1 -> 0.75 | G23: =ROUNDUP(E23/F23,-1) -> 70040 | H23: =+G23*C23 -> 210120
B24: In 2nd Floor | C24: 3 | D24: Nr | E24: =+E22*1.04 -> 53560 | F24: =+$I$1 -> 0.75 | G24: =ROUNDUP(E24/F24,-1) -> 71420 | H24: =+G24*C24 -> 214260
B25: Terrace Floor | C25: 1 | D25: Nr | E25: =+E22*1.06 -> 54590 | F25: =+$I$1 -> 0.75 | G25: =ROUNDUP(E25/F25,-1) -> 72790 | H25: =+G25*C25 -> 72790
A27: S 02 | B27: Supply and fix white vitreous china (vc) floor standing close coupled semi . back to wall water closet suite with wash down flushing with 6/3 liters dual flushing has horizontal outlet with vario drain bend and two lateral holes for bottom water connection , P trap, cistern with water inlet from rear of "Rocell" brand or approved equivalent complete to working order inclusive of universal bend of "Rocell" brand. (Prime cost of the water closet, tank and seat cover is Rs.55,000.00)
B28: In Ground floor | C28: 1 | D28: Nr | E28: =55000+7000 -> 62000 | F28: =+$I$1 -> 0.75 | G28: =ROUNDUP(E28/F28,-1) -> 82670 | H28: =+G28*C28 -> 82670
B29: In 1st floor | C29: 3 | D29: Nr | E29: =+E28*1.02 -> 63240 | F29: =+$I$1 -> 0.75 | G29: =ROUNDUP(E29/F29,-1) -> 84320 | H29: =+G29*C29 -> 252960
B30: In 2nd Floor | C30: 3 | D30: Nr | E30: =+E28*1.04 -> 64480 | F30: =+$I$1 -> 0.75 | G30: =ROUNDUP(E30/F30,-1) -> 85980 | H30: =+G30*C30 -> 257940
B31: Terrace Floor | C31: 1 | D31: Nr | E31: =+E28*1.06 -> 65720 | F31: =+$I$1 -> 0.75 | G31: =ROUNDUP(E31/F31,-1) -> 87630 | H31: =+G31*C31 -> 87630
A33: S 06 | B33: Supply and fix Urinal with sensor type "Rocell " brand or approved equivalent complete to working order. (Prime cost of the Urinal is Rs. 77,130.00)
B34: Fouth Floor | D34: Nr
A36: S 03 | B36: Supply and fix Chromium plated 1/2" dia. angle valve of "Rocell" brand . model or approved equivalent. (Prime cost of the Chromium plated 1/2" dia. angle valve is Rs. 2,500.00)
B37: In Ground floor | C37: 1 | D37: Nr | E37: =2500+300 -> 2800 | F37: =+$I$1 -> 0.75 | G37: =ROUNDUP(E37/F37,-1) -> 3740 | H37: =+G37*C37 -> 3740
B38: In 1st floor | C38: 3 | D38: Nr | E38: =2500+300 -> 2800 | F38: =+$I$1 -> 0.75 | G38: =ROUNDUP(E38/F38,-1) -> 3740 | H38: =+G38*C38 -> 11220
B39: In 2nd Floor | C39: 3 | D39: Nr | E39: =2500+300 -> 2800 | F39: =+$I$1 -> 0.75 | G39: =ROUNDUP(E39/F39,-1) -> 3740 | H39: =+G39*C39 -> 11220
B40: Terrace Floor | C40: 1 | D40: Nr | E40: =2500+300 -> 2800 | F40: =+$I$1 -> 0.75 | G40: =ROUNDUP(E40/F40,-1) -> 3740 | H40: =+G40*C40 -> 3740
A43: S 04 | B43: Supply and fix Chromium plated 1 1/4" chromium plated push type waste outlet of "Rocell" brand or approved equivalent. (Prime cost of the Chromium plated 1 1/4" chromium plated waste outlet is Rs. 2,500.00)
B44: In Ground floor | C44: 1 | D44: Nr | E44: =2500+350 -> 2850 | F44: =+$I$1 -> 0.75 | G44: =ROUNDUP(E44/F44,-1) -> 3800 | H44: =+G44*C44 -> 3800
B45: In 1st floor | C45: 3 | D45: Nr | E45: =+E44 -> 2850 | F45: =+$I$1 -> 0.75 | G45: =ROUNDUP(E45/F45,-1) -> 3800 | H45: =+G45*C45 -> 11400
B46: In 2nd Floor | C46: 3 | D46: Nr | E46: =+E44 -> 2850 | F46: =+$I$1 -> 0.75 | G46: =ROUNDUP(E46/F46,-1) -> 3800 | H46: =+G46*C46 -> 11400
B47: Terrace Floor | C47: 1 | D47: Nr | E47: =+E44 -> 2850 | F47: =+$I$1 -> 0.75 | G47: =ROUNDUP(E47/F47,-1) -> 3800 | H47: =+G47*C47 -> 3800
A50: S 05 | B50: Supply and fix Chromium plated 1/2" dia. 36" long flexible horse of "Rocell" brand or approved equivalent. (Prime cost of the Chromium plated 1/2" dia. 18" long flexible horse is Rs. 3,000.00)
B51: In Ground floor | C51: 1 | D51: Nr | E51: =3000+350 -> 3350 | F51: =+$I$1 -> 0.75 | G51: =ROUNDUP(E51/F51,-1) -> 4470 | H51: =+G51*C51 -> 4470
B52: In 1st floor | C52: 3 | D52: Nr | E52: =+E51 -> 3350 | F52: =+$I$1 -> 0.75 | G52: =ROUNDUP(E52/F52,-1) -> 4470 | H52: =+G52*C52 -> 13410
B53: In 2nd Floor | C53: 3 | D53: Nr | E53: =+E51 -> 3350 | F53: =+$I$1 -> 0.75 | G53: =ROUNDUP(E53/F53,-1) -> 4470 | H53: =+G53*C53 -> 13410
B54: Terrace Floor | C54: 1 | D54: Nr | E54: =+E51 -> 3350 | F54: =+$I$1 -> 0.75 | G54: =ROUNDUP(E54/F54,-1) -> 4470 | H54: =+G54*C54 -> 4470
A57: S 06 | B57: Supply and fix Chromium plated 1/2" dia. 15" long flexible horse of "Rocell" brand or approved equivalent. (Prime cost of the Chromium plated 1/2" dia. 12" long flexible horse is Rs. 2,500.00)
...

Sheet electicle 
A1: Nos | B1: Description | C1: Qty | D1: Unit | E1: COST | F1: OHP% | G1: Rate | H1: Amount | I1: =+summary!D16 -> 0.75
B2: V - ELECTRICAL INSTALLATION.
A4: V01 | B4: Testing
A6: V01.01 | B6: Testing of the electrical installation and submission of certificate from a chartered Electrical Engineer registered at CEB. | C6: 1 | D6: Item | E6: 30000 | F6: =+$I$1 -> 0.75 | G6: =ROUNDUP(E6/F6,-1) -> 40000 | H6: =+G6*C6 -> 40000
A8: V01.02 | B8: Charges for verifying the wiring done with meggar test & continuity test before commensing installation of Distribution Board & Electrical Fittings. | C8: 1 | D8: Item | E8: 45000 | F8: =+$I$1 -> 0.75 | G8: =ROUNDUP(E8/F8,-1) -> 60000 | H8: =+G8*C8 -> 60000
A10: V02 | B10: Main Cabling System
B12: Main cables for sub distribution boards of each floor shall be tapped from the bus bar riser
A14: V02.01 | B14: Supply, installation & termination of main cable from CEB supply to MDB | C14: 1 | D14: Item | E14: 52000 | F14: =+$I$1 -> 0.75 | G14: =ROUNDUP(E14/F14,-1) -> 69340 | H14: =+G14*C14 -> 69340
A16: V02.02 | B16: Supply, installation & termination of from MDB to DB-Lifts | D16: Item
A18: V02.03 | B18: Supply, installation & termination of from MDB to each DBs. | C18: 1 | D18: Item | E18: 43000 | F18: =+$I$1 -> 0.75 | G18: =ROUNDUP(E18/F18,-1) -> 57340 | H18: =+G18*C18 -> 57340
A20: V03 | B20: Main Distribution Board and SUB Distribution Boards and Isolators
B22: Supply and Installation of Power Distribution Panels
A23: V03.01 | B23: MDB
B24: 02 Nos 4P 63A MCCB /(10kA), 04 Nos 2P 32A MCB /(10kA),01 Nos 125A 4P Automatic Chainge over,01 Nos 40A 4P MCCB, 07 Nos 40A 4P MCCB, 07 Nos 40A 4P 30mA RCCB, 01 Nos 40A 2P 30mA RCCB,and nessasary bus bar and protective system and Cables Lugs and other suppotive meterials | C24: 3 | D24: Nos | F24: =+$I$1 -> 0.75 | G24: =ROUNDUP(E24/F24,-1) -> 0 | H24: =+G24*C24 -> 0
B25: 1 set of LED Phase indicator lamps c/w 3 x 2A fuse | F25: =+$I$1 -> 0.75 | G25: =ROUNDUP(E25/F25,-1) -> 0 | H25: =+G25*C25 -> 0
B26: Supply and mounted (LED Phase indicator lamps ) Wall/Surface mounted Powder Coated Steel Enclosure with lockable doors ,cover plate & internal wiring c/w bus bars and Accessories.(Rate to include necessary MCCB,MCB,RCCB,and other necessary fixturesand Other required supportive materials should include ) The contractor shoud take advise an electricle engineer before undataking the work. | E26: =94000+15000 -> 109000 | F26: =+$I$1 -> 0.75 | G26: =ROUNDUP(E26/F26,-1) -> 145340 | H26: =+G26*C24 -> 436020
B27: Surface mounted Powder Coated Steel Enclosure with lockable doors ,cover plate & internal wiring c/w bus bars and Accessories.
A28: V03.02 | B28: DB
B29: 01 No. 4P 63A MCCB (16kA Breaking capacity), 01 No. 4P 40A MCCB (16kA Breaking capacity),01 No. 2P 32A, MCB (16kA Breaking capacity),02 Nos. 1P 10A MCB (6kA Breaking capacity),02 Nos. 1P 20A MCB (6kA Breaking capacity),01 No. 2P 40A, 30mA RCCB, and nessasary bus bar and protective system and Cables Lugs and other suppotive meterials1 | C29: 2 | D29: Nos | F29: =+$I$1 -> 0.75 | G29: =ROUNDUP(E29/F29,-1) -> 0 | H29: =+G29*C29 -> 0
B30: Supply and mounted LED phase indicator lamps powder coated steel encloser with lockble door, Wall mounted distribution board (3 nr of DB) & internal wiring c/w bus bars and Accessories.(Rate to include necessary MCCB,MCB,RCCB,and other necessary fixturesand Other required supportive materials should include ) The contractor shoud take advise an electricle engineer before undataking the work. | E30: =60000+9000 -> 69000 | F30: =+$I$1 -> 0.75 | G30: =ROUNDUP(E30/F30,-1) -> 92000 | H30: =+G30*C29 -> 184000
B31: Surface mounted Powder Coated Steel Enclosure with lockable doors ,cover plate & internal wiring c/w bus bars and Accessories.
A33: V03.03 | B33: DB- For Lift
B34: Supply and mounted LED phase indicator lamps powder coated steel encloser with lockble door, Wall mounted distribution board & internal wiring c/w bus bars and Accessories.(Rate to include necessary MCCB,MCB,RCCB,and other necessary fixturesand Other required supportive materials should include ) The contractor shoud take advise an electricle engineer before undataking the work | D34: P.S
B35: Surface mounted Powder Coated Steel Enclosure c/w bus bars and Accessories.
A37: V03.04 | B37: DB- For bank- 4 nr of DB
B38: Supply and mounted LED phase indicator lamps powder coated steel encloser with lockble door, Wall mounted distribution board (4 nr of DB) & internal wiring c/w bus bars and Accessories.(Rate to include necessary MCCB,MCB,RCCB,and other necessary fixturesand Other required supportive materials should include ) The contractor shoud take advise an electricle engineer before undataking the work | D38: P.S
B39: Surface mounted Powder Coated Steel Enclosure with lockable doors ,cover plate & internal wiring c/w bus bars and Accessories.
A41: V03.04 | B41: DBs For Shop
B42: Supply and mounted Wall mounted distribution board( 42 nr) & internal wiring c/w bus bars and Accessories.(Rate to include necessary MCCB,MCB,RCCB,and other necessary fixturesand Other required supportive materials should include ) The contractor shoud take advise an electricle engineer before undataking the work | D42: P.S
B43: Surface mounted Powder Coated Steel Enclosure with lockable doors ,cover plate & internal wiring c/w bus bars and Accessories.
A53: V03.05 | B53: DBs For Banks
A54: V04 | B54: Wiring for light points, ceiling fans, socket outlets
B56: SUB CIRCUIT & LIGHT POINT WIRING
A58: V04.1 | B58: Point wiring for socket outlets 13A - ( 16A Circuits) Supply, Installation & wiring of 13A power Socket Outlet, by using 2x1C 2.5mm^2 Cu /PVC/PVC Cable + 1C 2.5 mm^2 Cu/PVC Earth Cable (in radial circuit) through slab & wall in PVC conduits including PVC conduits, sunk box, junction box, outlet and complete with all other relevant accessories.
B59: For Ground Floor | C59: 25 | D59: nr | E59: 9000 | F59: =+$I$1 -> 0.75 | G59: =ROUNDUP(E59/F59,-1) -> 12000 | H59: =+G59*C59 -> 300000
B60: For 1st Floor | C60: 35 | D60: nr | E60: 9000 | F60: =+$I$1 -> 0.75 | G60: =ROUNDUP(E60/F60,-1) -> 12000 | H60: =+G60*C60 -> 420000
B61: For 2nd Floor | C61: 35 | D61: nr | E61: 9000 | F61: =+$I$1 -> 0.75 | G61: =ROUNDUP(E61/F61,-1) -> 12000 | H61: =+G61*C61 -> 420000
B62: For Terrace Floor | C62: 12 | D62: nr | E62: 9000 | F62: =+$I$1 -> 0.75 | G62: =ROUNDUP(E62/F62,-1) -> 12000 | H62: =+G62*C62 -> 144000
A64: V04.2 | B64: Light Point Wiring (10A Circuits)-indoor/outdoor Supply & Installation of light Point Wiring, by using 2x1C 1.5mm^2 Cu/PVC/PVC Cable + 1C 1.5 mm^2 Cu/PVC Earth Cable through slab & wall in PVC conduits including PVC conduits, sunk box, junction box, 10A PVC Switch and complete with all other relevant accessories.
B65: For Ground Floor | C65: 22 | D65: nr | E65: 7500 | F65: =+$I$1 -> 0.75 | G65: =ROUNDUP(E65/F65,-1) -> 10000 | H65: =+G65*C65 -> 220000
...

Sheet metal 
A1: Nos | B1: Description | C1: Qty | D1: Unit | E1: COST | F1: OHP% | G1: Rate | H1: Amount | I1: =+summary!D17 -> 0.85
B2: U - METAL WORK
A3: 1 | B3: Metal Ceiling
A4: =A3+0.01 -> 1.01 | B4: Supplying & Installing of 600mmx 600mm non perforated white metal sheet ceiling, supported by concealed type furring suspended system installed in a flat horizontal manner using furing bars clipped on to inter locking hot dipped GI main tees with clips, ciling to be susppended using GI 04mm thick hanger rods (Prime cost of 2'-0" x 2'-0" sheet is Rs.2,640.00)
B5: Ground Floor- banak area | D5: Sqr.
B7: Aluminium Panel Ceiling
A8: =A3+0.01 -> 1.01 | B8: Supplying & installing of suspended Aluminium Panel Ceiling in 600mm x 600 grid size reveal / bevel type using hot dipped GI pre –engineered inter - locking main tees (38mm x 14mm) and cross tees (25mm x 14mm) and wall angles expose areas finished with white baked enamel finish and suspended on 4 mm dia. adjustable hanger rods with spring clips. Ceiling panels will be Compton aluminium tiles 600mm x 600mm x 0.7mm (thickness) and complete to working order as per manufacture's specifications..
B9: Ground Floor- | D9: Sqm
A11: U.1 | B11: Hand Rail
B12: G.I Tube Hand Rail
A13: U.1.1 | B13: Staircase & Balcony handrail (6mm Tempered Glass / SS Box bar etc. )as per the design | C13: =42+42+3 -> 87 | D13: m | E13: =11500*3.28 -> 37720 | F13: =+$I$1 -> 0.85 | G13: =ROUNDUP(E13/F13,-1) -> 44380 | H13: =+G13*C13 -> 3861060 | J13: =3*3*610 -> 5490
A15: =A13+0.01 -> #VALUE! | B15: Powder coated perforated mesh Hand Rail
B16: Supplying, fabricating & fixing of perforated mesh hand rail upto 1.2m height 50mm dia 2.3mm thick G.I round bar upright @ 3000mm c/c as vertical members fixed bottom end to steps with the 150mm dia 8mm thick M.S. plate connecting with 4 nos of 8mm dia.anchor bolts and work complete in order. Rate Shall include for applying one coat of etch primer (50% of etch primer base and 50% etch primer activator),one coat of anti-corrosive primer with two coats of enamel paint. (Prime cost is Rs, 1,250.00 per sqft)
A18: 3 | B18: Partitions
A20: =A18+0.01 -> 3.01 | B20: Tempored Glass Partition
B21: P1 in 37.5mm x 25mm x 1.4mm thick hairline finished stainless steel 'U' channel framed work and 12mm thick tempered glass with printed PVC stickering fixed with silicon joints as per the detailed drawing and finishes as specified as per the drawings | D21: Sqr.
A23: =A20+0.01 -> 3.02 | B23: HPL Partition
B25: First Floor | D25: Sqm
A27: =A23+0.01 -> 3.03 | B27: Tempored fixed Glass
B28: 37.5mm x 25mm x 1.4mm thick hairline finished stainless steel 'U' channel framed work and 12mm thick tempered glass with printed PVC stickering fixed with silicon joints as per the detailed drawing and finishes as specified as per the drawings
B29: Second Floor | D29: Sqr.
A31: U.2 | B31: Doors
A33: U.2.1 | B33: Door type D1 size 1500mm x 2700mm Teak Timber Framed Solid Teak Timber Double door as per the detail drawings with all necessary iron mongaries with smart lock. (Smart Lock PC - 72,000.00 per unit)
B34: In Ground Floor | C34: 1 | D34: nr | E34: =6450*5*9+72000 -> 362250 | F34: =+$I$1 -> 0.85 | G34: =ROUNDUP(E34/F34,-1) -> 426180 | H34: =+G34*C34 -> 426180
A36: U.2.2 | B36: Door type D2 size 1000mm x 2400mm Teak Timber Framed Solid Teak Timber single slash door as per the detail drawings with all necessary iron mongaries
B37: In Ground Floor | C37: 2 | D37: nr | E37: =6150*26 -> 159900 | F37: =+$I$1 -> 0.85 | G37: =ROUNDUP(E37/F37,-1) -> 188120 | H37: =+G37*C37 -> 376240
B38: In 1st Floor | C38: 4 | D38: nr | E38: =+E37*1.01 -> 161499 | F38: =+$I$1 -> 0.85 | G38: =ROUNDUP(E38/F38,-1) -> 190000 | H38: =+G38*C38 -> 760000
B39: In 2nd Floor | C39: 4 | D39: nr | E39: =+E38*1.01 -> 163113.99 | F39: =+$I$1 -> 0.85 | G39: =ROUNDUP(E39/F39,-1) -> 191900 | H39: =+G39*C39 -> 767600
A41: U.2.3 | B41: Door type D3 size 825mm x 2400mm Teak Timber Framed Solid Teak Timber single slash door as per the detail drawings with all necessary iron mongaries
B42: In Ground Floor | C42: 3 | D42: nr | E42: =6150*22 -> 135300 | F42: =+$I$1 -> 0.85 | G42: =ROUNDUP(E42/F42,-1) -> 159180 | H42: =+G42*C42 -> 477540
B43: In 1st Floor | C43: 3 | D43: nr | E43: =+E42*1.01 -> 136653 | F43: =+$I$1 -> 0.85 | G43: =ROUNDUP(E43/F43,-1) -> 160770 | H43: =+G43*C43 -> 482310
B44: In 2nd Floor | C44: 3 | D44: nr | E44: =+E42*1.02 -> 138006 | F44: =+$I$1 -> 0.85 | G44: =ROUNDUP(E44/F44,-1) -> 162360 | H44: =+G44*C44 -> 487080
B45: In Terrace Floor | C45: 1 | D45: nr | E45: =+E42*1.03 -> 139359 | F45: =+$I$1 -> 0.85 | G45: =ROUNDUP(E45/F45,-1) -> 163960 | H45: =+G45*C45 -> 163960
A47: U.2.4 | B47: Door type D4 size 1000mm x 2700mm Teak Timber Framed Solid Teak Timber single slash door as per the detail drawings with all necessary iron mongaries
B48: In Ground Floor | C48: 2 | D48: nr | E48: =6150*29 -> 178350 | F48: =+$I$1 -> 0.85 | G48: =ROUNDUP(E48/F48,-1) -> 209830 | H48: =+G48*C48 -> 419660
B49: In Terrace Floor | C49: 1 | D49: nr | E49: =+E48*1.04 -> 185484 | F49: =+$I$1 -> 0.85 | G49: =ROUNDUP(E49/F49,-1) -> 218220 | H49: =+G49*C49 -> 218220
A51: U.2.5 | B51: Door type GD size 900mm x 2700mm Teak Timber Framed Solid Teak Timber single slash door as per the detail drawings with all necessary iron mongaries
B52: In Ground Floor | C52: 2 | D52: nr | E52: =6150*27 -> 166050 | F52: =+$I$1 -> 0.85 | G52: =ROUNDUP(E52/F52,-1) -> 195360 | H52: =+G52*C52 -> 390720
A54: U.3 | B54: Windows
A56: U.3.1 | B56: Window type W1 , size 4425mm x1800mm Powder coated aluminum glazed Sliding window, complete with all necessary ironmongeries and complete as per thedetail drawings.
...

Sheet waterprof
A1: Nos | B1: Description | C1: Qty | D1: Unit | E1: COST | F1: OHP% | G1: Rate | H1: Amount | I1: 0.85
B2: R - WATER PROOFING WORK
A3: R.1 | B3: Internal Wet Areas without Exposure to Sunlight Sq.ft. (Cementitious water proofing using Barralastic or approved equivalnt)
B5: Application of cementitious water proofing using Barralastic or approved equivalnt for internal wet areas such as toilet floors and walls (Walls Up to 1.60m) where the surfaces are not directly exposed to sunlight and weathering. Rate will include to cleaning the substrate and 1:3 cement sand bedding and all other work as per manufacturer's specifications on application and shall include ponding test for a 300mm water height kept for a period of 48 hours for horizontal surfaces. | J5: WITH ANGLE FILLET
A6: R.1.1 | B6: Ground Floor | C6: =4+17 -> 21 | D6: S.qm | E6: =+J6*10.76 -> 3550.8 | F6: =+$I$1 -> 0.85 | G6: =ROUNDUP(E6/F6,-1) -> 4180 | H6: =+G6*C6 -> 87780 | J6: =275*1.2 -> 330
